Workbook

Sheet Katy (Old) House Pay Off
B2: Purchase Price | C2: 303000
B3: Initial Loan Amt | C3: 190000
B4: Interest Rate | C4: 0.04125
A10: Years | B10: Months | D10: Payment | E10: Add. Payment | F10: Principal Balance Before Payment | G10: Principal Applied | H10: Interest Accrued | I10: Escrow | J10: Escrow Balance | K10: PMI | L10: Loan Balance | M10: % Loan Owed | N10: Property Taxes | O10: Home Owners Insurance
C11: 41553 | F11: =C3 -> 190000 | G11: 0 | J11: =I11 -> 0 | L11: =F11+H11+I11-D11-E11 -> 190000 | M11: =L11/$C$2 -> 0.62706271
A12: 1 | B12: 1 | C12: 42808 | D12: 1934.04 | F12: 177926 | G12: =D12-H12-I12 -> 309.20937 | H12: =F12*$C$4/12 -> 611.62063 | I12: 1013.21 | J12: =J11+I12 -> 1013.21 | L12: =F12+H12+I12-D12-E12 -> 177616.79 | M12: =L12/$C$2 -> 0.58619403
B13: =B12+1 -> 2 | C13: =C12+30.5 -> 42838.5 | D13: 1914 | F13: =L12 -> 177616.79 | G13: =D13-H13-I13 -> 290.23228 | H13: =F13*$C$4/12 -> 610.55772 | I13: 1013.21 | J13: =J12+I13-N13-K13 -> 2026.42 | L13: =F13+H13+I13-D13-E13 -> 177326.56 | M13: =L13/$C$2 -> 0.58523617
B14: =B13+1 -> 3 | C14: =C13+30.5 -> 42869 | D14: 1914 | F14: =L13 -> 177326.56 | G14: =D14-H14-I14 -> 291.22996 | H14: =F14*$C$4/12 -> 609.56004 | I14: 1013.21 | J14: =J13+I14-K14 -> 3039.63 | L14: =F14+H14+I14-D14-E14 -> 177035.33 | M14: =L14/$C$2 -> 0.58427501
B15: =B14+1 -> 4 | C15: =C14+30.5 -> 42899.5 | D15: 1914 | F15: =L14 -> 177035.33 | G15: =D15-H15-I15 -> 292.23106 | H15: =F15*$C$4/12 -> 608.55894 | I15: 1013.21 | J15: =J14+I15-K15 -> 4052.84 | L15: =F15+H15+I15-D15-E15 -> 176743.1 | M15: =L15/$C$2 -> 0.58331055
B16: =B15+1 -> 5 | C16: =C15+30.5 -> 42930 | D16: 1914 | F16: =L15 -> 176743.1 | G16: =D16-H16-I16 -> 293.2356 | H16: =F16*$C$4/12 -> 607.5544 | I16: 1013.21 | J16: =J15+I16-K16 -> 5066.05 | L16: =F16+H16+I16-D16-E16 -> 176449.86 | M16: =L16/$C$2 -> 0.58234278
B17: =B16+1 -> 6 | C17: =C16+30.5 -> 42960.5 | D17: 1914 | F17: =L16 -> 176449.86 | G17: =D17-H17-I17 -> 294.2436 | H17: =F17*$C$4/12 -> 606.5464 | I17: 1013.21 | J17: =J16+I17-K17 -> 6079.26 | L17: =F17+H17+I17-D17-E17 -> 176155.62 | M17: =L17/$C$2 -> 0.58137168
B18: =B17+1 -> 7 | C18: =C17+30.5 -> 42991 | D18: 1914 | F18: =L17 -> 176155.62 | G18: =D18-H18-I18 -> 295.25506 | H18: =F18*$C$4/12 -> 605.53494 | I18: 1013.21 | J18: =J17+I18-K18 -> 7092.47 | L18: =F18+H18+I18-D18-E18 -> 175860.36 | M18: =L18/$C$2 -> 0.58039724
B19: =B18+1 -> 8 | C19: =C18+30.5 -> 43021.5 | D19: 1914 | F19: =L18 -> 175860.36 | G19: =D19-H19-I19 -> 296.27 | H19: =F19*$C$4/12 -> 604.52 | I19: 1013.21 | J19: =J18+I19-K19 -> 8105.68 | L19: =F19+H19+I19-D19-E19 -> 175564.09 | M19: =L19/$C$2 -> 0.57941945
B20: =B19+1 -> 9 | C20: =C19+30.5 -> 43052 | D20: 1914 | F20: =L19 -> 175564.09 | G20: =D20-H20-I20 -> 297.28843 | H20: =F20*$C$4/12 -> 603.50157 | I20: 1013.21 | J20: =J19+I20-K20 -> 9118.89 | L20: =F20+H20+I20-D20-E20 -> 175266.8 | M20: =L20/$C$2 -> 0.5784383
B21: =B20+1 -> 10 | C21: =C20+30.5 -> 43082.5 | D21: 1914 | F21: =L20 -> 175266.8 | G21: =D21-H21-I21 -> 298.31036 | H21: =F21*$C$4/12 -> 602.47964 | I21: 1013.21 | J21: =J20+I21-K21 -> 10132.1 | L21: =F21+H21+I21-D21-E21 -> 174968.49 | M21: =L21/$C$2 -> 0.57745378
B22: =B21+1 -> 11 | C22: =C21+30.5 -> 43113 | D22: 1914 | F22: =L21 -> 174968.49 | G22: =D22-H22-I22 -> 299.3358 | H22: =F22*$C$4/12 -> 601.4542 | I22: 1013.21 | J22: =J21+I22-K22-O22 -> 11145.31 | L22: =F22+H22+I22-D22-E22 -> 174669.16 | M22: =L22/$C$2 -> 0.57646587
B23: =B22+1 -> 12 | C23: =C22+30.5 -> 43143.5 | D23: 1914 | F23: =L22 -> 174669.16 | G23: =D23-H23-I23 -> 300.36477 | H23: =F23*$C$4/12 -> 600.42523 | I23: 1013.21 | J23: =J22+I23-K23-5075.59 -> 7082.93 | L23: =F23+H23+I23-D23-E23 -> 174368.79 | M23: =L23/$C$2 -> 0.57547457
A24: 2 | B24: =B23+1 -> 13 | C24: =C23+30.5 -> 43174 | D24: 1914 | F24: =L23 -> 174368.79 | G24: =D24-H24-I24 -> 301.39727 | H24: =F24*$C$4/12 -> 599.39273 | I24: 1013.21 | J24: =J23+I24-K24 -> 8096.14 | L24: =F24+H24+I24-D24-E24 -> 174067.4 | M24: =L24/$C$2 -> 0.57447986
B25: =B24+1 -> 14 | C25: =C24+30.5 -> 43204.5 | D25: 1914 | F25: =L24 -> 174067.4 | G25: =D25-H25-I25 -> 302.43332 | H25: =F25*$C$4/12 -> 598.35668 | I25: 1013.21 | J25: =J24+I25-K25-N25 -> 9109.35 | L25: =F25+H25+I25-D25-E25 -> 173764.96 | M25: =L25/$C$2 -> 0.57348173
B26: =B25+1 -> 15 | C26: =C25+30.5 -> 43235 | D26: 1914 | F26: =L25 -> 173764.96 | G26: =D26-H26-I26 -> 303.47294 | H26: =F26*$C$4/12 -> 597.31706 | I26: 1013.21 | J26: =J25+I26-K26 -> 10122.56 | L26: =F26+H26+I26-D26-E26 -> 173461.49 | M26: =L26/$C$2 -> 0.57248017
B27: =B26+1 -> 16 | C27: =C26+30.5 -> 43265.5 | D27: 1914 | F27: =L26 -> 173461.49 | G27: =D27-H27-I27 -> 304.51613 | H27: =F27*$C$4/12 -> 596.27387 | I27: 1013.21 | J27: =J26+I27-K27 -> 11135.77 | L27: =F27+H27+I27-D27-E27 -> 173156.97 | M27: =L27/$C$2 -> 0.57147516
B28: =B27+1 -> 17 | C28: =C27+30.5 -> 43296 | D28: 1914 | F28: =L27 -> 173156.97 | G28: =D28-H28-I28 -> 305.5629 | H28: =F28*$C$4/12 -> 595.2271 | I28: 1013.21 | J28: =J27+I28-K28 -> 12148.98 | L28: =F28+H28+I28-D28-E28 -> 172851.41 | M28: =L28/$C$2 -> 0.5704667
B29: =B28+1 -> 18 | C29: =C28+30.5 -> 43326.5 | D29: 1914 | F29: =L28 -> 172851.41 | G29: =D29-H29-I29 -> 306.61327 | H29: =F29*$C$4/12 -> 594.17673 | I29: 1013.21 | J29: =J28+I29-K29 -> 13162.19 | L29: =F29+H29+I29-D29-E29 -> 172544.8 | M29: =L29/$C$2 -> 0.56945478
B30: =B29+1 -> 19 | C30: =C29+30.5 -> 43357 | D30: 1914 | F30: =L29 -> 172544.8 | G30: =D30-H30-I30 -> 307.66726 | H30: =F30*$C$4/12 -> 593.12274 | I30: 1013.21 | J30: =J29+I30-K30 -> 14175.4 | L30: =F30+H30+I30-D30-E30 -> 172237.13 | M30: =L30/$C$2 -> 0.56843937
B31: =B30+1 -> 20 | C31: =C30+30.5 -> 43387.5 | D31: 1914 | F31: =L30 -> 172237.13 | G31: =D31-H31-I31 -> 308.72486 | H31: =F31*$C$4/12 -> 592.06514 | I31: 1013.21 | J31: =J30+I31-K31 -> 15188.61 | L31: =F31+H31+I31-D31-E31 -> 171928.41 | M31: =L31/$C$2 -> 0.56742048
B32: =B31+1 -> 21 | C32: =C31+30.5 -> 43418 | D32: 1914 | F32: =L31 -> 171928.41 | G32: =D32-H32-I32 -> 309.78611 | H32: =F32*$C$4/12 -> 591.00389 | I32: 1013.21 | J32: =J31+I32-K32 -> 16201.82 | L32: =F32+H32+I32-D32-E32 -> 171618.62 | M32: =L32/$C$2 -> 0.56639808
B33: =B32+1 -> 22 | C33: =C32+30.5 -> 43448.5 | D33: 1914 | F33: =L32 -> 171618.62 | G33: =D33-H33-I33 -> 310.85099 | H33: =F33*$C$4/12 -> 589.93901 | I33: 1013.21 | J33: =J32+I33-K33 -> 17215.03 | L33: =F33+H33+I33-D33-E33 -> 171307.77 | M33: =L33/$C$2 -> 0.56537217
B34: =B33+1 -> 23 | C34: =C33+30.5 -> 43479 | D34: 1914 | F34: =L33 -> 171307.77 | G34: =D34-H34-I34 -> 311.91955 | H34: =F34*$C$4/12 -> 588.87045 | I34: 1013.21 | J34: =J33+I34-K34-O34 -> 18228.24 | L34: =F34+H34+I34-D34-E34 -> 170995.85 | M34: =L34/$C$2 -> 0.56434274
B35: =B34+1 -> 24 | C35: =C34+30.5 -> 43509.5 | D35: 1914 | F35: =L34 -> 170995.85 | G35: =D35-H35-I35 -> 312.99177 | H35: =F35*$C$4/12 -> 587.79823 | I35: 1013.21 | J35: =J34+I35-K35 -> 19241.45 | L35: =F35+H35+I35-D35-E35 -> 170682.86 | M35: =L35/$C$2 -> 0.56330976
A36: 3 | B36: =B35+1 -> 25 | C36: =C35+30.5 -> 43540 | D36: 1914 | F36: =L35 -> 170682.86 | G36: =D36-H36-I36 -> 314.06768 | H36: =F36*$C$4/12 -> 586.72232 | I36: 1013.21 | J36: =J35+I36-K36 -> 20254.66 | L36: =F36+H36+I36-D36-E36 -> 170368.79 | M36: =L36/$C$2 -> 0.56227323
B37: =B36+1 -> 26 | C37: =C36+30.5 -> 43570.5 | D37: 1914 | F37: =L36 -> 170368.79 | G37: =D37-H37-I37 -> 315.14729 | H37: =F37*$C$4/12 -> 585.64271 | I37: 1013.21 | J37: =J36+I37-K37-N37 -> 21267.87 | L37: =F37+H37+I37-D37-E37 -> 170053.64 | M37: =L37/$C$2 -> 0.56123314
B38: =B37+1 -> 27 | C38: =C37+30.5 -> 43601 | D38: 1914 | F38: =L37 -> 170053.64 | G38: =D38-H38-I38 -> 316.2306 | H38: =F38*$C$4/12 -> 584.5594 | I38: 1013.21 | J38: =J37+I38-K38 -> 22281.08 | L38: =F38+H38+I38-D38-E38 -> 169737.41 | M38: =L38/$C$2 -> 0.56018948
B39: =B38+1 -> 28 | C39: =C38+30.5 -> 43631.5 | D39: 1914 | F39: =L38 -> 169737.41 | G39: =D39-H39-I39 -> 317.31765 | H39: =F39*$C$4/12 -> 583.47235 | I39: 1013.21 | J39: =J38+I39-K39 -> 23294.29 | L39: =F39+H39+I39-D39-E39 -> 169420.09 | M39: =L39/$C$2 -> 0.55914222
B40: =B39+1 -> 29 | C40: =C39+30.5 -> 43662 | D40: 1914 | F40: =L39 -> 169420.09 | G40: =D40-H40-I40 -> 318.40843 | H40: =F40*$C$4/12 -> 582.38157 | I40: 1013.21 | J40: =J39+I40-K40 -> 24307.5 | L40: =F40+H40+I40-D40-E40 -> 169101.69 | M40: =L40/$C$2 -> 0.55809137
B41: =B40+1 -> 30 | C41: =C40+30.5 -> 43692.5 | D41: 1914 | F41: =L40 -> 169101.69 | G41: =D41-H41-I41 -> 319.50296 | H41: =F41*$C$4/12 -> 581.28704 | I41: 1013.21 | J41: =J40+I41-K41 -> 25320.71 | L41: =F41+H41+I41-D41-E41 -> 168782.18 | M41: =L41/$C$2 -> 0.55703691
B42: =B41+1 -> 31 | C42: =C41+30.5 -> 43723 | D42: 1914 | F42: =L41 -> 168782.18 | G42: =D42-H42-I42 -> 320.60125 | H42: =F42*$C$4/12 -> 580.18875 | I42: 1013.21 | J42: =J41+I42-K42 -> 26333.92 | L42: =F42+H42+I42-D42-E42 -> 168461.58 | M42: =L42/$C$2 -> 0.55597882
B43: =B42+1 -> 32 | C43: =C42+30.5 -> 43753.5 | D43: 1914 | F43: =L42 -> 168461.58 | G43: =D43-H43-I43 -> 321.70331 | H43: =F43*$C$4/12 -> 579.08669 | I43: 1013.21 | J43: =J42+I43-K43 -> 27347.13 | L43: =F43+H43+I43-D43-E43 -> 168139.88 | M43: =L43/$C$2 -> 0.55491709
B44: =B43+1 -> 33 | C44: =C43+30.5 -> 43784 | D44: 1914 | F44: =L43 -> 168139.88 | G44: =D44-H44-I44 -> 322.80917 | H44: =F44*$C$4/12 -> 577.98083 | I44: 1013.21 | J44: =J43+I44-K44 -> 28360.34 | L44: =F44+H44+I44-D44-E44 -> 167817.07 | M44: =L44/$C$2 -> 0.55385171
B45: =B44+1 -> 34 | C45: =C44+30.5 -> 43814.5 | D45: 1914 | F45: =L44 -> 167817.07 | G45: =D45-H45-I45 -> 323.91883 | H45: =F45*$C$4/12 -> 576.87117 | I45: 1013.21 | J45: =J44+I45-K45 -> 29373.55 | L45: =F45+H45+I45-D45-E45 -> 167493.15 | M45: =L45/$C$2 -> 0.55278267
B46: =B45+1 -> 35 | C46: =C45+30.5 -> 43845 | D46: 1914 | F46: =L45 -> 167493.15 | G46: =D46-H46-I46 -> 325.0323 | H46: =F46*$C$4/12 -> 575.7577 | I46: 1013.21 | J46: =J45+I46-K46-O46 -> 30386.76 | L46: =F46+H46+I46-D46-E46 -> 167168.12 | M46: =L46/$C$2 -> 0.55170996
...

Sheet Jordan IRA Projection
B2: Interest Rate | D2: 0.08 | F2: End=Present*(1+(interest rate/number compoundings per year))^(compoundings per year * years)
B3: Monthly Contribution | D3: 0
B4: Average cost per year | D4: 25000
B5: Compounding Quarterly | D5: 4
B6: Years til College | D6: 1
A8: Date Updated | B8: Year | C8: Age | D8: Start | E8: Contributions | F8: Payment | G8: Earnings | H8: Jordan IRA End | I8: Actual
B9: 1 | C9: 26 | D9: 17278 | E9: 0 | F9: 0 | G9: =D9*(1+($D$2/$D$5))^($D$5*$D$6)-D9 -> 1424.2629 | H9: =G9+E9+D9 -> 18702.263
B10: =B9+1 -> 2 | C10: =C9+1 -> 27 | D10: =H9 -> 18702.263 | E10: 5500 | F10: 0 | G10: =D10*(1+($D$2/$D$5))^($D$5*$D$6)-D10 -> 1541.6679 | H10: =G10+E10+D10 -> 25743.931
B11: =B10+1 -> 3 | C11: =C10+1 -> 28 | D11: =H10 -> 25743.931 | E11: 5500 | F11: 0 | G11: =D11*(1+($D$2/$D$5))^($D$5*$D$6)-D11 -> 2122.1278 | H11: =G11+E11+D11 -> 33366.059
B12: =B11+1 -> 4 | C12: =C11+1 -> 29 | D12: =H11 -> 33366.059 | E12: 5500 | F12: 0 | G12: =D12*(1+($D$2/$D$5))^($D$5*$D$6)-D12 -> 2750.4363 | H12: =G12+E12+D12 -> 41616.495
B13: =B12+1 -> 5 | C13: =C12+1 -> 30 | D13: =H12 -> 41616.495 | E13: =$D$3*12 -> 0 | F13: 0 | G13: =D13*(1+($D$2/$D$5))^($D$5*$D$6)-D13 -> 3430.5376 | H13: =G13+E13+D13 -> 45047.032
B14: =B13+1 -> 6 | C14: =C13+1 -> 31 | D14: =H13 -> 45047.032 | E14: =$D$3*12 -> 0 | F14: 0 | G14: =D14*(1+($D$2/$D$5))^($D$5*$D$6)-D14 -> 3713.3242 | H14: =G14+E14+D14 -> 48760.357 | I14: 48372
B15: =B14+1 -> 7 | C15: =C14+1 -> 32 | D15: =H14 -> 48760.357 | E15: =$D$3*12 -> 0 | F15: 0 | G15: =D15*(1+($D$2/$D$5))^($D$5*$D$6)-D15 -> 4019.4215 | H15: =G15+E15+D15 -> 52779.778 | I15: 56495 | J15: =I15/I14-1 -> 0.16792773
B16: =B15+1 -> 8 | C16: =C15+1 -> 33 | D16: =H15 -> 52779.778 | E16: =$D$3*12 -> 0 | F16: 0 | G16: =D16*(1+($D$2/$D$5))^($D$5*$D$6)-D16 -> 4350.7511 | H16: =G16+E16+D16 -> 57130.529 | I16: 65709 | J16: =I16/I15-1 -> 0.16309408
B17: =B16+1 -> 9 | C17: =C16+1 -> 34 | D17: =H16 -> 57130.529 | E17: =$D$3*12 -> 0 | F17: 0 | G17: =D17*(1+($D$2/$D$5))^($D$5*$D$6)-D17 -> 4709.3929 | H17: =G17+E17+D17 -> 61839.922
B18: =B17+1 -> 10 | C18: =C17+1 -> 35 | D18: =H17 -> 61839.922 | E18: =$D$3*12 -> 0 | F18: 0 | G18: =D18*(1+($D$2/$D$5))^($D$5*$D$6)-D18 -> 5097.5984 | H18: =G18+E18+D18 -> 66937.521
B19: =B18+1 -> 11 | C19: =C18+1 -> 36 | D19: =H18 -> 66937.521 | E19: =$D$3*12 -> 0 | F19: 0 | G19: =D19*(1+($D$2/$D$5))^($D$5*$D$6)-D19 -> 5517.8044 | H19: =G19+E19+D19 -> 72455.325
B20: =B19+1 -> 12 | C20: =C19+1 -> 37 | D20: =H19 -> 72455.325 | E20: =$D$3*12 -> 0 | F20: 0 | G20: =D20*(1+($D$2/$D$5))^($D$5*$D$6)-D20 -> 5972.6489 | H20: =G20+E20+D20 -> 78427.974
B21: =B20+1 -> 13 | C21: =C20+1 -> 38 | D21: =H20 -> 78427.974 | E21: =$D$3*12 -> 0 | F21: 0 | G21: =D21*(1+($D$2/$D$5))^($D$5*$D$6)-D21 -> 6464.9873 | H21: =G21+E21+D21 -> 84892.961
B22: =B21+1 -> 14 | C22: =C21+1 -> 39 | D22: =H21 -> 84892.961 | E22: =$D$3*12 -> 0 | F22: 0 | G22: =D22*(1+($D$2/$D$5))^($D$5*$D$6)-D22 -> 6997.9102 | H22: =G22+E22+D22 -> 91890.871
B23: =B22+1 -> 15 | C23: =C22+1 -> 40 | D23: =H22 -> 91890.871 | E23: =$D$3*12 -> 0 | F23: 0 | G23: =D23*(1+($D$2/$D$5))^($D$5*$D$6)-D23 -> 7574.763 | H23: =G23+E23+D23 -> 99465.634
B24: =B23+1 -> 16 | C24: =C23+1 -> 41 | D24: =H23 -> 99465.634 | E24: =$D$3*12 -> 0 | F24: 0 | G24: =D24*(1+($D$2/$D$5))^($D$5*$D$6)-D24 -> 8199.1671 | H24: =G24+E24+D24 -> 107664.8
B25: =B24+1 -> 17 | C25: =C24+1 -> 42 | D25: =H24 -> 107664.8 | E25: =$D$3*12 -> 0 | F25: 0 | G25: =D25*(1+($D$2/$D$5))^($D$5*$D$6)-D25 -> 8875.0421 | H25: =G25+E25+D25 -> 116539.84
B26: =B25+1 -> 18 | C26: =C25+1 -> 43 | D26: =H25 -> 116539.84 | E26: =$D$3*12 -> 0 | F26: 0 | G26: =D26*(1+($D$2/$D$5))^($D$5*$D$6)-D26 -> 9606.631 | H26: =G26+E26+D26 -> 126146.47
B27: =B26+1 -> 19 | C27: =C26+1 -> 44 | D27: =H26 -> 126146.47 | E27: =$D$3*12 -> 0 | F27: 0 | G27: =D27*(1+($D$2/$D$5))^($D$5*$D$6)-D27 -> 10398.526 | H27: =G27+E27+D27-F27 -> 136545
B28: =B27+1 -> 20 | C28: =C27+1 -> 45 | D28: =H27 -> 136545 | E28: =$D$3*12 -> 0 | F28: 0 | G28: =D28*(1+($D$2/$D$5))^($D$5*$D$6)-D28 -> 11255.699 | H28: =G28+E28+D28-F28 -> 147800.7
B29: =B28+1 -> 21 | C29: =C28+1 -> 46 | D29: =H28 -> 147800.7 | E29: =$D$3*12 -> 0 | F29: 0 | G29: =D29*(1+($D$2/$D$5))^($D$5*$D$6)-D29 -> 12183.531 | H29: =G29+E29+D29-F29 -> 159984.23
B30: =B29+1 -> 22 | C30: =C29+1 -> 47 | D30: =H29 -> 159984.23 | E30: =$D$3*12 -> 0 | F30: 0 | G30: =D30*(1+($D$2/$D$5))^($D$5*$D$6)-D30 -> 13187.846 | H30: =G30+E30+D30-F30 -> 173172.08
B31: =B30+1 -> 23 | C31: =C30+1 -> 48 | D31: =H30 -> 173172.08 | E31: =$D$3*12 -> 0 | F31: 0 | G31: =D31*(1+($D$2/$D$5))^($D$5*$D$6)-D31 -> 14274.948 | H31: =G31+E31+D31-F31 -> 187447.03
B32: =B31+1 -> 24 | C32: =C31+1 -> 49 | D32: =H31 -> 187447.03 | E32: =$D$3*12 -> 0 | F32: 0 | G32: =D32*(1+($D$2/$D$5))^($D$5*$D$6)-D32 -> 15451.663 | H32: =G32+E32+D32-F32 -> 202898.69
B33: =B32+1 -> 25 | C33: =C32+1 -> 50 | D33: =H32 -> 202898.69 | E33: =$D$3*12 -> 0 | F33: 0 | G33: =D33*(1+($D$2/$D$5))^($D$5*$D$6)-D33 -> 16725.377 | H33: =G33+E33+D33-F33 -> 219624.07
B34: =B33+1 -> 26 | C34: =C33+1 -> 51 | D34: =H33 -> 219624.07 | E34: =$D$3*12 -> 0 | F34: 0 | G34: =D34*(1+($D$2/$D$5))^($D$5*$D$6)-D34 -> 18104.086 | H34: =G34+E34+D34-F34 -> 237728.15
B35: =B34+1 -> 27 | C35: =C34+1 -> 52 | D35: =H34 -> 237728.15 | E35: =$D$3*12 -> 0 | F35: 0 | G35: =D35*(1+($D$2/$D$5))^($D$5*$D$6)-D35 -> 19596.445 | H35: =G35+E35+D35-F35 -> 257324.6
B36: =B35+1 -> 28 | C36: =C35+1 -> 53 | D36: =H35 -> 257324.6 | E36: =$D$3*12 -> 0 | F36: 0 | G36: =D36*(1+($D$2/$D$5))^($D$5*$D$6)-D36 -> 21211.822 | H36: =G36+E36+D36-F36 -> 278536.42
B37: =B36+1 -> 29 | C37: =C36+1 -> 54 | D37: =H36 -> 278536.42 | E37: =$D$3*12 -> 0 | F37: 0 | G37: =D37*(1+($D$2/$D$5))^($D$5*$D$6)-D37 -> 22960.359 | H37: =G37+E37+D37-F37 -> 301496.78
B38: =B37+1 -> 30 | C38: =C37+1 -> 55 | D38: =H37 -> 301496.78 | E38: =$D$3*12 -> 0 | F38: 0 | G38: =D38*(1+($D$2/$D$5))^($D$5*$D$6)-D38 -> 24853.031 | H38: =G38+E38+D38-F38 -> 326349.81
... B43: =B42+1 -> 35 | C43: =C42+1 -> 60 | D43: =H42 -> 448008.35 | E43: =$D$3*12 -> 0 | F43: 0 | G43: =D43*(1+($D$2/$D$5))^($D$5*$D$6)-D43 -> 36930.296 | H43: =G43+E43+D43-F43 -> 484938.65
E45: =SUM(E9:E43) -> 16500 | G45: =SUM(G9:G43) -> 451160.65

Sheet Matt IRA Projection
B2: Interest Rate | D2: 0.08 | F2: End=Present*(1+(interest rate/number compoundings per year))^(compoundings per year * years)
B3: Monthly Contribution | D3: 0
B4: Average cost per year | D4: 25000
B5: Compounding Quarterly | D5: 4
B6: Years til College | D6: 1
A8: Date Updated | B8: Year | C8: Age | D8: Start | E8: Contributions | F8: Payment | G8: Earnings | H8: Matt IRA End | I8: Actual
B9: 1 | C9: 30 | D9: 28160 | E9: 3666 | F9: 0 | G9: =D9*(1+($D$2/$D$5))^($D$5*$D$6)-D9 -> 2321.2896 | H9: =G9+E9+D9 -> 34147.29
B10: =B9+1 -> 2 | C10: =C9+1 -> 31 | D10: =H9 -> 34147.29 | E10: 5500 | F10: 0 | G10: =D10*(1+($D$2/$D$5))^($D$5*$D$6)-D10 -> 2814.8348 | H10: =G10+E10+D10 -> 42462.124
B11: =B10+1 -> 3 | C11: =C10+1 -> 32 | D11: =H10 -> 42462.124 | E11: 5500 | F11: 0 | G11: =D11*(1+($D$2/$D$5))^($D$5*$D$6)-D11 -> 3500.2446 | H11: =G11+E11+D11 -> 51462.369
B12: =B11+1 -> 4 | C12: =C11+1 -> 33 | D12: =H11 -> 51462.369 | E12: 5500 | F12: 0 | G12: =D12*(1+($D$2/$D$5))^($D$5*$D$6)-D12 -> 4242.1542 | H12: =G12+E12+D12 -> 61204.523
B13: =B12+1 -> 5 | C13: =C12+1 -> 34 | D13: =H12 -> 61204.523 | E13: 5500 | F13: 0 | G13: =D13*(1+($D$2/$D$5))^($D$5*$D$6)-D13 -> 5045.2211 | H13: =G13+E13+D13 -> 71749.744
B14: =B13+1 -> 6 | C14: =C13+1 -> 35 | D14: =H13 -> 71749.744 | E14: 0 | F14: 0 | G14: =D14*(1+($D$2/$D$5))^($D$5*$D$6)-D14 -> 5914.4864 | H14: =G14+E14+D14 -> 77664.231
B15: =B14+1 -> 7 | C15: =C14+1 -> 36 | D15: =H14 -> 77664.231 | E15: =$D$3*12 -> 0 | F15: 0 | G15: =D15*(1+($D$2/$D$5))^($D$5*$D$6)-D15 -> 6402.0303 | H15: =G15+E15+D15 -> 84066.261 | I15: 97400
B16: =B15+1 -> 8 | C16: =C15+1 -> 37 | D16: =H15 -> 84066.261 | E16: =$D$3*12 -> 0 | F16: 0 | G16: =D16*(1+($D$2/$D$5))^($D$5*$D$6)-D16 -> 6929.7635 | H16: =G16+E16+D16 -> 90996.025 | I16: =101159+12339 -> 113498 | J16: =I16/I15-1 -> 0.16527721
B17: =B16+1 -> 9 | C17: =C16+1 -> 38 | D17: =H16 -> 90996.025 | E17: =$D$3*12 -> 0 | F17: 0 | G17: =D17*(1+($D$2/$D$5))^($D$5*$D$6)-D17 -> 7500.9989 | H17: =G17+E17+D17 -> 98497.023 | I17: 133469 | J17: =I17/I16-1 -> 0.17595905
B18: =B17+1 -> 10 | C18: =C17+1 -> 39 | D18: =H17 -> 98497.023 | E18: =$D$3*12 -> 0 | F18: 0 | G18: =D18*(1+($D$2/$D$5))^($D$5*$D$6)-D18 -> 8119.3224 | H18: =G18+E18+D18 -> 106616.35
B19: =B18+1 -> 11 | C19: =C18+1 -> 40 | D19: =H18 -> 106616.35 | E19: =$D$3*12 -> 0 | F19: 0 | G19: =D19*(1+($D$2/$D$5))^($D$5*$D$6)-D19 -> 8788.6157 | H19: =G19+E19+D19 -> 115404.96
B20: =B19+1 -> 12 | C20: =C19+1 -> 41 | D20: =H19 -> 115404.96 | E20: =$D$3*12 -> 0 | F20: 0 | G20: =D20*(1+($D$2/$D$5))^($D$5*$D$6)-D20 -> 9513.0803 | H20: =G20+E20+D20 -> 124918.04
B21: =B20+1 -> 13 | C21: =C20+1 -> 42 | D21: =H20 -> 124918.04 | E21: =$D$3*12 -> 0 | F21: 0 | G21: =D21*(1+($D$2/$D$5))^($D$5*$D$6)-D21 -> 10297.264 | H21: =G21+E21+D21 -> 135215.31
B22: =B21+1 -> 14 | C22: =C21+1 -> 43 | D22: =H21 -> 135215.31 | E22: =$D$3*12 -> 0 | F22: 0 | G22: =D22*(1+($D$2/$D$5))^($D$5*$D$6)-D22 -> 11146.09 | H22: =G22+E22+D22 -> 146361.4
B23: =B22+1 -> 15 | C23: =C22+1 -> 44 | D23: =H22 -> 146361.4 | E23: =$D$3*12 -> 0 | F23: 0 | G23: =D23*(1+($D$2/$D$5))^($D$5*$D$6)-D23 -> 12064.886 | H23: =G23+E23+D23 -> 158426.28
B24: =B23+1 -> 16 | C24: =C23+1 -> 45 | D24: =H23 -> 158426.28 | E24: =$D$3*12 -> 0 | F24: 0 | G24: =D24*(1+($D$2/$D$5))^($D$5*$D$6)-D24 -> 13059.421 | H24: =G24+E24+D24 -> 171485.7
B25: =B24+1 -> 17 | C25: =C24+1 -> 46 | D25: =H24 -> 171485.7 | E25: =$D$3*12 -> 0 | F25: 0 | G25: =D25*(1+($D$2/$D$5))^($D$5*$D$6)-D25 -> 14135.937 | H25: =G25+E25+D25 -> 185621.64
B26: =B25+1 -> 18 | C26: =C25+1 -> 47 | D26: =H25 -> 185621.64 | E26: =$D$3*12 -> 0 | F26: 0 | G26: =D26*(1+($D$2/$D$5))^($D$5*$D$6)-D26 -> 15301.193 | H26: =G26+E26+D26 -> 200922.83
B27: =B26+1 -> 19 | C27: =C26+1 -> 48 | D27: =H26 -> 200922.83 | E27: =$D$3*12 -> 0 | F27: 0 | G27: =D27*(1+($D$2/$D$5))^($D$5*$D$6)-D27 -> 16562.503 | H27: =G27+E27+D27-F27 -> 217485.33
B28: =B27+1 -> 20 | C28: =C27+1 -> 49 | D28: =H27 -> 217485.33 | E28: =$D$3*12 -> 0 | F28: 0 | G28: =D28*(1+($D$2/$D$5))^($D$5*$D$6)-D28 -> 17927.786 | H28: =G28+E28+D28-F28 -> 235413.12
B29: =B28+1 -> 21 | C29: =C28+1 -> 50 | D29: =H28 -> 235413.12 | E29: =$D$3*12 -> 0 | F29: 0 | G29: =D29*(1+($D$2/$D$5))^($D$5*$D$6)-D29 -> 19405.612 | H29: =G29+E29+D29-F29 -> 254818.73
B30: =B29+1 -> 22 | C30: =C29+1 -> 51 | D30: =H29 -> 254818.73 | E30: =$D$3*12 -> 0 | F30: 0 | G30: =D30*(1+($D$2/$D$5))^($D$5*$D$6)-D30 -> 21005.259 | H30: =G30+E30+D30-F30 -> 275823.99
B31: =B30+1 -> 23 | C31: =C30+1 -> 52 | D31: =H30 -> 275823.99 | E31: =$D$3*12 -> 0 | F31: 0 | G31: =D31*(1+($D$2/$D$5))^($D$5*$D$6)-D31 -> 22736.767 | H31: =G31+E31+D31-F31 -> 298560.76
B32: =B31+1 -> 24 | C32: =C31+1 -> 53 | D32: =H31 -> 298560.76 | E32: =$D$3*12 -> 0 | F32: 0 | G32: =D32*(1+($D$2/$D$5))^($D$5*$D$6)-D32 -> 24611.008 | H32: =G32+E32+D32-F32 -> 323171.77
B33: =B32+1 -> 25 | C33: =C32+1 -> 54 | D33: =H32 -> 323171.77 | E33: =$D$3*12 -> 0 | F33: 0 | G33: =D33*(1+($D$2/$D$5))^($D$5*$D$6)-D33 -> 26639.747 | H33: =G33+E33+D33-F33 -> 349811.51
B34: =B33+1 -> 26 | C34: =C33+1 -> 55 | D34: =H33 -> 349811.51 | E34: =$D$3*12 -> 0 | F34: 0 | G34: =D34*(1+($D$2/$D$5))^($D$5*$D$6)-D34 -> 28835.719 | H34: =G34+E34+D34-F34 -> 378647.23
B35: =B34+1 -> 27 | C35: =C34+1 -> 56 | D35: =H34 -> 378647.23 | E35: =$D$3*12 -> 0 | F35: 0 | G35: =D35*(1+($D$2/$D$5))^($D$5*$D$6)-D35 -> 31212.709 | H35: =G35+E35+D35-F35 -> 409859.94
B36: =B35+1 -> 28 | C36: =C35+1 -> 57 | D36: =H35 -> 409859.94 | E36: =$D$3*12 -> 0 | F36: 0 | G36: =D36*(1+($D$2/$D$5))^($D$5*$D$6)-D36 -> 33785.64 | H36: =G36+E36+D36-F36 -> 443645.58
B37: =B36+1 -> 29 | C37: =C36+1 -> 58 | D37: =H36 -> 443645.58 | E37: =$D$3*12 -> 0 | F37: 0 | G37: =D37*(1+($D$2/$D$5))^($D$5*$D$6)-D37 -> 36570.664 | H37: =G37+E37+D37-F37 -> 480216.24
B38: =B37+1 -> 30 | C38: =C37+1 -> 59 | D38: =H37 -> 480216.24 | E38: =$D$3*12 -> 0 | F38: 0 | G38: =D38*(1+($D$2/$D$5))^($D$5*$D$6)-D38 -> 39585.262 | H38: =G38+E38+D38-F38 -> 519801.51
... B43: =B42+1 -> 35 | C43: =C42+1 -> 64 | D43: =H42 -> 713576.08 | E43: =$D$3*12 -> 0 | F43: 0 | G43: =D43*(1+($D$2/$D$5))^($D$5*$D$6)-D43 -> 58821.617 | H43: =G43+E43+D43-F43 -> 772397.7
E45: =SUM(E9:E43) -> 25666 | G45: =SUM(G9:G43) -> 718571.7

Sheet Matt 401K Projection
B2: Interest Rate | D2: 0.08 | F2: End=Present*(1+(interest rate/number compoundings per year))^(compoundings per year * years)
B3: Yearly Max Contribution | D3: 42000
B4: Monthly Contribution | D4: =D3/12 -> 3500
B5: Average cost per year | D5: 25000
B6: Compounding Quarterly | D6: 4
B7: Years til College | D7: 1
A9: Date Updated | B9: Year | C9: Age | D9: Start | E9: Contributions | F9: Payment | G9: Earnings | H9: Matt 401K End | I9: Actual
B10: 1 | C10: 30 | D10: 172860 | E10: 12000 | F10: 0 | G10: =D10*(1+($D$2/$D$6))^($D$6*$D$7)-D10 -> 14249.223 | H10: =G10+E10+D10 -> 199109.22
B11: =B10+1 -> 2 | C11: =C10+1 -> 31 | D11: =H10 -> 199109.22 | E11: 18000 | F11: 0 | G11: =D11*(1+($D$2/$D$6))^($D$6*$D$7)-D11 -> 16413.003 | H11: =G11+E11+D11 -> 233522.23
B12: =B11+1 -> 3 | C12: =C11+1 -> 32 | D12: =H11 -> 233522.23 | E12: 18000 | F12: 0 | G12: =D12*(1+($D$2/$D$6))^($D$6*$D$7)-D12 -> 19249.742 | H12: =G12+E12+D12 -> 270771.97
B13: =B12+1 -> 4 | C13: =C12+1 -> 33 | D13: =H12 -> 270771.97 | E13: 18000 | F13: 0 | G13: =D13*(1+($D$2/$D$6))^($D$6*$D$7)-D13 -> 22320.318 | H13: =G13+E13+D13 -> 311092.29
B14: =B13+1 -> 5 | C14: =C13+1 -> 34 | D14: =H13 -> 311092.29 | E14: 18000 | F14: 0 | G14: =D14*(1+($D$2/$D$6))^($D$6*$D$7)-D14 -> 25644.009 | H14: =G14+E14+D14 -> 354736.3
B15: =B14+1 -> 6 | C15: =C14+1 -> 35 | D15: =H14 -> 354736.3 | E15: 18000 | F15: 0 | G15: =D15*(1+($D$2/$D$6))^($D$6*$D$7)-D15 -> 29241.679 | H15: =G15+E15+D15 -> 401977.97
B16: =B15+1 -> 7 | C16: =C15+1 -> 36 | D16: =H15 -> 401977.97 | E16: =$D$3 -> 42000 | F16: 0 | G16: =D16*(1+($D$2/$D$6))^($D$6*$D$7)-D16 -> 33135.913 | H16: =G16+E16+D16 -> 477113.89 | I16: 499000 | J16: Contributions into BackDoor Roth, up to 62,000
B17: =B16+1 -> 8 | C17: =C16+1 -> 37 | D17: =H16 -> 477113.89 | E17: 42000 | F17: 0 | G17: =D17*(1+($D$2/$D$6))^($D$6*$D$7)-D17 -> 39329.528 | H17: =G17+E17+D17 -> 558443.42 | I17: 662644
B18: =B17+1 -> 9 | C18: =C17+1 -> 38 | D18: =H17 -> 558443.42 | E18: 42000 | F18: 0 | G18: =D18*(1+($D$2/$D$6))^($D$6*$D$7)-D18 -> 46033.697 | H18: =G18+E18+D18 -> 646477.11 | I18: 827448 | J18: =I18/I17-1 -> 0.2487067
B19: =B18+1 -> 10 | C19: =C18+1 -> 39 | D19: =H18 -> 646477.11 | E19: =$D$3 -> 42000 | F19: 0 | G19: =D19*(1+($D$2/$D$6))^($D$6*$D$7)-D19 -> 53290.505 | H19: =G19+E19+D19 -> 741767.62
B20: =B19+1 -> 11 | C20: =C19+1 -> 40 | D20: =H19 -> 741767.62 | E20: =$D$3 -> 42000 | F20: 0 | G20: =D20*(1+($D$2/$D$6))^($D$6*$D$7)-D20 -> 61145.507 | H20: =G20+E20+D20 -> 844913.12
B21: =B20+1 -> 12 | C21: =C20+1 -> 41 | D21: =H20 -> 844913.12 | E21: =$D$3 -> 42000 | F21: 0 | G21: =D21*(1+($D$2/$D$6))^($D$6*$D$7)-D21 -> 69648.014 | H21: =G21+E21+D21 -> 956561.14
B22: =B21+1 -> 13 | C22: =C21+1 -> 42 | D22: =H21 -> 956561.14 | E22: =$D$3 -> 42000 | F22: 0 | G22: =D22*(1+($D$2/$D$6))^($D$6*$D$7)-D22 -> 78851.401 | H22: =G22+E22+D22 -> 1077412.5
B23: =B22+1 -> 14 | C23: =C22+1 -> 43 | D23: =H22 -> 1077412.5 | E23: =$D$3 -> 42000 | F23: 0 | G23: =D23*(1+($D$2/$D$6))^($D$6*$D$7)-D23 -> 88813.443 | H23: =G23+E23+D23 -> 1208226
B24: =B23+1 -> 15 | C24: =C23+1 -> 44 | D24: =H23 -> 1208226 | E24: =$D$3 -> 42000 | F24: 0 | G24: =D24*(1+($D$2/$D$6))^($D$6*$D$7)-D24 -> 99596.677 | H24: =G24+E24+D24 -> 1349822.7
B25: =B24+1 -> 16 | C25: =C24+1 -> 45 | D25: =H24 -> 1349822.7 | E25: =$D$3 -> 42000 | F25: 0 | G25: =D25*(1+($D$2/$D$6))^($D$6*$D$7)-D25 -> 111268.8 | H25: =G25+E25+D25 -> 1503091.5
B26: =B25+1 -> 17 | C26: =C25+1 -> 46 | D26: =H25 -> 1503091.5 | E26: =$D$3 -> 42000 | F26: 0 | G26: =D26*(1+($D$2/$D$6))^($D$6*$D$7)-D26 -> 123903.08 | H26: =G26+E26+D26 -> 1668994.5
B27: =B26+1 -> 18 | C27: =C26+1 -> 47 | D27: =H26 -> 1668994.5 | E27: =$D$3 -> 42000 | F27: 0 | G27: =D27*(1+($D$2/$D$6))^($D$6*$D$7)-D27 -> 137578.82 | H27: =G27+E27+D27 -> 1848573.4
B28: =B27+1 -> 19 | C28: =C27+1 -> 48 | D28: =H27 -> 1848573.4 | E28: =$D$3 -> 42000 | F28: 0 | G28: =D28*(1+($D$2/$D$6))^($D$6*$D$7)-D28 -> 152381.89 | H28: =G28+E28+D28-F28 -> 2042955.3
B29: =B28+1 -> 20 | C29: =C28+1 -> 49 | D29: =H28 -> 2042955.3 | E29: =$D$3 -> 42000 | F29: 0 | G29: =D29*(1+($D$2/$D$6))^($D$6*$D$7)-D29 -> 168405.21 | H29: =G29+E29+D29-F29 -> 2253360.5
B30: =B29+1 -> 21 | C30: =C29+1 -> 50 | D30: =H29 -> 2253360.5 | E30: =$D$3 -> 42000 | F30: 0 | G30: =D30*(1+($D$2/$D$6))^($D$6*$D$7)-D30 -> 185749.37 | H30: =G30+E30+D30-F30 -> 2481109.8
B31: =B30+1 -> 22 | C31: =C30+1 -> 51 | D31: =H30 -> 2481109.8 | E31: =$D$3 -> 42000 | F31: 0 | G31: =D31*(1+($D$2/$D$6))^($D$6*$D$7)-D31 -> 204523.24 | H31: =G31+E31+D31-F31 -> 2727633.1
B32: =B31+1 -> 23 | C32: =C31+1 -> 52 | D32: =H31 -> 2727633.1 | E32: =$D$3 -> 42000 | F32: 0 | G32: =D32*(1+($D$2/$D$6))^($D$6*$D$7)-D32 -> 224844.69 | H32: =G32+E32+D32-F32 -> 2994477.8
B33: =B32+1 -> 24 | C33: =C32+1 -> 53 | D33: =H32 -> 2994477.8 | E33: =$D$3 -> 42000 | F33: 0 | G33: =D33*(1+($D$2/$D$6))^($D$6*$D$7)-D33 -> 246841.27 | H33: =G33+E33+D33-F33 -> 3283319
B34: =B33+1 -> 25 | C34: =C33+1 -> 54 | D34: =H33 -> 3283319 | E34: =$D$3 -> 42000 | F34: 0 | G34: =D34*(1+($D$2/$D$6))^($D$6*$D$7)-D34 -> 270651.08 | H34: =G34+E34+D34-F34 -> 3595970.1
B35: =B34+1 -> 26 | C35: =C34+1 -> 55 | D35: =H34 -> 3595970.1 | E35: =$D$3 -> 42000 | F35: 0 | G35: =D35*(1+($D$2/$D$6))^($D$6*$D$7)-D35 -> 296423.58 | H35: =G35+E35+D35-F35 -> 3934393.7
B36: =B35+1 -> 27 | C36: =C35+1 -> 56 | D36: =H35 -> 3934393.7 | E36: =$D$3 -> 42000 | F36: 0 | G36: =D36*(1+($D$2/$D$6))^($D$6*$D$7)-D36 -> 324320.57 | H36: =G36+E36+D36-F36 -> 4300714.3
B37: =B36+1 -> 28 | C37: =C36+1 -> 57 | D37: =H36 -> 4300714.3 | E37: =$D$3 -> 42000 | F37: 0 | G37: =D37*(1+($D$2/$D$6))^($D$6*$D$7)-D37 -> 354517.17 | H37: =G37+E37+D37-F37 -> 4697231.4
B38: =B37+1 -> 29 | C38: =C37+1 -> 58 | D38: =H37 -> 4697231.4 | E38: =$D$3 -> 42000 | F38: 0 | G38: =D38*(1+($D$2/$D$6))^($D$6*$D$7)-D38 -> 387202.93 | H38: =G38+E38+D38-F38 -> 5126434.4
B39: =B38+1 -> 30 | C39: =C38+1 -> 59 | D39: =H38 -> 5126434.4 | E39: =$D$3 -> 42000 | F39: 0 | G39: =D39*(1+($D$2/$D$6))^($D$6*$D$7)-D39 -> 422583.06 | H39: =G39+E39+D39-F39 -> 5591017.4
... B44: =B43+1 -> 35 | C44: =C43+1 -> 64 | D44: =H43 -> 7865206.8 | E44: =$D$3 -> 42000 | F44: 0 | G44: =D44*(1+($D$2/$D$6))^($D$6*$D$7)-D44 -> 648345.99 | H44: =G44+E44+D44-F44 -> 8555552.8
E46: =SUM(E10:E44) -> 1320000 | G46: =SUM(G10:G44) -> 7062692.8

Sheet Combined Accounts Estimate
B2: Interest Rate | D2: 0.08 | F2: End=Present*(1+(interest rate/number compoundings per year))^(compoundings per year * years) | Q2: Target | R2: 54 | S2: 0
B3: Yearly Max Contribution | D3: 42000 | R3: 54 | S3: 6000000
B4: Monthly Contribution | D4: =D3/12 -> 3500
B5: Average cost per year | D5: 25000
B6: Compounding Quarterly | D6: 4
B7: Years til College | D7: 1
A9: Date Updated | B9: Year | C9: Age | D9: Start | E9: Contributions | F9: Payment | G9: Earnings | H9: Matt 401K End | I9: Jordan IRA End | J9: Matt IRA End | K9: Combined | L9: COP Pension Actual | M9: Actual (Fidelity+Vanguard-College) | N9: Difference | O9: Actual + COP Pension
B10: 1 | C10: 30 | D10: 172860 | E10: 12000 | F10: 0 | G10: =D10*(1+($D$2/$D$6))^($D$6*$D$7)-D10 -> 14249.223 | H10: =G10+E10+D10 -> 199109.22 | I10: ='Jordan IRA Projection'!H9 -> 18702.263 | J10: ='Matt IRA Projection'!H9 -> 34147.29 | K10: =SUM(H10:J10) -> 251958.78
B11: =B10+1 -> 2 | C11: =C10+1 -> 31 | D11: =H10 -> 199109.22 | E11: 18000 | F11: 0 | G11: =D11*(1+($D$2/$D$6))^($D$6*$D$7)-D11 -> 16413.003 | H11: =G11+E11+D11 -> 233522.23 | I11: ='Jordan IRA Projection'!H10 -> 25743.931 | J11: ='Matt IRA Projection'!H10 -> 42462.124 | K11: =SUM(H11:J11) -> 301728.28
B12: =B11+1 -> 3 | C12: =C11+1 -> 32 | D12: =H11 -> 233522.23 | E12: 18000 | F12: 0 | G12: =D12*(1+($D$2/$D$6))^($D$6*$D$7)-D12 -> 19249.742 | H12: =G12+E12+D12 -> 270771.97 | I12: ='Jordan IRA Projection'!H11 -> 33366.059 | J12: ='Matt IRA Projection'!H11 -> 51462.369 | K12: =SUM(H12:J12) -> 355600.4
B13: =B12+1 -> 4 | C13: =C12+1 -> 33 | D13: =H12 -> 270771.97 | E13: 18000 | F13: 0 | G13: =D13*(1+($D$2/$D$6))^($D$6*$D$7)-D13 -> 22320.318 | H13: =G13+E13+D13 -> 311092.29 | I13: ='Jordan IRA Projection'!H12 -> 41616.495 | J13: ='Matt IRA Projection'!H12 -> 61204.523 | K13: =SUM(H13:J13) -> 413913.3
B14: =B13+1 -> 5 | C14: =C13+1 -> 34 | D14: =H13 -> 311092.29 | E14: 18000 | F14: 0 | G14: =D14*(1+($D$2/$D$6))^($D$6*$D$7)-D14 -> 25644.009 | H14: =G14+E14+D14 -> 354736.3 | I14: ='Jordan IRA Projection'!H13 -> 45047.032 | J14: ='Matt IRA Projection'!H13 -> 71749.744 | K14: =SUM(H14:J14) -> 471533.07
B15: =B14+1 -> 6 | C15: =C14+1 -> 35 | D15: =H14 -> 354736.3 | E15: 18000 | F15: 0 | G15: =D15*(1+($D$2/$D$6))^($D$6*$D$7)-D15 -> 29241.679 | H15: =G15+E15+D15 -> 401977.97 | I15: ='Jordan IRA Projection'!H14 -> 48760.357 | J15: ='Matt IRA Projection'!H14 -> 77664.231 | K15: =SUM(H15:J15) -> 528402.56
B16: =B15+1 -> 7 | C16: =C15+1 -> 36 | D16: =H15 -> 401977.97 | E16: =$D$3 -> 42000 | F16: 0 | G16: =D16*(1+($D$2/$D$6))^($D$6*$D$7)-D16 -> 33135.913 | H16: =G16+E16+D16 -> 477113.89 | I16: ='Jordan IRA Projection'!H15 -> 52779.778 | J16: ='Matt IRA Projection'!H15 -> 84066.261 | K16: =SUM(H16:J16) -> 613959.93 | L16: 123000 | M16: =499000+250000 -> 749000 | N16: =M16-K16 -> 135040.07 | O16: =M16+L16 -> 872000
B17: =B16+1 -> 8 | C17: =C16+1 -> 37 | D17: =H16 -> 477113.89 | E17: =$D$3 -> 42000 | F17: 0 | G17: =D17*(1+($D$2/$D$6))^($D$6*$D$7)-D17 -> 39329.528 | H17: =G17+E17+D17 -> 558443.42 | I17: ='Jordan IRA Projection'!H16 -> 57130.529 | J17: ='Matt IRA Projection'!H16 -> 90996.025 | K17: =SUM(H17:J17) -> 706569.97 | L17: 148258 | M17: 967000 | N17: =M17-K17 -> 260430.03 | O17: =M17+L17 -> 1115258
B18: =B17+1 -> 9 | C18: =C17+1 -> 38 | D18: =H17 -> 558443.42 | E18: =$D$3 -> 42000 | F18: 0 | G18: =D18*(1+($D$2/$D$6))^($D$6*$D$7)-D18 -> 46033.697 | H18: =G18+E18+D18 -> 646477.11 | I18: ='Jordan IRA Projection'!H17 -> 61839.922 | J18: ='Matt IRA Projection'!H17 -> 98497.023 | K18: =SUM(H18:J18) -> 806814.06 | L18: 173310 | M18: 1139860 | N18: =M18-K18 -> 333045.94 | O18: =M18+L18 -> 1313170
B19: =B18+1 -> 10 | C19: =C18+1 -> 39 | D19: =H18 -> 646477.11 | E19: =$D$3 -> 42000 | F19: 0 | G19: =D19*(1+($D$2/$D$6))^($D$6*$D$7)-D19 -> 53290.505 | H19: =G19+E19+D19 -> 741767.62 | I19: ='Jordan IRA Projection'!H18 -> 66937.521 | J19: ='Matt IRA Projection'!H18 -> 106616.35 | K19: =SUM(H19:J19) -> 915321.48
B20: =B19+1 -> 11 | C20: =C19+1 -> 40 | D20: =H19 -> 741767.62 | E20: =$D$3 -> 42000 | F20: 0 | G20: =D20*(1+($D$2/$D$6))^($D$6*$D$7)-D20 -> 61145.507 | H20: =G20+E20+D20 -> 844913.12 | I20: ='Jordan IRA Projection'!H19 -> 72455.325 | J20: ='Matt IRA Projection'!H19 -> 115404.96 | K20: =SUM(H20:J20) -> 1032773.4
B21: =B20+1 -> 12 | C21: =C20+1 -> 41 | D21: =H20 -> 844913.12 | E21: =$D$3 -> 42000 | F21: 0 | G21: =D21*(1+($D$2/$D$6))^($D$6*$D$7)-D21 -> 69648.014 | H21: =G21+E21+D21 -> 956561.14 | I21: ='Jordan IRA Projection'!H20 -> 78427.974 | J21: ='Matt IRA Projection'!H20 -> 124918.04 | K21: =SUM(H21:J21) -> 1159907.2
B22: =B21+1 -> 13 | C22: =C21+1 -> 42 | D22: =H21 -> 956561.14 | E22: =$D$3 -> 42000 | F22: 0 | G22: =D22*(1+($D$2/$D$6))^($D$6*$D$7)-D22 -> 78851.401 | H22: =G22+E22+D22 -> 1077412.5 | I22: ='Jordan IRA Projection'!H21 -> 84892.961 | J22: ='Matt IRA Projection'!H21 -> 135215.31 | K22: =SUM(H22:J22) -> 1297520.8
B23: =B22+1 -> 14 | C23: =C22+1 -> 43 | D23: =H22 -> 1077412.5 | E23: =$D$3 -> 42000 | F23: 0 | G23: =D23*(1+($D$2/$D$6))^($D$6*$D$7)-D23 -> 88813.443 | H23: =G23+E23+D23 -> 1208226 | I23: ='Jordan IRA Projection'!H22 -> 91890.871 | J23: ='Matt IRA Projection'!H22 -> 146361.4 | K23: =SUM(H23:J23) -> 1446478.2
B24: =B23+1 -> 15 | C24: =C23+1 -> 44 | D24: =H23 -> 1208226 | E24: =$D$3 -> 42000 | F24: 0 | G24: =D24*(1+($D$2/$D$6))^($D$6*$D$7)-D24 -> 99596.677 | H24: =G24+E24+D24 -> 1349822.7 | I24: ='Jordan IRA Projection'!H23 -> 99465.634 | J24: ='Matt IRA Projection'!H23 -> 158426.28 | K24: =SUM(H24:J24) -> 1607714.6
B25: =B24+1 -> 16 | C25: =C24+1 -> 45 | D25: =H24 -> 1349822.7 | E25: =$D$3 -> 42000 | F25: 0 | G25: =D25*(1+($D$2/$D$6))^($D$6*$D$7)-D25 -> 111268.8 | H25: =G25+E25+D25 -> 1503091.5 | I25: ='Jordan IRA Projection'!H24 -> 107664.8 | J25: ='Matt IRA Projection'!H24 -> 171485.7 | K25: =SUM(H25:J25) -> 1782242
B26: =B25+1 -> 17 | C26: =C25+1 -> 46 | D26: =H25 -> 1503091.5 | E26: =$D$3 -> 42000 | F26: 0 | G26: =D26*(1+($D$2/$D$6))^($D$6*$D$7)-D26 -> 123903.08 | H26: =G26+E26+D26 -> 1668994.5 | I26: ='Jordan IRA Projection'!H25 -> 116539.84 | J26: ='Matt IRA Projection'!H25 -> 185621.64 | K26: =SUM(H26:J26) -> 1971156
B27: =B26+1 -> 18 | C27: =C26+1 -> 47 | D27: =H26 -> 1668994.5 | E27: =$D$3 -> 42000 | F27: 0 | G27: =D27*(1+($D$2/$D$6))^($D$6*$D$7)-D27 -> 137578.82 | H27: =G27+E27+D27 -> 1848573.4 | I27: ='Jordan IRA Projection'!H26 -> 126146.47 | J27: ='Matt IRA Projection'!H26 -> 200922.83 | K27: =SUM(H27:J27) -> 2175642.7
B28: =B27+1 -> 19 | C28: =C27+1 -> 48 | D28: =H27 -> 1848573.4 | E28: =$D$3 -> 42000 | F28: 0 | G28: =D28*(1+($D$2/$D$6))^($D$6*$D$7)-D28 -> 152381.89 | H28: =G28+E28+D28-F28 -> 2042955.3 | I28: ='Jordan IRA Projection'!H27 -> 136545 | J28: ='Matt IRA Projection'!H27 -> 217485.33 | K28: =SUM(H28:J28) -> 2396985.6
B29: =B28+1 -> 20 | C29: =C28+1 -> 49 | D29: =H28 -> 2042955.3 | E29: =$D$3 -> 42000 | F29: 0 | G29: =D29*(1+($D$2/$D$6))^($D$6*$D$7)-D29 -> 168405.21 | H29: =G29+E29+D29-F29 -> 2253360.5 | I29: ='Jordan IRA Projection'!H28 -> 147800.7 | J29: ='Matt IRA Projection'!H28 -> 235413.12 | K29: =SUM(H29:J29) -> 2636574.3
B30: =B29+1 -> 21 | C30: =C29+1 -> 50 | D30: =H29 -> 2253360.5 | E30: =$D$3 -> 42000 | F30: 0 | G30: =D30*(1+($D$2/$D$6))^($D$6*$D$7)-D30 -> 185749.37 | H30: =G30+E30+D30-F30 -> 2481109.8 | I30: ='Jordan IRA Projection'!H29 -> 159984.23 | J30: ='Matt IRA Projection'!H29 -> 254818.73 | K30: =SUM(H30:J30) -> 2895912.8
B31: =B30+1 -> 22 | C31: =C30+1 -> 51 | D31: =H30 -> 2481109.8 | E31: =$D$3 -> 42000 | F31: 0 | G31: =D31*(1+($D$2/$D$6))^($D$6*$D$7)-D31 -> 204523.24 | H31: =G31+E31+D31-F31 -> 2727633.1 | I31: ='Jordan IRA Projection'!H30 -> 173172.08 | J31: ='Matt IRA Projection'!H30 -> 275823.99 | K31: =SUM(H31:J31) -> 3176629.1
B32: =B31+1 -> 23 | C32: =C31+1 -> 52 | D32: =H31 -> 2727633.1 | E32: =$D$3 -> 42000 | F32: 0 | G32: =D32*(1+($D$2/$D$6))^($D$6*$D$7)-D32 -> 224844.69 | H32: =G32+E32+D32-F32 -> 2994477.8 | I32: ='Jordan IRA Projection'!H31 -> 187447.03 | J32: ='Matt IRA Projection'!H31 -> 298560.76 | K32: =SUM(H32:J32) -> 3480485.5
B33: =B32+1 -> 24 | C33: =C32+1 -> 53 | D33: =H32 -> 2994477.8 | E33: =$D$3 -> 42000 | F33: 0 | G33: =D33*(1+($D$2/$D$6))^($D$6*$D$7)-D33 -> 246841.27 | H33: =G33+E33+D33-F33 -> 3283319 | I33: ='Jordan IRA Projection'!H32 -> 202898.69 | J33: ='Matt IRA Projection'!H32 -> 323171.77 | K33: =SUM(H33:J33) -> 3809389.5
B34: =B33+1 -> 25 | C34: =C33+1 -> 54 | D34: =H33 -> 3283319 | E34: =$D$3 -> 42000 | F34: 0 | G34: =D34*(1+($D$2/$D$6))^($D$6*$D$7)-D34 -> 270651.08 | H34: =G34+E34+D34-F34 -> 3595970.1 | I34: ='Jordan IRA Projection'!H33 -> 219624.07 | J34: ='Matt IRA Projection'!H33 -> 349811.51 | K34: =SUM(H34:J34) -> 4165405.7
B35: =B34+1 -> 26 | C35: =C34+1 -> 55 | D35: =H34 -> 3595970.1 | E35: =$D$3 -> 42000 | F35: 0 | G35: =D35*(1+($D$2/$D$6))^($D$6*$D$7)-D35 -> 296423.58 | H35: =G35+E35+D35-F35 -> 3934393.7 | I35: ='Jordan IRA Projection'!H34 -> 237728.15 | J35: ='Matt IRA Projection'!H34 -> 378647.23 | K35: =SUM(H35:J35) -> 4550769.1
B36: =B35+1 -> 27 | C36: =C35+1 -> 56 | D36: =H35 -> 3934393.7 | E36: =$D$3 -> 42000 | F36: 0 | G36: =D36*(1+($D$2/$D$6))^($D$6*$D$7)-D36 -> 324320.57 | H36: =G36+E36+D36-F36 -> 4300714.3 | I36: ='Jordan IRA Projection'!H35 -> 257324.6 | J36: ='Matt IRA Projection'!H35 -> 409859.94 | K36: =SUM(H36:J36) -> 4967898.8
B37: =B36+1 -> 28 | C37: =C36+1 -> 57 | D37: =H36 -> 4300714.3 | E37: =$D$3 -> 42000 | F37: 0 | G37: =D37*(1+($D$2/$D$6))^($D$6*$D$7)-D37 -> 354517.17 | H37: =G37+E37+D37-F37 -> 4697231.4 | I37: ='Jordan IRA Projection'!H36 -> 278536.42 | J37: ='Matt IRA Projection'!H36 -> 443645.58 | K37: =SUM(H37:J37) -> 5419413.4
B38: =B37+1 -> 29 | C38: =C37+1 -> 58 | D38: =H37 -> 4697231.4 | E38: =$D$3 -> 42000 | F38: 0 | G38: =D38*(1+($D$2/$D$6))^($D$6*$D$7)-D38 -> 387202.93 | H38: =G38+E38+D38-F38 -> 5126434.4 | I38: ='Jordan IRA Projection'!H37 -> 301496.78 | J38: ='Matt IRA Projection'!H37 -> 480216.24 | K38: =SUM(H38:J38) -> 5908147.4
B39: =B38+1 -> 30 | C39: =C38+1 -> 59 | D39: =H38 -> 5126434.4 | E39: =$D$3 -> 42000 | F39: 0 | G39: =D39*(1+($D$2/$D$6))^($D$6*$D$7)-D39 -> 422583.06 | H39: =G39+E39+D39-F39 -> 5591017.4 | I39: ='Jordan IRA Projection'!H38 -> 326349.81 | J39: ='Matt IRA Projection'!H38 -> 519801.51 | K39: =SUM(H39:J39) -> 6437168.7
... B44: =B43+1 -> 35 | C44: =C43+1 -> 64 | D44: =H43 -> 7865206.8 | E44: =$D$3 -> 42000 | F44: 0 | G44: =D44*(1+($D$2/$D$6))^($D$6*$D$7)-D44 -> 648345.99 | H44: =G44+E44+D44-F44 -> 8555552.8 | I44: ='Jordan IRA Projection'!H43 -> 484938.65 | J44: ='Matt IRA Projection'!H43 -> 772397.7 | K44: =SUM(H44:J44) -> 9812889.1
E46: =SUM(E10:E44) -> 1320000 | G46: =SUM(G10:G44) -> 7062692.8

Sheet Net Worth
B1: Loan Amount | C1: Remaining Balance | D1: Equity
A2: Home Equity (initial) | B2: 500500 | C2: 371403 | D2: =B2-C2 -> 129097
A3: 2881 Cordell (initial) | B3: 179400 | C3: 134550 | D3: =B3-C3 -> 44850
A4: Jordan Expedition Value | D4: 35863 | E4: KBB Value
A5: Matt Truck | B5: 75000 | C5: 17242 | D5: =B5-C5 -> 57758
A6: Camper | B6: 0 | C6: 0 | D6: 27000 | E6: Guess
B8: Age | C8: Wells Fargo Checking/ Savings | D8: Fidelity 401k Total | E8: Vanguard Total | F8: Vanguard 529 Hudson | G8: HSA Total | H8: COP Stock | I8: Capital One Savings All | J8: COP Pension | K8: BHI Pension | L8: Crypto | M8: Vehicle Equity (KBB) | N8: Remaining Truck Loan | O8: Remaining Home Loan | P8: Home Equity | Q8: 2881 Cordell Savings | R8: 2881 Cordell Remaining Loan | S8: 2881 Cordell Home Equity | T8: Total Investments (Excluding 529) | U8: Total Short Term Cash (Checking/ Emergency) | V8: Total Net Worth (No Home Equity) | W8: Net Worth Including Home Equity
A9: 44909 | B9: 36 | D9: 499000 | E9: 250000 | J9: 123000 | K9: 7000 | M9: 80000 | O9: -371403 | P9: =$B$2+O9 -> 129097 | T9: =SUM(D9:E9,G9,J9:K9,H9,L9) -> 879000 | U9: =SUM(C9,I9) -> 0 | V9: =SUM(C9:O9) -> 587597 | W9: =SUM(C9:P9) -> 716694
A10: 44927 | B10: =$B$9+(A10-$A$9)/365 -> 36.049315 | D10: 501366 | E10: 269283 | F10: 24195 | G10: 19007 | I10: 42508 | J10: 125000 | K10: 7000 | M10: =79567+27000 -> 106567 | O10: -370249 | P10: =$B$2+O10 -> 130251 | T10: =SUM(D10:E10,G10,J10:K10,H10,L10) -> 921656 | U10: =SUM(C10,I10) -> 42508 | V10: =SUM(C10:O10) -> 724677 | W10: =SUM(C10:P10) -> 854928
A11: 45084 | B11: =$B$9+(A11-$A$9)/365 -> 36.479452 | C11: 31109 | D11: 574736 | E11: 302069 | F11: 27130 | G11: 20027 | I11: 42622 | J11: 137321 | K11: 7000 | M11: =35863+75000+27000 -> 137863 | N11: -25823 | O11: -363266 | P11: =$B$2+O11 -> 137234 | T11: =SUM(D11:E11,G11,J11:K11,H11,L11) -> 1041153 | U11: =SUM(C11,I11) -> 73731 | V11: =SUM(C11:O11) -> 890788 | W11: =SUM(C11:P11) -> 1028022
A12: 45227 | B12: =$B$9+(A12-$A$9)/365 -> 36.871233 | C12: 15654 | D12: 568894 | E12: 256186 | F12: 26891 | G12: 19149 | I12: 44286 | J12: 140000 | K12: 7000 | M12: =35863+50000+27000 -> 112863 | N12: -24680 | O12: -358554 | P12: =$B$2+O12 -> 141946 | T12: =SUM(D12:E12,G12,J12:K12,H12,L12) -> 991229 | U12: =SUM(C12,I12) -> 59940 | V12: =SUM(C12:O12) -> 807689 | W12: =SUM(C12:P12) -> 949635
A13: 45294 | B13: =$B$9+(A13-$A$9)/365 -> 37.054795 | C13: 2170 | D13: 662644 | E13: 304391 | F13: 30722 | G13: 21454 | H13: 79961 | I13: 45319 | J13: 148258 | K13: 7000 | L13: 2704 | M13: 112863 | N13: -23146 | O13: -356181 | P13: =$B$2+O13 -> 144319 | T13: =SUM(D13:E13,G13,J13:K13,H13,L13) -> 1226412 | U13: =SUM(C13,I13) -> 47489 | V13: =SUM(C13:O13) -> 1038159 | W13: =SUM(C13:P13) -> 1182478
A14: 45352 | B14: =$B$9+(A14-$A$9)/365 -> 37.213699 | C14: 67476 | D14: 708983 | E14: 323099 | F14: 32116 | G14: 23197 | H14: 68874 | I14: 44496 | J14: 151623 | K14: 7500 | L14: 4318 | M14: 112863 | N14: -22366 | O14: -353797 | P14: =$B$2+O14 -> 146703 | T14: =SUM(D14:E14,G14,J14:K14,H14,L14) -> 1287594 | U14: =SUM(C14,I14) -> 111972 | V14: =SUM(C14:O14) -> 1168382 | W14: =SUM(C14:P14) -> 1315085
A15: 45462 | B15: =$B$9+(A15-$A$9)/365 -> 37.515068 | C15: 27273 | D15: 767167 | E15: 343375 | F15: 34337 | G15: 24693 | H15: 66959 | I15: 47605 | J15: 162319 | K15: 7500 | L15: 4323 | M15: 112863 | N15: -21202 | O15: -350712 | P15: =$B$2+O15 -> 149788 | T15: =SUM(D15:E15,G15,J15:K15,H15,L15) -> 1376336 | U15: =SUM(C15,I15) -> 74878 | V15: =SUM(C15:O15) -> 1226500 | W15: =SUM(C15:P15) -> 1376288
A16: =A15+91 -> 45553 | B16: =$B$9+(A16-$A$9)/365 -> 37.764384 | C16: 9630 | D16: 811538 | E16: 337193 | F16: 36231 | G16: 25406 | H16: 66475 | I16: 30962 | J16: 167760 | K16: 7500 | L16: 3000 | M16: 112863 | N16: -20028 | O16: -348380 | P16: =$B$2+O16 -> 152120 | R16: -134550 | S16: =$B$3+R16 -> 44850 | T16: =SUM(D16:E16,G16,J16:K16,H16,L16) -> 1418872 | U16: =SUM(C16,I16) -> 40592 | V16: =SUM(C16:O16,R16) -> 1105600 | W16: =SUM(C16:S16) -> 1302570
A17: 45659 | B17: =$B$9+(A17-$A$9)/365 -> 38.054795 | C17: 15078 | D17: 827448 | E17: 349260 | F17: 36848 | G17: 24113 | H17: 61248 | I17: 34475 | J17: 173310 | K17: 0 | L17: 4288 | M17: 112863 | N17: -18441 | O17: -346030 | P17: =$B$2+O17 -> 154470 | Q17: 4576 | R17: -134047 | S17: =$B$3+R17 -> 45353 | T17: =SUM(D17:E17,G17,J17:K17,H17,L17) -> 1439667 | U17: =SUM(C17,I17,Q17) -> 54129 | V17: =SUM(C17:O17,Q17,R17) -> 1144989 | W17: =SUM(C17:S17) -> 1344812
A18: 45775 | B18: =$B$9+(A18-$A$9)/365 -> 38.372603 | C18: 47704 | D18: 831695 | E18: 351751 | F18: 38000 | G18: 21964 | H18: 63200 | I18: 37819 | J18: 184696 | K18: 0 | L18: 2245 | M18: 112863 | N18: -17242 | O18: -342871 | P18: =$B$2+O18 -> 157629 | Q18: 4189 | R18: -133633 | S18: =$B$3+R18 -> 45767 | T18: =SUM(D18:E18,G18,J18:K18,H18,L18) -> 1455551 | U18: =SUM(C18,I18,Q18) -> 89712 | V18: =SUM(C18:O18,Q18,R18) -> 1202380 | W18: =SUM(C18:S18) -> 1405776
A19: 45815 | B19: =$B$9+(A19-$A$9)/365 -> 38.482192 | C19: 34171 | D19: 896386 | E19: 379103 | F19: 39921 | G19: 23250 | H19: 60094 | I19: 38945 | J19: 186681 | K19: 0 | L19: 2990 | M19: 112863 | N19: -16443 | O19: -341280 | P19: =$B$2+O19 -> 159220 | Q19: 4442 | R19: -133404 | S19: =$B$3+R19 -> 45996 | T19: =SUM(D19:E19,G19,J19:K19,H19,L19) -> 1548504 | U19: =SUM(C19,I19,Q19) -> 77558 | V19: =SUM(C19:O19,Q19,R19) -> 1287719 | W19: =SUM(C19:S19) -> 1492935
A20: 45914 | B20: =$B$9+(A20-$A$9)/365 -> 38.753425 | C20: 37144 | D20: 983914 | E20: 370076 | F20: 43281 | G20: 24960 | H20: 63684 | I20: 41645 | J20: 194704 | K20: 0 | L20: 5188 | M20: 112863 | N20: -15232 | O20: -338879 | P20: =$B$2+O20 -> 161621 | Q20: 4139 | R20: -133010 | S20: =$B$3+R20 -> 46390 | T20: =SUM(D20:E20,G20,J20:K20,H20,L20-F20) -> 1599245 | U20: =SUM(C20,I20,Q20) -> 82928 | V20: =SUM(C20:O20,Q20,R20) -> 1394477 | W20: =SUM(C20:S20) -> 1602488
A21: =A20+91 -> 46005 | B21: =$B$9+(A21-$A$9)/365 -> 39.00274
A22: =A21+91 -> 46096 | B22: =$B$9+(A22-$A$9)/365 -> 39.252055
A23: =A22+91 -> 46187 | B23: =$B$9+(A23-$A$9)/365 -> 39.50137
A24: =A23+91 -> 46278 | B24: =$B$9+(A24-$A$9)/365 -> 39.750685
A25: =A24+91 -> 46369 | B25: =$B$9+(A25-$A$9)/365 -> 40
A26: =A25+91 -> 46460 | B26: =$B$9+(A26-$A$9)/365 -> 40.249315
A27: =A26+91 -> 46551 | B27: =$B$9+(A27-$A$9)/365 -> 40.49863
A28: =A27+91 -> 46642 | B28: =$B$9+(A28-$A$9)/365 -> 40.747945
A29: =A28+91 -> 46733 | B29: =$B$9+(A29-$A$9)/365 -> 40.99726
A30: =A29+91 -> 46824 | B30: =$B$9+(A30-$A$9)/365 -> 41.246575
A31: =A30+91 -> 46915 | B31: =$B$9+(A31-$A$9)/365 -> 41.49589
A32: =A31+91 -> 47006 | B32: =$B$9+(A32-$A$9)/365 -> 41.745205
... A119: =A118+91 -> 54923 | B119: =$B$9+(A119-$A$9)/365 -> 63.435616

Sheet Projection College Cost by year
D2: Interest Rate | E2: 0.06 | G2: End=Present*(1+(interest rate/number compoundings per year))^(compoundings per year * years) | AC2: All Kids Done | AD2: 2043 | AE2: 200000
D3: Monthly Contribution | E3: 200 | AD3: 2043 | AE3: 0
D4: Average cost per year | E4: 25000
D5: Compounding Quarterly | E5: 4 | AC5: ="Shortfall " &(AD6-AD5) &" years" -> Shortfall 4 years | AD5: =C31 -> 2039 | AE5: 5000
D6: Years til College | E6: 1 | AD6: 2043 | AE6: 5000
A8: Kid Age | B8: Date (updated Dec 31 each year) | C8: Year | D8: Child Age | E8: Start | F8: Contributions | G8: College Payment | H8: Hudson Earnings | I8: Hudson Projected College Balance | J8: Hudson Actual | K8: Riley Starting Balance | L8: Riley Contributions | M8: College Payment | N8: Riley Earnings | O8: Riley Projected College Balance | P8: Riley Actual | Q8: Sunny Starting Balance | R8: Sunny Contributions | S8: College Payment | T8: Sunny Earnings | U8: Sunny Projected College Balance | V8: Sunny Actual | W8: Total Projected College Fund All 3 | X8: Total Payment, All 3 | Y8: Actual Funds, All 3
D9: 1 | E9: 3000 | F9: =$E$3*12 -> 2400 | G9: 0 | H9: =E9*(1+($E$2/$E$5))^($E$5*$E$6)-E9 -> 184.09065 | I9: =H9+F9+E9 -> 5584.0907
D10: =D9+1 -> 2 | E10: =IF(J9>I9,J9,I9) -> 5584.0907 | F10: =$E$3*12 -> 2400 | G10: 0 | H10: =E10*(1+($E$2/$E$5))^($E$5*$E$6)-E10 -> 342.65963 | I10: =H10+F10+E10 -> 8326.7503
D11: =D10+1 -> 3 | E11: =IF(J10>I10,J10,I10) -> 8326.7503 | F11: =$E$3*12 -> 2400 | G11: 0 | H11: =E11*(1+($E$2/$E$5))^($E$5*$E$6)-E11 -> 510.95896 | I11: =H11+F11+E11 -> 11237.709
D12: =D11+1 -> 4 | E12: =IF(J11>I11,J11,I11) -> 11237.709 | F12: =$E$3*12 -> 2400 | G12: 0 | H12: =E12*(1+($E$2/$E$5))^($E$5*$E$6)-E12 -> 689.58574 | I12: =H12+F12+E12 -> 14327.295
D13: =D12+1 -> 5 | E13: =IF(J12>I12,J12,I12) -> 14327.295 | F13: =$E$3*12 -> 2400 | G13: 0 | H13: =E13*(1+($E$2/$E$5))^($E$5*$E$6)-E13 -> 879.17369 | I13: =H13+F13+E13 -> 17606.469
C14: 2022 | D14: =D13+1 -> 6 | E14: =IF(J13>I13,J13,I13) -> 17606.469 | F14: =$E$3*12 -> 2400 | G14: 0 | H14: =E14*(1+($E$2/$E$5))^($E$5*$E$6)-E14 -> 1080.3954 | I14: =H14+F14+E14 -> 21086.864 | J14: 24072 | K14: 0 | L14: =$E$3*12 -> 2400 | M14: 0 | N14: =K14*(1+($E$2/$E$5))^($E$5*$E$6)-K14 -> 0 | O14: =K14+L14+N14-M14 -> 2400 | Q14: 0 | R14: =$E$3*12 -> 2400 | S14: 0 | T14: =Q14*(1+($E$2/$E$5))^($E$5*$E$6)-Q14 -> 0 | U14: =Q14+R14+T14-S14 -> 2400 | W14: =SUM(I14+O14+U14)-X14 -> 25886.864 | X14: =SUM(S14+M14+G14) -> 0 | Y14: =SUM(J14+P14+V14) -> 24072
C15: 2023 | D15: =D14+1 -> 7 | E15: =IF(J14>I14,J14,I14) -> 24072 | F15: =$E$3*12 -> 2400 | G15: 0 | H15: =E15*(1+($E$2/$E$5))^($E$5*$E$6)-E15 -> 1477.1434 | I15: =H15+F15+E15 -> 27949.143 | J15: 30722 | K15: =IF(P14>O14,P14,O14) -> 2400 | L15: =$E$3*12 -> 2400 | M15: 0 | N15: =K15*(1+($E$2/$E$5))^($E$5*$E$6)-K15 -> 147.27252 | O15: =K15+L15+N15-M15 -> 4947.2725 | Q15: =IF(V14>U14,V14,U14) -> 2400 | R15: =$E$3*12 -> 2400 | S15: 0 | T15: =Q15*(1+($E$2/$E$5))^($E$5*$E$6)-Q15 -> 147.27252 | U15: =Q15+R15+T15-S15 -> 4947.2725 | W15: =SUM(I15+O15+U15)-X15 -> 37843.688 | X15: =SUM(S15+M15+G15) -> 0 | Y15: =SUM(J15+P15+V15) -> 30722
C16: =C15+1 -> 2024 | D16: =D15+1 -> 8 | E16: =IF(J15>I15,J15,I15) -> 30722 | F16: =$E$3*12 -> 2400 | G16: 0 | H16: =E16*(1+($E$2/$E$5))^($E$5*$E$6)-E16 -> 1885.211 | I16: =H16+F16+E16 -> 35007.211 | J16: 36848 | K16: =IF(P15>O15,P15,O15) -> 4947.2725 | L16: =$E$3*12 -> 2400 | M16: 0 | N16: =K16*(1+($E$2/$E$5))^($E$5*$E$6)-K16 -> 303.58221 | O16: =K16+L16+N16-M16 -> 7650.8547 | Q16: =IF(V15>U15,V15,U15) -> 4947.2725 | R16: =$E$3*12 -> 2400 | S16: 0 | T16: =Q16*(1+($E$2/$E$5))^($E$5*$E$6)-Q16 -> 303.58221 | U16: =Q16+R16+T16-S16 -> 7650.8547 | W16: =SUM(I16+O16+U16)-X16 -> 50308.92 | X16: =SUM(S16+M16+G16) -> 0 | Y16: =SUM(J16+P16+V16) -> 36848
C17: =C16+1 -> 2025 | D17: =D16+1 -> 9 | E17: =IF(J16>I16,J16,I16) -> 36848 | F17: =$E$3*12 -> 2400 | G17: 0 | H17: =E17*(1+($E$2/$E$5))^($E$5*$E$6)-E17 -> 2261.1241 | I17: =H17+F17+E17 -> 41509.124 | K17: =IF(P16>O16,P16,O16) -> 7650.8547 | L17: =$E$3*12 -> 2400 | M17: 0 | N17: =K17*(1+($E$2/$E$5))^($E$5*$E$6)-K17 -> 469.48361 | O17: =K17+L17+N17-M17 -> 10520.338 | Q17: =IF(V16>U16,V16,U16) -> 7650.8547 | R17: =$E$3*12 -> 2400 | S17: 0 | T17: =Q17*(1+($E$2/$E$5))^($E$5*$E$6)-Q17 -> 469.48361 | U17: =Q17+R17+T17-S17 -> 10520.338 | W17: =SUM(I17+O17+U17)-X17 -> 62549.801 | X17: =SUM(S17+M17+G17) -> 0 | Y17: =SUM(J17+P17+V17) -> 0
C18: =C17+1 -> 2026 | D18: =D17+1 -> 10 | E18: =IF(J17>I17,J17,I17) -> 41509.124 | F18: =$E$3*12 -> 2400 | G18: 0 | H18: =E18*(1+($E$2/$E$5))^($E$5*$E$6)-E18 -> 2547.1472 | I18: =H18+F18+E18 -> 46456.271 | K18: =IF(P17>O17,P17,O17) -> 10520.338 | L18: =$E$3*12 -> 2400 | M18: 0 | N18: =K18*(1+($E$2/$E$5))^($E$5*$E$6)-K18 -> 645.56531 | O18: =K18+L18+N18-M18 -> 13565.904 | Q18: =IF(V17>U17,V17,U17) -> 10520.338 | R18: =$E$3*12 -> 2400 | S18: 0 | T18: =Q18*(1+($E$2/$E$5))^($E$5*$E$6)-Q18 -> 645.56531 | U18: =Q18+R18+T18-S18 -> 13565.904 | W18: =SUM(I18+O18+U18)-X18 -> 73588.079 | X18: =SUM(S18+M18+G18) -> 0 | Y18: =SUM(J18+P18+V18) -> 0
C19: =C18+1 -> 2027 | D19: =D18+1 -> 11 | E19: =IF(J18>I18,J18,I18) -> 46456.271 | F19: =$E$3*12 -> 2400 | G19: 0 | H19: =E19*(1+($E$2/$E$5))^($E$5*$E$6)-E19 -> 2850.7218 | I19: =H19+F19+E19 -> 51706.993 | K19: =IF(P18>O18,P18,O18) -> 13565.904 | L19: =$E$3*12 -> 2400 | M19: 0 | N19: =K19*(1+($E$2/$E$5))^($E$5*$E$6)-K19 -> 832.45202 | O19: =K19+L19+N19-M19 -> 16798.356 | Q19: =IF(V18>U18,V18,U18) -> 13565.904 | R19: =$E$3*12 -> 2400 | S19: 0 | T19: =Q19*(1+($E$2/$E$5))^($E$5*$E$6)-Q19 -> 832.45202 | U19: =Q19+R19+T19-S19 -> 16798.356 | W19: =SUM(I19+O19+U19)-X19 -> 85303.704 | X19: =SUM(S19+M19+G19) -> 0 | Y19: =SUM(J19+P19+V19) -> 0
C20: =C19+1 -> 2028 | D20: =D19+1 -> 12 | E20: =IF(J19>I19,J19,I19) -> 51706.993 | F20: =$E$3*12 -> 2400 | G20: 0 | H20: =E20*(1+($E$2/$E$5))^($E$5*$E$6)-E20 -> 3172.9247 | I20: =H20+F20+E20 -> 57279.918 | K20: =IF(P19>O19,P19,O19) -> 16798.356 | L20: =$E$3*12 -> 2400 | M20: 0 | N20: =K20*(1+($E$2/$E$5))^($E$5*$E$6)-K20 -> 1030.8067 | O20: =K20+L20+N20-M20 -> 20229.162 | Q20: =IF(V19>U19,V19,U19) -> 16798.356 | R20: =$E$3*12 -> 2400 | S20: 0 | T20: =Q20*(1+($E$2/$E$5))^($E$5*$E$6)-Q20 -> 1030.8067 | U20: =Q20+R20+T20-S20 -> 20229.162 | W20: =SUM(I20+O20+U20)-X20 -> 97738.243 | X20: =SUM(S20+M20+G20) -> 0 | Y20: =SUM(J20+P20+V20) -> 0
C21: =C20+1 -> 2029 | D21: =D20+1 -> 13 | E21: =IF(J20>I20,J20,I20) -> 57279.918 | F21: =$E$3*12 -> 2400 | G21: 0 | H21: =E21*(1+($E$2/$E$5))^($E$5*$E$6)-E21 -> 3514.8991 | I21: =H21+F21+E21 -> 63194.817 | K21: =IF(P20>O20,P20,O20) -> 20229.162 | L21: =$E$3*12 -> 2400 | M21: 0 | N21: =K21*(1+($E$2/$E$5))^($E$5*$E$6)-K21 -> 1241.3332 | O21: =K21+L21+N21-M21 -> 23870.496 | Q21: =IF(V20>U20,V20,U20) -> 20229.162 | R21: =$E$3*12 -> 2400 | S21: 0 | T21: =Q21*(1+($E$2/$E$5))^($E$5*$E$6)-Q21 -> 1241.3332 | U21: =Q21+R21+T21-S21 -> 23870.496 | W21: =SUM(I21+O21+U21)-X21 -> 110935.81 | X21: =SUM(S21+M21+G21) -> 0 | Y21: =SUM(J21+P21+V21) -> 0
C22: =C21+1 -> 2030 | D22: =D21+1 -> 14 | E22: =IF(J21>I21,J21,I21) -> 63194.817 | F22: =$E$3*12 -> 2400 | G22: 0 | H22: =E22*(1+($E$2/$E$5))^($E$5*$E$6)-E22 -> 3877.8583 | I22: =H22+F22+E22 -> 69472.675 | K22: =IF(P21>O21,P21,O21) -> 23870.496 | L22: =$E$3*12 -> 2400 | M22: 0 | N22: =K22*(1+($E$2/$E$5))^($E$5*$E$6)-K22 -> 1464.7784 | O22: =K22+L22+N22-M22 -> 27735.274 | Q22: =IF(V21>U21,V21,U21) -> 23870.496 | R22: =$E$3*12 -> 2400 | S22: 0 | T22: =Q22*(1+($E$2/$E$5))^($E$5*$E$6)-Q22 -> 1464.7784 | U22: =Q22+R22+T22-S22 -> 27735.274 | W22: =SUM(I22+O22+U22)-X22 -> 124943.22 | X22: =SUM(S22+M22+G22) -> 0 | Y22: =SUM(J22+P22+V22) -> 0
C23: =C22+1 -> 2031 | D23: =D22+1 -> 15 | E23: =IF(J22>I22,J22,I22) -> 69472.675 | F23: =$E$3*12 -> 2400 | G23: 0 | H23: =E23*(1+($E$2/$E$5))^($E$5*$E$6)-E23 -> 4263.09 | I23: =H23+F23+E23 -> 76135.765 | K23: =IF(P22>O22,P22,O22) -> 27735.274 | L23: =$E$3*12 -> 2400 | M23: 0 | N23: =K23*(1+($E$2/$E$5))^($E$5*$E$6)-K23 -> 1701.9349 | O23: =K23+L23+N23-M23 -> 31837.209 | Q23: =IF(V22>U22,V22,U22) -> 27735.274 | R23: =$E$3*12 -> 2400 | S23: 0 | T23: =Q23*(1+($E$2/$E$5))^($E$5*$E$6)-Q23 -> 1701.9349 | U23: =Q23+R23+T23-S23 -> 31837.209 | W23: =SUM(I23+O23+U23)-X23 -> 139810.18 | X23: =SUM(S23+M23+G23) -> 0 | Y23: =SUM(J23+P23+V23) -> 0
C24: =C23+1 -> 2032 | D24: =D23+1 -> 16 | E24: =IF(J23>I23,J23,I23) -> 76135.765 | F24: =$E$3*12 -> 2400 | G24: 0 | H24: =E24*(1+($E$2/$E$5))^($E$5*$E$6)-E24 -> 4671.9609 | I24: =H24+F24+E24 -> 83207.726 | K24: =IF(P23>O23,P23,O23) -> 31837.209 | L24: =$E$3*12 -> 2400 | M24: 0 | N24: =K24*(1+($E$2/$E$5))^($E$5*$E$6)-K24 -> 1953.6442 | O24: =K24+L24+N24-M24 -> 36190.853 | Q24: =IF(V23>U23,V23,U23) -> 31837.209 | R24: =$E$3*12 -> 2400 | S24: 0 | T24: =Q24*(1+($E$2/$E$5))^($E$5*$E$6)-Q24 -> 1953.6442 | U24: =Q24+R24+T24-S24 -> 36190.853 | W24: =SUM(I24+O24+U24)-X24 -> 155589.43 | X24: =SUM(S24+M24+G24) -> 0 | Y24: =SUM(J24+P24+V24) -> 0
C25: =C24+1 -> 2033 | D25: =D24+1 -> 17 | E25: =IF(J24>I24,J24,I24) -> 83207.726 | F25: =$E$3*12 -> 2400 | G25: 0 | H25: =E25*(1+($E$2/$E$5))^($E$5*$E$6)-E25 -> 5105.9215 | I25: =H25+F25+E25 -> 90713.648 | K25: =IF(P24>O24,P24,O24) -> 36190.853 | L25: =$E$3*12 -> 2400 | M25: 0 | N25: =K25*(1+($E$2/$E$5))^($E$5*$E$6)-K25 -> 2220.7992 | O25: =K25+L25+N25-M25 -> 40811.652 | Q25: =IF(V24>U24,V24,U24) -> 36190.853 | R25: =$E$3*12 -> 2400 | S25: 0 | T25: =Q25*(1+($E$2/$E$5))^($E$5*$E$6)-Q25 -> 2220.7992 | U25: =Q25+R25+T25-S25 -> 40811.652 | W25: =SUM(I25+O25+U25)-X25 -> 172336.95 | X25: =SUM(S25+M25+G25) -> 0 | Y25: =SUM(J25+P25+V25) -> 0
A26: Hudson 18 | B26: 49280 | C26: =C25+1 -> 2034 | D26: =D25+1 -> 18 | E26: =IF(J25>I25,J25,I25) -> 90713.648 | F26: =$E$3*12 -> 2400 | G26: 0 | H26: =E26*(1+($E$2/$E$5))^($E$5*$E$6)-E26 -> 5566.5115 | I26: =H26+F26+E26 -> 98680.159 | K26: =IF(P25>O25,P25,O25) -> 40811.652 | L26: =$E$3*12 -> 2400 | M26: 0 | N26: =K26*(1+($E$2/$E$5))^($E$5*$E$6)-K26 -> 2504.3479 | O26: =K26+L26+N26-M26 -> 45716 | Q26: =IF(V25>U25,V25,U25) -> 40811.652 | R26: =$E$3*12 -> 2400 | S26: 0 | T26: =Q26*(1+($E$2/$E$5))^($E$5*$E$6)-Q26 -> 2504.3479 | U26: =Q26+R26+T26-S26 -> 45716 | W26: =SUM(I26+O26+U26)-X26 -> 190112.16 | X26: =SUM(S26+M26+G26) -> 0 | Y26: =SUM(J26+P26+V26) -> 0
C27: =C26+1 -> 2035 | D27: =D26+1 -> 19 | E27: =IF(J26>I26,J26,I26) -> 98680.159 | F27: =$E$3*12 -> 2400 | G27: =$E$4 -> 25000 | H27: =E27*(1+($E$2/$E$5))^($E$5*$E$6)-E27 -> 6055.3649 | I27: =H27+F27+E27-G27 -> 82135.524 | K27: =IF(P26>O26,P26,O26) -> 45716 | L27: =$E$3*12 -> 2400 | M27: 0 | N27: =K27*(1+($E$2/$E$5))^($E$5*$E$6)-K27 -> 2805.2961 | O27: =K27+L27+N27-M27 -> 50921.296 | Q27: =IF(V26>U26,V26,U26) -> 45716 | R27: =$E$3*12 -> 2400 | S27: 0 | T27: =Q27*(1+($E$2/$E$5))^($E$5*$E$6)-Q27 -> 2805.2961 | U27: =Q27+R27+T27-S27 -> 50921.296 | W27: =SUM(I27+O27+U27)-X27 -> 158978.12 | X27: =SUM(S27+M27+G27) -> 25000 | Y27: =SUM(J27+P27+V27) -> 0
A28: Riley 18 | B28: 49879 | C28: =C27+1 -> 2036 | D28: =D27+1 -> 20 | E28: =IF(J27>I27,J27,I27) -> 82135.524 | F28: =$E$3*12 -> 2400 | G28: =$E$4 -> 25000 | H28: =E28*(1+($E$2/$E$5))^($E$5*$E$6)-E28 -> 5040.1274 | I28: =H28+F28+E28-G28 -> 64575.652 | K28: =IF(P27>O27,P27,O27) -> 50921.296 | L28: =$E$3*12 -> 2400 | M28: =$E$4 -> 25000 | N28: =K28*(1+($E$2/$E$5))^($E$5*$E$6)-K28 -> 3124.7115 | O28: =K28+L28+N28-M28 -> 31446.008 | Q28: =IF(V27>U27,V27,U27) -> 50921.296 | R28: =$E$3*12 -> 2400 | S28: 0 | T28: =Q28*(1+($E$2/$E$5))^($E$5*$E$6)-Q28 -> 3124.7115 | U28: =Q28+R28+T28-S28 -> 56446.008 | W28: =SUM(I28+O28+U28)-X28 -> 102467.67 | X28: =SUM(S28+M28+G28) -> 50000 | Y28: =SUM(J28+P28+V28) -> 0
C29: =C28+1 -> 2037 | D29: =D28+1 -> 21 | E29: =IF(J28>I28,J28,I28) -> 64575.652 | F29: =$E$3*12 -> 2400 | G29: =$E$4 -> 25000 | H29: =E29*(1+($E$2/$E$5))^($E$5*$E$6)-E29 -> 3962.5913 | I29: =H29+F29+E29-G29 -> 45938.243 | K29: =IF(P28>O28,P28,O28) -> 31446.008 | L29: =$E$3*12 -> 2400 | M29: =$E$4 -> 25000 | N29: =K29*(1+($E$2/$E$5))^($E$5*$E$6)-K29 -> 1929.6387 | O29: =K29+L29+N29-M29 -> 10775.647 | Q29: =IF(V28>U28,V28,U28) -> 56446.008 | R29: =$E$3*12 -> 2400 | S29: 0 | T29: =Q29*(1+($E$2/$E$5))^($E$5*$E$6)-Q29 -> 3463.7275 | U29: =Q29+R29+T29-S29 -> 62309.735 | W29: =SUM(I29+O29+U29)-X29 -> 69023.625 | X29: =SUM(S29+M29+G29) -> 50000 | Y29: =SUM(J29+P29+V29) -> 0
A30: Hudson 22 | B30: 50741 | C30: =C29+1 -> 2038 | D30: =D29+1 -> 22 | E30: =IF(J29>I29,J29,I29) -> 45938.243 | F30: =$E$3*12 -> 2400 | G30: =$E$4 -> 25000 | H30: =E30*(1+($E$2/$E$5))^($E$5*$E$6)-E30 -> 2818.9337 | I30: =H30+F30+E30-G30 -> 26157.177 | K30: =IF(P29>O29,P29,O29) -> 10775.647 | L30: =$E$3*12 -> 2400 | M30: =$E$4 -> 25000 | N30: =K30*(1+($E$2/$E$5))^($E$5*$E$6)-K30 -> 661.23193 | O30: =K30+L30+N30-M30 -> -11163.121 | Q30: =IF(V29>U29,V29,U29) -> 62309.735 | R30: =$E$3*12 -> 2400 | S30: 0 | T30: =Q30*(1+($E$2/$E$5))^($E$5*$E$6)-Q30 -> 3823.5466 | U30: =Q30+R30+T30-S30 -> 68533.282 | W30: =SUM(I30+O30+U30)-X30 -> 33527.337 | X30: =SUM(S30+M30+G30) -> 50000 | Y30: =SUM(J30+P30+V30) -> 0
A31: Sunny 18 | B31: 51066 | C31: =C30+1 -> 2039 | D31: =D30+1 -> 23 | E31: =IF(J30>I30,J30,I30) -> 26157.177 | F31: =$E$3*12 -> 2400 | G31: =$E$4 -> 25000 | H31: =E31*(1+($E$2/$E$5))^($E$5*$E$6)-E31 -> 1605.0972 | I31: =H31+F31+E31-G31 -> 5162.2738 | K31: =IF(P30>O30,P30,O30) -> 0 | L31: =$E$3*12 -> 2400 | M31: =$E$4 -> 25000 | N31: =K31*(1+($E$2/$E$5))^($E$5*$E$6)-K31 -> 0 | O31: =K31+L31+N31-M31 -> -22600 | Q31: =IF(V30>U30,V30,U30) -> 68533.282 | R31: =$E$3*12 -> 2400 | S31: =$E$4 -> 25000 | T31: =Q31*(1+($E$2/$E$5))^($E$5*$E$6)-Q31 -> 4205.4455 | U31: =Q31+R31+T31-S31 -> 50138.727 | W31: =SUM(I31+O31+U31)-X31 -> -42298.999 | X31: =SUM(S31+M31+G31) -> 75000 | Y31: =SUM(J31+P31+V31) -> 0
