Workbook

Sheet Sheet3
A1: 4488
A2: 4714
A3: 432.25
A4: 3669
A5: 4519
A6: 2451.25
A7: 472
A8: 1325
A9: 4235.25
A10: 4879
A11: 4984
A12: 4364.25
... A52: 1892

Sheet Chapter 1
B2: Personal Financial Statement | I2: Liquid Assets | L2: Investable Assets | O2: Savings Rate
B3: 1. Assets | O3: 3 Images from Savings Rate Table
B4: 2. Liabilities | O4: Income
B5: 3. Full PFS | O5: Expenses
O6: Total
B7: PERSONAL FINANCIAL STATEMENT: John Robinson
B8: As of December 31, 2022
B10: Assets | E10: Liabilities | I10: LIQUID ASSETS: John Robinson | L10: INVESTABLE ASSETS: John Robinson | O10: SAVINGS RATE: John Robinson
I11: As of December 31, 2022 | L11: As of December 31, 2022 | O11: As of December 31, 2022
C12: Estimated Value | F12: Estimated Value | I12: Cash or Cash Equivalent
B13: Cash or Cash Equivalent | E13: Loans | I13: Cash on Hand | J13: =C14 -> 200 | L13: Monthly Income | M13: =S26 -> 4000 | O13: Income | R13: Expenses
B14: Cash on Hand | C14: 200 | E14: Mortgage - Personal Residence | F14: 138200 | I14: Bank - Checking Account | J14: =C15 -> 20000 | L14: Desired Reserve (months) | M14: 3
B15: Bank - Checking Account | C15: 20000 | E15: School Loan | F15: 26300 | L15: Required Reserve ($) | M15: =M14*S26 -> 12000 | P15: Estimated Value | S15: Estimated Value
B16: Money Owed from Bill Jones | C16: 5000 | E16: Car Loan | F16: 3200 | I16: Investments | O16: Cash or Cash Equivalent | R16: Expenses
I17: Stocks | J17: =C22 -> 3200 | L17: Liquid Assets | M17: =J20 -> 24200 | O17: Monthly Salary | P17: 4500 | R17: Tax Withholdings | S17: =P17*0.3 -> 1350
B18: Retirement Accounts | E18: Revolving Debt | I18: Bonds | J18: =C23 -> 800 | L18: Required Reserves | M18: =-M15 -> -12000 | O18: Ridesharing Income | P18: 500 | R18: Mortgage Payments | S18: 1150
B19: Self-Directed IRA | C19: 54500 | E19: Credit Cards | F19: 6800 | R19: Student Loan Payments | S19: 200
I20: Total Liquid Assets | J20: =SUM(J13:J18) -> 24200 | L20: Investable Assets | M20: =M17-M15 -> 12200 | R20: Food & Groceries | S20: 400
B21: Investments | E21: Other | R21: Entertainment | S21: 300
B22: Stocks | C22: 3200 | E22: Estimated Taxes Owed on April 15 | F22: 18000 | R22: Car Loan payments | S22: 200
B23: Bonds | C23: 800 | R23: Gas | S23: 100
R24: Misc. | S24: 300
B25: Business Interests
B26: ABC Properties, LLC | C26: 65000 | I26: LIQUID ASSETS: John Robinson | O26: Total Income | P26: =SUM(P17:P23) -> 5000 | R26: Total Expenses | S26: =SUM(S17:S24) -> 4000
I27: As of December 31, 2022
B28: Real/Personal Property Owned | R28: Savings Rate | S28: =P26-S26 -> 1000
B29: Personal Residence | C29: 185000 | I29: Starting Liquid Assets | J29: 24200
B30: 2013 Honda CRV | C30: 7000 | I30: Investment Amount | J30: 20000
B31: Furniture and Household Goods | C31: 5000 | I31: Ending Liquid Assets | J31: =J29-J30 -> 4200 | R31: VARIABLE INCOME: John Robinson
B32: Jewelry | C32: 2000
R33: Rideshare Income May | S33: 350
B34: Assets Total | C34: =SUM(C14:C33) -> 347700 | E34: Liabilities Total | F34: =SUM(F14:F33) -> 192500 | R34: Rideshare Income June | S34: 475
R35: Rideshare Income July | S35: 675
E36: Estimated Net Worth: | F36: =C34-F34 -> 155200 | R36: Average Income | S36: =AVERAGE(S33:S35) -> 500
R39: VARIABLE EXPENSES: John Robinson
R41: May Expenses | S41: 3100
R42: June Expenses | S42: 3450
R43: July Expenses | S43: 3050
R44: Average Expenses | S44: =AVERAGE(S41:S43) -> 3200
R47: Month | S47: Savings Rate | T47: Investment(s) | U47: Liquid Assets
...

Sheet IP Examples
C2: 457 Main St. | D2: 38 Holland Dr. | E2: 845 Chestnut Rd.
C3: Rental | D3: STR | E3: House Hack | J3: * different down payment amounts for House hack
B4: Price | C4: 122000 | D4: 175000 | E4: 165000 | J4: * interest only vs fully amortized for STR
B5: Expected Down Payment | C5: =C4*0.25 -> 30500 | D5: =D4*0.25 -> 43750 | E5: =E4*0.1 -> 16500 | J5: * Two interest rates
B6: Closing Costs | C6: 6000 | D6: 6000 | E6: 4500 | J6: * play our scenarios and explain pros/cons of each
B7: Reserve Funds | C7: =C4*0.05 -> 6100 | D7: =D4*0.08 -> 14000 | E7: =E4*0.05 -> 8250 | J7: * should we model an equity partner scenario? Maybe we do this in the flipping section?
B8: Cash Needed | C8: =SUM(C5:C7) -> 42600 | D8: =SUM(D5:D7) -> 63750 | E8: =SUM(E5:E7) -> 29250
B9: Cash on Hand | C9: ='Example PFS'!J47 -> 12200 | D9: =C9 -> 12200 | E9: =D9 -> 12200
B10: Cash Remaining | C10: =C9-C8 -> -30400 | D10: =D9-D8 -> -51550 | E10: =E9-E8 -> -17050
B11: Time to Afford (Months) | C11: =IF(C10>0, "Now", C10/'Example PFS'!$F$55) -> -30.4 | D11: =IF(D10>0, "Now", -D10/'Example PFS'!$F$55) -> 51.55 | E11: =IF(E10>0, "Now", E10/'Example PFS'!$F$55) -> -17.05
B16: Loan Option 1 | C16: 457 Main St. | D16: 457 Main St. | E16: 38 Holland Dr. | F16: 38 Holland Dr. | G16: 845 Chestnut Rd. | H16: 845 Chestnut Rd. | L16: Same property, different strategies?
B17: Purchase Price | C17: 122000 | D17: 122000 | E17: 175000 | F17: 175000 | G17: 165000 | H17: 165000 | L17: 3 different properties?
B18: Down Payment (%) | C18: 0.25 | D18: 0.25 | E18: 0.25 | F18: 0.25 | G18: 0.05 | H18: 0.2 | L18: * bonus videos of doing this analysis
B19: Loan Amount (Principal) | C19: 91500 | D19: 91500 | E19: =(1-E18)*E17 -> 131250 | F19: 131250 | G19: 156750 | H19: 132000 | L19: *
B20: Annual Interest Rate | C20: 0.04 | D20: 0.035 | E20: 0.0425 | F20: 0.035 | G20: 0.035 | H20: 0.035
B21: Term (Years) | C21: 30 | D21: 30 | E21: 30 | F21: 30 | G21: 30 | H21: 30
B22: Payments/year | C22: 12 | D22: 12 | E22: 12 | F22: 12 | G22: 12 | H22: 12
B23: Total Payments | C23: 360 | D23: 360 | E23: =E22*E21 -> 360 | F23: 360 | G23: 360 | H23: 360
B24: Payment per Period | C24: 436.835 | D24: 410.87589 | E24: =-PMT(E20/E22, E23, E19, 0) -> 645.67111 | F24: 589.37115 | G24: 703.87755 | H24: 592.73899
B25: PMI per Period | C25: 0 | D25: 0 | E25: 0 | F25: 0 | G25: 82 | H25: 0
B26: Sum of Payments | C26: 157260.6 | D26: 147915.32 | E26: =E24*E23 -> 232441.6 | F26: 212173.61 | G26: =253395.91733052+(G25*G23) -> 282915.92 | H26: 213386.04
B27: Interest Cost + PMI | C27: 65760.598 | D27: 56415.32 | E27: =E26-E19 -> 101191.6 | F27: 80923.615 | G27: =96645.9173305196+G25*G23 -> 126165.92 | H27: 81386.036
B28: Estimated Closing Costs | C28: 6000 | D28: 6000 | E28: 6000 | F28: 6000 | G28: 4500 | H28: 4500
B30: Loan Constant | C30: =((SUM(C24:C25)*12)/C19) -> 0.057289835 | D30: =((SUM(D24:D25)*12)/D19) -> 0.053885363 | E30: =((SUM(E24:E25)*12)/E19) -> 0.059032787 | F30: =((SUM(F24:F25)*12)/F19) -> 0.053885363 | G30: =((SUM(G24:G25)*12)/G19) -> 0.060162874 | H30: =((SUM(H24:H25)*12)/H19) -> 0.053885363
B31: Cap Rate
B32: Breakeven loan value
B35: Income Property Pro Forma

Sheet Chapter 2
B2: All images in Chapter 2 derived from this table
B5: BALANCE SHEET
B6: For Year Ending December 31, 2022
B8: ASSETS
B9: Investment in 123 Main Street
B10: Land | C10: 75462
B11: Buildings/Improvements | C11: =281559-7021 -> 274538
B12: Furniture & Fixtures | C12: 8254
B13: Accumulated Depreciation | C13: =-27115+7021 -> -20094
C14: =SUM(C10:C13) -> 338160
B16: Other Assets
B17: Cash in Operating Account | C17: 16581
B18: Replacement Reserves | C18: 14000
B19: Rents Receivable | C19: 2220
C20: =SUM(C17:C19) -> 32801
B22: TOTAL ASSETS | C22: =C14+C20 -> 370961
B24: LIABILITIES & OWNER EQUITY
B25: Liabilities
B26: Mortgage Principal Balance | C26: 276841
B27: Accounts Payable | C27: 16875
B28: Taxes Payable | C28: 12254
B29: Tenant Security Deposits | C29: 8450
B30: TOTAL LIABILITIES | C30: =SUM(C26:C29) -> 314420
B32: Owner Equity
B33: Initial Contributions | C33: 40000
B34: Retained Earnings | C34: =C22-C30-C33 -> 16541
B35: TOTAL OWNER EQUITY | C35: =SUM(C31:C34) -> 56541
B37: TOTAL LIABILITIES & OWNER EQUITY | C37: =C30+C35 -> 370961

Sheet Chapter 3
B2: All images in Chapter 3 derived from these 2 tables
B5: PROFIT & LOSS STATEMENT - GREAT FLIPS, LLC | E5: PROFIT & LOSS STATEMENT - GREAT FLIPS, LLC
B6: For the Fiscal Year 2022 (Jan. 1–Dec. 31, 2022) | E6: For the Fiscal Year 2022 (Jan. 1–Dec. 31, 2022)
B8: INCOME | E8: INCOME
B9: Revenue Source #1 | C9: 0 | E9: Revenue from Sale of Properties | F9: 375000
B10: Revenue Source #2 | C10: 0 | E10: Revenue from Commissions | F10: 25000
B11: … | E11: …
B12: TOTAL INCOME: | C12: 0 | E12: TOTAL INCOME | F12: =F9+F10 -> 400000
B14: Cost of Goods Sold (COGS) #1 | C14: 0 | E14: Property Purchase Costs | F14: 120000
B15: Cost of Goods Sold (COGS) #2 | C15: 0 | E15: Rehab Labor | F15: 75000
B16: … | E16: Rehab Materials | F16: 30000
B17: TOTAL COGS: | C17: 0 | E17: Closing Costs | F17: 6000
E18: TOTAL COGS | F18: =SUM(F14:F17) -> 231000
B19: GROSS PROFIT: | C19: 0
E20: GROSS PROFIT | F20: =F12-F18 -> 169000
B21: EXPENSES
B22: Expense Source #1 | C22: 0 | E22: EXPENSES
B23: Expense Source #2 | C23: 0 | E23: Rent | F23: 7200
B24: … | E24: Owner Salary | F24: 50000
B25: TOTAL OPERATING EXPENSES: | C25: 0 | E25: Insurance | F25: 2500
E26: Office Supplies | F26: 300
B27: OPERATING INCOME: | C27: 0
E28: Tools | F28: 2200
E30: Utilities | F30: 1800
E31: TOTAL OPERATING EXPENSES: | F31: =SUM(F23:F30) -> 64000
E33: OPERATING INCOME: | F33: =F20-F31 -> 105000
E35: 2022 Taxes | F35: 21000
E37: NET INCOME: | F37: =F33-F35 -> 84000
E39: Gross Profit Margin | F39: =F20/F12 -> 0.4225
E40: Operating Profit Margin | F40: =F33/F12 -> 0.2625
E41: Net Profit Margin | F41: =F37/F12 -> 0.21

Sheet Chapter 4
B2: All images in Chapter 4 derived from these 2 tables
E6: PROFIT & LOSS STATEMENT - Catherine Corp.
E7: For the Fiscal Year 2022 (Jan. 1 - Dec. 31, 2022)
B8: INCOME | E8: INCOME
B9: Gross Potential Rent | C9: - | E9: Gross Potential Rent | F9: 120000
B10: Rent Loss | C10: - | E10: Rent Loss | F10: -12000
B11: Other Income | C11: - | E11: Other Income | F11: 3000
B12: GROSS OPERATING INCOME: | C12: - | E12: GROSS OPERATING INCOME: | F12: 111000
E13: EXPENSES
E14: Property Taxes | F14: 5250
B15: EXPENSES | E15: Insurance | F15: 2810
B16: Property Taxes | C16: - | E16: Property Management | F16: 8640
B17: Insurance | C17: - | E17: Turnover | F17: 4800
B18: Property Management | C18: - | E18: Repairs & Maintenance | F18: 10000
B19: Turnover | C19: - | E19: Utilities | F19: 400
B20: Repairs & Maintenance | C20: - | E20: Lawn Care | F20: 3600
B21: Utilities | C21: - | E21: Snow Removal | F21: 0
B22: Lawn Care | C22: - | E22: Dumpster/Trash Removal | F22: 0
B23: Snow Removal | C23: - | E23: Grounds Cleanup | F23: 3000
B24: Dumpster/Trash Removal | C24: - | E24: Office Costs | F24: 0
B25: Grounds Cleanup | C25: - | E25: Legal | F25: 0
B26: Office Costs | C26: - | E26: Accounting | F26: 1500
B27: Legal | C27: - | E27: OPERATING EXPENSES: | F27: 40000
B28: Accounting | C28: - | E28: NET OPERATING INCOME: | F28: 71000
E29: Debt Service | F29: -40200
E30: Capital Expenses | F30: -5000
E31: CASH FLOW BEFORE TAX | F31: =SUM(F28:F30) -> 25800

Sheet Chapter 6
C6: Year-End Balance | D6: Interest Rate | E6: Annual Profit
B7: Year 1 | C7: 10000 | D7: 0.05 | E7: =D7*C7 -> 500
B8: Year 2 | C8: 10000 | D8: 0.05 | E8: =D8*C8 -> 500
B9: Year 3 | C9: 10000 | D9: 0.05 | E9: =D9*C9 -> 500
B10: Year 4 | C10: 10000 | D10: 0.05 | E10: =D10*C10 -> 500
B11: Year 5 | C11: 10000 | D11: 0.05 | E11: =D11*C11 -> 500
C14: Year-End Balance | D14: Interest Rate | E14: Annual Profit
B15: Year 1 | C15: 10000 | D15: 0.05 | E15: =D15*C15 -> 500
B16: Year 2 | C16: =C15+E15 -> 10500 | D16: 0.05 | E16: =D16*C16 -> 525
B17: Year 3 | C17: =C16+E16 -> 11025 | D17: 0.05 | E17: =D17*C17 -> 551.25
B18: Year 4 | C18: =C17+E17 -> 11576.25 | D18: 0.05 | E18: =D18*C18 -> 578.8125
B19: Year 5 | C19: =C18+E18 -> 12155.062 | D19: 0.05 | E19: =D19*C19 -> 607.75313
B27: Compounding
B28: Year | C28: Compounding Interest | D28: Simple Interest | E28: Interest Rate | F28: Compounding vs. Simple % Difference
B29: 0 | C29: 10000 | D29: 10000 | E29: 0.08
B30: 1 | C30: =C29*(1+E29) -> 10800 | D30: =D29+(C$29*E30) -> 10800 | E30: 0.08 | F30: =C30/D30-1 -> 0
B31: 2 | C31: =C30*(1+E30) -> 11664 | D31: =D30+(C$29*E31) -> 11600 | E31: 0.08 | F31: =C31/D31-1 -> 0.0055172414
B32: 3 | C32: =C31*(1+E31) -> 12597.12 | D32: =D31+(C$29*E32) -> 12400 | E32: 0.08 | F32: =C32/D32-1 -> 0.015896774
B33: 4 | C33: =C32*(1+E32) -> 13604.89 | D33: =D32+(C$29*E33) -> 13200 | E33: 0.08 | F33: =C33/D33-1 -> 0.030673455
B34: 5 | C34: =C33*(1+E33) -> 14693.281 | D34: =D33+(C$29*E34) -> 14000 | E34: 0.08 | F34: =C34/D34-1 -> 0.049520055
B35: 6 | C35: =C34*(1+E34) -> 15868.743 | D35: =D34+(C$29*E35) -> 14800 | E35: 0.08 | F35: =C35/D35-1 -> 0.07221238
B36: 7 | C36: =C35*(1+E35) -> 17138.243 | D36: =D35+(C$29*E36) -> 15600 | E36: 0.08 | F36: =C36/D36-1 -> 0.0986053
B37: 8 | C37: =C36*(1+E36) -> 18509.302 | D37: =D36+(C$29*E37) -> 16400 | E37: 0.08 | F37: =C37/D37-1 -> 0.12861598
B38: 9 | C38: =C37*(1+E37) -> 19990.046 | D38: =D37+(C$29*E38) -> 17200 | E38: 0.08 | F38: =C38/D38-1 -> 0.16221199
B39: 10 | C39: =C38*(1+E38) -> 21589.25 | D39: =D38+(C$29*E39) -> 18000 | E39: 0.08 | F39: =C39/D39-1 -> 0.19940278
B40: 11 | C40: =C39*(1+E39) -> 23316.39 | D40: =D39+(C$29*E40) -> 18800 | E40: 0.08 | F40: =C40/D40-1 -> 0.24023351
B41: 12 | C41: =C40*(1+E40) -> 25181.701 | D41: =D40+(C$29*E41) -> 19600 | E41: 0.08 | F41: =C41/D41-1 -> 0.28478067
... B59: 30 | C59: =C58*(1+E58) -> 100626.57 | D59: =D58+(C$29*E59) -> 34000 | E59: 0.08 | F59: =C59/D59-1 -> 1.959605

Sheet Chapter 8
B5: Month | C5: Principal | D5: ROR | E5: Return | H5: Month | I5: FV | J5: Discount Rate | K5: PV
B6: January | C6: 1000 | D6: 0.01 | E6: 10 | H6: December | I6: 1000 | J6: 0.01 | K6: 990.1
B7: February | C7: =C6+E6 -> 1010 | D7: 0.01 | E7: 10.1 | H7: November | I7: 990.1 | J7: 0.01 | K7: 980.3
B8: March | C8: =C7+E7 -> 1020.1 | D8: 0.01 | E8: 10.2 | H8: October | I8: 980.3 | J8: 0.01 | K8: 970.59
B9: April | C9: =C8+E8 -> 1030.3 | D9: 0.01 | E9: 10.3 | H9: September | I9: 970.59 | J9: 0.01 | K9: 960.98
B10: May | C10: =C9+E9 -> 1040.6 | D10: 0.01 | E10: 10.41 | H10: August | I10: 960.98 | J10: 0.01 | K10: 951.47
B11: June | C11: =C10+E10 -> 1051.01 | D11: 0.01 | E11: 10.51 | H11: July | I11: 951.47 | J11: 0.01 | K11: 942.05
B12: July | C12: =C11+E11 -> 1061.52 | D12: 0.01 | E12: 10.62 | H12: June | I12: 942.05 | J12: 0.01 | K12: 932.72
B13: August | C13: =C12+E12 -> 1072.14 | D13: 0.01 | E13: 10.72 | H13: May | I13: 932.72 | J13: 0.01 | K13: 923.48
B14: September | C14: =C13+E13 -> 1082.86 | D14: 0.01 | E14: 10.83 | H14: April | I14: 923.48 | J14: 0.01 | K14: 914.34
B15: October | C15: =C14+E14 -> 1093.69 | D15: 0.01 | E15: 10.94 | H15: March | I15: 914.34 | J15: 0.01 | K15: 905.29
B16: November | C16: =C15+E15 -> 1104.63 | D16: 0.01 | E16: 11.05 | H16: February | I16: 905.29 | J16: 0.01 | K16: 896.32
B17: December | C17: =C16+E16 -> 1115.68 | D17: 0.01 | E17: 11.16 | H17: January | I17: 896.32 | J17: 0.01 | K17: 887.45
B18: End of Year | C18: 1126.83 | J18: Present Value = | K18: 887.45

Sheet Chapter 9
B4: Year | C4: Property #1 | D4: Property #2 | F4: Discount Rate | G4: 0.08
B5: 1 | C5: 5000 | D5: 15000
B6: 2 | C6: 8000 | D6: 15000 | F6: Year | G6: Cash Flow | H6: Present Value | I6: Equation
B7: 3 | C7: 12000 | D7: 15000 | F7: 1 | G7: 200000 | H7: =G7/(1+$G$4)^F7 -> 185185.19 | I7: $200,000 ¸ ((1 + 0.08) ^ 1)
B8: 4 | C8: 125000 | D8: 105000 | F8: 2 | G8: 200000 | H8: =G8/(1+$G$4)^F8 -> 171467.76 | I8: $200,000 ¸ ((1 + 0.08) ^ 2)
B9: Totals: | C9: 150000 | D9: 150000 | F9: 3 | G9: 200000 | H9: =G9/(1+$G$4)^F9 -> 158766.45 | I9: $200,000 ¸ ((1 + 0.08) ^ 3)
F10: 4 | G10: 200000 | H10: =G10/(1+$G$4)^F10 -> 147005.97 | I10: $200,000 ¸ ((1 + 0.08) ^ 4)
F11: 5 | G11: 200000 | H11: =G11/(1+$G$4)^F11 -> 136116.64 | I11: $200,000 ¸ ((1 + 0.08) ^ 5)
F12: 6 | G12: 200000 | H12: =G12/(1+$G$4)^F12 -> 126033.93 | I12: $200,000 ¸ ((1 + 0.08) ^ 6)
B13: Property 1 | F13: 7 | G13: 200000 | H13: =G13/(1+$G$4)^F13 -> 116698.08 | I13: $200,000 ¸ ((1 + 0.08) ^ 7)
B14: Discount Rate | C14: 0.08 | F14: 8 | G14: 200000 | H14: =G14/(1+$G$4)^F14 -> 108053.78 | I14: $200,000 ¸ ((1 + 0.08) ^ 8)
F15: 9 | G15: 200000 | H15: =G15/(1+$G$4)^F15 -> 100049.79 | I15: $200,000 ¸ ((1 + 0.08) ^ 9)
B16: Year | C16: Cash Flow | D16: Present Value | F16: 10 | G16: 200000 | H16: =G16/(1+$G$4)^F16 -> 92638.698 | I16: $200,000 ¸ ((1 + 0.08) ^ 10)
B17: 1 | C17: 5000 | D17: =C17/(1+$C$14)^B17 -> 4629.6296 | F17: 11 | G17: 200000 | H17: =G17/(1+$G$4)^F17 -> 85776.572 | I17: $200,000 ¸ ((1 + 0.08) ^ 11)
B18: 2 | C18: 8000 | D18: =C18/(1+$C$14)^B18 -> 6858.7106 | F18: 12 | G18: 200000 | H18: =G18/(1+$G$4)^F18 -> 79422.752 | I18: $200,000 ¸ ((1 + 0.08) ^ 12)
B19: 3 | C19: 12000 | D19: =C19/(1+$C$14)^B19 -> 9525.9869 | F19: 13 | G19: 200000 | H19: =G19/(1+$G$4)^F19 -> 73539.585 | I19: $200,000 ¸ ((1 + 0.08) ^ 13)
B20: 4 | C20: 125000 | D20: =C20/(1+$C$14)^B20 -> 91878.732 | F20: 14 | G20: 200000 | H20: =G20/(1+$G$4)^F20 -> 68092.208 | I20: $200,000 ¸ ((1 + 0.08) ^ 14)
B21: Totals: | C21: 150000 | D21: =SUM(D17:D20) -> 112893.06 | F21: 15 | G21: 200000 | H21: =G21/(1+$G$4)^F21 -> 63048.341 | I21: $200,000 ¸ ((1 + 0.08) ^ 15)
F22: 16 | G22: 200000 | H22: =G22/(1+$G$4)^F22 -> 58378.094 | I22: $200,000 ¸ ((1 + 0.08) ^ 16)
F23: 17 | G23: 200000 | H23: =G23/(1+$G$4)^F23 -> 54053.79 | I23: $200,000 ¸ ((1 + 0.08) ^ 17)
B24: Property 2 | F24: 18 | G24: 200000 | H24: =G24/(1+$G$4)^F24 -> 50049.806 | I24: $200,000 ¸ ((1 + 0.08) ^ 18)
B25: Discount Rate | C25: 0.08 | F25: 19 | G25: 200000 | H25: =G25/(1+$G$4)^F25 -> 46342.413 | I25: $200,000 ¸ ((1 + 0.08) ^ 19)
F26: 20 | G26: 200000 | H26: =G26/(1+$G$4)^F26 -> 42909.641 | I26: $200,000 ¸ ((1 + 0.08) ^ 20)
B27: Year | C27: Cash Flow | D27: Present Value | F27: 21 | G27: 200000 | H27: =G27/(1+$G$4)^F27 -> 39731.15 | I27: $200,000 ¸ ((1 + 0.08) ^ 21)
B28: 1 | C28: 15000 | D28: =C28/(1+$C$25)^B28 -> 13888.889 | F28: 22 | G28: 200000 | H28: =G28/(1+$G$4)^F28 -> 36788.101 | I28: $200,000 ¸ ((1 + 0.08) ^ 22)
B29: 2 | C29: 15000 | D29: =C29/(1+$C$25)^B29 -> 12860.082 | F29: 23 | G29: 200000 | H29: =G29/(1+$G$4)^F29 -> 34063.057 | I29: $200,000 ¸ ((1 + 0.08) ^ 23)
B30: 3 | C30: 15000 | D30: =C30/(1+$C$25)^B30 -> 11907.484 | F30: 24 | G30: 200000 | H30: =G30/(1+$G$4)^F30 -> 31539.867 | I30: $200,000 ¸ ((1 + 0.08) ^ 24)
B31: 4 | C31: 105000 | D31: =C31/(1+$C$25)^B31 -> 77178.135 | F31: 25 | G31: 200000 | H31: =G31/(1+$G$4)^F31 -> 29203.581 | I31: $200,000 ¸ ((1 + 0.08) ^ 25)
B32: Totals: | C32: 150000 | D32: =SUM(D28:D31) -> 115834.59 | F32: Totals: | H32: =SUM(H7:H31) -> 2134955.2

Sheet Chapter 10
B2: Discount Rate | C2: 0.12
B3: Initial Cost | C3: 77000
C5: Year | D5: Cash Flow | E5: Present Value | F5: Formula
B6: 43831 | C6: 0 | D6: =-C3 -> -77000 | E6: =-C3 -> -77000
B7: 44197 | C7: 1 | D7: 9600 | E7: =D7/(1+C$2)^C7 -> 8571.4286 | F7: PV = (9,600 ÷ (1+.12)1
B8: 44562 | C8: 2 | D8: 9600 | E8: =D8/(1+C$2)^C8 -> 7653.0612 | F8: PV = (9,600 ÷ (1+.12)2
B9: 44927 | C9: 3 | D9: 9600 | E9: =D9/(1+C$2)^C9 -> 6833.0904 | F9: PV = (9,600 ÷ (1+.12)3
B10: 45292 | C10: 4 | D10: 9600 | E10: =D10/(1+C$2)^C10 -> 6100.9736 | F10: PV = (9,600 ÷ (1+.12)4
B11: 45658 | C11: 5 | D11: 9600 | E11: =D11/(1+C$2)^C11 -> 5447.2978 | F11: PV = (9,600 ÷ (1+.12)5
B12: 46023 | C12: 6 | D12: 9600 | E12: =D12/(1+C$2)^C12 -> 4863.6588 | F12: PV = (9,600 ÷ (1+.12)6
B13: 46388 | C13: 7 | D13: 9600 | E13: =D13/(1+C$2)^C13 -> 4342.5525 | F13: PV = (9,600 ÷ (1+.12)7
B14: 46753 | C14: 8 | D14: 9600 | E14: =D14/(1+C$2)^C14 -> 3877.279 | F14: PV = (9,600 ÷ (1+.12)8
B15: 47119 | C15: 9 | D15: 9600 | E15: =D15/(1+C$2)^C15 -> 3461.8562 | F15: PV = (9,600 ÷ (1+.12)9
B16: 47484 | C16: 10 | D16: 9600 | E16: =D16/(1+C$2)^C16 -> 3090.9431 | F16: PV = (9,600 ÷ (1+.12)10
C17: Net Present Value | E17: =SUM(E6:E16) -> -22757.859
C18: IRR | E18: =XIRR(D6:D16,B6:B16) -> 0.042209962
B22: Discount Rate | C22: 0.12
B23: Initial Cost | C23: 54242
C25: Year | D25: Cash Flow | E25: Present Value
B26: 43831 | C26: 0 | D26: =-C23 -> -54242 | E26: =-C23 -> -54242
B27: 44197 | C27: 1 | D27: 9600 | E27: =D27/(1+C$22)^C27 -> 8571.4286
B28: 44562 | C28: 2 | D28: 9600 | E28: =D28/(1+C$22)^C28 -> 7653.0612
B29: 44927 | C29: 3 | D29: 9600 | E29: =D29/(1+C$22)^C29 -> 6833.0904
B30: 45292 | C30: 4 | D30: 9600 | E30: =D30/(1+C$22)^C30 -> 6100.9736
B31: 45658 | C31: 5 | D31: 9600 | E31: =D31/(1+C$22)^C31 -> 5447.2978
B32: 46023 | C32: 6 | D32: 9600 | E32: =D32/(1+C$22)^C32 -> 4863.6588
B33: 46388 | C33: 7 | D33: 9600 | E33: =D33/(1+C$22)^C33 -> 4342.5525
B34: 46753 | C34: 8 | D34: 9600 | E34: =D34/(1+C$22)^C34 -> 3877.279
B35: 47119 | C35: 9 | D35: 9600 | E35: =D35/(1+C$22)^C35 -> 3461.8562
B36: 47484 | C36: 10 | D36: 9600 | E36: =D36/(1+C$22)^C36 -> 3090.9431
C37: Net Present Value | D37: =ROUND(NPV(C22, D27:D36)+D26,0) -> 0 | E37: =ROUND(SUM(E26:E36),0) -> 0 | G37: Added rounding functions here
C38: IRR | E38: =ROUND(XIRR(D26:D36,B26:B36),2) -> 0.12 | G38: Added rounding functions here
B42: Discount Rate | C42: 0.07
B43: Initial Cost | C43: 100000
C45: Year | D45: Cashflow | E45: Present Value
B46: 43831 | C46: 0 | D46: 50000 | E46: -100000
B47: 44197 | C47: 1 | D47: 1500 | E47: =D47/(1+$C$42)^C47 -> 1401.8692
B48: 44562 | C48: 2 | D48: 1500 | E48: =D48/(1+$C$42)^C48 -> 1310.1581
B49: 44927 | C49: 3 | D49: 1500 | E49: =D49/(1+$C$42)^C49 -> 1224.4468
B50: 45292 | C50: 4 | D50: 1500 | E50: =D50/(1+$C$42)^C50 -> 1144.3428
...

Sheet Chapter 11
B9: Discount Rate | C9: 0.05
B10: Initial Cost | C10: 100000
C12: Year | D12: Cashflow | E12: Present Value
B13: 43831 | C13: 0 | D13: -100000 | E13: -100000
B14: 44197 | C14: 1 | D14: 2000 | E14: =D14/(1+$C$9)^C14 -> 1904.7619
B15: 44562 | C15: 2 | D15: 2000 | E15: =D15/(1+$C$9)^C15 -> 1814.059
B16: 44927 | C16: 3 | D16: 2000 | E16: =D16/(1+$C$9)^C16 -> 1727.6752
B17: 45292 | C17: 4 | D17: 2000 | E17: =D17/(1+$C$9)^C17 -> 1645.4049
B18: 45658 | C18: 5 | D18: 130000 | E18: =D18/(1+$C$9)^C18 -> 101858.4
C19: Net Present Value | E19: =SUM(E13:E18) -> 8950.3026
B23: Discount Rate | C23: =D44 -> 0.068727639
B24: Initial Cost | C24: 100000
C26: Year | D26: Cashflow | E26: Present Value
B27: 43831 | C27: 0 | D27: -100000 | E27: -100000
B28: 44197 | C28: 1 | D28: 2000 | E28: =D28/(1+$C$23)^C28 -> 1871.3842
B29: 44562 | C29: 2 | D29: 2000 | E29: =D29/(1+$C$23)^C29 -> 1751.0394
B30: 44927 | C30: 3 | D30: 2000 | E30: =D30/(1+$C$23)^C30 -> 1638.4337
B31: 45292 | C31: 4 | D31: 2000 | E31: =D31/(1+$C$23)^C31 -> 1533.0695
B32: 45658 | C32: 5 | D32: 130000 | E32: =D32/(1+$C$23)^C32 -> 93241.263
C33: Net Present Value | E33: =ROUND(SUM(E27:E32),-2) -> 0
C37: Year | D37: Cashflow
B38: 43831 | C38: 0 | D38: -100000
B39: 44197 | C39: 1 | D39: 2000
B40: 44562 | C40: 2 | D40: 2000
B41: 44927 | C41: 3 | D41: 2000
B42: 45292 | C42: 4 | D42: 2000
B43: 45658 | C43: 5 | D43: 130000
C44: IRR | D44: =XIRR(D38:D43, B38:B43) -> 0.068727639

Sheet Chapter 12
B3: NOI | C3: 61428
B5: Interest Paid | C5: 32817
B7: Purchase Price | C7: 1000000
B8: Structure Value (%) | C8: 0.73
B9: Structure Cost ($) | C9: =C8*C7 -> 730000
B10: Depreciation Period (Years) | C10: 27.5
B11: Depreciation ($) | C11: =C9/C10 -> 26545.455
B13: Mortgage "Points" | C13: 13000
B14: Amortization Period (Years) | C14: 25
B15: Amortization ($) | C15: =C13/C14 -> 520
B16: Taxable Income | C16: =C3-C5-C11-C15 -> 1545.5455
B17: Tax Rate | C17: 0.24
B18: Taxes Owed | C18: =C17*C16 -> 370.93091
B22: Purchase Price | C22: 250000
B23: Closing Costs | C23: 5000
B24: Basis | C24: =SUM(C22:C23) -> 255000
B26: Purchase Price | C26: 250000
B27: Purchase Costs | C27: 5000
B28: Capital Expenditures | C28: 45000
B29: Sellings Costs | C29: 35000
B30: Depreciation ($) | C30: -30000
B31: Adjusted Basis | C31: =SUM(C26:C30) -> 305000
B36: Sale Price | C36: 400000
B37: Adjusted Basis | C37: 305000
B38: Taxable Gain | C38: =C36-C37 -> 95000
B40: Depreciation Recapture | C40: 30000
B41: Depreciation Recapture Rate | C41: 0.24
B42: Depreciation Recapture Owed | C42: =C40*C41 -> 7200
B44: Capital Gains | C44: 65000
B45: Capital Gains Tax Rate | C45: =15% -> 0.15
B46: Capital Gains Tax Owed | C46: =C45*C44 -> 9750
B47: Total Tax Owed | C47: =C42+C46 -> 16950

Sheet Chapter 14
B8: Return Metric | C8: Answers Q1 | D8: Answers Q2 | E8: Answers Q3 | F8: Answers Q4
B9: Profit | C9: X
B10: Net Operating Income (NOI) | C10: X
B11: Cash Flow (CF) | C11: X
B12: Return on Investment (ROI) | D12: X
B13: Equity Multiplier (EM) | D13: X
B14: Capitalization Rate (Cap Rate) | E14: X
B15: Cash-on-Cash Return (COC) | E15: X
B16: Average Annual Return (AAR) | E16: X
B17: Compound Annual Growth Rate (CAGR) | F17: X
B18: Internal Rate of Return (IRR) | F18: X

Sheet Chapter 15
B5: PROFIT & LOSS STATEMENT - Catherine Corp
B6: For the Fiscal Year 2022 (Jan. 1–Dec. 31, 2022)
B7: INCOME
B8: Gross Potential Rent | C8: 120000
B9: Rent Loss | C9: -12000
B10: Other Income | C10: 3000
B11: GROSS OPERATING INCOME: | C11: 111000
B12: EXPENSES
B13: Property Taxes | C13: 5250
B14: Insurance | C14: 2810
B15: Property Management | C15: 8640
B16: Turnover | C16: 4800
B17: Repairs & Maintenance | C17: 10000
B18: Utilities | C18: 400
B19: Lawn Care | C19: 3600
B20: Snow Removal | C20: 0
B21: Dumpster/Trash Removal | C21: 0
B22: Grounds Cleanup | C22: 3000
B23: Office Costs | C23: 0
B24: Legal | C24: 0
... B29: Capital Expenses | C29: -5000
B30: CASH FLOW BEFORE TAX | C30: =SUM(C27:C29) -> 25800
B31: Tax Rate | C31: 0.35
B32: Taxes Owed | C32: =-C31*C30 -> -9030
B33: Cash Flow After Taxes | C33: =C30+C32 -> 16770

Sheet Chapter 17
C2: Year | D2: Cash Flow
C3: Year 1 | D3: 5000
C4: Year 2 | D4: 8000
C5: Year 3 | D5: 12000
C6: Year 4 | D6: 200000
C7: Ending Value | D7: =SUM(D3:D6) -> 225000

Sheet Chapter 18
C4: Deal #1 | D4: Deal #2 | E4: Deal #3
B5: NOI | C5: 1058000 | D5: 2157000 | E5: 1165000
B6: Value (Asking Price) | C6: 22000000 | D6: 36000000 | E6: 30000000
B7: Cap Rate (NOI ÷ Value) | C7: 0.048 | D7: 0.06 | E7: 0.039

Sheet Chapter 20
B5: Year | C5: Portfolio Value | D5: Annual Growth Rate
B6: Year 0 | C6: 10000
B7: Year 1 | C7: =C6*(1+D7) -> 11500 | D7: 0.15
B8: Year 2 | C8: =C7*(1+D8) -> 13570 | D8: 0.18
B9: Year 3 | C9: =C8*(1+D9) -> 11941.6 | D9: -0.12
B10: Year 4 | C10: =C9*(1+D10) -> 10866.856 | D10: -0.09
B11: Year 5 | C11: =C10*(1+D11) -> 10323.513 | D11: -0.05
B12: Year 6 | C12: =C11*(1+D12) -> 9084.6916 | D12: -0.12
B13: Year 7 | C13: =C12*(1+D13) -> 10901.63 | D13: 0.2
B14: Year 8 | C14: =C13*(1+D14) -> 12536.874 | D14: 0.15
B15: Year 9 | C15: =C14*(1+D15) -> 14041.299 | D15: 0.12
B16: ROI | C16: =C15/C6-1 -> 0.40412994
B17: AAR | C17: =SUM(D7:D15)/9 -> 0.046666667
B18: CAGR | C18: =_xlfn.RRI(9, C6, C15) -> 0.038433258
C22: Portfolio Value | D22: % Change
B23: Year 0 | C23: 10000
B24: Year 1 | C24: =C23*(1+D24) -> 12000 | D24: 0.2
B25: Year 2 | C25: =C24*(1+D25) -> 9600 | D25: -0.2
C44: SCENARIO #1 | E44: SCENARIO #2 | G44: SCENARIO #3 | I44: SCENARIO #4
B45: Year | C45: ROI | D45: Balance | E45: ROI | F45: Balance | G45: ROI | H45: Balance | I45: ROI | J45: Balance
B46: 0 | D46: 100000 | F46: 100000 | H46: 100000 | J46: 100000
B47: 1 | C47: 0.1 | D47: 110000 | E47: 0.15 | F47: 115000 | G47: 0.2 | H47: 120000 | I47: 0.3 | J47: 130000
B48: 2 | C48: 0.1 | D48: 121000 | E48: 0.1 | F48: 126500 | G48: 0.1 | H48: 132000 | I48: 0 | J48: 130000
B49: 3 | C49: 0.1 | D49: 133100 | E49: 0.05 | F49: 132825 | G49: 0 | H49: 132000 | I49: 0 | J49: 130000
C50: AAR = 10% | E50: AAR = 10% | G50: AAR = 10% | I50: AAR = 10%

Sheet Chapter 21
B5: Year | C5: Annual Growth Rate | D5: Portfolio Value
B6: Year 0 | D6: 10000
B7: Year 1 | C7: 0.15 | D7: =D6*(1+C7) -> 11500
B8: Year 2 | C8: 0.18 | D8: =D7*(1+C8) -> 13570
B9: Year 3 | C9: -0.12 | D9: =D8*(1+C9) -> 11941.6
B10: Year 4 | C10: -0.09 | D10: =D9*(1+C10) -> 10866.856
B11: Year 5 | C11: -0.05 | D11: =D10*(1+C11) -> 10323.513
B12: Year 6 | C12: -0.12 | D12: =D11*(1+C12) -> 9084.6916
B13: Year 7 | C13: 0.2 | D13: =D12*(1+C13) -> 10901.63
B14: Year 8 | C14: 0.15 | D14: =D13*(1+C14) -> 12536.874 | F14: CAGR
B15: Year 9 | C15: 0.12 | D15: =D14*(1+C15) -> 14041.299 | F15: =_xlfn.RRI(9,D6,D15) -> 0.038433258
C18: Annual Growth Rate | D18: Portfolio Value
B19: Year 0 | D19: 10000
B20: Year 1 | C20: =F15 -> 0.038433258 | D20: =D19*(1+C20) -> 10384.333
B21: Year 2 | C21: =C20 -> 0.038433258 | D21: =D20*(1+C21) -> 10783.436
B22: Year 3 | C22: =C21 -> 0.038433258 | D22: =D21*(1+C22) -> 11197.879
B23: Year 4 | C23: =C22 -> 0.038433258 | D23: =D22*(1+C23) -> 11628.25
B24: Year 5 | C24: =C23 -> 0.038433258 | D24: =D23*(1+C24) -> 12075.161
B25: Year 6 | C25: =C24 -> 0.038433258 | D25: =D24*(1+C25) -> 12539.249
B26: Year 7 | C26: =C25 -> 0.038433258 | D26: =D25*(1+C26) -> 13021.173
B27: Year 8 | C27: =C26 -> 0.038433258 | D27: =D26*(1+C27) -> 13521.619
B28: Year 9 | C28: =C27 -> 0.038433258 | D28: =D27*(1+C28) -> 14041.299
C32: Purchase Price | D32: Current Value | E32: Hold Period (Years) | F32: CAGR | I32: =D33/C33 -> 1.7866667 | J32: =1/12 -> 0.083333333 | K32: =I32^J32 -> 1.0495512
B33: Property 1 | C33: 150000 | D33: 268000 | E33: 12 | F33: =_xlfn.RRI(E33,C33,D33) -> 0.049551196 | I33: =D34/C34 -> 1.7045455 | J33: =1/12 -> 0.083333333 | K33: =I33^J33 -> 1.0454439
B34: Property 2 | C34: 220000 | D34: 375000 | E34: 12 | F34: =_xlfn.RRI(E34,C34,D34) -> 0.045443858

Sheet Chapter 22
B3: Date | C3: Month # | D3: Cashflows
B4: 39661 | C4: 0 | D4: -63500
B5: 39692 | C5: 1 | D5: -17000
B6: 39722 | C6: 2 | D6: -17000
B7: 39753 | C7: 3 | D7: 0
B8: 39783 | C8: 4 | D8: 0
B9: 39814 | C9: 5 | D9: 0
B10: 39845 | C10: 6 | D10: 0
B11: 39873 | C11: 7 | D11: 0
B12: 39904 | C12: 8 | D12: 0
B13: 39934 | C13: 9 | D13: 1000
B14: 39965 | C14: 10 | D14: 1000
B15: 39995 | C15: 11 | D15: 1000
B16: 40026 | C16: 12 | D16: =1000-1400 -> -400
B17: 40057 | C17: 13 | D17: 1000
B18: 40087 | C18: 14 | D18: 1000
B19: 40118 | C19: 15 | D19: 1000
B20: 40148 | C20: 16 | D20: 1000
B21: 40179 | C21: 17 | D21: 1000
B22: 40210 | C22: 18 | D22: 1000
B23: 40238 | C23: 19 | D23: 1000
B24: 40269 | C24: 20 | D24: 1000
B25: 40299 | C25: 21 | D25: 1000
B26: 40330 | C26: 22 | D26: 1000
B27: 40360 | C27: 23 | D27: 1000
B28: 40391 | C28: 24 | D28: =66320+100-2300-1200 -> 62920
B29: 40422 | C29: 25 | D29: 1000
B30: 40452 | C30: 26 | D30: 1000
B31: 40483 | C31: 27 | D31: 1000
B32: 40513 | C32: 28 | D32: 1000
B33: 40544 | C33: 29 | D33: 1000
B34: 40575 | C34: 30 | D34: 1000
B35: 40603 | C35: 31 | D35: 1000
B36: 40634 | C36: 32 | D36: 1000
B37: 40664 | C37: 33 | D37: 1000
B38: 40695 | C38: 34 | D38: 1000
B39: 40725 | C39: 35 | D39: 50000
B40: IRR | D40: =XIRR(D4:D39, B4:B39) -> 0.1621164

Sheet Chapter 23
B2: Investment 1
B3: Year | C3: Account Balance | D3: ROI
B4: Year 0 | C4: 1000
B5: Year 1 | C5: 1200 | D5: =C5/C4-1 -> 0.2
B6: Year 2 | C6: 1250 | D6: =C6/C5-1 -> 0.041666667
B7: Year 3 | C7: 1400 | D7: =C7/C6-1 -> 0.12
B8: Year 4 | C8: 1300 | D8: =C8/C7-1 -> -0.071428571
B9: Year 5 | C9: 1150 | D9: =C9/C8-1 -> -0.11538462
B10: Year 6 | C10: 1600 | D10: =C10/C9-1 -> 0.39130435
B11: Year 7 | C11: 1800 | D11: =C11/C10-1 -> 0.125
B12: Year 8 | C12: 2000 | D12: =C12/C11-1 -> 0.11111111
B13: Year 9 | C13: 2100 | D13: =C13/C12-1 -> 0.05
B14: Year 10 | C14: 2400 | D14: =C14/C13-1 -> 0.14285714
B15: ROI | C15: =C14/C4-1 -> 1.4
B16: AAR | C16: =SUM(D5:D14)/COUNT(D5:D14) -> 0.099512608
B17: CAGR | C17: =_xlfn.RRI(10, C4, C14) -> 0.091493426
B21: Investment 2
B22: Year | C22: Account Balance | D22: ROI
B23: Year 0 | C23: 1000
B24: Year 1 | C24: 1200 | D24: =C24/C23-1 -> 0.2
B25: Year 2 | C25: 1250 | D25: =C25/C24-1 -> 0.041666667
B26: Year 3 | C26: 1400 | D26: =C26/C25-1 -> 0.12
B27: Year 4 | C27: 1300 | D27: =C27/C26-1 -> -0.071428571
B28: Year 5 | C28: 1450 | D28: =C28/C27-1 -> 0.11538462
B29: Year 6 | C29: 1600 | D29: =C29/C28-1 -> 0.10344828
B30: Year 7 | C30: 1900 | D30: =C30/C29-1 -> 0.1875
B31: ROI | C31: =C30/C23-1 -> 0.9
B32: AAR | C32: =SUM(D24:D30)/COUNT(D24:D30) -> 0.099510141
B33: CAGR | C33: =_xlfn.RRI(7, C23, C30) -> 0.096028742
A36: S | B36: Scenario 1 | G36: Scenario 2
B37: Purchase Price | C37: 480000 | G37: Purchase Price | H37: 480000
B38: Financing | C38: 0.8 | G38: Financing | H38: 0.8
B39: Down Payment | C39: =(1-C38)*C37 -> 96000 | G39: Down Payment | H39: =(1-H38)*H37 -> 96000
B40: Rehab & CapEx | C40: 120000 | G40: Rehab & CapEx | H40: 10000
B41: Total Initial Investment | C41: =SUM(C39:C40) -> 216000 | G41: Total Initial Investment | H41: =SUM(H39:H40) -> 106000
B43: Rehab Time Frame | C43: 6 Months | G43: Rehab Time Frame | H43: N/A
B44: Current Rent | C44: 2200 | G44: Current Rent | H44: =C44 -> 2200
B45: Post-Rehab Rent | C45: 3600 | G45: Post-Rehab Rent | H45: =H44 -> 2200
B46: Rent Growth | C46: 0.03 | G46: Rent Growth | H46: 0.01
B47: Property Appreciation | C47: 0.03 | G47: Property Appreciation | H47: 0.01
...

Sheet Chapter 24
B5: Discount Rate | C5: 0.075
B7: Year | C7: Cashflow | D7: Property Sale | E7: Present Value | G7: Math Check
B8: 1 | C8: 115000 | E8: 106977 | G8: =PV($C$5, B8, 0, C8) -> -106976.74
B9: 2 | C9: 122000 | E9: 105571 | G9: =PV($C$5, B9, 0, C9) -> -105570.58
B10: 3 | C10: 173000 | E10: 139258 | G10: =PV($C$5, B10, 0, C10) -> -139258.18
B11: 4 | C11: 154000 | E11: 115315 | G11: =PV($C$5, B11, 0, C11) -> -115315.28
B12: 5 | C12: 160000 | D12: 2380000 | E12: 1769259 | G12: =PV($C$5, B12, 0, C12+D12) -> -1769258.9
B13: Totals: | E13: 2236380 | G13: =SUM(G8:G12) -> -2236379.7

Sheet Chapter 25
B2: 200 Post Rd.
B3: Expense | C3: Amount | F3: Capital Source | G3: Financing Type | H3: Capital Type | I3: Capital Contribution
B4: Purchase Price | C4: 250000 | F4: Equity | G4: None (Sponsor) | H4: Common Equity | I4: 285000
B5: Closing Costs | C5: 5000 | F5: Total | I5: =I4 -> 285000
B6: Rehab Costs | C6: 20000
B7: Operating Reserve | C7: 10000 | F7: Capital Source | G7: Financing Type | H7: Capital Type | I7: Capital Contribution
B8: Total | C8: =SUM(C4:C7) -> 285000 | F8: Equity | G8: None (Sponsor) | H8: Common Equity | I8: 85000
F9: Debt | G9: Debt | H9: Debt | I9: 200000
F10: Total | I10: =SUM(I8:I9) -> 285000
F12: Capital Source | G12: Financing Type | H12: Capital Type | I12: Capital Contribution
F13: Common Equity | G13: None (Sponsor) | H13: Common Equity | I13: 250000
B14: Deal Proceeds | C14: 300000 | F14: Preferred Equity | G14: Equity Financing | H14: Preferred Equity | I14: 500000
B15: Loan Balance | C15: 190000 | F15: Mezzanine Debt | G15: Debt | H15: Debt | I15: 500000
B16: Owner Equity | C16: =C14-C15 -> 110000 | F16: Senior Debt | I16: 1000000
F17: Total | I17: =SUM(I13:I16) -> 2250000
B18: Initial Investment | C18: 85000
B19: ROI | C19: =C16/C18-1 -> 0.29411765
B20: Annualized ROI | C20: =C19/2 -> 0.14705882
B24: Deal Proceeds | C24: 260000
B25: Loan Balance | C25: 190000
B26: Owner Equity | C26: =C24-C25 -> 70000
B28: Initial Investment | C28: 85000
B29: ROI | C29: =C26/C28-1 -> -0.17647059
B30: Annualized ROI | C30: =C29/2 -> -0.088235294

Sheet Chapter 26
C3: Capital Source | D3: Financing Type | E3: Capital Type | F3: Capital Contribution
C4: Equity | D4: None (Sponsor) | E4: Common Equity | F4: 285000
C5: Total | F5: =F4 -> 285000
C8: Capital Source | D8: Financing Type | E8: Capital Type | F8: Capital Contribution
C9: Equity(Brian) | D9: None (Sponsor) | E9: Equity | F9: =285000/2 -> 142500
C10: Equity (Melissa) | D10: Equity Financing | E10: Equity | F10: =285000/2 -> 142500
C11: Total | F11: =SUM(F9:F10) -> 285000
C77: Expense | D77: Amount | E77: Senior Debt | F77: Mezzanine Debt | G77: Common Equity
C78: Purchase Price | D78: 250000 | E78: =D78*0.75 -> 187500 | F78: 0 | G78: =D78-E78 -> 62500
C79: Closing Costs | D79: 5000 | E79: 0 | F79: 0 | G79: =D79 -> 5000
C80: Rehab Costs | D80: 20000 | E80: 0 | F80: 20000 | G80: 0
C81: Operating Reserve | D81: 10000 | E81: 0 | F81: 10000 | G81: 0
C82: Total | D82: =SUM(D78:D81) -> 285000 | E82: =SUM(E78:E81) -> 187500 | F82: =SUM(F78:F81) -> 30000 | G82: =SUM(G78:G81) -> 67500

Sheet Chapter 28
D7: Capital Source | E7: Financing Type | F7: Capital Type | G7: Capital Contribution
D8: Equity | E8: None (Sponsor) | F8: Common Equity | G8: 85000
D9: Debt | E9: Debt | F9: Debt | G9: 200000
D10: Total | G10: =SUM(G8:G9) -> 285000
D14: Capital Source | E14: Financing Type | F14: Capital Type | G14: Capital Contribution
D15: Debt (Mortgage Company) | E15: None (Sponsor) | F15: Common Equity | G15: 285000
D16: Total | G16: =G15 -> 285000
D19: Capital Source | E19: Financing Type | F19: Capital Type | G19: Capital Contribution
D20: Common Equity | E20: None (Sponsor) | F20: Common Equity | G20: =285000-G21 -> 97500
D21: Senior Debt | E21: Debt | F21: Debt | G21: =0.75*250000 -> 187500
D22: Total | G22: =SUM(G20:G21) -> 285000
D26: Expense | E26: Amount | F26: Debt | G26: Equity
D27: Purchase Price | E27: 250000 | F27: =E27*0.75 -> 187500 | G27: =E27-F27 -> 62500
D28: Closing Costs | E28: 5000 | F28: 0 | G28: =E28 -> 5000
D29: Rehab Costs | E29: 20000 | F29: 0 | G29: =E29 -> 20000
D30: Operating Reserve | E30: 10000 | F30: 0 | G30: =E30 -> 10000
D31: Total | E31: =SUM(E27:E30) -> 285000 | F31: =SUM(F27:F30) -> 187500 | G31: =SUM(G27:G30) -> 97500
D35: Capital Source | E35: Financing Type | F35: Capital Type | G35: Capital Contribution
D36: Equity | E36: None (Sponsor) | F36: Common Equity | G36: 67500
D37: Debt 2 | G37: 30000
D38: Debt 1 | E38: Debt | F38: Debt | G38: =0.75*250000 -> 187500
D39: Total | G39: =SUM(G36:G38) -> 285000
D42: Expense | E42: Amount | F42: Senior Debt | G42: Mezzanine Debt | H42: Common Equity
D43: Purchase Price | E43: 250000 | F43: =E43*0.75 -> 187500 | G43: 0 | H43: =E43-F43 -> 62500
D44: Closing Costs | E44: 5000 | F44: 0 | G44: 0 | H44: =E44 -> 5000
D45: Rehab Costs | E45: 20000 | F45: 0 | G45: 20000 | H45: 0
D46: Operating Reserve | E46: 10000 | F46: 0 | G46: 10000 | H46: 0
D47: Total | E47: =SUM(E43:E46) -> 285000 | F47: =SUM(F43:F46) -> 187500 | G47: =SUM(G43:G46) -> 30000 | H47: =SUM(H43:H46) -> 67500

Sheet Finance Other
A2: 200 Post Rd.
A3: Expense | B3: Amount | E3: Capital Source | F3: Financing Type | G3: Capital Type | H3: Capital Contribution
A4: Purchase Price | B4: 250000 | E4: Common Equity | F4: None (Sponsor) | G4: Common Equity | H4: 285000
A5: Closing Costs | B5: 5000 | E5: Total | H5: =H4 -> 285000
A6: Rehab Costs | B6: 20000
A7: Operating Reserve | B7: 10000 | E7: Capital Source | F7: Financing Type | G7: Capital Type | H7: Capital Contribution
A8: Total | B8: =SUM(B4:B7) -> 285000 | E8: Equity | F8: None (Sponsor) | G8: Common Equity | H8: 85000
E9: Debt | F9: Debt | G9: Debt | H9: 200000
E10: Total | H10: =SUM(H8:H9) -> 285000
E12: Capital Source | F12: Financing Type | G12: Capital Type | H12: Capital Contribution
E13: Common Equity | F13: None (Sponsor) | G13: Common Equity | H13: 250000
E14: Preferred Equity | F14: Equity Financing | G14: Preferred Equity | H14: 500000
E15: Mezzanine Debt | F15: Debt | G15: Debt | H15: 500000
E16: Senior Debt | H16: 1000000
E17: Total | H17: =SUM(H13:H16) -> 2250000
E19: Capital Source | F19: Financing Type | G19: Capital Type | H19: Capital Contribution
E20: Common Equity (Brian) | F20: None (Sponsor) | G20: Equity | H20: =285000/2 -> 142500
A21: Deal Proceeds | B21: 300000 | E21: Preferred Equity (Melissa) | F21: Equity Financing | G21: Equity | H21: =285000/2 -> 142500
A22: Loan Balance | B22: 190000 | E22: Total | H22: =SUM(H20:H21) -> 285000
A23: Owner Equity | B23: =B21-B22 -> 110000
A25: Initial Investment | B25: 85000
A26: ROI | B26: =B23/B25-1 -> 0.29411765 | E26: Capital Source | F26: Financing Type | G26: Capital Type | H26: Capital Contribution
A27: AAROI | B27: =B26/2 -> 0.14705882 | E27: Senior Debt (Mortgage Company) | F27: None (Sponsor) | G27: Common Equity | H27: 285000
E28: Total | H28: =H27 -> 285000
E31: Capital Source | F31: Financing Type | G31: Capital Type | H31: Capital Contribution
E32: Common Equity | F32: None (Sponsor) | G32: Common Equity | H32: =285000-H33 -> 97500
E33: Senior Debt | F33: Debt | G33: Debt | H33: =0.75*250000 -> 187500
E34: Total | H34: =SUM(H32:H33) -> 285000
A36: Deal Proceeds | B36: 260000
A37: Loan Balance | B37: 190000
A38: Owner Equity | B38: =B36-B37 -> 70000 | E38: Expense | F38: Amount | G38: Debt | H38: Equity
E39: Purchase Price | F39: 250000 | G39: =F39*0.75 -> 187500 | H39: =F39-G39 -> 62500
A40: Initial Investment | B40: 85000 | E40: Closing Costs | F40: 5000 | G40: 0 | H40: =F40 -> 5000
A41: ROI | B41: =B38/B40-1 -> -0.17647059 | E41: Rehab Costs | F41: 20000 | G41: 0 | H41: =F41 -> 20000
A42: AAROI | B42: =B41/2 -> -0.088235294 | E42: Operating Reserve | F42: 10000 | G42: 0 | H42: =F42 -> 10000
E43: Total | F43: =SUM(F39:F42) -> 285000 | G43: =SUM(G39:G42) -> 187500 | H43: =SUM(H39:H42) -> 97500
E47: Capital Source | F47: Financing Type | G47: Capital Type | H47: Capital Contribution
E48: Common Equity | F48: None (Sponsor) | G48: Common Equity | H48: 67500
E49: Mezzanine Debt | H49: 30000
E50: Senior Debt | F50: Debt | G50: Debt | H50: =0.75*250000 -> 187500
...

Sheet Financing Intro
B3: Expenses | E3: Capital Source | F3: Financing Type | G3: Capital Type | H3: Capital Contribution
A4: Purchase Price | B4: 250000 | E4: Primary Owner (Sponsor) | F4: None (self-financed) | G4: Equity Capital | H4: 285000
A5: Closing Costs | B5: 5000 | E5: Total | H5: =H4 -> 285000
A6: Rehab Costs | B6: 20000
A7: Operating Reserve | B7: 10000 | E7: Capital Source | F7: Financing Type | G7: Capital Type | H7: Capital Contribution
A8: Total | B8: =SUM(B4:B7) -> 285000 | E8: Primary Owner | F8: None (self-financed) | G8: Equity Capital | H8: 85000
E9: Mortgage Company | F9: Debt | G9: Debt | H9: 200000
E10: Total | H10: =SUM(H8:H9) -> 285000
E12: Capital Source | F12: Financing Type | G12: Capital Type | H12: Capital Contribution
E13: Primary Owner (Sponsor) | F13: None (self-financed) | G13: Equity Capital | H13: 50000
E14: Investor Partner | F14: Equity Financing | G14: Equity Capital | H14: 35000
E15: Mortgage Company | F15: Debt | G15: Debt | H15: 200000
E16: Total | H16: =SUM(H13:H15) -> 285000

Sheet Chapter 30 - Balloon
A1: Purchase Price | B1: 400000 | E1: Payment Number | F1: Payment ($) | G1: Interest Paid | H1: Prinicpal Paid | I1: Total Interest Paid | J1: Total Principal Paid | K1: Principal Balance | L1: Sale Price | M1: Profit
A2: Down Payment (%) | B2: 0.2 | E2: 0 | F2: =B8 -> 1717.8292 | G2: =(B$4/B$6)*K2 -> 1333.3333 | H2: =F2-G2 -> 384.49586 | I2: =G2 -> 1333.3333 | J2: =H2 -> 384.49586 | K2: =B3 -> 320000 | L2: 400000 | M2: =L2-K2 -> 80000
A3: Loan Amount (Principal) | B3: =(1-B2)*B1 -> 320000 | E3: 1 | F3: =F2 -> 1717.8292 | G3: =(B$4/B$6)*K3 -> 1331.7313 | H3: =F3-G3 -> 386.09793 | I3: =I2+G3 -> 2665.0646 | J3: =J2+H3 -> 770.59379 | K3: =K2-H2 -> 319615.5 | L3: 400000 | M3: =L3-K3 -> 80384.496
A4: Annual Interest Rate | B4: 0.05 | E4: 2 | F4: =F3 -> 1717.8292 | G4: =(B$4/B$6)*K4 -> 1330.1225 | H4: =F4-G4 -> 387.70667 | I4: =I3+G4 -> 3995.1871 | J4: =J3+H4 -> 1158.3005 | K4: =K3-H3 -> 319229.41 | L4: 400000 | M4: =L4-K4 -> 80770.594
A5: Term (Years) | B5: 30 | E5: 3 | F5: =F4 -> 1717.8292 | G5: =(B$4/B$6)*K5 -> 1328.5071 | H5: =F5-G5 -> 389.32211 | I5: =I4+G5 -> 5323.6942 | J5: =J4+H5 -> 1547.6226 | K5: =K4-H4 -> 318841.7 | L5: 400000 | M5: =L5-K5 -> 81158.3
A6: Payments/year | B6: 12 | E6: 4 | F6: =F5 -> 1717.8292 | G6: =(B$4/B$6)*K6 -> 1326.8849 | H6: =F6-G6 -> 390.94429 | I6: =I5+G6 -> 6650.5791 | J6: =J5+H6 -> 1938.5669 | K6: =K5-H5 -> 318452.38 | L6: 400000 | M6: =L6-K6 -> 81547.623 | R6: =320000*(0.05/12) -> 1333.3333
A7: Total Payments | B7: =B6*B5 -> 360 | E7: 5 | F7: =F6 -> 1717.8292 | G7: =(B$4/B$6)*K7 -> 1325.256 | H7: =F7-G7 -> 392.57322 | I7: =I6+G7 -> 7975.8351 | J7: =J6+H7 -> 2331.1401 | K7: =K6-H6 -> 318061.43 | L7: 400000 | M7: =L7-K7 -> 81938.567
A8: Payment per Period | B8: =-PMT(B4/B6, B7, B3, 0) -> 1717.8292 | E8: 6 | F8: =F7 -> 1717.8292 | G8: =(B$4/B$6)*K8 -> 1323.6202 | H8: =F8-G8 -> 394.20894 | I8: =I7+G8 -> 9299.4553 | J8: =J7+H8 -> 2725.349 | K8: =K7-H7 -> 317668.86 | L8: 400000 | M8: =L8-K8 -> 82331.14
A9: Sum of Payments | B9: =B8*B7 -> 618418.51 | E9: 7 | F9: =F8 -> 1717.8292 | G9: =(B$4/B$6)*K9 -> 1321.9777 | H9: =F9-G9 -> 395.85148 | I9: =I8+G9 -> 10621.433 | J9: =J8+H9 -> 3121.2005 | K9: =K8-H8 -> 317274.65 | L9: 400000 | M9: =L9-K9 -> 82725.349
A10: Interest Cost | B10: =B9-B3 -> 298418.51 | E10: 8 | F10: =F9 -> 1717.8292 | G10: =(B$4/B$6)*K10 -> 1320.3283 | H10: =F10-G10 -> 397.50086 | I10: =I9+G10 -> 11941.761 | J10: =J9+H10 -> 3518.7014 | K10: =K9-H9 -> 316878.8 | L10: 400000 | M10: =L10-K10 -> 83121.201
E11: 9 | F11: =F10 -> 1717.8292 | G11: =(B$4/B$6)*K11 -> 1318.6721 | H11: =F11-G11 -> 399.15712 | I11: =I10+G11 -> 13260.433 | J11: =J10+H11 -> 3917.8585 | K11: =K10-H10 -> 316481.3 | L11: 400000 | M11: =L11-K11 -> 83518.701
E12: 10 | F12: =F11 -> 1717.8292 | G12: =(B$4/B$6)*K12 -> 1317.0089 | H12: =F12-G12 -> 400.82027 | I12: =I11+G12 -> 14577.442 | J12: =J11+H12 -> 4318.6788 | K12: =K11-H11 -> 316082.14 | L12: 400000 | M12: =L12-K12 -> 83917.858
E13: 11 | F13: =F12 -> 1717.8292 | G13: =(B$4/B$6)*K13 -> 1315.3388 | H13: =F13-G13 -> 402.49036 | I13: =I12+G13 -> 15892.781 | J13: =J12+H13 -> 4721.1691 | K13: =K12-H12 -> 315681.32 | L13: 400000 | M13: =L13-K13 -> 84318.679 | O13: Year | P13: Payment ($) | Q13: Interest Paid | R13: Principal Paid | S13: Total Interest Paid | T13: Total Principal Paid | U13: Principal Balance
E14: 12 | F14: =F13 -> 1717.8292 | G14: =(B$4/B$6)*K14 -> 1313.6618 | H14: =F14-G14 -> 404.1674 | I14: =I13+G14 -> 17206.443 | J14: =J13+H14 -> 5125.3365 | K14: =K13-H13 -> 315278.83 | L14: 400000 | M14: =L14-K14 -> 84721.169 | O14: 1 | P14: =F13 -> 1717.8292 | Q14: =G13 -> 1315.3388 | R14: =H13 -> 402.49036 | S14: =I13 -> 15892.781 | T14: =J13 -> 4721.1691 | U14: =K13 -> 315681.32
E15: 13 | F15: =F14 -> 1717.8292 | G15: =(B$4/B$6)*K15 -> 1311.9778 | H15: =F15-G15 -> 405.85143 | I15: =I14+G15 -> 18518.421 | J15: =J14+H15 -> 5531.1879 | K15: =K14-H14 -> 314874.66 | L15: 400000 | M15: =L15-K15 -> 85125.337 | O15: 2 | P15: =F25 -> 1717.8292 | Q15: =G25 -> 1294.7467 | R15: =H25 -> 423.08253 | S15: =I25 -> 31544.018 | T15: =J25 -> 9683.8822 | U15: =K25 -> 310739.2
E16: 14 | F16: =F15 -> 1717.8292 | G16: =(B$4/B$6)*K16 -> 1310.2867 | H16: =F16-G16 -> 407.54248 | I16: =I15+G16 -> 19828.707 | J16: =J15+H16 -> 5938.7304 | K16: =K15-H15 -> 314468.81 | L16: 400000 | M16: =L16-K16 -> 85531.188 | O16: 3 | P16: =F37 -> 1717.8292 | Q16: =G37 -> 1273.101 | R16: =H37 -> 444.72823 | S16: =I37 -> 46941.354 | T16: =J37 -> 14900.497 | U16: =K37 -> 305544.23
E17: 15 | F17: =F16 -> 1717.8292 | G17: =(B$4/B$6)*K17 -> 1308.5886 | H17: =F17-G17 -> 409.24057 | I17: =I16+G17 -> 21137.296 | J17: =J16+H17 -> 6347.971 | K17: =K16-H16 -> 314061.27 | L17: 400000 | M17: =L17-K17 -> 85938.73 | O17: 4 | P17: =F49 -> 1717.8292 | Q17: =G49 -> 1250.3478 | R17: =H49 -> 467.48137 | S17: =I49 -> 62071.797 | T17: =J49 -> 20384.004 | U17: =K49 -> 300083.48
A18: =B4/12 -> 0.0041666667 | E18: 16 | F18: =F17 -> 1717.8292 | G18: =(B$4/B$6)*K18 -> 1306.8835 | H18: =F18-G18 -> 410.94574 | I18: =I17+G18 -> 22444.18 | J18: =J17+H18 -> 6758.9167 | K18: =K17-H17 -> 313652.03 | L18: 400000 | M18: =L18-K18 -> 86347.971 | O18: 5 | P18: =F61 -> 1717.8292 | Q18: =G61 -> 1226.4306 | R18: =H61 -> 491.3986 | S18: =I61 -> 76921.694 | T18: =J61 -> 26148.057 | U18: =K61 -> 294343.34
B19: =319615.33*A18 -> 1331.7305 | E19: 17 | F19: =F18 -> 1717.8292 | G19: =(B$4/B$6)*K19 -> 1305.1712 | H19: =F19-G19 -> 412.65801 | I19: =I18+G19 -> 23749.351 | J19: =J18+H19 -> 7171.5747 | K19: =K18-H18 -> 313241.08 | L19: 400000 | M19: =L19-K19 -> 86758.917 | O19: 6 | P19: =F73 -> 1717.8292 | Q19: =G73 -> 1201.2897 | R19: =H73 -> 516.53949 | S19: =I73 -> 91476.691 | T19: =J73 -> 32207.011 | U19: =K73 -> 288309.53
B20: =A18*B3 -> 1333.3333 | E20: 18 | F20: =F19 -> 1717.8292 | G20: =(B$4/B$6)*K20 -> 1303.4518 | H20: =F20-G20 -> 414.37742 | I20: =I19+G20 -> 25052.803 | J20: =J19+H20 -> 7585.9522 | K20: =K19-H19 -> 312828.43 | L20: 400000 | M20: =L20-K20 -> 87171.575 | O20: 7 | P20: =F85 -> 1717.8292 | Q20: =G85 -> 1174.8626 | R20: =H85 -> 542.96663 | S20: =I85 -> 105721.7 | T20: =J85 -> 38575.952 | U20: =K85 -> 281967.02
E21: 19 | F21: =F20 -> 1717.8292 | G21: =(B$4/B$6)*K21 -> 1301.7252 | H21: =F21-G21 -> 416.10399 | I21: =I20+G21 -> 26354.528 | J21: =J20+H21 -> 8002.0561 | K21: =K20-H20 -> 312414.05 | L21: 400000 | M21: =L21-K21 -> 87585.952 | O21: 8 | P21: =F97 -> 1717.8292 | Q21: =G97 -> 1147.0834 | R21: =H97 -> 570.74583 | S21: =I97 -> 119640.86 | T21: =J97 -> 45270.74 | U21: =K97 -> 275300.01
E22: 20 | F22: =F21 -> 1717.8292 | G22: =(B$4/B$6)*K22 -> 1299.9914 | H22: =F22-G22 -> 417.83776 | I22: =I21+G22 -> 27654.519 | J22: =J21+H22 -> 8419.8939 | K22: =K21-H21 -> 311997.94 | L22: 400000 | M22: =L22-K22 -> 88002.056 | O22: 9 | P22: =F109 -> 1717.8292 | Q22: =G109 -> 1117.8829 | R22: =H109 -> 599.94627 | S22: =I109 -> 133217.51 | T22: =J109 -> 52308.046 | U22: =K109 -> 268291.9
E23: 21 | F23: =F22 -> 1717.8292 | G23: =(B$4/B$6)*K23 -> 1298.2504 | H23: =F23-G23 -> 419.57875 | I23: =I22+G23 -> 28952.77 | J23: =J22+H23 -> 8839.4727 | K23: =K22-H22 -> 311580.11 | L23: 400000 | M23: =L23-K23 -> 88419.894 | O23: 10 | P23: =U22 -> 268291.9 | Q23: 0 | R23: =P23 -> 268291.9 | S23: =S22 -> 133217.51 | T23: =800000 -> 800000 | U23: 0
E24: 22 | F24: =F23 -> 1717.8292 | G24: =(B$4/B$6)*K24 -> 1296.5022 | H24: =F24-G24 -> 421.327 | I24: =I23+G24 -> 30249.272 | J24: =J23+H24 -> 9260.7997 | K24: =K23-H23 -> 311160.53 | L24: 400000 | M24: =L24-K24 -> 88839.473 | O24: 11 | P24: =F133 -> 1717.8292 | Q24: =G133 -> 1054.9238 | R24: =H133 -> 662.90544 | S24: =I133 -> 159272.25 | T24: =J133 -> 67481.204 | U24: =K133 -> 253181.7
E25: 23 | F25: =F24 -> 1717.8292 | G25: =(B$4/B$6)*K25 -> 1294.7467 | H25: =F25-G25 -> 423.08253 | I25: =I24+G25 -> 31544.018 | J25: =J24+H25 -> 9683.8822 | K25: =K24-H24 -> 310739.2 | L25: 400000 | M25: =L25-K25 -> 89260.8 | O25: 12 | P25: =F145 -> 1717.8292 | Q25: =G145 -> 1021.0083 | R25: =H145 -> 696.82094 | S25: =I145 -> 171712.56 | T25: =J145 -> 75654.84 | U25: =K145 -> 245041.98
E26: 24 | F26: =F25 -> 1717.8292 | G26: =(B$4/B$6)*K26 -> 1292.9838 | H26: =F26-G26 -> 424.84537 | I26: =I25+G26 -> 32837.002 | J26: =J25+H26 -> 10108.728 | K26: =K25-H25 -> 310316.12 | L26: 400000 | M26: =L26-K26 -> 89683.882 | O26: 13 | P26: =F157 -> 1717.8292 | Q26: =G157 -> 985.35757 | R26: =H157 -> 732.47162 | S26: =I157 -> 183734.7 | T26: =J157 -> 84246.654 | U26: =K157 -> 236485.82
E27: 25 | F27: =F26 -> 1717.8292 | G27: =(B$4/B$6)*K27 -> 1291.2136 | H27: =F27-G27 -> 426.61556 | I27: =I26+G27 -> 34128.216 | J27: =J26+H27 -> 10535.343 | K27: =K26-H26 -> 309891.27 | L27: 400000 | M27: =L27-K27 -> 90108.728 | O27: 14 | P27: =F169 -> 1717.8292 | Q27: =G169 -> 947.88294 | R27: =H169 -> 769.94626 | S27: =I169 -> 195317.26 | T27: =J169 -> 93278.042 | U27: =K169 -> 227491.9
E28: 26 | F28: =F27 -> 1717.8292 | G28: =(B$4/B$6)*K28 -> 1289.4361 | H28: =F28-G28 -> 428.39312 | I28: =I27+G28 -> 35417.652 | J28: =J27+H28 -> 10963.736 | K28: =K27-H27 -> 309464.66 | L28: 400000 | M28: =L28-K28 -> 90535.343 | O28: 15 | P28: =F181 -> 1717.8292 | Q28: =G181 -> 908.49102 | R28: =H181 -> 809.33817 | S28: =I181 -> 206437.76 | T28: =J181 -> 102771.49 | U28: =K181 -> 218037.85
E29: 27 | F29: =F28 -> 1717.8292 | G29: =(B$4/B$6)*K29 -> 1287.6511 | H29: =F29-G29 -> 430.17809 | I29: =I28+G29 -> 36705.303 | J29: =J28+H29 -> 11393.914 | K29: =K28-H28 -> 309036.26 | L29: 400000 | M29: =L29-K29 -> 90963.736 | O29: 16 | P29: =F193 -> 1717.8292 | Q29: =G193 -> 867.08375 | R29: =H193 -> 850.74545 | S29: =I193 -> 217072.56 | T29: =J193 -> 112750.65 | U29: =K193 -> 208100.1
E30: 28 | F30: =F29 -> 1717.8292 | G30: =(B$4/B$6)*K30 -> 1285.8587 | H30: =F30-G30 -> 431.9705 | I30: =I29+G30 -> 37991.162 | J30: =J29+H30 -> 11825.885 | K30: =K29-H29 -> 308606.09 | L30: 400000 | M30: =L30-K30 -> 91393.914 | O30: 17 | P30: =F205 -> 1717.8292 | Q30: =G205 -> 823.558 | R30: =H205 -> 894.2712 | S30: =I205 -> 227196.8 | T30: =J205 -> 123240.35 | U30: =K205 -> 197653.92
E31: 29 | F31: =F30 -> 1717.8292 | G31: =(B$4/B$6)*K31 -> 1284.0588 | H31: =F31-G31 -> 433.77038 | I31: =I30+G31 -> 39275.221 | J31: =J30+H31 -> 12259.655 | K31: =K30-H30 -> 308174.12 | L31: 400000 | M31: =L31-K31 -> 91825.885 | O31: 18 | P31: =F217 -> 1717.8292 | Q31: =G217 -> 777.80538 | R31: =H217 -> 940.02381 | S31: =I217 -> 236784.37 | T31: =J217 -> 134266.73 | U31: =K217 -> 186673.29
E32: 30 | F32: =F31 -> 1717.8292 | G32: =(B$4/B$6)*K32 -> 1282.2514 | H32: =F32-G32 -> 435.57776 | I32: =I31+G32 -> 40557.472 | J32: =J31+H32 -> 12695.233 | K32: =K31-H31 -> 307740.34 | L32: 400000 | M32: =L32-K32 -> 92259.655 | O32: 19 | P32: =F229 -> 1717.8292 | Q32: =G229 -> 729.71198 | R32: =H229 -> 988.11721 | S32: =I229 -> 245807.81 | T32: =J229 -> 145857.24 | U32: =K229 -> 175130.88
E33: 31 | F33: =F32 -> 1717.8292 | G33: =(B$4/B$6)*K33 -> 1280.4365 | H33: =F33-G33 -> 437.39266 | I33: =I32+G33 -> 41837.909 | J33: =J32+H33 -> 13132.626 | K33: =K32-H32 -> 307304.77 | L33: 400000 | M33: =L33-K33 -> 92695.233 | O33: 20 | P33: =F241 -> 1717.8292 | Q33: =G241 -> 679.15803 | R33: =H241 -> 1038.6712 | S33: =I241 -> 254238.26 | T33: =J241 -> 158040.74 | U33: =K241 -> 162997.93
E34: 32 | F34: =F33 -> 1717.8292 | G34: =(B$4/B$6)*K34 -> 1278.6141 | H34: =F34-G34 -> 439.21513 | I34: =I33+G34 -> 43116.523 | J34: =J33+H34 -> 13571.841 | K34: =K33-H33 -> 306867.37 | L34: 400000 | M34: =L34-K34 -> 93132.626 | O34: 21 | P34: =F253 -> 1717.8292 | Q34: =G253 -> 626.01764 | R34: =H253 -> 1091.8116 | S34: =I253 -> 262045.38 | T34: =J253 -> 170847.58 | U34: =K253 -> 150244.23
E35: 33 | F35: =F34 -> 1717.8292 | G35: =(B$4/B$6)*K35 -> 1276.784 | H35: =F35-G35 -> 441.0452 | I35: =I34+G35 -> 44393.307 | J35: =J34+H35 -> 14012.886 | K35: =K34-H34 -> 306428.16 | L35: 400000 | M35: =L35-K35 -> 93571.841 | O35: 22 | P35: =F265 -> 1717.8292 | Q35: =G265 -> 570.15849 | R35: =H265 -> 1147.6707 | S35: =I265 -> 269197.27 | T35: =J265 -> 184309.63 | U35: =K265 -> 136838.04
E36: 34 | F36: =F35 -> 1717.8292 | G36: =(B$4/B$6)*K36 -> 1274.9463 | H36: =F36-G36 -> 442.88289 | I36: =I35+G36 -> 45668.253 | J36: =J35+H36 -> 14455.769 | K36: =K35-H35 -> 305987.11 | L36: 400000 | M36: =L36-K36 -> 94012.886 | O36: 23 | P36: =F277 -> 1717.8292 | Q36: =G277 -> 511.44148 | R36: =H277 -> 1206.3877 | S36: =I277 -> 275660.42 | T36: =J277 -> 198460.43 | U36: =K277 -> 122745.96
E37: 35 | F37: =F36 -> 1717.8292 | G37: =(B$4/B$6)*K37 -> 1273.101 | H37: =F37-G37 -> 444.72823 | I37: =I36+G37 -> 46941.354 | J37: =J36+H37 -> 14900.497 | K37: =K36-H36 -> 305544.23 | L37: 400000 | M37: =L37-K37 -> 94455.769 | O37: 24 | P37: =F289 -> 1717.8292 | Q37: =G289 -> 449.72039 | R37: =H289 -> 1268.1088 | S37: =I289 -> 281399.59 | T37: =J289 -> 213335.21 | U37: =K289 -> 107932.89
E38: 36 | F38: =F37 -> 1717.8292 | G38: =(B$4/B$6)*K38 -> 1271.2479 | H38: =F38-G38 -> 446.58126 | I38: =I37+G38 -> 48212.602 | J38: =J37+H38 -> 15347.078 | K38: =K37-H37 -> 305099.5 | L38: 400000 | M38: =L38-K38 -> 94900.497 | O38: 25 | P38: =F301 -> 1717.8292 | Q38: =G301 -> 384.84154 | R38: =H301 -> 1332.9877 | S38: =I301 -> 286377.74 | T38: =J301 -> 228971.02 | U38: =K301 -> 92361.97
E39: 37 | F39: =F38 -> 1717.8292 | G39: =(B$4/B$6)*K39 -> 1269.3872 | H39: =F39-G39 -> 448.44202 | I39: =I38+G39 -> 49481.989 | J39: =J38+H39 -> 15795.52 | K39: =K38-H38 -> 304652.92 | L39: 400000 | M39: =L39-K39 -> 95347.078 | O39: 26 | P39: =F313 -> 1717.8292 | Q39: =G313 -> 316.64336 | R39: =H313 -> 1401.1858 | S39: =I313 -> 290555.93 | T39: =J313 -> 245406.78 | U39: =K313 -> 75994.407 | AH39: =320000*(0.591^360)/((1.417^360)-1) -> 6.0743108e-132 | AI39: =1.417^360 -> 3.1127632e+54
E40: 38 | F40: =F39 -> 1717.8292 | G40: =(B$4/B$6)*K40 -> 1267.5187 | H40: =F40-G40 -> 450.31053 | I40: =I39+G40 -> 50749.508 | J40: =J39+H40 -> 16245.831 | K40: =K39-H39 -> 304204.48 | L40: 400000 | M40: =L40-K40 -> 95795.52 | O40: 27 | P40: =F325 -> 1717.8292 | Q40: =G325 -> 244.95604 | R40: =H325 -> 1472.8732 | S40: =I325 -> 293893.23 | T40: =J325 -> 262683.42 | U40: =K325 -> 58789.449
...

Sheet Chapter 30 - Full
A1: Do Not Delete
A2: Purchase Price | B2: 400000 | E2: Payment Number | F2: Payment ($) | G2: Interest Paid | H2: Prinicipal Paid | I2: Total Interest Paid | J2: Total Principal Paid | K2: Principal Balance | L2: Sale Price | M2: Profit
A3: Down Payment (%) | B3: 0.2 | E3: 0 | F3: =B9 -> 1717.8292 | G3: =(B$5/B$7)*K3 -> 1333.3333 | H3: =F3-G3 -> 384.49586 | I3: =G3 -> 1333.3333 | J3: =H3 -> 384.49586 | K3: =B4 -> 320000 | L3: 400000 | M3: =L3-K3 -> 80000
A4: Loan Amount (Principal) | B4: =(1-B3)*B2 -> 320000 | E4: 1 | F4: =F3 -> 1717.8292 | G4: =(B$5/B$7)*K4 -> 1331.7313 | H4: =F4-G4 -> 386.09793 | I4: =I3+G4 -> 2665.0646 | J4: =J3+H4 -> 770.59379 | K4: =K3-H3 -> 319615.5 | L4: 400000 | M4: =L4-K4 -> 80384.496
A5: Annual Interest Rate | B5: =0.05 -> 0.05 | E5: 2 | F5: =F4 -> 1717.8292 | G5: =(B$5/B$7)*K5 -> 1330.1225 | H5: =F5-G5 -> 387.70667 | I5: =I4+G5 -> 3995.1871 | J5: =J4+H5 -> 1158.3005 | K5: =K4-H4 -> 319229.41 | L5: 400000 | M5: =L5-K5 -> 80770.594
A6: Term (Years) | B6: 30 | E6: 3 | F6: =F5 -> 1717.8292 | G6: =(B$5/B$7)*K6 -> 1328.5071 | H6: =F6-G6 -> 389.32211 | I6: =I5+G6 -> 5323.6942 | J6: =J5+H6 -> 1547.6226 | K6: =K5-H5 -> 318841.7 | L6: 400000 | M6: =L6-K6 -> 81158.3
A7: Payments/year | B7: 12 | E7: 4 | F7: =F6 -> 1717.8292 | G7: =(B$5/B$7)*K7 -> 1326.8849 | H7: =F7-G7 -> 390.94429 | I7: =I6+G7 -> 6650.5791 | J7: =J6+H7 -> 1938.5669 | K7: =K6-H6 -> 318452.38 | L7: 400000 | M7: =L7-K7 -> 81547.623
A8: Total Payments | B8: =B7*B6 -> 360 | E8: 5 | F8: =F7 -> 1717.8292 | G8: =(B$5/B$7)*K8 -> 1325.256 | H8: =F8-G8 -> 392.57322 | I8: =I7+G8 -> 7975.8351 | J8: =J7+H8 -> 2331.1401 | K8: =K7-H7 -> 318061.43 | L8: 400000 | M8: =L8-K8 -> 81938.567
A9: Payment per Period | B9: =-PMT(B5/B7, B8, B4, 0) -> 1717.8292 | E9: 6 | F9: =F8 -> 1717.8292 | G9: =(B$5/B$7)*K9 -> 1323.6202 | H9: =F9-G9 -> 394.20894 | I9: =I8+G9 -> 9299.4553 | J9: =J8+H9 -> 2725.349 | K9: =K8-H8 -> 317668.86 | L9: 400000 | M9: =L9-K9 -> 82331.14
A10: Sum of Payments | B10: =B9*B8 -> 618418.51 | E10: 7 | F10: =F9 -> 1717.8292 | G10: =(B$5/B$7)*K10 -> 1321.9777 | H10: =F10-G10 -> 395.85148 | I10: =I9+G10 -> 10621.433 | J10: =J9+H10 -> 3121.2005 | K10: =K9-H9 -> 317274.65 | L10: 400000 | M10: =L10-K10 -> 82725.349
A11: Interest Cost | B11: =B10-B4 -> 298418.51 | E11: 8 | F11: =F10 -> 1717.8292 | G11: =(B$5/B$7)*K11 -> 1320.3283 | H11: =F11-G11 -> 397.50086 | I11: =I10+G11 -> 11941.761 | J11: =J10+H11 -> 3518.7014 | K11: =K10-H10 -> 316878.8 | L11: 400000 | M11: =L11-K11 -> 83121.201
E12: 9 | F12: =F11 -> 1717.8292 | G12: =(B$5/B$7)*K12 -> 1318.6721 | H12: =F12-G12 -> 399.15712 | I12: =I11+G12 -> 13260.433 | J12: =J11+H12 -> 3917.8585 | K12: =K11-H11 -> 316481.3 | L12: 400000 | M12: =L12-K12 -> 83518.701
E13: 10 | F13: =F12 -> 1717.8292 | G13: =(B$5/B$7)*K13 -> 1317.0089 | H13: =F13-G13 -> 400.82027 | I13: =I12+G13 -> 14577.442 | J13: =J12+H13 -> 4318.6788 | K13: =K12-H12 -> 316082.14 | L13: 400000 | M13: =L13-K13 -> 83917.858
E14: 11 | F14: =F13 -> 1717.8292 | G14: =(B$5/B$7)*K14 -> 1315.3388 | H14: =F14-G14 -> 402.49036 | I14: =I13+G14 -> 15892.781 | J14: =J13+H14 -> 4721.1691 | K14: =K13-H13 -> 315681.32 | L14: 400000 | M14: =L14-K14 -> 84318.679 | O14: Year | Q14: Total Principal Paid | R14: Principal/Year
E15: 12 | F15: =F14 -> 1717.8292 | G15: =(B$5/B$7)*K15 -> 1313.6618 | H15: =F15-G15 -> 404.1674 | I15: =I14+G15 -> 17206.443 | J15: =J14+H15 -> 5125.3365 | K15: =K14-H14 -> 315278.83 | L15: 400000 | M15: =L15-K15 -> 84721.169 | O15: 1 | P15: =I14 -> 15892.781 | Q15: =J14 -> 4721.1691 | R15: =Q15 -> 4721.1691
E16: 13 | F16: =F15 -> 1717.8292 | G16: =(B$5/B$7)*K16 -> 1311.9778 | H16: =F16-G16 -> 405.85143 | I16: =I15+G16 -> 18518.421 | J16: =J15+H16 -> 5531.1879 | K16: =K15-H15 -> 314874.66 | L16: 400000 | M16: =L16-K16 -> 85125.337 | O16: 2 | P16: =I26 -> 31544.018 | Q16: =J26 -> 9683.8822 | R16: =Q16-Q15 -> 4962.7131
E17: 14 | F17: =F16 -> 1717.8292 | G17: =(B$5/B$7)*K17 -> 1310.2867 | H17: =F17-G17 -> 407.54248 | I17: =I16+G17 -> 19828.707 | J17: =J16+H17 -> 5938.7304 | K17: =K16-H16 -> 314468.81 | L17: 400000 | M17: =L17-K17 -> 85531.188 | O17: 3 | P17: =I38 -> 46941.354 | Q17: =J38 -> 14900.497 | R17: =Q17-Q16 -> 5216.6149
