Workbook

Sheet Independence 1930 Condos
A1: 1930 Independence
A2: 5271 | B2: sqft
A3: 875000 | B3: asking price | C3: =A3/A2 -> 166.00266
A5: Purchase Price | B5: 875000 | C5: =B5/A2 -> 166.00266 | G5: Loan Interest Rate | H5: 0.09 | K5: Hard Money Lender Points Paid | L5: 4 | M5: =B5*(L5/100) -> 35000
A6: Closing Costs (3%) | B6: =B5*0.03 -> 26250 | G6: Monthly Interest Payment on Purchase Price | H6: =((B5-B7)*H5)/12 -> 5250 | K6: Term (months) | L6: 24
A7: Down Payment (20%) | B7: =B5*0.2 -> 175000 | K7: Hard Money Interest rate | L7: 0.12
A8: Total Loan Amount | B8: =B5-B7 -> 700000 | G8: Total Monthly(Interest+Principle+Prop Tax+Insurance) | H8: =SUM(C44:C48,C53:C55) -> 8889.0294 | K8: Monthly Loan Payment to Hard Money Lender | L8: =(B5*L7)/12 -> 8750
G9: Total Monthly Utilities | H9: =SUM(C49:C52) -> 649
G10: Total Monthly Payment | H10: =H9+H8 -> 9538.0294
A11: All In Price (Purchase+Repairs) | B11: =SUM(B5,E41) -> 878022.78 | G11: Total Montly, including Renovations/Reserves | H11: =H10+E41 -> 12560.807
A12: Estimated ARV (After Repair Value) | B12: 875000 | C12: =B12/A2 -> 166.00266
A14: Average Rent (4 units) | B14: 1811 | C14: 2023#s | K14: One Time Costs at Closing (Closing+Down+HML) | L14: =SUM(M5+B6+B7) -> 236250
B15: =B14*4 -> 7244 | C15: monthly rent | G15: Financials | K15: Repairs | L15: =E41 -> 3022.7778
A16: Calculated Gross Revenue | B16: =B15*$C$43 -> 86928 | C16: yearly rent | G16: Monthly Cash Flow | H16: =B15-H10 -> -2294.0294
G17: Cash On Cash Return (CoC) | H17: =(H16*C43)/(B7) -> -0.15730487
A18: Actual Gross Revenue | B18: 86970 | G18: Cap Rate | H18: =(B15-C55-C47-C46-C45-C53-C54)*C43/(B5) -> 0.048969488
A19: Repairs/Management Fees | B19: =SUM(B45,B53:B54) -> 22483.298 | C19: 45353 | G19: ROI (Return on Investment) | H19: =((B20+(B24-B5))/B22)/B25*12 -> 0.070765488
A20: Net Income | B20: =B18-B19 -> 64486.702 | C20: =B20/12 -> 5373.8918 | D20: per month | G20: ROE (Return on Equity) | H20: =((H16*12)/(B7+H22)) -> -0.14706124 | I20: Down Payment + Mortgage Pay Down
A21: Capital Contributions | B21: =E41*12 -> 36273.333 | G21: Yearly Cash Flow / Profit ($) | H21: =H16*C43 -> -27528.353
A22: Total Investment (Purchase + Capital) | B22: =B5+B21 -> 911273.33 | G22: Mortgage Pay Down yr 1 (Based on Amortization Schedule) | H22: =SUM('McRae Road Amorization'!E6:E17) -> 12189.718
A24: Current Property Value | B24: 875000 | G24: Rules of Thumb
A25: Months Owned | B25: 12 | G25: 50% Rule | H25: =(B15/2)-C44 -> -1368.7212
G26: 2% Rule | H26: =B15/B5 -> 0.0082788571
A29: Estimated CapEx | B29: Timeline of Repair (yrs) | C29: Cost per Unit (2000sqft each) | D29: Total Cost (all 8 units) | E29: Monthly Cost
A30: Roof | B30: 25 | C30: 7000 | D30: =C30*8 -> 56000 | E30: =D30/B30/12 -> 186.66667
A31: Master Bath | B31: 20 | C31: 10000 | D31: =C31*8 -> 80000 | E31: =D31/B31/12 -> 333.33333
A32: Kitchen | B32: 20 | C32: 5000 | D32: =C32*8 -> 40000 | E32: =D32/B32/12 -> 166.66667
A33: Flooring | B33: 10 | C33: 8000 | D33: =C33*8 -> 64000 | E33: =D33/B33/12 -> 533.33333
A34: Guest baths | B34: 20 | C34: 3000 | D34: =C34*8 -> 24000 | E34: =D34/B34/12 -> 100
A35: Exterior Paint | B35: 6 | C35: 5000 | D35: =C35*8 -> 40000 | E35: =D35/B35/12 -> 555.55556
A36: Interior Paint | B36: 6 | C36: 5000 | D36: =C36*8 -> 40000 | E36: =D36/B36/12 -> 555.55556
A37: Cabinets | B37: 20 | C37: 5000 | D37: =C37*8 -> 40000 | E37: =D37/B37/12 -> 166.66667
A38: Siding Repairs | B38: 10 | C38: 4000 | D38: =C38*8 -> 32000 | E38: =D38/B38/12 -> 266.66667
A39: Driveway Re-Pave | B39: 10 | C39: 15000 | D39: =C39 -> 15000 | E39: =D39/B39/12 -> 125
A40: Miscellaneous (light fixtures/door knobs etc) | B40: 10 | C40: 500 | D40: =C40*8 -> 4000 | E40: =D40/B40/12 -> 33.333333
A41: Total Estimated Repairs | E41: =SUM(E30:E40) -> 3022.7778
A43: Estimated Expenses | C43: 12 | D43: months
A44: Mortgage Payment | B44: =C44*$C$43 -> 59888.655 | C44: ='1930 Independence Amortization'!D6 -> 4990.7212
A45: Management Fees | B45: =C45*C43 -> 8983.2982 | C45: =C44*D45 -> 748.60818 | D45: 0.15
A46: Property Taxes / Year (1.8%) | B46: =B5*D46 -> 12250 | C46: =B46/$C$43 -> 1020.8333 | D46: 0.014
...

Sheet 1930 Independence Amortization
A1: Interest | B1: 0.077 | E1: =B1/12 -> 0.0064166667 | F1: r
A2: Term | B2: =30*12 -> 360 | C2: 30 years | E2: =(1+E1)^B2 -> 10.000352 | F2: (1+r)^n
A5: paymentNumber | B5: paymentDate | C5: startingBalance | D5: Monthly Payment | E5: principalPayment | F5: Principle Pay Down | G5: interestPayment | H5: Interest Percent | I5: cumulativePrincipal | J5: cumulativeInterest | K5: endingBalance | L5: Total Paid End of Loan
A6: 1 | B6: 44866 | C6: ='Independence 1930 Condos'!B5-'Independence 1930 Condos'!B7 -> 700000 | D6: =$C$6/((($E$2)-1)/($E$1*$E$2)) -> 4990.7212 | E6: =D6-G6 -> 499.05455 | F6: =(E6/C6)*12 -> 0.0085552209 | G6: =C6*($B$1/12) -> 4491.6667 | H6: =(G6/C6)*12 -> 0.077 | I6: =E6 -> 499.05455 | J6: =G6 -> 4491.6667 | K6: =C6-E6 -> 699500.95 | L6: =I6+J6 -> 4990.7212
A7: 2 | B7: 44896 | C7: =K6 -> 699500.95 | D7: =$C$6/((($E$2)-1)/($E$1*$E$2)) -> 4990.7212 | E7: =D7-G7 -> 502.25682 | F7: =(E7/C7)*12 -> 0.0086162597 | G7: =C7*($B$1/12) -> 4488.4644 | H7: =(G7/C7)*12 -> 0.077 | I7: =I6+E7 -> 1001.3114 | J7: =J6+G7 -> 8980.1311 | K7: =C7-E7 -> 698998.69 | L7: =I7+J7 -> 9981.4424
A8: 3 | B8: 44927 | C8: =K7 -> 698998.69 | D8: =$C$6/((($E$2)-1)/($E$1*$E$2)) -> 4990.7212 | E8: =D8-G8 -> 505.47963 | F8: =(E8/C8)*12 -> 0.0086777782 | G8: =C8*($B$1/12) -> 4485.2416 | H8: =(G8/C8)*12 -> 0.077 | I8: =I7+E8 -> 1506.791 | J8: =J7+G8 -> 13465.373 | K8: =C8-E8 -> 698493.21 | L8: =I8+J8 -> 14972.164
A9: 4 | B9: 44958 | C9: =K8 -> 698493.21 | D9: =$C$6/((($E$2)-1)/($E$1*$E$2)) -> 4990.7212 | E9: =D9-G9 -> 508.72313 | F9: =(E9/C9)*12 -> 0.0087397808 | G9: =C9*($B$1/12) -> 4481.9981 | H9: =(G9/C9)*12 -> 0.077 | I9: =I8+E9 -> 2015.5141 | J9: =J8+G9 -> 17947.371 | K9: =C9-E9 -> 697984.49 | L9: =I9+J9 -> 19962.885
A10: 5 | B10: 44986 | C10: =K9 -> 697984.49 | D10: =$C$6/((($E$2)-1)/($E$1*$E$2)) -> 4990.7212 | E10: =D10-G10 -> 511.98743 | F10: =(E10/C10)*12 -> 0.0088022718 | G10: =C10*($B$1/12) -> 4478.7338 | H10: =(G10/C10)*12 -> 0.077 | I10: =I9+E10 -> 2527.5016 | J10: =J9+G10 -> 22426.105 | K10: =C10-E10 -> 697472.5 | L10: =I10+J10 -> 24953.606
A11: 6 | B11: 45017 | C11: =K10 -> 697472.5 | D11: =$C$6/((($E$2)-1)/($E$1*$E$2)) -> 4990.7212 | E11: =D11-G11 -> 515.27269 | F11: =(E11/C11)*12 -> 0.008865256 | G11: =C11*($B$1/12) -> 4475.4485 | H11: =(G11/C11)*12 -> 0.077 | I11: =I10+E11 -> 3042.7742 | J11: =J10+G11 -> 26901.553 | K11: =C11-E11 -> 696957.23 | L11: =I11+J11 -> 29944.327
A12: 7 | B12: 45047 | C12: =K11 -> 696957.23 | D12: =$C$6/((($E$2)-1)/($E$1*$E$2)) -> 4990.7212 | E12: =D12-G12 -> 518.57902 | F12: =(E12/C12)*12 -> 0.0089287376 | G12: =C12*($B$1/12) -> 4472.1422 | H12: =(G12/C12)*12 -> 0.077 | I12: =I11+E12 -> 3561.3533 | J12: =J11+G12 -> 31373.695 | K12: =C12-E12 -> 696438.65 | L12: =I12+J12 -> 34935.049
A13: 8 | B13: 45078 | C13: =K12 -> 696438.65 | D13: =$C$6/((($E$2)-1)/($E$1*$E$2)) -> 4990.7212 | E13: =D13-G13 -> 521.90657 | F13: =(E13/C13)*12 -> 0.0089927215 | G13: =C13*($B$1/12) -> 4468.8146 | H13: =(G13/C13)*12 -> 0.077 | I13: =I12+E13 -> 4083.2598 | J13: =J12+G13 -> 35842.51 | K13: =C13-E13 -> 695916.74 | L13: =I13+J13 -> 39925.77
A14: 9 | B14: 45108 | C14: =K13 -> 695916.74 | D14: =$C$6/((($E$2)-1)/($E$1*$E$2)) -> 4990.7212 | E14: =D14-G14 -> 525.25547 | F14: =(E14/C14)*12 -> 0.0090572122 | G14: =C14*($B$1/12) -> 4465.4657 | H14: =(G14/C14)*12 -> 0.077 | I14: =I13+E14 -> 4608.5153 | J14: =J13+G14 -> 40307.976 | K14: =C14-E14 -> 695391.48 | L14: =I14+J14 -> 44916.491
A15: 10 | B15: 45139 | C15: =K14 -> 695391.48 | D15: =$C$6/((($E$2)-1)/($E$1*$E$2)) -> 4990.7212 | E15: =D15-G15 -> 528.62586 | F15: =(E15/C15)*12 -> 0.0091222145 | G15: =C15*($B$1/12) -> 4462.0954 | H15: =(G15/C15)*12 -> 0.077 | I15: =I14+E15 -> 5137.1412 | J15: =J14+G15 -> 44770.071 | K15: =C15-E15 -> 694862.86 | L15: =I15+J15 -> 49907.212
A16: 11 | B16: 45170 | C16: =K15 -> 694862.86 | D16: =$C$6/((($E$2)-1)/($E$1*$E$2)) -> 4990.7212 | E16: =D16-G16 -> 532.01787 | F16: =(E16/C16)*12 -> 0.0091877331 | G16: =C16*($B$1/12) -> 4458.7033 | H16: =(G16/C16)*12 -> 0.077 | I16: =I15+E16 -> 5669.159 | J16: =J15+G16 -> 49228.774 | K16: =C16-E16 -> 694330.84 | L16: =I16+J16 -> 54897.933
A17: 12 | B17: 45200 | C17: =K16 -> 694330.84 | D17: =$C$6/((($E$2)-1)/($E$1*$E$2)) -> 4990.7212 | E17: =D17-G17 -> 535.43165 | F17: =(E17/C17)*12 -> 0.0092537728 | G17: =C17*($B$1/12) -> 4455.2896 | H17: =(G17/C17)*12 -> 0.077 | I17: =I16+E17 -> 6204.5907 | J17: =J16+G17 -> 53684.064 | K17: =C17-E17 -> 693795.41 | L17: =I17+J17 -> 59888.655
A18: 13 | B18: 45231 | C18: =K17 -> 693795.41 | D18: =$C$6/((($E$2)-1)/($E$1*$E$2)) -> 4990.7212 | E18: =D18-G18 -> 538.86734 | F18: =(E18/C18)*12 -> 0.0093203385 | G18: =C18*($B$1/12) -> 4451.8539 | H18: =(G18/C18)*12 -> 0.077 | I18: =I17+E18 -> 6743.458 | J18: =J17+G18 -> 58135.918 | K18: =C18-E18 -> 693256.54 | L18: =I18+J18 -> 64879.376
... A340: 335 | B340: 55032 | C340: =K339 -> 119161.42 | D340: =$C$6/((($E$2)-1)/($E$1*$E$2)) -> 4990.7212 | E340: =D340-G340 -> 4226.1021 | F340: =(E340/C340)*12 -> 0.42558425 | G340: =C340*($B$1/12) -> 764.61913 | H340: =(G340/C340)*12 -> 0.077 | I340: =I339+E340 -> 585064.68 | J340: =J339+G340 -> 1086826.9 | K340: =C340-E340 -> 114935.32 | L340: =I340+J340 -> 1671891.6
A341: =A340+1 -> 336 | C341: =K340 -> 114935.32 | D341: =$C$6/((($E$2)-1)/($E$1*$E$2)) -> 4990.7212 | E341: =D341-G341 -> 4253.2196 | F341: =(E341/C341)*12 -> 0.44406397 | G341: =C341*($B$1/12) -> 737.50164 | H341: =(G341/C341)*12 -> 0.077 | I341: =I340+E341 -> 589317.9 | J341: =J340+G341 -> 1087564.4 | K341: =C341-E341 -> 110682.1 | L341: =I341+J341 -> 1676882.3
A342: =A341+1 -> 337 | C342: =K341 -> 110682.1 | D342: =$C$6/((($E$2)-1)/($E$1*$E$2)) -> 4990.7212 | E342: =D342-G342 -> 4280.5111 | F342: =(E342/C342)*12 -> 0.46408708 | G342: =C342*($B$1/12) -> 710.21015 | H342: =(G342/C342)*12 -> 0.077 | I342: =I341+E342 -> 593598.41 | J342: =J341+G342 -> 1088274.6 | K342: =C342-E342 -> 106401.59 | L342: =I342+J342 -> 1681873.1
A343: =A342+1 -> 338 | C343: =K342 -> 106401.59 | D343: =$C$6/((($E$2)-1)/($E$1*$E$2)) -> 4990.7212 | E343: =D343-G343 -> 4307.9777 | F343: =(E343/C343)*12 -> 0.48585489 | G343: =C343*($B$1/12) -> 682.74353 | H343: =(G343/C343)*12 -> 0.077 | I343: =I342+E343 -> 597906.39 | J343: =J342+G343 -> 1088957.4 | K343: =C343-E343 -> 102093.61 | L343: =I343+J343 -> 1686863.8
A344: =A343+1 -> 339 | C344: =K343 -> 102093.61 | D344: =$C$6/((($E$2)-1)/($E$1*$E$2)) -> 4990.7212 | E344: =D344-G344 -> 4335.6205 | F344: =(E344/C344)*12 -> 0.50960531 | G344: =C344*($B$1/12) -> 655.10068 | H344: =(G344/C344)*12 -> 0.077 | I344: =I343+E344 -> 602242.01 | J344: =J343+G344 -> 1089612.5 | K344: =C344-E344 -> 97757.991 | L344: =I344+J344 -> 1691854.5
A345: =A344+1 -> 340 | C345: =K344 -> 97757.991 | D345: =$C$6/((($E$2)-1)/($E$1*$E$2)) -> 4990.7212 | E345: =D345-G345 -> 4363.4408 | F345: =(E345/C345)*12 -> 0.53562157 | G345: =C345*($B$1/12) -> 627.28044 | H345: =(G345/C345)*12 -> 0.077 | I345: =I344+E345 -> 606605.45 | J345: =J344+G345 -> 1090239.8 | K345: =C345-E345 -> 93394.551 | L345: =I345+J345 -> 1696845.2
A346: =A345+1 -> 341 | C346: =K345 -> 93394.551 | D346: =$C$6/((($E$2)-1)/($E$1*$E$2)) -> 4990.7212 | E346: =D346-G346 -> 4391.4395 | F346: =(E346/C346)*12 -> 0.56424357 | G346: =C346*($B$1/12) -> 599.2817 | H346: =(G346/C346)*12 -> 0.077 | I346: =I345+E346 -> 610996.89 | J346: =J345+G346 -> 1090839 | K346: =C346-E346 -> 89003.111 | L346: =I346+J346 -> 1701835.9
A347: =A346+1 -> 342 | C347: =K346 -> 89003.111 | D347: =$C$6/((($E$2)-1)/($E$1*$E$2)) -> 4990.7212 | E347: =D347-G347 -> 4419.6179 | F347: =(E347/C347)*12 -> 0.59588271 | G347: =C347*($B$1/12) -> 571.1033 | H347: =(G347/C347)*12 -> 0.077 | I347: =I346+E347 -> 615416.51 | J347: =J346+G347 -> 1091410.1 | K347: =C347-E347 -> 84583.493 | L347: =I347+J347 -> 1706826.7
A348: =A347+1 -> 343 | C348: =K347 -> 84583.493 | D348: =$C$6/((($E$2)-1)/($E$1*$E$2)) -> 4990.7212 | E348: =D348-G348 -> 4447.9771 | F348: =(E348/C348)*12 -> 0.63104187 | G348: =C348*($B$1/12) -> 542.74408 | H348: =(G348/C348)*12 -> 0.077 | I348: =I347+E348 -> 619864.48 | J348: =J347+G348 -> 1091952.9 | K348: =C348-E348 -> 80135.516 | L348: =I348+J348 -> 1711817.4
A349: =A348+1 -> 344 | C349: =K348 -> 80135.516 | D349: =$C$6/((($E$2)-1)/($E$1*$E$2)) -> 4990.7212 | E349: =D349-G349 -> 4476.5183 | F349: =(E349/C349)*12 -> 0.67034222 | G349: =C349*($B$1/12) -> 514.20289 | H349: =(G349/C349)*12 -> 0.077 | I349: =I348+E349 -> 624341 | J349: =J348+G349 -> 1092467.1 | K349: =C349-E349 -> 75658.998 | L349: =I349+J349 -> 1716808.1
A350: =A349+1 -> 345 | C350: =K349 -> 75658.998 | D350: =$C$6/((($E$2)-1)/($E$1*$E$2)) -> 4990.7212 | E350: =D350-G350 -> 4505.2426 | F350: =(E350/C350)*12 -> 0.71456024 | G350: =C350*($B$1/12) -> 485.47857 | H350: =(G350/C350)*12 -> 0.077 | I350: =I349+E350 -> 628846.24 | J350: =J349+G350 -> 1092952.6 | K350: =C350-E350 -> 71153.755 | L350: =I350+J350 -> 1721798.8
A351: =A350+1 -> 346 | C351: =K350 -> 71153.755 | D351: =$C$6/((($E$2)-1)/($E$1*$E$2)) -> 4990.7212 | E351: =D351-G351 -> 4534.1513 | F351: =(E351/C351)*12 -> 0.76467947 | G351: =C351*($B$1/12) -> 456.56993 | H351: =(G351/C351)*12 -> 0.077 | I351: =I350+E351 -> 633380.4 | J351: =J350+G351 -> 1093409.1 | K351: =C351-E351 -> 66619.604 | L351: =I351+J351 -> 1726789.5
A352: =A351+1 -> 347 | C352: =K351 -> 66619.604 | D352: =$C$6/((($E$2)-1)/($E$1*$E$2)) -> 4990.7212 | E352: =D352-G352 -> 4563.2454 | F352: =(E352/C352)*12 -> 0.82196444 | G352: =C352*($B$1/12) -> 427.47579 | H352: =(G352/C352)*12 -> 0.077 | I352: =I351+E352 -> 637943.64 | J352: =J351+G352 -> 1093836.6 | K352: =C352-E352 -> 62056.358 | L352: =I352+J352 -> 1731780.3
... A365: =A364+1 -> 360 | C365: =K364 -> 4958.9016 | D365: =$C$6/((($E$2)-1)/($E$1*$E$2)) -> 4990.7212 | E365: =D365-G365 -> 4958.9016 | F365: =(E365/C365)*12 -> 12 | G365: =C365*($B$1/12) -> 31.819619 | H365: =(G365/C365)*12 -> 0.077 | I365: =I364+E365 -> 700000 | J365: =J364+G365 -> 1096659.6 | K365: =C365-E365 -> 3.4964614e-08 | L365: =I365+J365 -> 1796659.6

Sheet Amortization Schedule
A1: paymentNumber | B1: paymentDate | C1: startingBalance | D1: principalPayment | E1: Principle Pay Down | F1: interestPayment | G1: Interest Percent | H1: cumulativePrincipal | I1: cumulativeInterest | J1: endingBalance | K1: 0.07
A2: 1 | B2: 44866 | C2: 371403.71 | D2: 726.19 | E2: =(D2/C2)*12 -> 0.023463094 | F2: 889.82 | G2: =(F2/C2)*12 -> 0.028749955 | H2: 726.19 | I2: 889.82 | J2: 370677.52 | K2: =C2*($K$1/12) -> 2166.5216 | L2: Interest Only Payments
A3: 2 | B3: 44896 | C3: 370677.52 | D3: 727.93 | E3: =(D3/C3)*12 -> 0.023565389 | F3: 888.08 | G3: =(F3/C3)*12 -> 0.02874995 | H3: 1454.12 | I3: 1777.9 | J3: 369949.59
A4: 3 | B4: 44927 | C4: 369949.59 | D4: 729.67 | E4: =(D4/C4)*12 -> 0.023668198 | F4: 886.34 | G4: =(F4/C4)*12 -> 0.028750079 | H4: 2183.79 | I4: 2664.24 | J4: 369219.92
A5: 4 | B5: 44958 | C5: 369219.92 | D5: 731.42 | E5: =(D5/C5)*12 -> 0.023771848 | F5: 884.59 | G5: =(F5/C5)*12 -> 0.02875002 | H5: 2915.21 | I5: 3548.83 | J5: 368488.5
A6: 5 | B6: 44986 | C6: 368488.5 | D6: 733.17 | E6: =(D6/C6)*12 -> 0.023876023 | F6: 882.84 | G6: =(F6/C6)*12 -> 0.028750097 | H6: 3648.38 | I6: 4431.67 | J6: 367755.33
A7: 6 | B7: 45017 | C7: 367755.33 | D7: 734.93 | E7: =(D7/C7)*12 -> 0.023981053 | F7: 881.08 | G7: =(F7/C7)*12 -> 0.028749984 | H7: 4383.31 | I7: 5312.75 | J7: 367020.4
A8: 7 | B8: 45047 | C8: 367020.4 | D8: 736.69 | E8: =(D8/C8)*12 -> 0.024086618 | F8: 879.32 | G8: =(F8/C8)*12 -> 0.02875001 | H8: 5120 | I8: 6192.07 | J8: 366283.71
A9: 8 | B9: 45078 | C9: 366283.71 | D9: 738.46 | E9: =(D9/C9)*12 -> 0.02419305 | F9: 877.55 | G9: =(F9/C9)*12 -> 0.028749845 | H9: 5858.46 | I9: 7069.62 | J9: 365545.25
A10: 9 | B10: 45108 | C10: 365545.25 | D10: 740.22 | E10: =(D10/C10)*12 -> 0.0242997 | F10: 875.79 | G10: =(F10/C10)*12 -> 0.028750148 | H10: 6598.68 | I10: 7945.41 | J10: 364805.03
A11: 10 | B11: 45139 | C11: 364805.03 | D11: 742 | E11: =(D11/C11)*12 -> 0.024407558 | F11: 874.01 | G11: =(F11/C11)*12 -> 0.028749933 | H11: 7340.68 | I11: 8819.42 | J11: 364063.03
A12: 11 | B12: 45170 | C12: 364063.03 | D12: 743.78 | E12: =(D12/C12)*12 -> 0.024515975 | F12: 872.23 | G12: =(F12/C12)*12 -> 0.028749857 | H12: 8084.46 | I12: 9691.65 | J12: 363319.25
A13: 12 | B13: 45200 | C13: 363319.25 | D13: 745.56 | E13: =(D13/C13)*12 -> 0.024624954 | F13: 870.45 | G13: =(F13/C13)*12 -> 0.028749922 | H13: 8830.01 | I13: 10562.11 | J13: 362573.7
A14: 13 | B14: 45231 | C14: 362573.7 | D14: 747.34 | E14: =(D14/C14)*12 -> 0.024734502 | F14: 868.67 | G14: =(F14/C14)*12 -> 0.028750127 | H14: 9577.36 | I14: 11430.77 | J14: 361826.35
... A336: 335 | B336: 55032 | C336: 441.24 | D336: 1614.95 | E336: =(D336/C336)*12 -> 43.920315 | F336: 1.06 | G336: =(F336/C336)*12 -> 0.028827849 | H336: 372577.43 | I336: 168785.92 | J336: -1173.72

Sheet Flipping Calculator
A1: 2921 Admiralty Bay | B1: 4 bed 3 bath
A2: 2418 | B2: sqft
A3: 479000 | B3: asking price | C3: =A3/A2 -> 198.0976
A5: Purchase Price | B5: 400000 | C5: =B5/A2 -> 165.42597 | F5: Loan Interest Rate | G5: 0.07 | J5: Hard Money Lender Points Paid | K5: 4 | L5: =B5*(K5/100) -> 16000
A6: Closing Costs (3%) | B6: =B5*0.03 -> 12000 | F6: Monthly Interest Payment on Loan Amount (Purchase - Down) | G6: =((B5-B7)*($G$5/12)) -> 1866.6667 | J6: Term (months) | K6: 24
A7: Down Payment (20%) | B7: =B5*0.2 -> 80000 | J7: Hard Money Interest rate | K7: 0.12
F8: Total Monthly(Interest+Principle+Prop Tax+Insurance) | G8: =G6+C28+C29+C30+C32 -> 3425 | J8: Monthly Loan Payment to Hard Money Lender | K8: =(B5*K7)/12 -> 4000
A9: All In Price (Purchase+Repairs+Holding) | B9: =SUM(B5,B6,B26,B40) -> 562228 | F9: Total Monthly Utilities | G9: =SUM(C33:C35) -> 513
A10: Estimated ARV (After Repair Value) | B10: 550000 | C10: =B10/A2 -> 227.46071 | F10: Total Monthly Payment | G10: =G9+G8 -> 3938
A11: 80% ARV (Refinance) | B11: =B10*0.8 -> 440000
A13: Estimated Profit | B13: =B10-B9 -> -12228
J14: One Time Costs at Closing (Closing+Down+HML) | K14: =SUM(L5+B6+B7) -> 108000
A15: Estimated Repairs | J15: Repairs | K15: =B26 -> 131000
A16: Master Bath | B16: 25000
A17: Kitchen | B17: 25000
A18: Flooring | B18: 20000
A19: Guest baths (2) | B19: 15000 | F19: Financials
A20: Exterior Paint | B20: 15000 | F20: Cash On Cash Return (CoC)
A21: Interior Paint | B21: 10000 | F21: ROI (Return on Investment)
A22: Cabinets | B22: 5000 | F22: ROE (Return on Equity)
A23: Siding Repairs | B23: 7000 | F23: Profit ($)
A24: Driveway Re-Pave | B24: 4000
A25: Miscellaneous (blinds, light fixtures, door knobs, deck etc) | B25: 5000
A26: Total Estimated Repairs | B26: =SUM(B16:B25) -> 131000
C27: 12 | D27: months
A28: Property Taxes / Year (1.8%) | B28: =B5*0.018 -> 7200 | C28: =B28/$C$27 -> 600 | G28: Mill Rate | H28: 16.4 | I28: =(B5/1000)*H28 -> 6560
A29: Insurance / Year | B29: 2400 | C29: =B29/$C$27 -> 200 | I29: =I28/B5 -> 0.0164 | J29: yearly
A30: Principle / Year (Based on Amortization Schedule) | B30: 8800 | C30: =B30/$C$27 -> 733.33333
A31: Interest Only | B31: =C31*$C$27 -> 22400 | C31: =G6 -> 1866.6667 | D31: ="7% Interest on $" & (B5-B7) &" loan" -> 7% Interest on $320000 loan
A32: HOA / year | B32: 300 | C32: =B32/$C$27 -> 25
A33: Electricity | B33: =C33*$C$27 -> 2400 | C33: 200
A34: Nat Gas | B34: =C34*$C$27 -> 2400 | C34: 200
A35: Water | B35: =C35*$C$27 -> 1356 | C35: 113
A36: Total Holding Costs / Year | B36: =SUM(B28:B35) -> 47256 | C36: =B36/$C$27 -> 3938
A37: Total Holding - Interest Only Payments | B37: =SUM(B28:B29,B31,B32:B35) -> 38456 | C37: =B37/C27 -> 3204.6667
A39: Expected Holding Period | B39: 6 | C39: months
A40: Actual Holding Costs Interest Only | B40: =C37*B39 -> 19228
A41: Actual Holding Costs Total | B41: =C36*B39 -> 23628

Sheet 2921 Admiralty Bay
A1: 2921 Admiralty Bay | B1: Location Location Location
A2: 2418 | B2: sqft
A3: 479000 | B3: asking price | C3: =A3/A2 -> 198.0976
A5: Purchase Price | B5: 400000 | C5: =B5/A2 -> 165.42597 | F5: Loan Interest Rate | G5: 0.07 | J5: Hard Money Lender Points Paid | K5: 4 | L5: =B5*(K5/100) -> 16000
A6: Closing Costs (3%) | B6: =B5*0.03 -> 12000 | F6: Monthly Interest Payment on Purchase Price | G6: =(B5*G5)/12 -> 2333.3333 | J6: Term (months) | K6: 24
A7: Down Payment (20%) | B7: =B5*0.2 -> 80000 | J7: Hard Money Interest rate | K7: 0.12
F8: Total Monthly(Interest+Principle+Prop Tax+Insurance) | G8: =G6+C29+C30+C31+C32 -> 3891.6667 | J8: Monthly Loan Payment to Hard Money Lender | K8: =(B5*K7)/12 -> 4000
A9: All In Price (Purchase+Repairs) | B9: =SUM(B5,B27) -> 536000 | F9: Total Monthly Utilities | G9: =SUM(C33:C35) -> 513
A10: Estimated ARV (After Repair Value) | B10: 550000 | C10: =B10/A2 -> 227.46071 | F10: Total Monthly Payment | G10: =G9+G8 -> 4404.6667
A11: ARV (80%) | B11: =B10*0.8 -> 440000
A12: LTV (70%) | B12: =B10*0.7 -> 385000
A14: Estimated Profit | B14: =B10-B9 -> 14000
J15: One Time Costs at Closing (Closing+Down+HML) | K15: =SUM(L5+B6+B7) -> 108000
A16: Estimated Repairs | J16: Repairs | K16: =B27 -> 136000
A17: Master Bath | B17: 25000
A18: Kitchen | B18: 25000
A19: Flooring | B19: 20000 | F19: Financials
A20: Guest baths (3) | B20: 20000 | F20: Cash On Cash Return (CoC)
A21: Exterior Paint | B21: 15000 | F21: ROI (Return on Investment)
A22: Interior Paint | B22: 10000 | F22: ROE (Return on Equity)
A23: Cabinets | B23: 5000 | F23: Profit ($)
A24: Siding Repairs | B24: 7000
A25: Driveway Re-Pave | B25: 4000
A26: Miscellaneous (light fixtures/door knobs etc) | B26: 5000
A27: Total Estimated Repairs | B27: =SUM(B17:B26) -> 136000
C28: 12
A29: Property Taxes / Year (1.8%) | B29: =B5*0.018 -> 7200 | C29: =B29/$C$28 -> 600 | E29: Mill Rate | F29: 16.4 | G29: =(B5/1000)*F29 -> 6560
A30: Insurance / Year | B30: 2400 | C30: =B30/$C$28 -> 200 | G30: =G29/B5 -> 0.0164 | H30: yearly
A31: Principle / Year (Based on Amortization Schedule) | B31: 8800 | C31: =B31/$C$28 -> 733.33333
A32: HOA / year | B32: 300 | C32: =B32/$C$28 -> 25
A33: Electricity | C33: 200
A34: Nat Gas | C34: 200
A35: Water | C35: 113

Sheet McRae Road Amorization
A1: Interest | B1: 0.07 | E1: =B1/12 -> 0.0058333333 | F1: r
A2: Term | B2: =30*12 -> 360 | C2: 30 years | E2: =(1+E1)^B2 -> 8.1164975 | F2: (1+r)^n
A5: paymentNumber | B5: paymentDate | C5: startingBalance | D5: Monthly Payment | E5: principalPayment | F5: Principle Pay Down | G5: interestPayment | H5: Interest Percent | I5: cumulativePrincipal | J5: cumulativeInterest | K5: endingBalance | L5: Total Paid End of Loan
A6: 1 | B6: 44866 | C6: ='McRae Road Condos'!B5-'McRae Road Condos'!B7 -> 1200000 | D6: =$C$6/((($E$2)-1)/($E$1*$E$2)) -> 7983.6299 | E6: =D6-G6 -> 983.62994 | F6: =(E6/C6)*12 -> 0.0098362994 | G6: =C6*($B$1/12) -> 7000 | H6: =(G6/C6)*12 -> 0.07 | I6: =E6 -> 983.62994 | J6: =G6 -> 7000 | K6: =C6-E6 -> 1199016.4 | L6: =I6+J6 -> 7983.6299
A7: 2 | B7: 44896 | C7: =K6 -> 1199016.4 | D7: =$C$6/((($E$2)-1)/($E$1*$E$2)) -> 7983.6299 | E7: =D7-G7 -> 989.36778 | F7: =(E7/C7)*12 -> 0.0099017943 | G7: =C7*($B$1/12) -> 6994.2622 | H7: =(G7/C7)*12 -> 0.07 | I7: =I6+E7 -> 1972.9977 | J7: =J6+G7 -> 13994.262 | K7: =C7-E7 -> 1198027 | L7: =I7+J7 -> 15967.26
A8: 3 | B8: 44927 | C8: =K7 -> 1198027 | D8: =$C$6/((($E$2)-1)/($E$1*$E$2)) -> 7983.6299 | E8: =D8-G8 -> 995.1391 | F8: =(E8/C8)*12 -> 0.0099677796 | G8: =C8*($B$1/12) -> 6988.4908 | H8: =(G8/C8)*12 -> 0.07 | I8: =I7+E8 -> 2968.1368 | J8: =J7+G8 -> 20982.753 | K8: =C8-E8 -> 1197031.9 | L8: =I8+J8 -> 23950.89
A9: 4 | B9: 44958 | C9: =K8 -> 1197031.9 | D9: =$C$6/((($E$2)-1)/($E$1*$E$2)) -> 7983.6299 | E9: =D9-G9 -> 1000.9441 | F9: =(E9/C9)*12 -> 0.01003426 | G9: =C9*($B$1/12) -> 6982.6859 | H9: =(G9/C9)*12 -> 0.07 | I9: =I8+E9 -> 3969.0809 | J9: =J8+G9 -> 27965.439 | K9: =C9-E9 -> 1196030.9 | L9: =I9+J9 -> 31934.52
A10: 5 | B10: 44986 | C10: =K9 -> 1196030.9 | D10: =$C$6/((($E$2)-1)/($E$1*$E$2)) -> 7983.6299 | E10: =D10-G10 -> 1006.7829 | F10: =(E10/C10)*12 -> 0.01010124 | G10: =C10*($B$1/12) -> 6976.847 | H10: =(G10/C10)*12 -> 0.07 | I10: =I9+E10 -> 4975.8638 | J10: =J9+G10 -> 34942.286 | K10: =C10-E10 -> 1195024.1 | L10: =I10+J10 -> 39918.15
A11: 6 | B11: 45017 | C11: =K10 -> 1195024.1 | D11: =$C$6/((($E$2)-1)/($E$1*$E$2)) -> 7983.6299 | E11: =D11-G11 -> 1012.6558 | F11: =(E11/C11)*12 -> 0.010168723 | G11: =C11*($B$1/12) -> 6970.9741 | H11: =(G11/C11)*12 -> 0.07 | I11: =I10+E11 -> 5988.5196 | J11: =J10+G11 -> 41913.26 | K11: =C11-E11 -> 1194011.5 | L11: =I11+J11 -> 47901.78
A12: 7 | B12: 45047 | C12: =K11 -> 1194011.5 | D12: =$C$6/((($E$2)-1)/($E$1*$E$2)) -> 7983.6299 | E12: =D12-G12 -> 1018.563 | F12: =(E12/C12)*12 -> 0.010236715 | G12: =C12*($B$1/12) -> 6965.067 | H12: =(G12/C12)*12 -> 0.07 | I12: =I11+E12 -> 7007.0826 | J12: =J11+G12 -> 48878.327 | K12: =C12-E12 -> 1192992.9 | L12: =I12+J12 -> 55885.41
A13: 8 | B13: 45078 | C13: =K12 -> 1192992.9 | D13: =$C$6/((($E$2)-1)/($E$1*$E$2)) -> 7983.6299 | E13: =D13-G13 -> 1024.5046 | F13: =(E13/C13)*12 -> 0.010305221 | G13: =C13*($B$1/12) -> 6959.1254 | H13: =(G13/C13)*12 -> 0.07 | I13: =I12+E13 -> 8031.5872 | J13: =J12+G13 -> 55837.452 | K13: =C13-E13 -> 1191968.4 | L13: =I13+J13 -> 63869.04
A14: 9 | B14: 45108 | C14: =K13 -> 1191968.4 | D14: =$C$6/((($E$2)-1)/($E$1*$E$2)) -> 7983.6299 | E14: =D14-G14 -> 1030.4809 | F14: =(E14/C14)*12 -> 0.010374243 | G14: =C14*($B$1/12) -> 6953.1491 | H14: =(G14/C14)*12 -> 0.07 | I14: =I13+E14 -> 9062.0681 | J14: =J13+G14 -> 62790.601 | K14: =C14-E14 -> 1190937.9 | L14: =I14+J14 -> 71852.669
A15: 10 | B15: 45139 | C15: =K14 -> 1190937.9 | D15: =$C$6/((($E$2)-1)/($E$1*$E$2)) -> 7983.6299 | E15: =D15-G15 -> 1036.492 | F15: =(E15/C15)*12 -> 0.010443789 | G15: =C15*($B$1/12) -> 6947.1379 | H15: =(G15/C15)*12 -> 0.07 | I15: =I14+E15 -> 10098.56 | J15: =J14+G15 -> 69737.739 | K15: =C15-E15 -> 1189901.4 | L15: =I15+J15 -> 79836.299
A16: 11 | B16: 45170 | C16: =K15 -> 1189901.4 | D16: =$C$6/((($E$2)-1)/($E$1*$E$2)) -> 7983.6299 | E16: =D16-G16 -> 1042.5382 | F16: =(E16/C16)*12 -> 0.010513861 | G16: =C16*($B$1/12) -> 6941.0917 | H16: =(G16/C16)*12 -> 0.07 | I16: =I15+E16 -> 11141.098 | J16: =J15+G16 -> 76678.831 | K16: =C16-E16 -> 1188858.9 | L16: =I16+J16 -> 87819.929
A17: 12 | B17: 45200 | C17: =K16 -> 1188858.9 | D17: =$C$6/((($E$2)-1)/($E$1*$E$2)) -> 7983.6299 | E17: =D17-G17 -> 1048.6197 | F17: =(E17/C17)*12 -> 0.010584466 | G17: =C17*($B$1/12) -> 6935.0103 | H17: =(G17/C17)*12 -> 0.07 | I17: =I16+E17 -> 12189.718 | J17: =J16+G17 -> 83613.841 | K17: =C17-E17 -> 1187810.3 | L17: =I17+J17 -> 95803.559
A18: 13 | B18: 45231 | C18: =K17 -> 1187810.3 | D18: =$C$6/((($E$2)-1)/($E$1*$E$2)) -> 7983.6299 | E18: =D18-G18 -> 1054.7366 | F18: =(E18/C18)*12 -> 0.010655607 | G18: =C18*($B$1/12) -> 6928.8933 | H18: =(G18/C18)*12 -> 0.07 | I18: =I17+E18 -> 13244.455 | J18: =J17+G18 -> 90542.735 | K18: =C18-E18 -> 1186755.5 | L18: =I18+J18 -> 103787.19
... A340: 335 | B340: 55032 | C340: =K339 -> 192081.51 | D340: =$C$6/((($E$2)-1)/($E$1*$E$2)) -> 7983.6299 | E340: =D340-G340 -> 6863.1545 | F340: =(E340/C340)*12 -> 0.42876513 | G340: =C340*($B$1/12) -> 1120.4755 | H340: =(G340/C340)*12 -> 0.07 | I340: =I339+E340 -> 1014781.6 | J340: =J339+G340 -> 1659734.4 | K340: =C340-E340 -> 185218.36 | L340: =I340+J340 -> 2674516
A341: =A340+1 -> 336 | C341: =K340 -> 185218.36 | D341: =$C$6/((($E$2)-1)/($E$1*$E$2)) -> 7983.6299 | E341: =D341-G341 -> 6903.1895 | F341: =(E341/C341)*12 -> 0.44724657 | G341: =C341*($B$1/12) -> 1080.4404 | H341: =(G341/C341)*12 -> 0.07 | I341: =I340+E341 -> 1021684.8 | J341: =J340+G341 -> 1660814.8 | K341: =C341-E341 -> 178315.17 | L341: =I341+J341 -> 2682499.7
A342: =A341+1 -> 337 | C342: =K341 -> 178315.17 | D342: =$C$6/((($E$2)-1)/($E$1*$E$2)) -> 7983.6299 | E342: =D342-G342 -> 6943.4581 | F342: =(E342/C342)*12 -> 0.46727095 | G342: =C342*($B$1/12) -> 1040.1718 | H342: =(G342/C342)*12 -> 0.07 | I342: =I341+E342 -> 1028628.3 | J342: =J341+G342 -> 1661855 | K342: =C342-E342 -> 171371.71 | L342: =I342+J342 -> 2690483.3
A343: =A342+1 -> 338 | C343: =K342 -> 171371.71 | D343: =$C$6/((($E$2)-1)/($E$1*$E$2)) -> 7983.6299 | E343: =D343-G343 -> 6983.9616 | F343: =(E343/C343)*12 -> 0.48903953 | G343: =C343*($B$1/12) -> 999.6683 | H343: =(G343/C343)*12 -> 0.07 | I343: =I342+E343 -> 1035612.3 | J343: =J342+G343 -> 1662854.7 | K343: =C343-E343 -> 164387.75 | L343: =I343+J343 -> 2698466.9
A344: =A343+1 -> 339 | C344: =K343 -> 164387.75 | D344: =$C$6/((($E$2)-1)/($E$1*$E$2)) -> 7983.6299 | E344: =D344-G344 -> 7024.7014 | F344: =(E344/C344)*12 -> 0.51279014 | G344: =C344*($B$1/12) -> 958.92853 | H344: =(G344/C344)*12 -> 0.07 | I344: =I343+E344 -> 1042637 | J344: =J343+G344 -> 1663813.6 | K344: =C344-E344 -> 157363.05 | L344: =I344+J344 -> 2706450.6
A345: =A344+1 -> 340 | C345: =K344 -> 157363.05 | D345: =$C$6/((($E$2)-1)/($E$1*$E$2)) -> 7983.6299 | E345: =D345-G345 -> 7065.6788 | F345: =(E345/C345)*12 -> 0.53880595 | G345: =C345*($B$1/12) -> 917.9511 | H345: =(G345/C345)*12 -> 0.07 | I345: =I344+E345 -> 1049702.6 | J345: =J344+G345 -> 1664731.5 | K345: =C345-E345 -> 150297.37 | L345: =I345+J345 -> 2714434.2
A346: =A345+1 -> 341 | C346: =K345 -> 150297.37 | D346: =$C$6/((($E$2)-1)/($E$1*$E$2)) -> 7983.6299 | E346: =D346-G346 -> 7106.8953 | F346: =(E346/C346)*12 -> 0.56742673 | G346: =C346*($B$1/12) -> 876.73464 | H346: =(G346/C346)*12 -> 0.07 | I346: =I345+E346 -> 1056809.5 | J346: =J345+G346 -> 1665608.3 | K346: =C346-E346 -> 143190.47 | L346: =I346+J346 -> 2722417.8
A347: =A346+1 -> 342 | C347: =K346 -> 143190.47 | D347: =$C$6/((($E$2)-1)/($E$1*$E$2)) -> 7983.6299 | E347: =D347-G347 -> 7148.3522 | F347: =(E347/C347)*12 -> 0.59906379 | G347: =C347*($B$1/12) -> 835.27775 | H347: =(G347/C347)*12 -> 0.07 | I347: =I346+E347 -> 1063957.9 | J347: =J346+G347 -> 1666443.6 | K347: =C347-E347 -> 136042.12 | L347: =I347+J347 -> 2730401.4
A348: =A347+1 -> 343 | C348: =K347 -> 136042.12 | D348: =$C$6/((($E$2)-1)/($E$1*$E$2)) -> 7983.6299 | E348: =D348-G348 -> 7190.0509 | F348: =(E348/C348)*12 -> 0.63421984 | G348: =C348*($B$1/12) -> 793.57903 | H348: =(G348/C348)*12 -> 0.07 | I348: =I347+E348 -> 1071147.9 | J348: =J347+G348 -> 1667237.1 | K348: =C348-E348 -> 128852.07 | L348: =I348+J348 -> 2738385.1
A349: =A348+1 -> 344 | C349: =K348 -> 128852.07 | D349: =$C$6/((($E$2)-1)/($E$1*$E$2)) -> 7983.6299 | E349: =D349-G349 -> 7231.9929 | F349: =(E349/C349)*12 -> 0.67351588 | G349: =C349*($B$1/12) -> 751.63707 | H349: =(G349/C349)*12 -> 0.07 | I349: =I348+E349 -> 1078379.9 | J349: =J348+G349 -> 1667988.8 | K349: =C349-E349 -> 121620.08 | L349: =I349+J349 -> 2746368.7
A350: =A349+1 -> 345 | C350: =K349 -> 121620.08 | D350: =$C$6/((($E$2)-1)/($E$1*$E$2)) -> 7983.6299 | E350: =D350-G350 -> 7274.1795 | F350: =(E350/C350)*12 -> 0.71772816 | G350: =C350*($B$1/12) -> 709.45044 | H350: =(G350/C350)*12 -> 0.07 | I350: =I349+E350 -> 1085654.1 | J350: =J349+G350 -> 1668698.2 | K350: =C350-E350 -> 114345.9 | L350: =I350+J350 -> 2754352.3
A351: =A350+1 -> 346 | C351: =K350 -> 114345.9 | D351: =$C$6/((($E$2)-1)/($E$1*$E$2)) -> 7983.6299 | E351: =D351-G351 -> 7316.6122 | F351: =(E351/C351)*12 -> 0.76783994 | G351: =C351*($B$1/12) -> 667.01773 | H351: =(G351/C351)*12 -> 0.07 | I351: =I350+E351 -> 1092970.7 | J351: =J350+G351 -> 1669365.2 | K351: =C351-E351 -> 107029.28 | L351: =I351+J351 -> 2762336
A352: =A351+1 -> 347 | C352: =K351 -> 107029.28 | D352: =$C$6/((($E$2)-1)/($E$1*$E$2)) -> 7983.6299 | E352: =D352-G352 -> 7359.2924 | F352: =(E352/C352)*12 -> 0.82511539 | G352: =C352*($B$1/12) -> 624.33749 | H352: =(G352/C352)*12 -> 0.07 | I352: =I351+E352 -> 1100330 | J352: =J351+G352 -> 1669989.6 | K352: =C352-E352 -> 99669.992 | L352: =I352+J352 -> 2770319.6
... A365: =A364+1 -> 360 | C365: =K364 -> 7937.3289 | D365: =$C$6/((($E$2)-1)/($E$1*$E$2)) -> 7983.6299 | E365: =D365-G365 -> 7937.3289 | F365: =(E365/C365)*12 -> 12 | G365: =C365*($B$1/12) -> 46.301085 | H365: =(G365/C365)*12 -> 0.07 | I365: =I364+E365 -> 1200000 | J365: =J364+G365 -> 1674106.8 | K365: =C365-E365 -> 8.9748937e-09 | L365: =I365+J365 -> 2874106.8

Sheet McRae Road Condos
A1: McCrae Road Condos
A2: 15000 | B2: sqft
A3: 1750000 | B3: asking price | C3: =A3/A2 -> 116.66667
A5: Purchase Price | B5: 1500000 | C5: =B5/A2 -> 100 | G5: Loan Interest Rate | H5: 0.07 | K5: Hard Money Lender Points Paid | L5: 4 | M5: =B5*(L5/100) -> 60000
A6: Closing Costs (3%) | B6: =B5*0.03 -> 45000 | G6: Monthly Interest Payment on Purchase Price | H6: =((B5-B7)*H5)/12 -> 7000 | K6: Term (months) | L6: 24
A7: Down Payment (20%) | B7: =B5*0.2 -> 300000 | K7: Hard Money Interest rate | L7: 0.12
A8: Total Loan Amount | B8: =B5-B7 -> 1200000 | G8: Total Monthly(Interest+Principle+Prop Tax+Insurance) | H8: =C56 -> 14828.174 | K8: Monthly Loan Payment to Hard Money Lender | L8: =(B5*L7)/12 -> 15000
G9: Total Monthly Utilities | H9: =SUM(C49:C51) -> 0
G10: Total Monthly Payment | H10: =H9+H8 -> 14828.174
A11: All In Price (Purchase+Repairs) | B11: =SUM(B5,E41) -> 1503836.1 | G11: Total Montly, including Renovations/Reserves | H11: =H10+E41 -> 18664.286
A12: Estimated ARV (After Repair Value) | B12: 1600000 | C12: =B12/A2 -> 106.66667
A14: Average Rent (8 units) | B14: 2180 | C14: 2023#s | K14: One Time Costs at Closing (Closing+Down+HML) | L14: =SUM(M5+B6+B7) -> 405000
B15: =B14*8 -> 17440 | C15: monthly rent | G15: Financials | K15: Repairs | L15: =E41 -> 3836.1111
A16: Calculated Gross Revenue | B16: =B15*$C$43 -> 209280 | C16: yearly rent | G16: Monthly Cash Flow | H16: =B15-H10 -> 2611.8256
G17: Cash On Cash Return (CoC) | H17: =(H16*C43)/(B7) -> 0.10447302
A18: Actual Gross Revenue | B18: 166785 | G18: Cap Rate | H18: =(B15-C54-C47-C46-C45-C52-C53)*C43/(B5) -> 0.084963644
A19: Repairs/Management Fees | B19: =SUM(B45,B52:B53) -> 39370.534 | C19: 45353 | G19: ROI (Return on Investment) | H19: =((B20+(B24-B5))/B22)/B25*12 -> 0.08241379
A20: Net Income | B20: =B18-B19 -> 127414.47 | C20: =B20/12 -> 10617.872 | D20: per month | G20: ROE (Return on Equity) | H20: =((H16*12)/(B7+H22)) -> 0.10039378 | I20: Down Payment + Mortgage Pay Down
A21: Capital Contributions | B21: =E41*12 -> 46033.333 | G21: Yearly Cash Flow / Profit ($) | H21: =H16*C43 -> 31341.907
A22: Total Investment (Purchase + Capital) | B22: =B5+B21 -> 1546033.3 | G22: Mortgage Pay Down yr 1 (Based on Amortization Schedule) | H22: =SUM('McRae Road Amorization'!E6:E17) -> 12189.718
A24: Current Property Value | B24: 1500000 | G24: Rules of Thumb
A25: Months Owned | B25: 12 | G25: 50% Rule | H25: =(B15/2)-C44 -> 736.37006
G26: 2% Rule | H26: =B15/B5 -> 0.011626667
A29: Estimated CapEx | B29: Timeline of Repair (yrs) | C29: Cost per Unit (2000sqft each) | D29: Total Cost (all 8 units) | E29: Monthly Cost
A30: Roof | B30: 20 | C30: 7000 | D30: =C30*8 -> 56000 | E30: =D30/B30/12 -> 233.33333
A31: Master Bath | B31: 10 | C31: 10000 | D31: =C31*8 -> 80000 | E31: =D31/B31/12 -> 666.66667
A32: Kitchen | B32: 10 | C32: 5000 | D32: =C32*8 -> 40000 | E32: =D32/B32/12 -> 333.33333
A33: Flooring | B33: 10 | C33: 8000 | D33: =C33*8 -> 64000 | E33: =D33/B33/12 -> 533.33333
A34: Guest baths | B34: 10 | C34: 3000 | D34: =C34*8 -> 24000 | E34: =D34/B34/12 -> 200
A35: Exterior Paint | B35: 6 | C35: 5000 | D35: =C35*8 -> 40000 | E35: =D35/B35/12 -> 555.55556
A36: Interior Paint | B36: 6 | C36: 5000 | D36: =C36*8 -> 40000 | E36: =D36/B36/12 -> 555.55556
A37: Cabinets | B37: 10 | C37: 5000 | D37: =C37*8 -> 40000 | E37: =D37/B37/12 -> 333.33333
A38: Siding Repairs | B38: 10 | C38: 4000 | D38: =C38*8 -> 32000 | E38: =D38/B38/12 -> 266.66667
A39: Driveway Re-Pave | B39: 10 | C39: 15000 | D39: =C39 -> 15000 | E39: =D39/B39/12 -> 125
A40: Miscellaneous (light fixtures/door knobs etc) | B40: 10 | C40: 500 | D40: =C40*8 -> 4000 | E40: =D40/B40/12 -> 33.333333
A41: Total Estimated Repairs | E41: =SUM(E30:E40) -> 3836.1111
A43: Estimated Expenses | C43: 12 | D43: months
A44: Mortgage Payment | B44: =C44*$C$43 -> 95803.559 | C44: ='McRae Road Amorization'!D6 -> 7983.6299
A45: Management Fees | B45: =C45*C43 -> 14370.534 | C45: =C44*D45 -> 1197.5445 | D45: 0.15
A46: Property Taxes / Year (1.8%) | B46: =B5*D46 -> 27000 | C46: =B46/$C$43 -> 2250 | D46: 0.018
...

Sheet Hard Money Lender Calculator
A1: 2921 Admiralty Bay | B1: Location Location Location
A2: 2418 | B2: sqft
A3: 479000 | B3: asking price | C3: =A3/A2 -> 198.0976
A5: Purchase Price | B5: 400000 | C5: =B5/A2 -> 165.42597 | F5: Loan Interest Rate | G5: 0.07 | J5: Hard Money Lender Points Paid | K5: 4 | L5: =B5*(K5/100) -> 16000
A6: Closing Costs (3%) | B6: =B5*0.03 -> 12000 | F6: Monthly Interest Payment on Purchase Price | G6: =(B5*G5)/12 -> 2333.3333 | J6: Term (months) | K6: 24
A7: Down Payment (20%) | B7: =B5*0.2 -> 80000 | J7: Hard Money Interest rate | K7: 0.12
F8: Total Monthly(Interest+Principle+Prop Tax+Insurance) | G8: =G6+C29+C30+C31+C32 -> 3891.6667 | J8: Monthly Loan Payment to Hard Money Lender | K8: =(B5*K7)/12 -> 4000
A9: All In Price (Purchase+Repairs) | B9: =SUM(B5,B27) -> 536000 | F9: Total Monthly Utilities | G9: =SUM(C33:C35) -> 513
A10: Estimated ARV (After Repair Value) | B10: 550000 | C10: =B10/A2 -> 227.46071 | F10: Total Monthly Payment | G10: =G9+G8 -> 4404.6667
A11: 80% ARV (Refinance) | B11: =B10*0.8 -> 440000
A13: Estimated Profit | B13: =B10-B9 -> 14000
J14: One Time Costs at Closing (Closing+Down+HML) | K14: =SUM(L5+B6+B7) -> 108000
A15: Estimated Repairs | J15: Repairs | K15: =B27 -> 136000
A16: Master Bath | B16: 25000
A17: Kitchen | B17: 25000
A18: Flooring | B18: 20000
A19: Guest baths (3) | B19: 20000 | F19: Financials
A20: Exterior Paint | B20: 15000 | F20: Cash On Cash Return (CoC)
A21: Interior Paint | B21: 10000 | F21: ROI (Return on Investment)
A22: Cabinets | B22: 5000 | F22: ROE (Return on Equity)
A23: Siding Repairs | B23: 7000 | F23: Profit ($)
A24: Driveway Re-Pave | B24: 4000
A25: Miscellaneous (light fixtures/door knobs etc) | B25: 5000
A26: Permits
A27: Total Estimated Repairs | B27: =SUM(B16:B25) -> 136000
C28: 12
A29: Property Taxes / Year (1.8%) | B29: =B5*0.018 -> 7200 | C29: =B29/$C$28 -> 600 | E29: Mill Rate | F29: 16.4 | G29: =(B5/1000)*F29 -> 6560
A30: Insurance / Year | B30: 2400 | C30: =B30/$C$28 -> 200 | G30: =G29/B5 -> 0.0164 | H30: yearly
A31: Principle / Year (Based on Amortization Schedule) | B31: 8800 | C31: =B31/$C$28 -> 733.33333
A32: HOA / year | B32: 300 | C32: =B32/$C$28 -> 25
A33: Electricity | C33: 200
A34: Nat Gas | C34: 200
A35: Water | C35: 113

Sheet HELOC Calculator
A1: 2950 Admiralty Bay Drive | B1: 2646 | C1: sqft | G1: HELOC Interest | H1: 0.08 | K1: =H1/12 -> 0.0066666667 | L1: r
B2: 246 | C2: $/sqft Market Estimate | G2: Term | H2: =$I$2*12 -> 360 | I2: 30 | J2: years | K2: =(1+K1)^H2 -> 10.93573 | L2: (1+r)^n
A3: Original Purchase Price | B3: 500500 | C3: =B3/B1 -> 189.15344 | D3: sqft | G3: Monthly Payment
A4: Current Market Price | B4: =B1*B2 -> 650916
A5: Current Loan Balance | B5: 355000 | C5: as of 11/13/22 | G5: paymentNumber | H5: paymentDate | I5: startingBalance | J5: Monthly Payment | K5: principalPayment | L5: Principle Pay Down | M5: interestPayment | N5: Interest Percent | O5: cumulativePrincipal | P5: cumulativeInterest | Q5: endingBalance | R5: Total Paid End of Loan
A6: Current Equity | B6: =B4-B5 -> 295916 | G6: 1 | H6: 44866 | I6: ='HELOC Calculator'!B9 -> 165732.8 | J6: =$I$6/((($K$2)-1)/($K$1*$K$2)) -> 1216.0886 | K6: =J6-M6 -> 111.20324 | L6: =(K6/I6)*12 -> 0.0080517489 | M6: =I6*($H$1/12) -> 1104.8853 | N6: =(M6/I6)*12 -> 0.08 | O6: =K6 -> 111.20324 | P6: =M6 -> 1104.8853 | Q6: =I6-K6 -> 165621.6 | R6: =O6+P6 -> 1216.0886
G7: 2 | H7: 44896 | I7: =Q6 -> 165621.6 | J7: =$I$6/((($K$2)-1)/($K$1*$K$2)) -> 1216.0886 | K7: =J7-M7 -> 111.9446 | L7: =(K7/I7)*12 -> 0.0081108694 | M7: =I7*($H$1/12) -> 1104.144 | N7: =(M7/I7)*12 -> 0.08 | O7: =O6+K7 -> 223.14784 | P7: =P6+M7 -> 2209.0293 | Q7: =I7-K7 -> 165509.65 | R7: =O7+P7 -> 2432.1771
A8: 80% Market Price | B8: =B4*0.8 -> 520732.8 | G8: 3 | H8: 44927 | I8: =Q7 -> 165509.65 | J8: =$I$6/((($K$2)-1)/($K$1*$K$2)) -> 1216.0886 | K8: =J8-M8 -> 112.69089 | L8: =(K8/I8)*12 -> 0.0081704643 | M8: =I8*($H$1/12) -> 1103.3977 | N8: =(M8/I8)*12 -> 0.08 | O8: =O7+K8 -> 335.83873 | P8: =P7+M8 -> 3312.427 | Q8: =I8-K8 -> 165396.96 | R8: =O8+P8 -> 3648.2657
A9: Total Cash Available HELOC (Current Market Price - Current Loan Balance) | B9: =B8-B5 -> 165732.8 | G9: 4 | H9: 44958 | I9: =Q8 -> 165396.96 | J9: =$I$6/((($K$2)-1)/($K$1*$K$2)) -> 1216.0886 | K9: =J9-M9 -> 113.44217 | L9: =(K9/I9)*12 -> 0.008230538 | M9: =I9*($H$1/12) -> 1102.6464 | N9: =(M9/I9)*12 -> 0.08 | O9: =O8+K9 -> 449.28089 | P9: =P8+M9 -> 4415.0734 | Q9: =I9-K9 -> 165283.52 | R9: =O9+P9 -> 4864.3543
G10: 5 | H10: 44986 | I10: =Q9 -> 165283.52 | J10: =$I$6/((($K$2)-1)/($K$1*$K$2)) -> 1216.0886 | K10: =J10-M10 -> 114.19845 | L10: =(K10/I10)*12 -> 0.008291095 | M10: =I10*($H$1/12) -> 1101.8901 | N10: =(M10/I10)*12 -> 0.08 | O10: =O9+K10 -> 563.47934 | P10: =P9+M10 -> 5516.9635 | Q10: =I10-K10 -> 165169.32 | R10: =O10+P10 -> 6080.4429
G11: 6 | H11: 45017 | I11: =Q10 -> 165169.32 | J11: =$I$6/((($K$2)-1)/($K$1*$K$2)) -> 1216.0886 | K11: =J11-M11 -> 114.95977 | L11: =(K11/I11)*12 -> 0.0083521396 | M11: =I11*($H$1/12) -> 1101.1288 | N11: =(M11/I11)*12 -> 0.08 | O11: =O10+K11 -> 678.43911 | P11: =P10+M11 -> 6618.0923 | Q11: =I11-K11 -> 165054.36 | R11: =O11+P11 -> 7296.5314
G12: 7 | H12: 45047 | I12: =Q11 -> 165054.36 | J12: =$I$6/((($K$2)-1)/($K$1*$K$2)) -> 1216.0886 | K12: =J12-M12 -> 115.72617 | L12: =(K12/I12)*12 -> 0.0084136766 | M12: =I12*($H$1/12) -> 1100.3624 | N12: =(M12/I12)*12 -> 0.08 | O12: =O11+K12 -> 794.16528 | P12: =P11+M12 -> 7718.4547 | Q12: =I12-K12 -> 164938.63 | R12: =O12+P12 -> 8512.62
A13: Purchase Price | B13: 135000 | D13: r | E13: =B16/12 -> 0.0072916667 | G13: 8 | H13: 45078 | I13: =Q12 -> 164938.63 | J13: =$I$6/((($K$2)-1)/($K$1*$K$2)) -> 1216.0886 | K13: =J13-M13 -> 116.49768 | L13: =(K13/I13)*12 -> 0.0084757104 | M13: =I13*($H$1/12) -> 1099.5909 | N13: =(M13/I13)*12 -> 0.08 | O13: =O12+K13 -> 910.66295 | P13: =P12+M13 -> 8818.0456 | Q13: =I13-K13 -> 164822.14 | R13: =O13+P13 -> 9728.7086
A14: Down Payment | B14: =B13*C14 -> 33750 | C14: 0.25 | D14: (1+r)^n | E14: =(1+E13)^H2 -> 13.673723 | G14: 9 | H14: 45108 | I14: =Q13 -> 164822.14 | J14: =$I$6/((($K$2)-1)/($K$1*$K$2)) -> 1216.0886 | K14: =J14-M14 -> 117.27433 | L14: =(K14/I14)*12 -> 0.0085382458 | M14: =I14*($H$1/12) -> 1098.8142 | N14: =(M14/I14)*12 -> 0.08 | O14: =O13+K14 -> 1027.9373 | P14: =P13+M14 -> 9916.8599 | Q14: =I14-K14 -> 164704.86 | R14: =O14+P14 -> 10944.797
A15: Heloc Amount | B15: =B13-B14 -> 101250 | G15: 10 | H15: 45139 | I15: =Q14 -> 164704.86 | J15: =$I$6/((($K$2)-1)/($K$1*$K$2)) -> 1216.0886 | K15: =J15-M15 -> 118.05616 | L15: =(K15/I15)*12 -> 0.0086012874 | M15: =I15*($H$1/12) -> 1098.0324 | N15: =(M15/I15)*12 -> 0.08 | O15: =O14+K15 -> 1145.9934 | P15: =P14+M15 -> 11014.892 | Q15: =I15-K15 -> 164586.81 | R15: =O15+P15 -> 12160.886
A16: Interest Rate | B16: 0.0875 | G16: 11 | H16: 45170 | I16: =Q15 -> 164586.81 | J16: =$I$6/((($K$2)-1)/($K$1*$K$2)) -> 1216.0886 | K16: =J16-M16 -> 118.8432 | L16: =(K16/I16)*12 -> 0.0086648401 | M16: =I16*($H$1/12) -> 1097.2454 | N16: =(M16/I16)*12 -> 0.08 | O16: =O15+K16 -> 1264.8366 | P16: =P15+M16 -> 12112.138 | Q16: =I16-K16 -> 164467.96 | R16: =O16+P16 -> 13376.974
A17: Payment | B17: =$B$15/((($E$14)-1)/($E$13*$E$14)) -> 796.53416 | G17: 12 | H17: 45200 | I17: =Q16 -> 164467.96 | J17: =$I$6/((($K$2)-1)/($K$1*$K$2)) -> 1216.0886 | K17: =J17-M17 -> 119.63548 | L17: =(K17/I17)*12 -> 0.0087289086 | M17: =I17*($H$1/12) -> 1096.4531 | N17: =(M17/I17)*12 -> 0.08 | O17: =O16+K17 -> 1384.4721 | P17: =P16+M17 -> 13208.591 | Q17: =I17-K17 -> 164348.33 | R17: =O17+P17 -> 14593.063
A18: Monthly Rent | B18: 1400 | G18: 13 | H18: 45231 | I18: =Q17 -> 164348.33 | J18: =$I$6/((($K$2)-1)/($K$1*$K$2)) -> 1216.0886 | K18: =J18-M18 -> 120.43305 | L18: =(K18/I18)*12 -> 0.0087934978 | M18: =I18*($H$1/12) -> 1095.6555 | N18: =(M18/I18)*12 -> 0.08 | O18: =O17+K18 -> 1504.9052 | P18: =P17+M18 -> 14304.246 | Q18: =I18-K18 -> 164227.89 | R18: =O18+P18 -> 15809.151
A19: Monthly Expenses | B19: 509 | C19: Rent - Expenses - Payment | G19: 14 | H19: 45261 | I19: =Q18 -> 164227.89 | J19: =$I$6/((($K$2)-1)/($K$1*$K$2)) -> 1216.0886 | K19: =J19-M19 -> 121.23594 | L19: =(K19/I19)*12 -> 0.0088586126 | M19: =I19*($H$1/12) -> 1094.8526 | N19: =(M19/I19)*12 -> 0.08 | O19: =O18+K19 -> 1626.1411 | P19: =P18+M19 -> 15399.099 | Q19: =I19-K19 -> 164106.66 | R19: =O19+P19 -> 17025.24
A20: Monthly Cash Flow (financed) | B20: =B18-B19-B17 -> 94.465839 | G20: 15 | H20: 45292 | I20: =Q19 -> 164106.66 | J20: =$I$6/((($K$2)-1)/($K$1*$K$2)) -> 1216.0886 | K20: =J20-M20 -> 122.04418 | L20: =(K20/I20)*12 -> 0.0089242581 | M20: =I20*($H$1/12) -> 1094.0444 | N20: =(M20/I20)*12 -> 0.08 | O20: =O19+K20 -> 1748.1853 | P20: =P19+M20 -> 16493.143 | Q20: =I20-K20 -> 163984.61 | R20: =O20+P20 -> 18241.329
A21: DSCR | B21: =B18/SUM(B19,B17) -> 1.072358 | G21: 16 | H21: 45323 | I21: =Q20 -> 163984.61 | J21: =$I$6/((($K$2)-1)/($K$1*$K$2)) -> 1216.0886 | K21: =J21-M21 -> 122.85781 | L21: =(K21/I21)*12 -> 0.0089904392 | M21: =I21*($H$1/12) -> 1093.2308 | N21: =(M21/I21)*12 -> 0.08 | O21: =O20+K21 -> 1871.0431 | P21: =P20+M21 -> 17586.374 | Q21: =I21-K21 -> 163861.76 | R21: =O21+P21 -> 19457.417
G22: 17 | H22: 45352 | I22: =Q21 -> 163861.76 | J22: =$I$6/((($K$2)-1)/($K$1*$K$2)) -> 1216.0886 | K22: =J22-M22 -> 123.67686 | L22: =(K22/I22)*12 -> 0.0090571611 | M22: =I22*($H$1/12) -> 1092.4117 | N22: =(M22/I22)*12 -> 0.08 | O22: =O21+K22 -> 1994.72 | P22: =P21+M22 -> 18678.786 | Q22: =I22-K22 -> 163738.08 | R22: =O22+P22 -> 20673.506
G23: 18 | H23: 45383 | I23: =Q22 -> 163738.08 | J23: =$I$6/((($K$2)-1)/($K$1*$K$2)) -> 1216.0886 | K23: =J23-M23 -> 124.50137 | L23: =(K23/I23)*12 -> 0.009124429 | M23: =I23*($H$1/12) -> 1091.5872 | N23: =(M23/I23)*12 -> 0.08 | O23: =O22+K23 -> 2119.2213 | P23: =P22+M23 -> 19770.373 | Q23: =I23-K23 -> 163613.58 | R23: =O23+P23 -> 21889.594
A24: Monthly Payment HELOC | B24: =$B$13/((($E$14)-1)/($E$13*$E$14))+B19 -> 1571.0455 | G24: 19 | H24: 45413 | I24: =Q23 -> 163613.58 | J24: =$I$6/((($K$2)-1)/($K$1*$K$2)) -> 1216.0886 | K24: =J24-M24 -> 125.33138 | L24: =(K24/I24)*12 -> 0.009192248 | M24: =I24*($H$1/12) -> 1090.7572 | N24: =(M24/I24)*12 -> 0.08 | O24: =O23+K24 -> 2244.5527 | P24: =P23+M24 -> 20861.13 | Q24: =I24-K24 -> 163488.25 | R24: =O24+P24 -> 23105.683
A25: Monthly Cash Flow (paid off) | B25: =B18-B24 -> -171.04555 | G25: 20 | H25: 45444 | I25: =Q24 -> 163488.25 | J25: =$I$6/((($K$2)-1)/($K$1*$K$2)) -> 1216.0886 | K25: =J25-M25 -> 126.16693 | L25: =(K25/I25)*12 -> 0.0092606235 | M25: =I25*($H$1/12) -> 1089.9216 | N25: =(M25/I25)*12 -> 0.08 | O25: =O24+K25 -> 2370.7196 | P25: =P24+M25 -> 21951.052 | Q25: =I25-K25 -> 163362.08 | R25: =O25+P25 -> 24321.771
G26: 21 | H26: 45474 | I26: =Q25 -> 163362.08 | J26: =$I$6/((($K$2)-1)/($K$1*$K$2)) -> 1216.0886 | K26: =J26-M26 -> 127.00804 | L26: =(K26/I26)*12 -> 0.0093295608 | M26: =I26*($H$1/12) -> 1089.0805 | N26: =(M26/I26)*12 -> 0.08 | O26: =O25+K26 -> 2497.7277 | P26: =P25+M26 -> 23040.132 | Q26: =I26-K26 -> 163235.07 | R26: =O26+P26 -> 25537.86
G27: 22 | H27: 45505 | I27: =Q26 -> 163235.07 | J27: =$I$6/((($K$2)-1)/($K$1*$K$2)) -> 1216.0886 | K27: =J27-M27 -> 127.85476 | L27: =(K27/I27)*12 -> 0.0093990653 | M27: =I27*($H$1/12) -> 1088.2338 | N27: =(M27/I27)*12 -> 0.08 | O27: =O26+K27 -> 2625.5824 | P27: =P26+M27 -> 24128.366 | Q27: =I27-K27 -> 163107.22 | R27: =O27+P27 -> 26753.949
G28: 23 | H28: 45536 | I28: =Q27 -> 163107.22 | J28: =$I$6/((($K$2)-1)/($K$1*$K$2)) -> 1216.0886 | K28: =J28-M28 -> 128.70712 | L28: =(K28/I28)*12 -> 0.0094691425 | M28: =I28*($H$1/12) -> 1087.3815 | N28: =(M28/I28)*12 -> 0.08 | O28: =O27+K28 -> 2754.2896 | P28: =P27+M28 -> 25215.748 | Q28: =I28-K28 -> 162978.51 | R28: =O28+P28 -> 27970.037
G29: 24 | H29: 45566 | I29: =Q28 -> 162978.51 | J29: =$I$6/((($K$2)-1)/($K$1*$K$2)) -> 1216.0886 | K29: =J29-M29 -> 129.56517 | L29: =(K29/I29)*12 -> 0.0095397979 | M29: =I29*($H$1/12) -> 1086.5234 | N29: =(M29/I29)*12 -> 0.08 | O29: =O28+K29 -> 2883.8547 | P29: =P28+M29 -> 26302.271 | Q29: =I29-K29 -> 162848.95 | R29: =O29+P29 -> 29186.126
G30: 25 | H30: 45597 | I30: =Q29 -> 162848.95 | J30: =$I$6/((($K$2)-1)/($K$1*$K$2)) -> 1216.0886 | K30: =J30-M30 -> 130.42894 | L30: =(K30/I30)*12 -> 0.0096110372 | M30: =I30*($H$1/12) -> 1085.6596 | N30: =(M30/I30)*12 -> 0.08 | O30: =O29+K30 -> 3014.2837 | P30: =P29+M30 -> 27387.931 | Q30: =I30-K30 -> 162718.52 | R30: =O30+P30 -> 30402.214
G31: 26 | H31: 45627 | I31: =Q30 -> 162718.52 | J31: =$I$6/((($K$2)-1)/($K$1*$K$2)) -> 1216.0886 | K31: =J31-M31 -> 131.29846 | L31: =(K31/I31)*12 -> 0.0096828659 | M31: =I31*($H$1/12) -> 1084.7901 | N31: =(M31/I31)*12 -> 0.08 | O31: =O30+K31 -> 3145.5821 | P31: =P30+M31 -> 28472.721 | Q31: =I31-K31 -> 162587.22 | R31: =O31+P31 -> 31618.303
G32: 27 | H32: 45658 | I32: =Q31 -> 162587.22 | J32: =$I$6/((($K$2)-1)/($K$1*$K$2)) -> 1216.0886 | K32: =J32-M32 -> 132.17379 | L32: =(K32/I32)*12 -> 0.00975529 | M32: =I32*($H$1/12) -> 1083.9148 | N32: =(M32/I32)*12 -> 0.08 | O32: =O31+K32 -> 3277.7559 | P32: =P31+M32 -> 29556.636 | Q32: =I32-K32 -> 162455.04 | R32: =O32+P32 -> 32834.391
G33: 28 | H33: 45689 | I33: =Q32 -> 162455.04 | J33: =$I$6/((($K$2)-1)/($K$1*$K$2)) -> 1216.0886 | K33: =J33-M33 -> 133.05495 | L33: =(K33/I33)*12 -> 0.0098283151 | M33: =I33*($H$1/12) -> 1083.0336 | N33: =(M33/I33)*12 -> 0.08 | O33: =O32+K33 -> 3410.8109 | P33: =P32+M33 -> 30639.669 | Q33: =I33-K33 -> 162321.99 | R33: =O33+P33 -> 34050.48
G34: 29 | H34: 45717 | I34: =Q33 -> 162321.99 | J34: =$I$6/((($K$2)-1)/($K$1*$K$2)) -> 1216.0886 | K34: =J34-M34 -> 133.94198 | L34: =(K34/I34)*12 -> 0.0099019471 | M34: =I34*($H$1/12) -> 1082.1466 | N34: =(M34/I34)*12 -> 0.08 | O34: =O33+K34 -> 3544.7529 | P34: =P33+M34 -> 31721.816 | Q34: =I34-K34 -> 162188.05 | R34: =O34+P34 -> 35266.569
G35: 30 | H35: 45748 | I35: =Q34 -> 162188.05 | J35: =$I$6/((($K$2)-1)/($K$1*$K$2)) -> 1216.0886 | K35: =J35-M35 -> 134.83493 | L35: =(K35/I35)*12 -> 0.0099761921 | M35: =I35*($H$1/12) -> 1081.2536 | N35: =(M35/I35)*12 -> 0.08 | O35: =O34+K35 -> 3679.5878 | P35: =P34+M35 -> 32803.069 | Q35: =I35-K35 -> 162053.21 | R35: =O35+P35 -> 36482.657
G36: 31 | H36: 45778 | I36: =Q35 -> 162053.21 | J36: =$I$6/((($K$2)-1)/($K$1*$K$2)) -> 1216.0886 | K36: =J36-M36 -> 135.73383 | L36: =(K36/I36)*12 -> 0.010051056 | M36: =I36*($H$1/12) -> 1080.3547 | N36: =(M36/I36)*12 -> 0.08 | O36: =O35+K36 -> 3815.3216 | P36: =P35+M36 -> 33883.424 | Q36: =I36-K36 -> 161917.48 | R36: =O36+P36 -> 37698.746
G37: 32 | H37: 45809 | I37: =Q36 -> 161917.48 | J37: =$I$6/((($K$2)-1)/($K$1*$K$2)) -> 1216.0886 | K37: =J37-M37 -> 136.63872 | L37: =(K37/I37)*12 -> 0.010126545 | M37: =I37*($H$1/12) -> 1079.4499 | N37: =(M37/I37)*12 -> 0.08 | O37: =O36+K37 -> 3951.9603 | P37: =P36+M37 -> 34962.874 | Q37: =I37-K37 -> 161780.84 | R37: =O37+P37 -> 38914.834
... G340: 335 | H340: 55032 | I340: =Q339 -> 28941.491 | J340: =$I$6/((($K$2)-1)/($K$1*$K$2)) -> 1216.0886 | K340: =J340-M340 -> 1023.1453 | L340: =(K340/I340)*12 -> 0.42422637 | M340: =I340*($H$1/12) -> 192.94327 | N340: =(M340/I340)*12 -> 0.08 | O340: =O339+K340 -> 137814.45 | P340: =P339+M340 -> 269575.22 | Q340: =I340-K340 -> 27918.346 | R340: =O340+P340 -> 407389.67
G341: =G340+1 -> 336 | I341: =Q340 -> 27918.346 | J341: =$I$6/((($K$2)-1)/($K$1*$K$2)) -> 1216.0886 | K341: =J341-M341 -> 1029.9663 | L341: =(K341/I341)*12 -> 0.44270514 | M341: =I341*($H$1/12) -> 186.1223 | N341: =(M341/I341)*12 -> 0.08 | O341: =O340+K341 -> 138844.42 | P341: =P340+M341 -> 269761.34 | Q341: =I341-K341 -> 26888.379 | R341: =O341+P341 -> 408605.76
G342: =G341+1 -> 337 | I342: =Q341 -> 26888.379 | J342: =$I$6/((($K$2)-1)/($K$1*$K$2)) -> 1216.0886 | K342: =J342-M342 -> 1036.8327 | L342: =(K342/I342)*12 -> 0.4627275 | M342: =I342*($H$1/12) -> 179.25586 | N342: =(M342/I342)*12 -> 0.08 | O342: =O341+K342 -> 139881.25 | P342: =P341+M342 -> 269940.6 | Q342: =I342-K342 -> 25851.547 | R342: =O342+P342 -> 409821.85
...

Sheet Lenders
B1: Northern Skies | C1: Credit Union 1 | D1: Credit Union 1 HELOAN | E1: KeyBank | F1: KeyBank - HELOAN
A2: LTV (%) | B2: 0.8 | C2: 80-85 | D2: 80-85 | E2: 80 | F2: 80
A3: Current Rate | B3: 8 | C3: 8.75 | D3: 7.75 | E3: 13 | F3: 13.5
A4: Fixed/Variable | B4: Variable | C4: Variable | D4: Fixed | E4: Variable | F4: Fixed
A5: When it adjusts | B5: With prime/Quarterly - payment stays same, amount towards principle changes | C5: With prime | E5: With prime
A6: Terms | B6: 20 yrs / 5yr draw | C6: 20 yr / 10yr draw | D6: 20yr | E6: 15yr / 15yr draw | F6: 30
A7: Appraisal | B7: $1000+Title Search ($700) | C7: AVM - $150 Broker Opinion - $500 Used for <$250k | E7: Included | F7: Included
A8: DTI | C8: <43%
A9: Prepayment Penalties | B9: No | C9: No | D9: No | E9: Pre-Closing fee if within 36 months (appraisal that was waived) | F9: No
E10: Option for interest only payments
