Workbook
Name If: #REF!
Name If: #REF!

Sheet Calculators
A3: Year | C3: Annual ROI | G3: Year | I3: Annual ROI | S3: IRR | T3: =XIRR(T4:T10,R4:R10) -> 0.21632629
A4: 0 | B4: 100000 | G4: 0 | H4: 100000 | M4: Present Value=Future Value /( 1+i)^n | R4: 45292 | S4: Initial Investment | T4: -8500000
A5: =A4+1 -> 1 | B5: 110000 | C5: =(B5/B4)-1 -> 0.1 | G5: =G4+1 -> 1 | H5: 110000 | I5: =(H5/H4)-1 -> 0.1 | M5: interest | N5: 0.08 | R5: =R4+365 -> 45657 | S5: Year 1 Cashflow | T5: =-$T$4*$U$5 -> 1360000 | U5: 0.16 | V5: Cash On Cash
A6: =A5+1 -> 2 | B6: 105000 | C6: =(B6/B5)-1 -> -0.045454545 | G6: =G5+1 -> 2 | H6: 105000 | I6: =(H6/H5)-1 -> -0.045454545 | M6: time (yrs) | N6: 5 | O6: =N6*12 -> 60 | R6: =R5+365 -> 46022 | S6: Year 2 Cashflow | T6: =-$T$4*$U$5 -> 1360000
A7: =A6+1 -> 3 | B7: 120000 | C7: =(B7/B6)-1 -> 0.14285714 | G7: =G6+1 -> 3 | H7: 120000 | I7: =(H7/H6)-1 -> 0.14285714 | R7: =R6+365 -> 46387 | S7: Year 3 Cashflow | T7: =-$T$4*$U$5 -> 1360000
A8: =A7+1 -> 4 | B8: =B7+5000 -> 125000 | C8: =(B8/B7)-1 -> 0.041666667 | G8: =G7+1 -> 4 | H8: =H7+5000 -> 125000 | I8: =(H8/H7)-1 -> 0.041666667 | R8: =R7+365 -> 46752 | S8: Year 4 Cashflow | T8: =-$T$4*$U$5 -> 1360000
A9: =A8+1 -> 5 | B9: =B8+5000 -> 130000 | C9: =(B9/B8)-1 -> 0.04 | G9: =G8+1 -> 5 | H9: =H8+5000 -> 130000 | I9: =(H9/H8)-1 -> 0.04 | R9: =R8+365 -> 47117 | S9: Year 5 Cashflow | T9: =-$T$4*$U$5 -> 1360000
A10: =A9+1 -> 6 | B10: =B9+5000 -> 135000 | C10: =(B10/B9)-1 -> 0.038461538 | R10: =R9+365 -> 47482 | S10: 6 | T10: =-T4*(1+U10)^S10 -> 14813534 | U10: 0.097 | V10: Assumed Appreciation
A11: =A10+1 -> 7 | B11: =B10+5000 -> 140000 | C11: =(B11/B10)-1 -> 0.037037037 | I11: =(H9-H4)/H4 -> 0.3 | J11: ROI
A12: =A11+1 -> 8 | B12: =B11+5000 -> 145000 | C12: =(B12/B11)-1 -> 0.035714286 | I12: =SUM(I5:I9)/COUNT(I5:I9) -> 0.055813853 | J12: AAR
A13: =A12+1 -> 9 | B13: =B12+5000 -> 150000 | C13: =(B13/B12)-1 -> 0.034482759 | I13: =(H9/H4)^(1/COUNT(I4:I9))-1 -> 0.053873952 | J13: CAGR | M13: 0.105 | N13: projected Cash On Cash Return
A14: =A13+1 -> 10 | B14: =B13+5000 -> 155000 | C14: =(B14/B13)-1 -> 0.033333333 | I14: =H9/H4 -> 1.3 | J14: Equity Multiplier | M14: 8500000 | N14: initial investment
M15: =O15*12 -> 60 | N15: hold period | O15: 5
C16: =(B14-B4)/B4 -> 0.55 | D16: ROI
C17: =SUM(C5:C14)/COUNT(C5:C14) -> 0.045809822 | D17: AAR | M17: Future | N17: =M14*(1+M13/12)^(M15) -> 14336125 | O17: =N17/M14 -> 1.686603 | P17: Equity Multiple
C18: =(B14/B4)^(1/COUNT(C4:C14))-1 -> 0.044800014 | D18: CAGR | M18: CAGR | N18: =(N17/M14)^(1/(O15*4))-1 -> 0.026480357
C19: =B14/B4 -> 1.55 | D19: Equity Multiplier

Sheet STR Calculator
A1: 2974 Ginas Way, Sevierville, TN 37862 | MLS #303878 | Zillow | B1: https://www.youtube.com/watch?v=htWCJ51RIyg | H1: Heloc Down Payment | I1: 0.0825
A2: 2974 Ginas Way - 3bd / 4bath - 1927 sqft | B2: 1927 | C2: sqft | D2: =A3/B2 -> 415.15309 | E2: per sqft | H2: Heloc Loan Terms | I2: 20 | J2: yrs
A3: =B5 -> 800000 | B3: asking price | H3: HELOC Amount | I3: =SUM(B7+B6-C5-C4) -> 105000
C4: 5000 | D4: earnest money | H4: HELOC P&I Payment | I4: =-PMT($I$1/12,$I$2*12,I3) -> 894.66893 | J4: =I4*12 -> 10736.027 | L4: IRR | M4: =IRR(M5:M11) -> 0.031714733
A5: Purchase Price | B5: 800000 | C5: 50000 | D5: cash | H5: HELOC Principle Payment | I5: =-PPMT($I$1/12,1,$I$2*12,I3) -> 172.79393 | J5: =I5*12 -> 2073.5272 | L5: Initial Investment | M5: =-B5 -> -800000
A6: Closing Costs (4%) | B6: 0 | C6: $B$5*0.04 | H6: HELOC Interest Only Payment | I6: =-IPMT($I$1/12,1,$I$2*12,I3) -> 721.875 | J6: =I6*12 -> 8662.5 | L6: Year 1 Cashflow | M6: ='STR 10 Year'!B39 -> 9539.7062
A7: Down Payment | B7: =B5*C7 -> 160000 | C7: 0.2 | D7: downpayment | L7: Year 2 Cashflow | M7: ='STR 10 Year'!C39 -> 10787.706
A8: Total Loan Amount | B8: =B5-B7 -> 640000 | H8: Conventional Loan Interest Rate | I8: =IF(C7=0.1,0.08062,0.0775) -> 0.0775 | J8: IF(C7=0.1,0.08062,0.0775) | L8: Year 3 Cashflow | M8: ='STR 10 Year'!D39 -> 11742.036
H9: Loan Term | I9: 30 | J9: yrs | L9: Year 4 Cashflow | M9: ='STR 10 Year'!E39 -> 12702.64
B10: Nightly | C10: Monthly | D10: Annually | H10: Monthly Payment on Purchase Price | I10: =-PMT($I$8/12,$I$9*12,$B$8) -> 4585.0384 | L10: Year 5 Cashflow | M10: ='STR 10 Year'!F39 -> 13669.457
A11: Average Rent | B11: 300 | C11: =B11*30.5 -> 9150 | D11: =C11*12 -> 109800 | H11: Monthly Interest Payment on Purchase Price | I11: =-IPMT($I$8/12,1,$I$9*12,$B$8) -> 4133.3333 | L11: 6 | M11: =$B$5*(1+0.02)^L11 -> 900929.94 | N11: assumes 2%/yr appreciation
A12: Occupancy Rate | B12: 1 | C12: =-C11*(1-B12) -> 0 | D12: =C12*12 -> 0 | H12: Monthly Principle Payment on Purchase Price | I12: =-PPMT($I$8/12,1,$I$9*12,$B$8) -> 451.70504 | J12: =I12*12 -> 5420.4605
A13: Additional Income (Laundry/Storage etc) | C13: 0 | D13: =C13*12 -> 0
H14: Financials
A15: Calculated Gross Revenue | C15: =SUM(C11:C13) -> 9150 | D15: =C15*12 -> 109800 | H15: Cash On Cash Return (CoC) | I15: =C45/SUM($B$6:$B$7,B60) -> 0.022032636 | L15: Desired Return | M15: 0.08
H16: ROE (Return on Equity) | I16: =C45/B7 -> 0.022810664
A17: Estimated Expenses | B17: Monthly | C17: Annually | H17: AAR | I17: ='STR 10 Year'!L50 -> 0.16578848 | L17: IRR | O17: NPV
A18: Management Fees | B18: =C11*D18 -> 0 | C18: =B18*12 -> 0 | D18: 0 | E18: =IF(D18=0,1,0) -> 1 | H18: Mortgage Pay Down yr 1 | I18: =PPMT($I$8/12,1,$I$9*12,$B$8)*12 -> -5420.4605 | L18: 45536 | M18: 0 | N18: =-SUM('STR Calculator'!B6:B7,B60) -> -165650 | O18: =N18 -> -165650
A19: Subscriptions (AirDnA/Pricelabs/Guesty) | B19: 50 | C19: =B19*12 -> 600 | H19: Tax Savings at 25% | I19: =C45*0.25 -> 912.42655 | L19: 45901 | M19: 1 | N19: ='STR 10 Year'!B39 -> 9539.7062 | O19: =N19/(1+$M$15)^M19 -> 8833.0613
A20: AirBnB / VRBO Fee (3% of nightly) | B20: 0 | C20: =B20*12 -> 0 | L20: 46266 | M20: 2 | N20: ='STR 10 Year'!C39 -> 10787.706 | O20: =N20/(1+$M$15)^M20 -> 9248.7193
A21: Property Taxes / Year | B21: 200 | C21: =B21*12 -> 2400 | D21: =C21/B5 -> 0.003 | H21: Rules of Thumb | L21: 46631 | M21: 3 | N21: ='STR 10 Year'!D39 -> 11742.036 | O21: =N21/(1+$M$15)^M21 -> 9321.2069
A22: Insurance / Year | B22: 300 | C22: =B22*12 -> 3600 | D22: =C22/B5 -> 0.0045 | H22: 2% Rule | I22: =$C$11/$B$5 -> 0.0114375 | L22: 46997 | M22: 4 | N22: ='STR 10 Year'!E39 -> 12702.64 | O22: =N22/(1+$M$15)^M22 -> 9336.8198
A23: Cleaners (per stay, average 6/month) - Trash included. Soap/Toilet Paper/Detergent etc. | B23: =D23*6 -> 1500 | C23: =B23*12 -> 18000 | D23: 250 | H23: DSCR | I23: =B40/(B42+B41+B43) -> 1.1460313 | L23: 47362 | M23: 5 | N23: ='STR 10 Year'!F39 -> 13669.457 | O23: =N23/(1+$M$15)^M23 -> 9303.2029
A24: Handyman | B24: 250 | C24: =B24*12 -> 3000 | L24: 47727 | M24: 6 | N24: ='STR 10 Year'!G39 -> 14642.42 | O24: =N24/(1+$M$15)^M24 -> 9227.2086
A25: HOA / year | B25: 0 | C25: =B25*12 -> 0 | D25: =C25/B5 -> 0 | L25: 48092 | M25: 7 | N25: ='STR 10 Year'!H39 -> 15621.457 | O25: =N25/(1+$M$15)^M25 -> 9114.9703
A26: Electricity | B26: 250 | C26: =B26*12 -> 3000 | L26: 48458 | M26: 8 | N26: ='STR 10 Year'!I39 -> 16606.49 | O26: =N26/(1+$M$15)^M26 -> 8971.9698
A27: Nat Gas(~$2k for large tank, for ~1.5yrs) | B27: =2000/18 -> 111.11111 | C27: =B27*12 -> 1333.3333 | H27: Emergency Fund Needed (6 months) | I27: =B38*$J$27+SUM(B41:B42)*$J$27 -> 50250.147 | J27: 6 | K27: months | L27: 48823 | M27: 9 | N27: ='STR 10 Year'!J39 -> 17597.433 | O27: =N27/(1+$M$15)^M27 -> 8803.0979
A28: WIFI / Cable | B28: 150 | C28: =B28*12 -> 1800 | I28: =I27/2 -> 25125.073 | J28: =J27/2 -> 3 | K28: months | L28: 49188 | M28: 10 | N28: ='STR 10 Year'!K39+'STR 10 Year'!K44-('STR Calculator'!B8-SUM('STR 10 Year'!B46:K46)) -> 651171.76 | O28: =N28/(1+$M$15)^M28 -> 301618.52
A29: Pool Service (bi-weekly = 2xmonth) | B29: 150 | C29: =B29*12 -> 1800
A30: Water/Sewer ($0 for well/septic) | B30: 0 | C30: =B30*12 -> 0 | N30: =XIRR(N18:N28,L18:L28) -> 0.19071521 | O30: =SUM(O18:O28) -> 218128.77
A31: Building Maintenance | B31: =C31/12 -> 0 | C31: =B5*D31 -> 0 | D31: 0
A32: Capex (Future Repairs) | B32: =C32/12 -> 0 | C32: =D32*B5 -> 0 | D32: 0
A33: Grounds Cleanup/Services Maintenance/Snow Removal | B33: 0 | C33: =B33*12 -> 0
A34: City Permit Fees | B34: 25 | C34: =B34*12 -> 300
A35: Fire Marshal Permit | B35: 20 | C35: =B35*12 -> 240
A36: Incidentals (Coffee/Creamer etc) | B36: 25 | C36: =B36*12 -> 300
A37: Umbrella Insurance (Allstate Anchorage) | B37: 37 | C37: =B37*12 -> 444 | H37: Ask cleaners what is included vs not - Linens/soaps/shampoos/coffee/creamer
A38: Totals | B38: =SUM(B18:B37) -> 3068.1111 | C38: =SUM(C18:C37) -> 36817.333
A40: Net Operating Income | B40: =C15-B38 -> 6081.8889 | C40: =D15-C38 -> 72982.667 | D40: DSCR | E40: =B40/(B42+B41+B43) -> 1.1460313
A41: HELOC Payment (Interest Only) | B41: =IF(I6<0,0,I6) -> 721.875 | C41: =B41*12 -> 8662.5 | D41: =IF(B41=I6,1,0) -> 1
...

Sheet Interest Rate Comparison
A1: Purchase Price | C1: 0.1 | D1: 0.15 | E1: 0.2 | F1: 0.25 | H1: 5% Increase in Down Payment | I1: Time to recoup
A2: ='STR Calculator'!B5 -> 800000 | B2: Down Payment | C2: =$A$2*C1 -> 80000 | D2: =$A$2*D1 -> 120000 | E2: =$A$2*E1 -> 160000 | F2: =$A$2*F1 -> 200000 | H2: =D2-C2 -> 40000
A3: 30 | B3: 0.0825 | C3: =PMT($B$3/12,$A$3*12,($A$2-C2)) -> -5409.1195 | D3: =PMT($B$3/12,$A$3*12,($A$2-D2)) -> -5108.6129 | E3: =PMT($B$3/12,$A$3*12,($A$2-E2)) -> -4808.1063 | F3: =PMT($B$3/12,$A$3*12,($A$2-F2)) -> -4507.5996 | G3: =B3 -> 0.0825 | H3: =D3-C3 -> 300.50664 | I3: =$H$2/H3/12 -> 11.092378
B4: 0.08 | C4: =PMT($B$4/12,$A$3*12,($A$2-C2)) -> -5283.1049 | D4: =PMT($B$4/12,$A$3*12,($A$2-D2)) -> -4989.5991 | E4: =PMT($B$4/12,$A$3*12,($A$2-E2)) -> -4696.0933 | F4: =PMT($B$4/12,$A$3*12,($A$2-F2)) -> -4402.5874 | G4: =B4 -> 0.08 | H4: =D4-C4 -> 293.50583 | I4: =$H$2/H4/12 -> 11.356958
B5: 0.0775 | C5: =PMT($B$5/12,$A$3*12,($A$2-C2)) -> -5158.1682 | D5: =PMT($B$5/12,$A$3*12,($A$2-D2)) -> -4871.6033 | E5: =PMT($B$5/12,$A$3*12,($A$2-E2)) -> -4585.0384 | F5: =PMT($B$5/12,$A$3*12,($A$2-F2)) -> -4298.4735 | G5: =B5 -> 0.0775 | H5: =D5-C5 -> 286.5649 | I5: =$H$2/H5/12 -> 11.632036
B6: 0.075 | C6: =PMT($B$6/12,$A$3*12,($A$2-C2)) -> -5034.3445 | D6: =PMT($B$6/12,$A$3*12,($A$2-D2)) -> -4754.6587 | E6: =PMT($B$6/12,$A$3*12,($A$2-E2)) -> -4474.9729 | F6: =PMT($B$6/12,$A$3*12,($A$2-F2)) -> -4195.2871 | G6: =B6 -> 0.075 | H6: =D6-C6 -> 279.6858 | I6: =$H$2/H6/12 -> 11.918136
B7: 0.0725 | C7: =PMT($B$7/12,$A$3*12,($A$2-C2)) -> -4911.6692 | D7: =PMT($B$7/12,$A$3*12,($A$2-D2)) -> -4638.7987 | E7: =PMT($B$7/12,$A$3*12,($A$2-E2)) -> -4365.9282 | F7: =PMT($B$7/12,$A$3*12,($A$2-F2)) -> -4093.0577 | G7: =B7 -> 0.0725 | H7: =D7-C7 -> 272.87051 | I7: =$H$2/H7/12 -> 12.215806
B8: 0.07 | C8: =PMT($B$8/12,$A$3*12,($A$2-C2)) -> -4790.178 | D8: =PMT($B$8/12,$A$3*12,($A$2-D2)) -> -4524.057 | E8: =PMT($B$8/12,$A$3*12,($A$2-E2)) -> -4257.936 | F8: =PMT($B$8/12,$A$3*12,($A$2-F2)) -> -3991.815 | G8: =B8 -> 0.07 | H8: =D8-C8 -> 266.121 | I8: =$H$2/H8/12 -> 12.525631
G9: Higher delta between P&I payment at higher interest rate compared to lower = shorter payout, when factoring in increased down payment for lower rate
A12: Down Payment % | B12: Down Payment | C12: Interest Rate | D12: ="Interest Paid on Down Payment by Year "&ROUND(I4,0) -> Interest Paid on Down Payment by Year 11 | E12: Down Payment Difference | F12: ="Interest Paid Difference @ year "&ROUND(I4,0) -> Interest Paid Difference @ year 11 | G12: Down Payment vs Interest Paid | H12: =ROUND(I4,0)&"yr FV of down payment saved @ 8%" -> 11yr FV of down payment saved @ 8% | I12: NPV of Interest Saved/Lost | J12: ="Cum Interest Paid Year "&ROUND(I4,0) -> Cum Interest Paid Year 11 | K12: Interest Saved Compared to 10% Loan | L12: Total Interest Paid - Life of Loan
A13: =C1 -> 0.1 | B13: =$A$2*A13 -> 80000 | C13: =B4 -> 0.08 | D13: =B13*(1+C13)^$I$4 -> 191726.51 | E13: 0 | F13: 0 | G13: =F13-E13 -> 0 | H13: 0 | I13: 0 | J13: =VLOOKUP($I$4*12,'Amoritization Scenario 10% DP'!$W$8:$AH$367,10) -> 612077.9 | K13: 0 | L13: 1270301
A14: =D1 -> 0.15 | B14: =$A$2*A14 -> 120000 | C14: =B4 -> 0.08 | D14: =B14*(1+C14)^$I$4 -> 287589.77 | E14: =B14-B13 -> 40000 | F14: =D14-D13 -> 95863.255 | G14: =F14-E14 -> 55863.255 | H14: =E14*(1+0.08)^I4 -> 95863.255 | I14: =G14/(1+C14)^I4 -> 23309.559 | J14: =VLOOKUP($I$4*12,'Amoritization Scenario 15% DP'!$W$8:$AH$367,10) -> 578073.57 | K14: =J13-J14 -> 34004.328 | L14: 1199728 | M14: =L14+H14 -> 1295591.3
A15: =E1 -> 0.2 | B15: =$A$2*A15 -> 160000 | C15: =B5 -> 0.0775 | D15: =B15*(1+C15)^$I$4 -> 373492.3 | E15: =B15-B13 -> 80000 | F15: =D15-D13 -> 181765.79 | G15: =F15-E15 -> 101765.79 | H15: =E15*(1+0.08)^I4 -> 191726.51 | I15: =G15/(1+C15)^I4 -> 43595.346 | J15: =VLOOKUP($I$4*12,'Amoritization Scenario 20% DP'!$AJ$8:$AU$367,10) -> 525640.43 | K15: =J13-J15 -> 86437.47 | L15: 1034105 | M15: =L15+H15 -> 1225831.5
K17: Present Value=Future Value /( 1+i)^n

Sheet STR 10 Year
A1: Year | B1: 1 | C1: 2 | D1: 3 | E1: 4 | F1: 5 | G1: 6 | H1: 7 | I1: 8 | J1: 9 | K1: 10
A2: Property Income | L2: Desired Return | M2: 0.08 | N2: match stock market
A3: Yearly Revenue | B3: ='STR Calculator'!D11 -> 109800 | C3: =B3*(1+C5) -> 110898 | D3: =C3*(1+D5) -> 112006.98 | E3: =D3*(1+E5) -> 113127.05 | F3: =E3*(1+F5) -> 114258.32 | G3: =F3*(1+G5) -> 115400.9 | H3: =G3*(1+H5) -> 116554.91 | I3: =H3*(1+I5) -> 117720.46 | J3: =I3*(1+J5) -> 118897.67 | K3: =J3*(1+K5) -> 120086.64
A4: Monthly Revenue | B4: =B3/12 -> 9150 | C4: =C3/12 -> 9241.5 | D4: =D3/12 -> 9333.915 | E4: =E3/12 -> 9427.2541 | F4: =F3/12 -> 9521.5267 | G4: =G3/12 -> 9616.742 | H4: =H3/12 -> 9712.9094 | I4: =I3/12 -> 9810.0385 | ... K4: =K3/12 -> 10007.22 | M4: IRR | P4: NPV
A5: Rent Appreciation | B5: 0.01 | C5: =$B$5 -> 0.01 | D5: =$B$5 -> 0.01 | E5: =$B$5 -> 0.01 | F5: =$B$5 -> 0.01 | G5: =$B$5 -> 0.01 | H5: =$B$5 -> 0.01 | I5: =$B$5 -> 0.01 | J5: =$B$5 -> 0.01 | K5: =$B$5 -> 0.01 | M5: 45536 | N5: 0 | O5: =-SUM('STR Calculator'!B6:B7,'STR Calculator'!B60) -> -165650 | P5: =O5 -> -165650
A6: ="Vacancy Loss (Occupancy rate "&'STR Calculator'!$B$12&"%)" -> Vacancy Loss (Occupancy rate 1%) | B6: =B3*(1-'STR Calculator'!$B$12) -> 0 | C6: =C3*(1-'STR Calculator'!$B$12) -> 0 | D6: =D3*(1-'STR Calculator'!$B$12) -> 0 | E6: =E3*(1-'STR Calculator'!$B$12) -> 0 | F6: =F3*(1-'STR Calculator'!$B$12) -> 0 | G6: =G3*(1-'STR Calculator'!$B$12) -> 0 | H6: =H3*(1-'STR Calculator'!$B$12) -> 0 | I6: =I3*(1-'STR Calculator'!$B$12) -> 0 | ... K6: =K3*(1-'STR Calculator'!$B$12) -> 0 | M6: 45901 | N6: 1 | O6: =B39 -> 9539.7062 | P6: =O6/(1+$M$2)^N6 -> 8833.0613
M7: 46266 | N7: 2 | O7: =C39 -> 10787.706 | P7: =O7/(1+$M$2)^N7 -> 9248.7193
A8: Operating Income | B8: =B3-B6 -> 109800 | C8: =C3-C6 -> 110898 | D8: =D3-D6 -> 112006.98 | E8: =E3-E6 -> 113127.05 | F8: =F3-F6 -> 114258.32 | G8: =G3-G6 -> 115400.9 | H8: =H3-H6 -> 116554.91 | I8: =I3-I6 -> 117720.46 | ... K8: =K3-K6 -> 120086.64 | M8: 46631 | N8: 3 | O8: =D39 -> 11742.036 | P8: =O8/(1+$M$2)^N8 -> 9321.2069
M9: 46997 | N9: 4 | O9: =E39 -> 12702.64 | P9: =O9/(1+$M$2)^N9 -> 9336.8198
A10: Property Expenses | M10: 47362 | N10: 5 | O10: =F39 -> 13669.457 | P10: =O10/(1+$M$2)^N10 -> 9303.2029
A11: Management Fee | B11: ='STR Calculator'!$C$18 -> 0 | C11: =$B$11 -> 0 | D11: =$B$11 -> 0 | E11: =$B$11 -> 0 | F11: =$B$11 -> 0 | G11: =$B$11 -> 0 | H11: =$B$11 -> 0 | I11: =$B$11 -> 0 | J11: =$B$11 -> 0 | K11: =$B$11 -> 0 | M11: 47727 | N11: 6 | O11: =G39 -> 14642.42 | P11: =O11/(1+$M$2)^N11 -> 9227.2086
A12: Subscriptions | B12: ='STR Calculator'!$C$19 -> 600 | C12: ='STR Calculator'!$C$19 -> 600 | D12: ='STR Calculator'!$C$19 -> 600 | E12: ='STR Calculator'!$C$19 -> 600 | F12: ='STR Calculator'!$C$19 -> 600 | G12: ='STR Calculator'!$C$19 -> 600 | H12: ='STR Calculator'!$C$19 -> 600 | I12: ='STR Calculator'!$C$19 -> 600 | ... K12: ='STR Calculator'!$C$19 -> 600 | M12: 48092 | N12: 7 | O12: =H39 -> 15621.457 | P12: =O12/(1+$M$2)^N12 -> 9114.9703
A13: AirBnB/VRBO Fee (3% of nightly- Passed to guest) | B13: ='STR Calculator'!$C$20 -> 0 | C13: ='STR Calculator'!$C$20 -> 0 | D13: ='STR Calculator'!$C$20 -> 0 | E13: ='STR Calculator'!$C$20 -> 0 | F13: ='STR Calculator'!$C$20 -> 0 | G13: ='STR Calculator'!$C$20 -> 0 | H13: ='STR Calculator'!$C$20 -> 0 | I13: ='STR Calculator'!$C$20 -> 0 | ... K13: ='STR Calculator'!$C$20 -> 0 | M13: 48458 | N13: 8 | O13: =I39 -> 16606.49 | P13: =O13/(1+$M$2)^N13 -> 8971.9698
A14: Property Taxes (1.5%) | B14: ='STR Calculator'!$C$21 -> 2400 | C14: =B44*($B$14/'STR Calculator'!$B$5) -> 2496 | D14: =C44*($B$14/'STR Calculator'!$B$5) -> 2595.84 | E14: =D44*($B$14/'STR Calculator'!$B$5) -> 2699.6736 | F14: =E44*($B$14/'STR Calculator'!$B$5) -> 2807.6605 | G14: =F44*($B$14/'STR Calculator'!$B$5) -> 2919.967 | H14: =G44*($B$14/'STR Calculator'!$B$5) -> 3036.7656 | I14: =H44*($B$14/'STR Calculator'!$B$5) -> 3158.2363 | J14: =I44*($B$14/'STR Calculator'!$B$5) -> 3284.5657 | K14: =J44*($B$14/'STR Calculator'!$B$5) -> 3415.9483 | M14: 48823 | N14: 9 | O14: =J39 -> 17597.433 | P14: =O14/(1+$M$2)^N14 -> 8803.0979
A15: Insurance (1.5%) | B15: ='STR Calculator'!$C$22 -> 3600 | C15: =B15+(B15*0.015) -> 3654 | D15: =C15+(C15*0.015) -> 3708.81 | E15: =D15+(D15*0.015) -> 3764.4421 | F15: =E15+(E15*0.015) -> 3820.9088 | G15: =F15+(F15*0.015) -> 3878.2224 | H15: =G15+(G15*0.015) -> 3936.3958 | I15: =H15+(H15*0.015) -> 3995.4417 | J15: =I15+(I15*0.015) -> 4055.3733 | K15: =J15+(J15*0.015) -> 4116.2039 | M15: 49188 | N15: 10 | O15: =K39+K44-('STR Calculator'!B8-SUM('STR 10 Year'!B46:K46)) -> 651171.76 | P15: =O15/(1+$M$2)^N15 -> 301618.52
A16: Cleaners/Handyman | B16: =SUM('STR Calculator'!$C$23:$C$24) -> 21000 | C16: =SUM('STR Calculator'!$C$23:$C$24) -> 21000 | D16: =SUM('STR Calculator'!$C$23:$C$24) -> 21000 | E16: =SUM('STR Calculator'!$C$23:$C$24) -> 21000 | F16: =SUM('STR Calculator'!$C$23:$C$24) -> 21000 | G16: =SUM('STR Calculator'!$C$23:$C$24) -> 21000 | H16: =SUM('STR Calculator'!$C$23:$C$24) -> 21000 | I16: =SUM('STR Calculator'!$C$23:$C$24) -> 21000 | ... K16: =SUM('STR Calculator'!$C$23:$C$24) -> 21000
A17: HOA Fees | B17: ='STR Calculator'!$C$25 -> 0 | C17: ='STR Calculator'!$C$25 -> 0 | D17: ='STR Calculator'!$C$25 -> 0 | E17: ='STR Calculator'!$C$25 -> 0 | F17: ='STR Calculator'!$C$25 -> 0 | G17: ='STR Calculator'!$C$25 -> 0 | H17: ='STR Calculator'!$C$25 -> 0 | I17: ='STR Calculator'!$C$25 -> 0 | ... K17: ='STR Calculator'!$C$25 -> 0 | O17: =XIRR(O5:O15,M5:M15) -> 0.19071521 | P17: =SUM(P5:P15) -> 218128.77
A18: Electricity | B18: ='STR Calculator'!$C$26 -> 3000 | C18: ='STR Calculator'!$C$26 -> 3000 | D18: ='STR Calculator'!$C$26 -> 3000 | E18: ='STR Calculator'!$C$26 -> 3000 | F18: ='STR Calculator'!$C$26 -> 3000 | G18: ='STR Calculator'!$C$26 -> 3000 | H18: ='STR Calculator'!$C$26 -> 3000 | I18: ='STR Calculator'!$C$26 -> 3000 | ... K18: ='STR Calculator'!$C$26 -> 3000
A19: Natural Gas | B19: ='STR Calculator'!$C$27 -> 1333.3333 | C19: ='STR Calculator'!$C$27 -> 1333.3333 | D19: ='STR Calculator'!$C$27 -> 1333.3333 | E19: ='STR Calculator'!$C$27 -> 1333.3333 | F19: ='STR Calculator'!$C$27 -> 1333.3333 | G19: ='STR Calculator'!$C$27 -> 1333.3333 | H19: ='STR Calculator'!$C$27 -> 1333.3333 | I19: ='STR Calculator'!$C$27 -> 1333.3333 | ... K19: ='STR Calculator'!$C$27 -> 1333.3333
A20: WIFI/Cable | B20: ='STR Calculator'!$C$28 -> 1800 | C20: ='STR Calculator'!$C$28 -> 1800 | D20: ='STR Calculator'!$C$28 -> 1800 | E20: ='STR Calculator'!$C$28 -> 1800 | F20: ='STR Calculator'!$C$28 -> 1800 | G20: ='STR Calculator'!$C$28 -> 1800 | H20: ='STR Calculator'!$C$28 -> 1800 | I20: ='STR Calculator'!$C$28 -> 1800 | ... K20: ='STR Calculator'!$C$28 -> 1800
A21: Water/Sewer ($0 if septic/well) | B21: ='STR Calculator'!$C$30 -> 0 | C21: ='STR Calculator'!$C$30 -> 0 | D21: ='STR Calculator'!$C$30 -> 0 | E21: ='STR Calculator'!$C$30 -> 0 | F21: ='STR Calculator'!$C$30 -> 0 | G21: ='STR Calculator'!$C$30 -> 0 | H21: ='STR Calculator'!$C$30 -> 0 | I21: ='STR Calculator'!$C$30 -> 0 | ... K21: ='STR Calculator'!$C$30 -> 0
A22: Pool Service ($75/each x biweekly) | B22: ='STR Calculator'!$C$29 -> 1800 | C22: ='STR Calculator'!$C$29 -> 1800 | D22: ='STR Calculator'!$C$29 -> 1800 | E22: ='STR Calculator'!$C$29 -> 1800 | F22: ='STR Calculator'!$C$29 -> 1800 | G22: ='STR Calculator'!$C$29 -> 1800 | H22: ='STR Calculator'!$C$29 -> 1800 | I22: ='STR Calculator'!$C$29 -> 1800 | ... K22: ='STR Calculator'!$C$29 -> 1800
A23: Building Maintenance (1%) | B23: ='STR Calculator'!$C$31 -> 0 | C23: ='STR Calculator'!$B$5*'STR Calculator'!$D$32 -> 0 | D23: ='STR Calculator'!$B$5*'STR Calculator'!$D$32 -> 0 | E23: ='STR Calculator'!$B$5*'STR Calculator'!$D$32 -> 0 | F23: ='STR Calculator'!$B$5*'STR Calculator'!$D$32 -> 0 | G23: ='STR Calculator'!$B$5*'STR Calculator'!$D$32 -> 0 | H23: ='STR Calculator'!$B$5*'STR Calculator'!$D$32 -> 0 | I23: ='STR Calculator'!$B$5*'STR Calculator'!$D$32 -> 0 | J23: ='STR Calculator'!$B$5*'STR Calculator'!$D$32 -> 0 | K23: ='STR Calculator'!$B$5*'STR Calculator'!$D$32 -> 0
A24: Capex (1%) | B24: ='STR Calculator'!$C$32 -> 0 | C24: ='STR Calculator'!$C$32 -> 0 | D24: ='STR Calculator'!$C$32 -> 0 | E24: ='STR Calculator'!$C$32 -> 0 | F24: ='STR Calculator'!$C$32 -> 0 | G24: ='STR Calculator'!$C$32 -> 0 | H24: ='STR Calculator'!$C$32 -> 0 | I24: ='STR Calculator'!$C$32 -> 0 | ... K24: ='STR Calculator'!$C$32 -> 0
A25: Grounds Cleanup/Services/Snow Removal | B25: ='STR Calculator'!$C$33 -> 0 | C25: ='STR Calculator'!$C$33 -> 0 | D25: ='STR Calculator'!$C$33 -> 0 | E25: ='STR Calculator'!$C$33 -> 0 | F25: ='STR Calculator'!$C$33 -> 0 | G25: ='STR Calculator'!$C$33 -> 0 | H25: ='STR Calculator'!$C$33 -> 0 | I25: ='STR Calculator'!$C$33 -> 0 | ... K25: ='STR Calculator'!$C$33 -> 0
A26: City Permit Fee | B26: 300 | C26: 0 | D26: 0 | E26: 0 | F26: 0 | G26: 0 | H26: 0 | I26: 0 | J26: 0 | K26: 0
A27: Incidentals (Coffee/Creamer etc) | B27: ='STR Calculator'!$C$36 -> 300 | C27: ='STR Calculator'!$C$36 -> 300 | D27: ='STR Calculator'!$C$36 -> 300 | E27: ='STR Calculator'!$C$36 -> 300 | F27: ='STR Calculator'!$C$36 -> 300 | G27: ='STR Calculator'!$C$36 -> 300 | H27: ='STR Calculator'!$C$36 -> 300 | I27: ='STR Calculator'!$C$36 -> 300 | ... K27: ='STR Calculator'!$C$36 -> 300
A28: Umbrella Insurance | B28: ='STR Calculator'!$C$37 -> 444 | C28: ='STR Calculator'!$C$37 -> 444 | D28: ='STR Calculator'!$C$37 -> 444 | E28: ='STR Calculator'!$C$37 -> 444 | F28: ='STR Calculator'!$C$37 -> 444 | G28: ='STR Calculator'!$C$37 -> 444 | H28: ='STR Calculator'!$C$37 -> 444 | I28: ='STR Calculator'!$C$37 -> 444 | ... K28: ='STR Calculator'!$C$37 -> 444
A30: Operating Expenses | B30: =SUM(B12:B28) -> 36577.333 | C30: =SUM(C12:C28) -> 36427.333 | D30: =SUM(D12:D28) -> 36581.983 | E30: =SUM(E12:E28) -> 36741.449 | F30: =SUM(F12:F28) -> 36905.903 | G30: =SUM(G12:G28) -> 37075.523 | H30: =SUM(H12:H28) -> 37250.495 | I30: =SUM(I12:I28) -> 37431.011 | ... K30: =SUM(K12:K28) -> 37809.486
A32: Net Operating Income (NOI) | B32: =B8-B30 -> 73222.667 | C32: =C8-C30 -> 74470.667 | D32: =D8-D30 -> 75424.997 | E32: =E8-E30 -> 76385.601 | F32: =F8-F30 -> 77352.418 | G32: =G8-G30 -> 78325.381 | H32: =H8-H30 -> 79304.418 | I32: =I8-I30 -> 80289.45 | ... K32: =K8-K30 -> 82277.157
A33: Capitalization Rate (CAP Rate) | B33: =B32/'STR Calculator'!$B$5 -> 0.091528333 | C33: =C32/'STR Calculator'!$B$5 -> 0.093088333 | D33: =D32/'STR Calculator'!$B$5 -> 0.094281246 | E33: =E32/'STR Calculator'!$B$5 -> 0.095482001 | F33: =F32/'STR Calculator'!$B$5 -> 0.096690522 | G33: =G32/'STR Calculator'!$B$5 -> 0.097906726 | H33: =H32/'STR Calculator'!$B$5 -> 0.099130522 | I33: =I32/'STR Calculator'!$B$5 -> 0.10036181 | ... K33: =K32/'STR Calculator'!$B$5 -> 0.10284645
A35: Key Investment Indicators
A36: Mortgage Payment | B36: =PMT('STR Calculator'!$I$8/12, 'STR Calculator'!$I$9*12,'STR Calculator'!$B$8)*12 -> -55020.46 | C36: =PMT('STR Calculator'!$I$8/12, 'STR Calculator'!$I$9*12,'STR Calculator'!$B$8)*12 -> -55020.46 | D36: =PMT('STR Calculator'!$I$8/12, 'STR Calculator'!$I$9*12,'STR Calculator'!$B$8)*12 -> -55020.46 | E36: =PMT('STR Calculator'!$I$8/12, 'STR Calculator'!$I$9*12,'STR Calculator'!$B$8)*12 -> -55020.46 | F36: =PMT('STR Calculator'!$I$8/12, 'STR Calculator'!$I$9*12,'STR Calculator'!$B$8)*12 -> -55020.46 | G36: =PMT('STR Calculator'!$I$8/12, 'STR Calculator'!$I$9*12,'STR Calculator'!$B$8)*12 -> -55020.46 | H36: =PMT('STR Calculator'!$I$8/12, 'STR Calculator'!$I$9*12,'STR Calculator'!$B$8)*12 -> -55020.46 | I36: =PMT('STR Calculator'!$I$8/12, 'STR Calculator'!$I$9*12,'STR Calculator'!$B$8)*12 -> -55020.46 | ... K36: =PMT('STR Calculator'!$I$8/12, 'STR Calculator'!$I$9*12,'STR Calculator'!$B$8)*12 -> -55020.46
A37: ="HELOC Payment ($"& 'STR Calculator'!I3&")" -> HELOC Payment ($105000) | B37: =-'STR Calculator'!$C$41 -> -8662.5 | C37: =-'STR Calculator'!$C$41 -> -8662.5 | D37: =-'STR Calculator'!$C$41 -> -8662.5 | E37: =-'STR Calculator'!$C$41 -> -8662.5 | F37: =-'STR Calculator'!$C$41 -> -8662.5 | G37: =-'STR Calculator'!$C$41 -> -8662.5 | H37: =-'STR Calculator'!$C$41 -> -8662.5 | I37: =-'STR Calculator'!$C$41 -> -8662.5 | ... K37: =-'STR Calculator'!$C$41 -> -8662.5
A38: PMI if Down Payment less than 20% | B38: =-'STR Calculator'!$C$43 -> 0 | C38: =-'STR Calculator'!$C$43 -> 0 | D38: =-'STR Calculator'!$C$43 -> 0 | E38: =-'STR Calculator'!$C$43 -> 0 | F38: =-'STR Calculator'!$C$43 -> 0 | G38: =-'STR Calculator'!$C$43 -> 0 | H38: =-'STR Calculator'!$C$43 -> 0 | I38: =-'STR Calculator'!$C$43 -> 0 | ... K38: =-'STR Calculator'!$C$43 -> 0
A39: Net Cash Flow | B39: =B32+B36+B37+B38 -> 9539.7062 | C39: =C32+C36+C37+C38 -> 10787.706 | D39: =D32+D36+D37+D38 -> 11742.036 | E39: =E32+E36+E37+E38 -> 12702.64 | F39: =F32+F36+F37+F38 -> 13669.457 | G39: =G32+G36+G37+G38 -> 14642.42 | H39: =H32+H36+H37+H38 -> 15621.457 | I39: =I32+I36+I37+I38 -> 16606.49 | ... K39: =K32+K36+K37+K38 -> 18594.197 | L39: =SUM(B39:K39) -> 141503.54 | M39: FV of all cash flows
A40: Monthly Cash Flow | B40: =B39/12 -> 794.97552 | C40: =C39/12 -> 898.97552 | D40: =D39/12 -> 978.50302 | E40: =E39/12 -> 1058.5534 | F40: =F39/12 -> 1139.1214 | G40: =G39/12 -> 1220.2017 | H40: =H39/12 -> 1301.7881 | I40: =I39/12 -> 1383.8742 | ... K40: =K39/12 -> 1549.5164
A41: ="Discounted Cash Flow (DCF) @ "&M2&"% return" -> Discounted Cash Flow (DCF) @ 0.08% return | B41: =B39/(1+$M$2)^B1 -> 8833.0613 | C41: =C39/(1+$M$2)^C1 -> 9248.7193 | D41: =D39/(1+$M$2)^D1 -> 9321.2069 | E41: =E39/(1+$M$2)^E1 -> 9336.8198 | F41: =F39/(1+$M$2)^F1 -> 9303.2029 | G41: =G39/(1+$M$2)^G1 -> 9227.2086 | H41: =H39/(1+$M$2)^H1 -> 9114.9703 | I41: =I39/(1+$M$2)^I1 -> 8971.9698 | ... K41: =K39/(1+$M$2)^K1 -> 8612.7109 | L41: =SUM(B41:K41) -> 90772.968 | M41: PV of all cash flows
A42: Cash on Cash ROI | B42: =B39/(SUM('STR Calculator'!$B$7,'STR Calculator'!$B$6)) -> 0.059623164 | C42: =C39/(SUM('STR Calculator'!$B$7,'STR Calculator'!$B$6)) -> 0.067423164 | D42: =D39/(SUM('STR Calculator'!$B$7,'STR Calculator'!$B$6)) -> 0.073387726 | E42: =E39/(SUM('STR Calculator'!$B$7,'STR Calculator'!$B$6)) -> 0.079391502 | F42: =F39/(SUM('STR Calculator'!$B$7,'STR Calculator'!$B$6)) -> 0.085434107 | G42: =G39/(SUM('STR Calculator'!$B$7,'STR Calculator'!$B$6)) -> 0.091515127 | H42: =H39/(SUM('STR Calculator'!$B$7,'STR Calculator'!$B$6)) -> 0.097634108 | I42: =I39/(SUM('STR Calculator'!$B$7,'STR Calculator'!$B$6)) -> 0.10379056 | ... K42: =K39/(SUM('STR Calculator'!$B$7,'STR Calculator'!$B$6)) -> 0.11621373
A43: Property Appreciation | B43: 0.04 | C43: =$B$43 -> 0.04 | D43: =$B$43 -> 0.04 | E43: =$B$43 -> 0.04 | F43: =$B$43 -> 0.04 | G43: =$B$43 -> 0.04 | H43: =$B$43 -> 0.04 | I43: =$B$43 -> 0.04 | J43: =$B$43 -> 0.04 | K43: =$B$43 -> 0.04
...

Sheet STR 7yr IRR Financing
A1: ='STR Calculator'!A2 &" - FINANCING CALCULATIONS" -> 2974 Ginas Way - 3bd / 4bath - 1927 sqft - FINANCING CALCULATIONS
B4: Year 1 | C4: Year 2 | D4: Year 3 | E4: Year 4 | F4: Year 5 | G4: Year 6 | H4: Year 7
A5: Maintenance | B5: 0.01 | C5: 0.01 | D5: 0.01 | E5: 0.01 | F5: 0.01 | G5: 0.01 | H5: 0.01
A6: Property Appreciation | B6: 0.02 | C6: 0.02 | D6: 0.02 | E6: 0.02 | F6: 0.02 | G6: 0.02 | H6: 0.02
A7: Rental Appreciation | B7: 0.01 | C7: 0.01 | D7: 0.01 | E7: 0.01 | F7: 0.01 | G7: 0.01 | H7: 0.01
A8: Tax/Insurance/HOA Appreciation | B8: 0.015 | C8: 0.015 | D8: 0.015 | E8: 0.015 | F8: 0.015 | G8: 0.015 | H8: 0.015
A9: Vacancy | B9: =1-'STR Calculator'!$B$12 -> 0 | C9: =1-'STR Calculator'!$B$12 -> 0 | D9: =1-'STR Calculator'!$B$12 -> 0 | E9: =1-'STR Calculator'!$B$12 -> 0 | F9: =1-'STR Calculator'!$B$12 -> 0 | G9: =1-'STR Calculator'!$B$12 -> 0 | H9: =1-'STR Calculator'!$B$12 -> 0
B11: Year 1 | C11: Year 2 | D11: Year 3 | E11: Year 4 | F11: Year 5 | G11: Year 6 | H11: Year 7
A12: Revenues
A13: Rental Income | B13: ='STR Calculator'!D11 -> 109800 | C13: =SUM(B$13+(C$7*B$13)) -> 110898 | D13: =SUM(C$13+(D$7*C$13)) -> 112006.98 | E13: =SUM(D$13+(E$7*D$13)) -> 113127.05 | F13: =SUM(E$13+(F$7*E$13)) -> 114258.32 | G13: =SUM(F$13+(G$7*F$13)) -> 115400.9 | H13: =SUM(G$13+(H$7*G$13)) -> 116554.91
A14: Monthly Revenue | B14: =B13/12 -> 9150 | C14: =C13/12 -> 9241.5 | D14: =D13/12 -> 9333.915 | E14: =E13/12 -> 9427.2541 | F14: =F13/12 -> 9521.5267 | G14: =G13/12 -> 9616.742 | H14: =H13/12 -> 9712.9094
A15: Vacancy Rate | B15: ='STR Calculator'!D12 -> 0 | C15: =-(C13*C9) -> 0 | D15: =-(D13*D9) -> 0 | E15: =-(E13*E9) -> 0 | F15: =-(F13*F9) -> 0 | G15: =-(G13*G9) -> 0 | H15: =-(H13*H9) -> 0
A16: Net Revenue | B16: =SUM(B13,B15) -> 109800 | C16: =SUM(C13,C15) -> 110898 | D16: =SUM(D13,D15) -> 112006.98 | E16: =SUM(E13,E15) -> 113127.05 | F16: =SUM(F13,F15) -> 114258.32 | G16: =SUM(G13,G15) -> 115400.9 | H16: =SUM(H13,H15) -> 116554.91
A18: Expenses
A19: Management Fees | B19: 0 | C19: 0 | D19: 0 | E19: 0 | F19: 0 | G19: 0 | H19: 0
A20: Subscriptions | B20: ='STR Calculator'!$C$19 -> 600 | C20: ='STR Calculator'!$C$19 -> 600 | D20: ='STR Calculator'!$C$19 -> 600 | E20: ='STR Calculator'!$C$19 -> 600 | F20: ='STR Calculator'!$C$19 -> 600 | G20: ='STR Calculator'!$C$19 -> 600 | H20: ='STR Calculator'!$C$19 -> 600
A21: Property Taxes | B21: ='STR Calculator'!$C$21 -> 2400 | C21: =B$21+(B$21*C$8) -> 2436 | D21: =C$21+(C$21*D$8) -> 2472.54 | E21: =D$21+(D$21*E$8) -> 2509.6281 | F21: =E$21+(E$21*F$8) -> 2547.2725 | G21: =F$21+(F$21*G$8) -> 2585.4816 | H21: =G$21+(G$21*H$8) -> 2624.2638
A22: Insurance | B22: =('STR Calculator'!$C$22) -> 3600 | C22: =('STR Calculator'!$B$5+B48)*($B$22/'STR Calculator'!$B$5) -> 3672 | D22: =('STR Calculator'!$B$5+C48)*($B$22/'STR Calculator'!$B$5) -> 3673.44 | E22: =('STR Calculator'!$B$5+D48)*($B$22/'STR Calculator'!$B$5) -> 3673.4688 | F22: =('STR Calculator'!$B$5+E48)*($B$22/'STR Calculator'!$B$5) -> 3673.4694 | G22: =('STR Calculator'!$B$5+F48)*($B$22/'STR Calculator'!$B$5) -> 3673.4694 | H22: =('STR Calculator'!$B$5+G48)*($B$22/'STR Calculator'!$B$5) -> 3673.4694
A23: Cleaners/Handyman | B23: =SUM('STR Calculator'!$C$23:$C$24) -> 21000 | C23: =SUM('STR Calculator'!$C$23:$C$24) -> 21000 | D23: =SUM('STR Calculator'!$C$23:$C$24) -> 21000 | E23: =SUM('STR Calculator'!$C$23:$C$24) -> 21000 | F23: =SUM('STR Calculator'!$C$23:$C$24) -> 21000 | G23: =SUM('STR Calculator'!$C$23:$C$24) -> 21000 | H23: =SUM('STR Calculator'!$C$23:$C$24) -> 21000
A24: Electricity | B24: ='STR Calculator'!$C$26 -> 3000 | C24: ='STR Calculator'!$C$26 -> 3000 | D24: ='STR Calculator'!$C$26 -> 3000 | E24: ='STR Calculator'!$C$26 -> 3000 | F24: ='STR Calculator'!$C$26 -> 3000 | G24: ='STR Calculator'!$C$26 -> 3000 | H24: ='STR Calculator'!$C$26 -> 3000
A25: Natural Gas | B25: ='STR Calculator'!$C$27 -> 1333.3333 | C25: ='STR Calculator'!$C$27 -> 1333.3333 | D25: ='STR Calculator'!$C$27 -> 1333.3333 | E25: ='STR Calculator'!$C$27 -> 1333.3333 | F25: ='STR Calculator'!$C$27 -> 1333.3333 | G25: ='STR Calculator'!$C$27 -> 1333.3333 | H25: ='STR Calculator'!$C$27 -> 1333.3333
A26: WIFI/Cable | B26: ='STR Calculator'!$C$28 -> 1800 | C26: ='STR Calculator'!$C$28 -> 1800 | D26: ='STR Calculator'!$C$28 -> 1800 | E26: ='STR Calculator'!$C$28 -> 1800 | F26: ='STR Calculator'!$C$28 -> 1800 | G26: ='STR Calculator'!$C$28 -> 1800 | H26: ='STR Calculator'!$C$28 -> 1800
A27: Water/Sewer | B27: ='STR Calculator'!$C$30 -> 0 | C27: ='STR Calculator'!$C$30 -> 0 | D27: ='STR Calculator'!$C$30 -> 0 | E27: ='STR Calculator'!$C$30 -> 0 | F27: ='STR Calculator'!$C$30 -> 0 | G27: ='STR Calculator'!$C$30 -> 0 | H27: ='STR Calculator'!$C$30 -> 0
A28: Pool Service | B28: ='STR Calculator'!$C$29 -> 1800 | C28: ='STR Calculator'!$C$29 -> 1800 | D28: ='STR Calculator'!$C$29 -> 1800 | E28: ='STR Calculator'!$C$29 -> 1800 | F28: ='STR Calculator'!$C$29 -> 1800 | G28: ='STR Calculator'!$C$29 -> 1800 | H28: ='STR Calculator'!$C$29 -> 1800
A29: HOA | B29: ='STR Calculator'!$C$25 -> 0 | C29: =B29+(B29*C8) -> 0 | D29: =C29+(C29*D8) -> 0 | E29: =D29+(D29*E8) -> 0 | F29: =E29+(E29*F8) -> 0 | G29: =F29+(F29*G8) -> 0 | H29: =G29+(G29*H8) -> 0
A30: Maintenance & Repairs | B30: ='STR Calculator'!$C$31 -> 0 | C30: ='STR Calculator'!$B$5*C5 -> 8000 | D30: ='STR Calculator'!$B$5*D5 -> 8000 | E30: ='STR Calculator'!$B$5*E5 -> 8000 | F30: ='STR Calculator'!$B$5*F5 -> 8000 | G30: ='STR Calculator'!$B$5*G5 -> 8000 | H30: ='STR Calculator'!$B$5*H5 -> 8000
A31: Capex | B31: ='STR Calculator'!$C$32 -> 0 | C31: ='STR Calculator'!$C$32 -> 0 | D31: ='STR Calculator'!$C$32 -> 0 | E31: ='STR Calculator'!$C$32 -> 0 | F31: ='STR Calculator'!$C$32 -> 0 | G31: ='STR Calculator'!$C$32 -> 0 | H31: ='STR Calculator'!$C$32 -> 0
A32: City Permit | B32: ='STR Calculator'!C34 -> 300 | C32: 0 | D32: 0 | E32: 0 | F32: 0 | G32: 0 | H32: 0
A33: Incidentals (Coffee, etc) | B33: ='STR Calculator'!$C$36 -> 300 | C33: ='STR Calculator'!$C$36 -> 300 | D33: ='STR Calculator'!$C$36 -> 300 | E33: ='STR Calculator'!$C$36 -> 300 | F33: ='STR Calculator'!$C$36 -> 300 | G33: ='STR Calculator'!$C$36 -> 300 | H33: ='STR Calculator'!$C$36 -> 300
A34: Umbrella Insurance | B34: ='STR Calculator'!$C$37 -> 444 | C34: ='STR Calculator'!$C$37 -> 444 | D34: ='STR Calculator'!$C$37 -> 444 | E34: ='STR Calculator'!$C$37 -> 444 | F34: ='STR Calculator'!$C$37 -> 444 | G34: ='STR Calculator'!$C$37 -> 444 | H34: ='STR Calculator'!$C$37 -> 444
A35: Total Expenses | B35: =SUM(B20:B34) -> 36577.333 | C35: =SUM(C20:C34) -> 44385.333 | D35: =SUM(D20:D34) -> 44423.313 | E35: =SUM(E20:E34) -> 44460.43 | F35: =SUM(F20:F34) -> 44498.075 | G35: =SUM(G20:G34) -> 44536.284 | H35: =SUM(H20:H34) -> 44575.067
A37: Net Operating Income (NOI) | B37: =SUM(B16-B35) -> 73222.667 | C37: =SUM(C16-C35) -> 66512.667 | D37: =SUM(D16-D35) -> 67583.667 | E37: =SUM(E16-E35) -> 68666.62 | F37: =SUM(F16-F35) -> 69760.245 | G37: =SUM(G16-G35) -> 70864.619 | H37: =SUM(H16-H35) -> 71979.846
A39: Cash Flow
A40: NOI (Cash Available) | B40: =B37 -> 73222.667 | C40: =C37 -> 66512.667 | D40: =D37 -> 67583.667 | E40: =E37 -> 68666.62 | F40: =F37 -> 69760.245 | G40: =G37 -> 70864.619 | H40: =H37 -> 71979.846
A41: Conventional Mortgage | B41: ='STR Calculator'!$C$42 -> 55020.46 | C41: ='STR Calculator'!$C$42 -> 55020.46 | D41: ='STR Calculator'!$C$42 -> 55020.46 | E41: ='STR Calculator'!$C$42 -> 55020.46 | F41: ='STR Calculator'!$C$42 -> 55020.46 | G41: ='STR Calculator'!$C$42 -> 55020.46 | H41: ='STR Calculator'!$C$42 -> 55020.46
A42: HELOC Mortgage | B42: ='STR Calculator'!$C$41 -> 8662.5 | C42: ='STR Calculator'!$C$41 -> 8662.5 | D42: ='STR Calculator'!$C$41 -> 8662.5 | E42: ='STR Calculator'!$C$41 -> 8662.5 | F42: ='STR Calculator'!$C$41 -> 8662.5 | G42: ='STR Calculator'!$C$41 -> 8662.5 | H42: ='STR Calculator'!$C$41 -> 8662.5
A43: PMI if Down Payment less than 20% | B43: ='STR Calculator'!$C$43 -> 0 | C43: ='STR Calculator'!$C$43 -> 0 | D43: ='STR Calculator'!$C$43 -> 0 | E43: ='STR Calculator'!$C$43 -> 0 | F43: ='STR Calculator'!$C$43 -> 0 | G43: ='STR Calculator'!$C$43 -> 0 | H43: ='STR Calculator'!$C$43 -> 0
A44: Total Cash Flow | B44: =SUM(B40-B41-B42-B43) -> 9539.7062 | C44: =SUM(C40-C41-C42-C43) -> 2829.7062 | D44: =SUM(D40-D41-D42-D43) -> 3900.7062 | E44: =SUM(E40-E41-E42-E43) -> 4983.6591 | F44: =SUM(F40-F41-F42-F43) -> 6077.2846 | G44: =SUM(G40-G41-G42-G43) -> 7181.6587 | H44: =SUM(H40-H41-H42-H43) -> 8296.8855
A45: Monthly Cash Flow | B45: =B44/12 -> 794.97552 | C45: =C44/12 -> 235.80885 | D45: =D44/12 -> 325.05885 | E45: =E44/12 -> 415.30493 | F45: =F44/12 -> 506.44038 | G45: =G44/12 -> 598.47156 | H45: =H44/12 -> 691.40713
A46: DSCR | B46: =B40/SUM(B41:B43) -> 1.1498 | C46: =C40/SUM(C41:C43) -> 1.0444343 | D46: =D40/SUM(D41:D43) -> 1.061252 | E46: =E40/SUM(E41:E43) -> 1.0782573 | F46: =F40/SUM(F41:F43) -> 1.0954303 | G46: =G40/SUM(G41:G43) -> 1.1127721 | H46: =H40/SUM(H41:H43) -> 1.1302842
...

Sheet Amoritization Scenario 10% DP
A1: If deciding between different Down Payment % and Interest Rates, compare Cumulative Interest Payment over duration to recoup additional Down Payment Lump Sum, to see which is better. NPV / PV/FV money calculation
C3: sqft | J3: Interest | K3: ='Interest Rate Comparison'!B3 -> 0.0825 | N3: =K3/12 -> 0.006875 | O3: r | W3: Interest | X3: ='Interest Rate Comparison'!B4 -> 0.08 | AA3: =X3/12 -> 0.0066666667 | AB3: r | AJ3: Interest | AK3: ='Interest Rate Comparison'!B5 -> 0.0775 | AN3: =AK3/12 -> 0.0064583333 | AO3: r | AW3: Interest | AX3: ='Interest Rate Comparison'!B6 -> 0.075 | BA3: =AX3/12 -> 0.00625 | BB3: r | BJ3: Interest | BK3: ='Interest Rate Comparison'!B7 -> 0.0725 | BN3: =BK3/12 -> 0.0060416667 | BO3: r | BW3: Interest | BX3: ='Interest Rate Comparison'!B8 -> 0.07 | CA3: =BX3/12 -> 0.0058333333 | CB3: r
C4: $/sqft Market Estimate | J4: Term | K4: =$L$4*12 -> 360 | L4: ='STR Calculator'!I9 -> 30 | M4: years | N4: =(1+N3)^K4 -> 11.781506 | O4: (1+r)^n | W4: Term | X4: =$L$4*12 -> 360 | Y4: 30 | Z4: years | AA4: =(1+AA3)^X4 -> 10.93573 | AB4: (1+r)^n | AJ4: Term | AK4: =$L$4*12 -> 360 | AL4: 30 | AM4: years | AN4: =(1+AN3)^AK4 -> 10.150514 | AO4: (1+r)^n | AW4: Term | AX4: =$L$4*12 -> 360 | AY4: 30 | AZ4: years | BA4: =(1+BA3)^AX4 -> 9.4215339 | BB4: (1+r)^n | BJ4: Term | BK4: =$L$4*12 -> 360 | BL4: 30 | BM4: years | BN4: =(1+BN3)^BK4 -> 8.744772 | BO4: (1+r)^n | BW4: Term | BX4: =$L$4*12 -> 360 | BY4: 30 | BZ4: years | CA4: =(1+CA3)^BX4 -> 8.1164975 | CB4: (1+r)^n
A5: Original Purchase Price | B5: ='STR Calculator'!B5 -> 800000 | C5: =B5/B3 -> #DIV/0! | D5: sqft | J5: Monthly Payment | W5: Monthly Payment | AJ5: Monthly Payment | AW5: Monthly Payment | BJ5: Monthly Payment | BW5: Monthly Payment
A6: Down Payment | B6: 0.1
A7: Current Loan Balance | B7: =B5-(B5*B6) -> 720000 | C7: as of 11/13/22 | J7: paymentNumber | K7: paymentDate | L7: startingBalance | M7: Monthly Payment | N7: principalPayment | O7: Principle Pay Down | P7: interestPayment | Q7: Interest Percent | R7: cumulativePrincipal | S7: cumulativeInterest | T7: endingBalance | U7: Total Paid End of Loan | W7: paymentNumber | X7: paymentDate | Y7: startingBalance | Z7: Monthly Payment | AA7: principalPayment | AB7: Principle Pay Down | AC7: interestPayment | AD7: Interest Percent | AE7: cumulativePrincipal | AF7: cumulativeInterest | AG7: endingBalance | AH7: Total Paid End of Loan | AJ7: paymentNumber | AK7: paymentDate | AL7: startingBalance | AM7: Monthly Payment | AN7: principalPayment | AO7: Principle Pay Down | AP7: interestPayment | AQ7: Interest Percent | AR7: cumulativePrincipal | AS7: cumulativeInterest | AT7: endingBalance | AU7: Total Paid End of Loan | AW7: paymentNumber | AX7: paymentDate | AY7: startingBalance | AZ7: Monthly Payment | BA7: principalPayment | BB7: Principle Pay Down | BC7: interestPayment | BD7: Interest Percent | BE7: cumulativePrincipal | BF7: cumulativeInterest | BG7: endingBalance | BH7: Total Paid End of Loan | BJ7: paymentNumber | BK7: paymentDate | BL7: startingBalance | BM7: Monthly Payment | BN7: principalPayment | BO7: Principle Pay Down | BP7: interestPayment | BQ7: Interest Percent | BR7: cumulativePrincipal | BS7: cumulativeInterest | BT7: endingBalance | BU7: Total Paid End of Loan | BW7: paymentNumber | BX7: paymentDate | BY7: startingBalance | BZ7: Monthly Payment | CA7: principalPayment | CB7: Principle Pay Down | CC7: interestPayment | CD7: Interest Percent | CE7: cumulativePrincipal | CF7: cumulativeInterest | CG7: endingBalance | CH7: Total Paid End of Loan
A8: Current Equity | B8: =B5-B7 -> 80000 | J8: 1 | K8: 44866 | L8: ='Amoritization Scenario 10% DP'!$B$7 -> 720000 | M8: =$L$8/((($N$4)-1)/($N$3*$N$4)) -> 5409.1195 | N8: =M8-P8 -> 459.11955 | O8: =(N8/L8)*12 -> 0.0076519925 | P8: =L8*($K$3/12) -> 4950 | Q8: =(P8/L8)*12 -> 0.0825 | R8: =N8 -> 459.11955 | S8: =P8 -> 4950 | T8: =L8-N8 -> 719540.88 | U8: =R8+S8 -> 5409.1195 | W8: 1 | X8: 44866 | Y8: ='Amoritization Scenario 10% DP'!$B$7 -> 720000 | Z8: =$Y$8/((($AA$4)-1)/($AA$3*$AA$4)) -> 5283.1049 | AA8: =Z8-AC8 -> 483.10493 | AB8: =(AA8/Y8)*12 -> 0.0080517489 | AC8: =Y8*($X$3/12) -> 4800 | AD8: =(AC8/Y8)*12 -> 0.08 | AE8: =AA8 -> 483.10493 | AF8: =AC8 -> 4800 | AG8: =Y8-AA8 -> 719516.9 | AH8: =AE8+AF8 -> 5283.1049 | AJ8: 1 | AK8: 44866 | AL8: ='Amoritization Scenario 10% DP'!$B$7 -> 720000 | AM8: =$AL$8/((($AN$4)-1)/($AN$3*$AN$4)) -> 5158.1682 | AN8: =AM8-AP8 -> 508.16817 | AO8: =(AN8/AL8)*12 -> 0.0084694695 | AP8: =AL8*($AK$3/12) -> 4650 | AQ8: =(AP8/AL8)*12 -> 0.0775 | AR8: =AN8 -> 508.16817 | AS8: =AP8 -> 4650 | AT8: =AL8-AN8 -> 719491.83 | AU8: =AR8+AS8 -> 5158.1682 | AW8: 1 | AX8: 44866 | AY8: ='Amoritization Scenario 10% DP'!$B$7 -> 720000 | AZ8: =$AY$8/((($BA$4)-1)/($BA$3*$BA$4)) -> 5034.3445 | BA8: =AZ8-BC8 -> 534.34446 | BB8: =(BA8/AY8)*12 -> 0.008905741 | BC8: =AY8*($AX$3/12) -> 4500 | BD8: =(BC8/AY8)*12 -> 0.075 | BE8: =BA8 -> 534.34446 | BF8: =BC8 -> 4500 | BG8: =AY8-BA8 -> 719465.66 | BH8: =BE8+BF8 -> 5034.3445 | BJ8: 1 | BK8: 44866 | BL8: ='Amoritization Scenario 10% DP'!$B$7 -> 720000 | BM8: =$BL$8/((($BN$4)-1)/($BN$3*$BN$4)) -> 4911.6692 | BN8: =BM8-BP8 -> 561.66922 | BO8: =(BN8/BL8)*12 -> 0.0093611536 | BP8: =BL8*($BK$3/12) -> 4350 | BQ8: =(BP8/BL8)*12 -> 0.0725 | BR8: =BN8 -> 561.66922 | BS8: =BP8 -> 4350 | BT8: =BL8-BN8 -> 719438.33 | BU8: =BR8+BS8 -> 4911.6692 | BW8: 1 | BX8: 44866 | BY8: ='Amoritization Scenario 10% DP'!$B$7 -> 720000 | BZ8: =$BY$8/((($CA$4)-1)/($CA$3*$CA$4)) -> 4790.178 | CA8: =BZ8-CC8 -> 590.17797 | CB8: =(CA8/BY8)*12 -> 0.0098362994 | CC8: =BY8*($BX$3/12) -> 4200 | CD8: =(CC8/BY8)*12 -> 0.07 | CE8: =CA8 -> 590.17797 | CF8: =CC8 -> 4200 | CG8: =BY8-CA8 -> 719409.82 | CH8: =CE8+CF8 -> 4790.178
J9: 2 | K9: 44896 | L9: =T8 -> 719540.88 | M9: =$L$8/((($N$4)-1)/($N$3*$N$4)) -> 5409.1195 | N9: =M9-P9 -> 462.276 | O9: =(N9/L9)*12 -> 0.007709516 | P9: =L9*($K$3/12) -> 4946.8436 | Q9: =(P9/L9)*12 -> 0.0825 | R9: =R8+N9 -> 921.39555 | S9: =S8+P9 -> 9896.8436 | T9: =L9-N9 -> 719078.6 | U9: =R9+S9 -> 10818.239 | W9: 2 | X9: 44896 | Y9: =AG8 -> 719516.9 | Z9: =Z8 -> 5283.1049 | AA9: =Z9-AC9 -> 486.32563 | AB9: =(AA9/Y9)*12 -> 0.0081108694 | AC9: =Y9*($X$3/12) -> 4796.7793 | AD9: =(AC9/Y9)*12 -> 0.08 | AE9: =AE8+AA9 -> 969.43056 | AF9: =AF8+AC9 -> 9596.7793 | AG9: =Y9-AA9 -> 719030.57 | AH9: =AE9+AF9 -> 10566.21 | AJ9: 2 | AK9: 44896 | AL9: =AT8 -> 719491.83 | AM9: =AM8 -> 5158.1682 | AN9: =AM9-AP9 -> 511.45009 | AO9: =(AN9/AL9)*12 -> 0.0085301886 | AP9: =AL9*($AK$3/12) -> 4646.7181 | AQ9: =(AP9/AL9)*12 -> 0.0775 | AR9: =AR8+AN9 -> 1019.6183 | AS9: =AS8+AP9 -> 9296.7181 | AT9: =AL9-AN9 -> 718980.38 | AU9: =AR9+AS9 -> 10316.336 | AW9: 2 | AX9: 44896 | AY9: =BG8 -> 719465.66 | AZ9: =AZ8 -> 5034.3445 | BA9: =AZ9-BC9 -> 537.68411 | BB9: =(BA9/AY9)*12 -> 0.0089680575 | BC9: =AY9*($AX$3/12) -> 4496.6603 | BD9: =(BC9/AY9)*12 -> 0.075 | BE9: =BE8+BA9 -> 1072.0286 | BF9: =BF8+BC9 -> 8996.6603 | BG9: =AY9-BA9 -> 718927.97 | BH9: =BE9+BF9 -> 10068.689 | BJ9: 2 | BK9: 44896 | BL9: =BT8 -> 719438.33 | BM9: =BM8 -> 4911.6692 | BN9: =BM9-BP9 -> 565.06263 | BO9: =(BN9/BL9)*12 -> 0.009425063 | BP9: =BL9*($BK$3/12) -> 4346.6066 | BQ9: =(BP9/BL9)*12 -> 0.0725 | BR9: =BR8+BN9 -> 1126.7319 | BS9: =BS8+BP9 -> 8696.6066 | BT9: =BL9-BN9 -> 718873.27 | BU9: =BR9+BS9 -> 9823.3384 | BW9: 2 | BX9: 44896 | BY9: =CG8 -> 719409.82 | BZ9: =BZ8 -> 4790.178 | CA9: =BZ9-CC9 -> 593.62067 | CB9: =(CA9/BY9)*12 -> 0.0099017943 | CC9: =BY9*($BX$3/12) -> 4196.5573 | CD9: =(CC9/BY9)*12 -> 0.07 | CE9: =CE8+CA9 -> 1183.7986 | CF9: =CF8+CC9 -> 8396.5573 | CG9: =BY9-CA9 -> 718816.2 | CH9: =CE9+CF9 -> 9580.3559
A10: Year | B10: ="Cum Interest @ "&K3&"%" -> Cum Interest @ 0.0825% | C10: ="Cum Interest @ "&X3&"%" -> Cum Interest @ 0.08% | D10: ="Cum Interest @ "&AK3&"%" -> Cum Interest @ 0.0775% | E10: ="Cum Interest @ "&AX3&"%" -> Cum Interest @ 0.075% | F10: ="Cum Interest @ "&BK3&"%" -> Cum Interest @ 0.0725% | G10: ="Cum Interest @ "&BX3&"%" -> Cum Interest @ 0.07% | J10: 3 | K10: 44927 | L10: =T9 -> 719078.6 | M10: =$L$8/((($N$4)-1)/($N$3*$N$4)) -> 5409.1195 | N10: =M10-P10 -> 465.45414 | O10: =(N10/L10)*12 -> 0.0077675093 | P10: =L10*($K$3/12) -> 4943.6654 | Q10: =(P10/L10)*12 -> 0.0825 | R10: =R9+N10 -> 1386.8497 | S10: =S9+P10 -> 14840.509 | T10: =L10-N10 -> 718613.15 | U10: =R10+S10 -> 16227.359 | W10: 3 | X10: 44927 | Y10: =AG9 -> 719030.57 | Z10: =Z9 -> 5283.1049 | AA10: =Z10-AC10 -> 489.5678 | AB10: =(AA10/Y10)*12 -> 0.0081704643 | AC10: =Y10*($X$3/12) -> 4793.5371 | AD10: =(AC10/Y10)*12 -> 0.08 | AE10: =AE9+AA10 -> 1458.9984 | AF10: =AF9+AC10 -> 14390.316 | AG10: =Y10-AA10 -> 718541 | AH10: =AE10+AF10 -> 15849.315 | AJ10: 3 | AK10: 44927 | AL10: =AT9 -> 718980.38 | AM10: =AM9 -> 5158.1682 | AN10: =AM10-AP10 -> 514.7532 | AO10: =(AN10/AL10)*12 -> 0.0085913866 | AP10: =AL10*($AK$3/12) -> 4643.415 | AQ10: =(AP10/AL10)*12 -> 0.0775 | AR10: =AR9+AN10 -> 1534.3715 | AS10: =AS9+AP10 -> 13940.133 | AT10: =AL10-AN10 -> 718465.63 | AU10: =AR10+AS10 -> 15474.505 | AW10: 3 | AX10: 44927 | AY10: =BG9 -> 718927.97 | AZ10: =AZ9 -> 5034.3445 | BA10: =AZ10-BC10 -> 541.04464 | BB10: =(BA10/AY10)*12 -> 0.009030857 | BC10: =AY10*($AX$3/12) -> 4493.2998 | BD10: =(BC10/AY10)*12 -> 0.075 | BE10: =BE9+BA10 -> 1613.0732 | BF10: =BF9+BC10 -> 13489.96 | BG10: =AY10-BA10 -> 718386.93 | BH10: =BE10+BF10 -> 15103.033 | BJ10: 3 | BK10: 44927 | BL10: =BT9 -> 718873.27 | BM10: =BM9 -> 4911.6692 | BN10: =BM10-BP10 -> 568.47655 | BO10: =(BN10/BL10)*12 -> 0.0094894594 | BP10: =BL10*($BK$3/12) -> 4343.1927 | BQ10: =(BP10/BL10)*12 -> 0.0725 | BR10: =BR9+BN10 -> 1695.2084 | BS10: =BS9+BP10 -> 13039.799 | BT10: =BL10-BN10 -> 718304.79 | BU10: =BR10+BS10 -> 14735.008 | BW10: 3 | BX10: 44927 | BY10: =CG9 -> 718816.2 | BZ10: =BZ9 -> 4790.178 | CA10: =BZ10-CC10 -> 597.08346 | CB10: =(CA10/BY10)*12 -> 0.0099677796 | CC10: =BY10*($BX$3/12) -> 4193.0945 | CD10: =(CC10/BY10)*12 -> 0.07 | CE10: =CE9+CA10 -> 1780.8821 | CF10: =CF9+CC10 -> 12589.652 | CG10: =BY10-CA10 -> 718219.12 | CH10: =CE10+CF10 -> 14370.534
A11: 1 | B11: =VLOOKUP($A$11*12,$J$7:$U$367,10) -> 59186.826 | C11: =VLOOKUP(A11*12,$W$7:$AH$367,10) -> 57382.639 | D11: =VLOOKUP(A11*12,$AJ$7:$AU$367,10) -> 55578.662 | E11: =VLOOKUP(A11*12,$AW$7:$BH$367,10) -> 53774.926 | F11: =VLOOKUP(A11*12,$BJ$7:$BU$367,10) -> 51971.462 | G11: =VLOOKUP(A11*12,$BW$7:$CH$367,10) -> 50168.305 | J11: 4 | K11: 44958 | L11: =T10 -> 718613.15 | M11: =$L$8/((($N$4)-1)/($N$3*$N$4)) -> 5409.1195 | N11: =M11-P11 -> 468.65414 | O11: =(N11/L11)*12 -> 0.0078259766 | P11: =L11*($K$3/12) -> 4940.4654 | Q11: =(P11/L11)*12 -> 0.0825 | R11: =R10+N11 -> 1855.5038 | S11: =S10+P11 -> 19780.974 | T11: =L11-N11 -> 718144.5 | U11: =R11+S11 -> 21636.478 | W11: 4 | X11: 44958 | Y11: =AG10 -> 718541 | Z11: =Z10 -> 5283.1049 | AA11: =Z11-AC11 -> 492.83159 | AB11: =(AA11/Y11)*12 -> 0.008230538 | AC11: =Y11*($X$3/12) -> 4790.2733 | AD11: =(AC11/Y11)*12 -> 0.08 | AE11: =AE10+AA11 -> 1951.83 | AF11: =AF10+AC11 -> 19180.59 | AG11: =Y11-AA11 -> 718048.17 | AH11: =AE11+AF11 -> 21132.42 | AJ11: 4 | AK11: 44958 | AL11: =AT10 -> 718465.63 | AM11: =AM10 -> 5158.1682 | AN11: =AM11-AP11 -> 518.07765 | AO11: =(AN11/AL11)*12 -> 0.0086530678 | AP11: =AL11*($AK$3/12) -> 4640.0905 | AQ11: =(AP11/AL11)*12 -> 0.0775 | AR11: =AR10+AN11 -> 2052.4491 | AS11: =AS10+AP11 -> 18580.224 | AT11: =AL11-AN11 -> 717947.55 | AU11: =AR11+AS11 -> 20632.673 | AW11: 4 | AX11: 44958 | AY11: =BG10 -> 718386.93 | AZ11: =AZ10 -> 5034.3445 | BA11: =AZ11-BC11 -> 544.42617 | BB11: =(BA11/AY11)*12 -> 0.0090941438 | BC11: =AY11*($AX$3/12) -> 4489.9183 | BD11: =(BC11/AY11)*12 -> 0.075 | BE11: =BE10+BA11 -> 2157.4994 | BF11: =BF10+BC11 -> 17979.878 | BG11: =AY11-BA11 -> 717842.5 | BH11: =BE11+BF11 -> 20137.378 | BJ11: 4 | BK11: 44958 | BL11: =BT10 -> 718304.79 | BM11: =BM10 -> 4911.6692 | BN11: =BM11-BP11 -> 571.9111 | BO11: =(BN11/BL11)*12 -> 0.009554347 | BP11: =BL11*($BK$3/12) -> 4339.7581 | BQ11: =(BP11/BL11)*12 -> 0.0725 | BR11: =BR10+BN11 -> 2267.1195 | BS11: =BS10+BP11 -> 17379.557 | BT11: =BL11-BN11 -> 717732.88 | BU11: =BR11+BS11 -> 19646.677 | BW11: 4 | BX11: 44958 | BY11: =CG10 -> 718219.12 | BZ11: =BZ10 -> 4790.178 | CA11: =BZ11-CC11 -> 600.56644 | CB11: =(CA11/BY11)*12 -> 0.01003426 | CC11: =BY11*($BX$3/12) -> 4189.6115 | CD11: =(CC11/BY11)*12 -> 0.07 | CE11: =CE10+CA11 -> 2381.4485 | CF11: =CF10+CC11 -> 16779.263 | CG11: =BY11-CA11 -> 717618.55 | CH11: =CE11+CF11 -> 19160.712
A12: =A11+1 -> 2 | B12: =VLOOKUP(A12*12,$J$7:$U$367,10) -> 117883.27 | C12: =VLOOKUP(A12*12,$W$7:$AH$367,10) -> 114266.07 | D12: =VLOOKUP(A12*12,$AJ$7:$AU$367,10) -> 110649.8 | E12: =VLOOKUP(A12*12,$AW$7:$BH$367,10) -> 107034.59 | F12: =VLOOKUP(A12*12,$BJ$7:$BU$367,10) -> 103420.57 | G12: =VLOOKUP(A12*12,$BW$7:$CH$367,10) -> 99807.892 | J12: 5 | K12: 44986 | L12: =T11 -> 718144.5 | M12: =$L$8/((($N$4)-1)/($N$3*$N$4)) -> 5409.1195 | N12: =M12-P12 -> 471.87614 | O12: =(N12/L12)*12 -> 0.0078849224 | P12: =L12*($K$3/12) -> 4937.2434 | Q12: =(P12/L12)*12 -> 0.0825 | R12: =R11+N12 -> 2327.38 | S12: =S11+P12 -> 24718.218 | T12: =L12-N12 -> 717672.62 | U12: =R12+S12 -> 27045.598 | W12: 5 | X12: 44986 | Y12: =AG11 -> 718048.17 | Z12: =Z11 -> 5283.1049 | AA12: =Z12-AC12 -> 496.11713 | AB12: =(AA12/Y12)*12 -> 0.008291095 | AC12: =Y12*($X$3/12) -> 4786.9878 | AD12: =(AC12/Y12)*12 -> 0.08 | AE12: =AE11+AA12 -> 2447.9471 | AF12: =AF11+AC12 -> 23967.578 | AG12: =Y12-AA12 -> 717552.05 | AH12: =AE12+AF12 -> 26415.525 | AJ12: 5 | AK12: 44986 | AL12: =AT11 -> 717947.55 | AM12: =AM11 -> 5158.1682 | AN12: =AM12-AP12 -> 521.42357 | AO12: =(AN12/AL12)*12 -> 0.0087152367 | AP12: =AL12*($AK$3/12) -> 4636.7446 | AQ12: =(AP12/AL12)*12 -> 0.0775 | AR12: =AR11+AN12 -> 2573.8727 | AS12: =AS11+AP12 -> 23216.968 | AT12: =AL12-AN12 -> 717426.13 | AU12: =AR12+AS12 -> 25790.841 | AW12: 5 | AX12: 44986 | AY12: =BG11 -> 717842.5 | AZ12: =AZ11 -> 5034.3445 | BA12: =AZ12-BC12 -> 547.82883 | BB12: =(BA12/AY12)*12 -> 0.0091579225 | BC12: =AY12*($AX$3/12) -> 4486.5156 | BD12: =(BC12/AY12)*12 -> 0.075 | BE12: =BE11+BA12 -> 2705.3282 | BF12: =BF11+BC12 -> 22466.394 | BG12: =AY12-BA12 -> 717294.67 | BH12: =BE12+BF12 -> 25171.722 | BJ12: 5 | BK12: 44986 | BL12: =BT11 -> 717732.88 | BM12: =BM11 -> 4911.6692 | BN12: =BM12-BP12 -> 575.3664 | BO12: =(BN12/BL12)*12 -> 0.0096197303 | BP12: =BL12*($BK$3/12) -> 4336.3028 | BQ12: =(BP12/BL12)*12 -> 0.0725 | BR12: =BR11+BN12 -> 2842.4859 | BS12: =BS11+BP12 -> 21715.86 | BT12: =BL12-BN12 -> 717157.51 | BU12: =BR12+BS12 -> 24558.346 | BW12: 5 | BX12: 44986 | BY12: =CG11 -> 717618.55 | BZ12: =BZ11 -> 4790.178 | CA12: =BZ12-CC12 -> 604.06975 | CB12: =(CA12/BY12)*12 -> 0.01010124 | CC12: =BY12*($BX$3/12) -> 4186.1082 | CD12: =(CC12/BY12)*12 -> 0.07 | CE12: =CE11+CA12 -> 2985.5183 | CF12: =CF11+CC12 -> 20965.372 | CG12: =BY12-CA12 -> 717014.48 | CH12: =CE12+CF12 -> 23950.89
A13: =A12+1 -> 3 | B13: =VLOOKUP(A13*12,$J$7:$U$367,10) -> 176047.31 | C13: =VLOOKUP(A13*12,$W$7:$AH$367,10) -> 170608.85 | D13: =VLOOKUP(A13*12,$AJ$7:$AU$367,10) -> 165172.65 | E13: =VLOOKUP(A13*12,$AW$7:$BH$367,10) -> 159738.98 | F13: =VLOOKUP(A13*12,$BJ$7:$BU$367,10) -> 154308.18 | G13: =VLOOKUP(A13*12,$BW$7:$CH$367,10) -> 148880.54 | J13: 6 | K13: 45017 | L13: =T12 -> 717672.62 | M13: =$L$8/((($N$4)-1)/($N$3*$N$4)) -> 5409.1195 | N13: =M13-P13 -> 475.12029 | O13: =(N13/L13)*12 -> 0.0079443513 | P13: =L13*($K$3/12) -> 4933.9993 | Q13: =(P13/L13)*12 -> 0.0825 | R13: =R12+N13 -> 2802.5003 | S13: =S12+P13 -> 29652.217 | T13: =L13-N13 -> 717197.5 | U13: =R13+S13 -> 32454.717 | W13: 6 | X13: 45017 | Y13: =AG12 -> 717552.05 | Z13: =Z12 -> 5283.1049 | AA13: =Z13-AC13 -> 499.42458 | AB13: =(AA13/Y13)*12 -> 0.0083521396 | AC13: =Y13*($X$3/12) -> 4783.6804 | AD13: =(AC13/Y13)*12 -> 0.08 | AE13: =AE12+AA13 -> 2947.3717 | AF13: =AF12+AC13 -> 28751.258 | AG13: =Y13-AA13 -> 717052.63 | AH13: =AE13+AF13 -> 31698.63 | AJ13: 6 | AK13: 45017 | AL13: =AT12 -> 717426.13 | AM13: =AM12 -> 5158.1682 | AN13: =AM13-AP13 -> 524.7911 | AO13: =(AN13/AL13)*12 -> 0.0087778977 | AP13: =AL13*($AK$3/12) -> 4633.3771 | AQ13: =(AP13/AL13)*12 -> 0.0775 | AR13: =AR12+AN13 -> 3098.6638 | AS13: =AS12+AP13 -> 27850.345 | AT13: =AL13-AN13 -> 716901.34 | AU13: =AR13+AS13 -> 30949.009 | AW13: 6 | AX13: 45017 | AY13: =BG12 -> 717294.67 | AZ13: =AZ12 -> 5034.3445 | BA13: =AZ13-BC13 -> 551.25276 | BB13: =(BA13/AY13)*12 -> 0.0092221975 | BC13: =AY13*($AX$3/12) -> 4483.0917 | BD13: =(BC13/AY13)*12 -> 0.075 | BE13: =BE12+BA13 -> 3256.581 | BF13: =BF12+BC13 -> 26949.486 | BG13: =AY13-BA13 -> 716743.42 | BH13: =BE13+BF13 -> 30206.067 | BJ13: 6 | BK13: 45017 | BL13: =BT12 -> 717157.51 | BM13: =BM12 -> 4911.6692 | BN13: =BM13-BP13 -> 578.84257 | BO13: =(BN13/BL13)*12 -> 0.009685614 | BP13: =BL13*($BK$3/12) -> 4332.8266 | BQ13: =(BP13/BL13)*12 -> 0.0725 | BR13: =BR12+BN13 -> 3421.3285 | BS13: =BS12+BP13 -> 26048.687 | BT13: =BL13-BN13 -> 716578.67 | BU13: =BR13+BS13 -> 29470.015 | BW13: 6 | BX13: 45017 | BY13: =CG12 -> 717014.48 | BZ13: =BZ12 -> 4790.178 | CA13: =BZ13-CC13 -> 607.59349 | CB13: =(CA13/BY13)*12 -> 0.010168723 | CC13: =BY13*($BX$3/12) -> 4182.5845 | CD13: =(CC13/BY13)*12 -> 0.07 | CE13: =CE12+CA13 -> 3593.1118 | CF13: =CF12+CC13 -> 25147.956 | CG13: =BY13-CA13 -> 716406.89 | CH13: =CE13+CF13 -> 28741.068
A14: =A13+1 -> 4 | B14: =VLOOKUP(A14*12,$J$7:$U$367,10) -> 233633.32 | C14: =VLOOKUP(A14*12,$W$7:$AH$367,10) -> 226366.11 | D14: =VLOOKUP(A14*12,$AJ$7:$AU$367,10) -> 219103.17 | E14: =VLOOKUP(A14*12,$AW$7:$BH$367,10) -> 211845.01 | F14: =VLOOKUP(A14*12,$BJ$7:$BU$367,10) -> 204592.18 | G14: =VLOOKUP(A14*12,$BW$7:$CH$367,10) -> 197345.27 | J14: 7 | K14: 45047 | L14: =T13 -> 717197.5 | M14: =$L$8/((($N$4)-1)/($N$3*$N$4)) -> 5409.1195 | N14: =M14-P14 -> 478.38674 | O14: =(N14/L14)*12 -> 0.0080042678 | P14: =L14*($K$3/12) -> 4930.7328 | Q14: =(P14/L14)*12 -> 0.0825 | R14: =R13+N14 -> 3280.887 | S14: =S13+P14 -> 34582.95 | T14: =L14-N14 -> 716719.11 | U14: =R14+S14 -> 37863.837 | W14: 7 | X14: 45047 | Y14: =AG13 -> 717052.63 | Z14: =Z13 -> 5283.1049 | AA14: =Z14-AC14 -> 502.75408 | AB14: =(AA14/Y14)*12 -> 0.0084136766 | AC14: =Y14*($X$3/12) -> 4780.3509 | AD14: =(AC14/Y14)*12 -> 0.08 | AE14: =AE13+AA14 -> 3450.1257 | AF14: =AF13+AC14 -> 33531.609 | AG14: =Y14-AA14 -> 716549.87 | AH14: =AE14+AF14 -> 36981.735 | AJ14: 7 | AK14: 45047 | AL14: =AT13 -> 716901.34 | AM14: =AM13 -> 5158.1682 | AN14: =AM14-AP14 -> 528.18037 | AO14: =(AN14/AL14)*12 -> 0.0088410554 | AP14: =AL14*($AK$3/12) -> 4629.9878 | AQ14: =(AP14/AL14)*12 -> 0.0775 | AR14: =AR13+AN14 -> 3626.8441 | AS14: =AS13+AP14 -> 32480.333 | AT14: =AL14-AN14 -> 716373.16 | AU14: =AR14+AS14 -> 36107.177 | AW14: 7 | AX14: 45047 | AY14: =BG13 -> 716743.42 | AZ14: =AZ13 -> 5034.3445 | BA14: =AZ14-BC14 -> 554.69809 | BB14: =(BA14/AY14)*12 -> 0.0092869735 | BC14: =AY14*($AX$3/12) -> 4479.6464 | BD14: =(BC14/AY14)*12 -> 0.075 | BE14: =BE13+BA14 -> 3811.2791 | BF14: =BF13+BC14 -> 31429.132 | BG14: =AY14-BA14 -> 716188.72 | BH14: =BE14+BF14 -> 35240.411 | BJ14: 7 | BK14: 45047 | BL14: =BT13 -> 716578.67 | BM14: =BM13 -> 4911.6692 | BN14: =BM14-BP14 -> 582.33974 | BO14: =(BN14/BL14)*12 -> 0.0097520024 | BP14: =BL14*($BK$3/12) -> 4329.3295 | BQ14: =(BP14/BL14)*12 -> 0.0725 | BR14: =BR13+BN14 -> 4003.6682 | BS14: =BS13+BP14 -> 30378.016 | BT14: =BL14-BN14 -> 715996.33 | BU14: =BR14+BS14 -> 34381.685 | BW14: 7 | BX14: 45047 | BY14: =CG13 -> 716406.89 | BZ14: =BZ13 -> 4790.178 | CA14: =BZ14-CC14 -> 611.13778 | CB14: =(CA14/BY14)*12 -> 0.010236715 | CC14: =BY14*($BX$3/12) -> 4179.0402 | CD14: =(CC14/BY14)*12 -> 0.07 | CE14: =CE13+CA14 -> 4204.2496 | CF14: =CF13+CC14 -> 29326.996 | CG14: =BY14-CA14 -> 715795.75 | CH14: =CE14+CF14 -> 33531.246
A15: =A14+1 -> 5 | B15: =VLOOKUP(A15*12,$J$7:$U$367,10) -> 290591.77 | C15: =VLOOKUP(A15*12,$W$7:$AH$367,10) -> 281489.26 | D15: =VLOOKUP(A15*12,$AJ$7:$AU$367,10) -> 272393.8 | E15: =VLOOKUP(A15*12,$AW$7:$BH$367,10) -> 263306.21 | F15: =VLOOKUP(A15*12,$BJ$7:$BU$367,10) -> 254227.35 | G15: =VLOOKUP(A15*12,$BW$7:$CH$367,10) -> 245158.12 | J15: 8 | K15: 45078 | L15: =T14 -> 716719.11 | M15: =$L$8/((($N$4)-1)/($N$3*$N$4)) -> 5409.1195 | N15: =M15-P15 -> 481.67565 | O15: =(N15/L15)*12 -> 0.0080646765 | P15: =L15*($K$3/12) -> 4927.4439 | Q15: =(P15/L15)*12 -> 0.0825 | R15: =R14+N15 -> 3762.5626 | S15: =S14+P15 -> 39510.394 | T15: =L15-N15 -> 716237.44 | U15: =R15+S15 -> 43272.956 | W15: 8 | X15: 45078 | Y15: =AG14 -> 716549.87 | Z15: =Z14 -> 5283.1049 | AA15: =Z15-AC15 -> 506.10577 | AB15: =(AA15/Y15)*12 -> 0.0084757104 | AC15: =Y15*($X$3/12) -> 4776.9992 | AD15: =(AC15/Y15)*12 -> 0.08 | AE15: =AE14+AA15 -> 3956.2315 | AF15: =AF14+AC15 -> 38308.608 | AG15: =Y15-AA15 -> 716043.77 | AH15: =AE15+AF15 -> 42264.839 | AJ15: 8 | AK15: 45078 | AL15: =AT14 -> 716373.16 | AM15: =AM14 -> 5158.1682 | AN15: =AM15-AP15 -> 531.59154 | AO15: =(AN15/AL15)*12 -> 0.0089047145 | AP15: =AL15*($AK$3/12) -> 4626.5766 | AQ15: =(AP15/AL15)*12 -> 0.0775 | AR15: =AR14+AN15 -> 4158.4357 | AS15: =AS14+AP15 -> 37106.91 | AT15: =AL15-AN15 -> 715841.56 | AU15: =AR15+AS15 -> 41265.345 | AW15: 8 | AX15: 45078 | AY15: =BG14 -> 716188.72 | AZ15: =AZ14 -> 5034.3445 | BA15: =AZ15-BC15 -> 558.16496 | BB15: =(BA15/AY15)*12 -> 0.0093522549 | BC15: =AY15*($AX$3/12) -> 4476.1795 | BD15: =(BC15/AY15)*12 -> 0.075 | BE15: =BE14+BA15 -> 4369.444 | BF15: =BF14+BC15 -> 35905.312 | BG15: =AY15-BA15 -> 715630.56 | BH15: =BE15+BF15 -> 40274.756 | BJ15: 8 | BK15: 45078 | BL15: =BT14 -> 715996.33 | BM15: =BM14 -> 4911.6692 | BN15: =BM15-BP15 -> 585.85805 | BO15: =(BN15/BL15)*12 -> 0.0098189002 | BP15: =BL15*($BK$3/12) -> 4325.8112 | BQ15: =(BP15/BL15)*12 -> 0.0725 | BR15: =BR14+BN15 -> 4589.5263 | BS15: =BS14+BP15 -> 34703.827 | BT15: =BL15-BN15 -> 715410.47 | BU15: =BR15+BS15 -> 39293.354 | BW15: 8 | BX15: 45078 | BY15: =CG14 -> 715795.75 | BZ15: =BZ14 -> 4790.178 | CA15: =BZ15-CC15 -> 614.70275 | CB15: =(CA15/BY15)*12 -> 0.010305221 | CC15: =BY15*($BX$3/12) -> 4175.4752 | CD15: =(CC15/BY15)*12 -> 0.07 | CE15: =CE14+CA15 -> 4818.9523 | CF15: =CF14+CC15 -> 33502.471 | CG15: =BY15-CA15 -> 715181.05 | CH15: =CE15+CF15 -> 38321.424
