Workbook
Name If: #REF!
Name If: #REF!

Sheet Calculators
A3: Year | C3: Annual ROI | G3: Year | I3: Annual ROI | S3: IRR | T3: =XIRR(T4:T10,R4:R10) -> 0.21632629
A4: 0 | B4: 100000 | G4: 0 | H4: 100000 | M4: Present Value=Future Value /( 1+i)^n | R4: 45292 | S4: Initial Investment | T4: -8500000
A5: =A4+1 -> 1 | B5: 110000 | C5: =(B5/B4)-1 -> 0.1 | G5: =G4+1 -> 1 | H5: 110000 | I5: =(H5/H4)-1 -> 0.1 | M5: interest | N5: 0.08 | R5: =R4+365 -> 45657 | S5: Year 1 Cashflow | T5: =-$T$4*$U$5 -> 1360000 | U5: 0.16 | V5: Cash On Cash
A6: =A5+1 -> 2 | B6: 105000 | C6: =(B6/B5)-1 -> -0.045454545 | G6: =G5+1 -> 2 | H6: 105000 | I6: =(H6/H5)-1 -> -0.045454545 | M6: time (yrs) | N6: 5 | O6: =N6*12 -> 60 | R6: =R5+365 -> 46022 | S6: Year 2 Cashflow | T6: =-$T$4*$U$5 -> 1360000
A7: =A6+1 -> 3 | B7: 120000 | C7: =(B7/B6)-1 -> 0.14285714 | G7: =G6+1 -> 3 | H7: 120000 | I7: =(H7/H6)-1 -> 0.14285714 | R7: =R6+365 -> 46387 | S7: Year 3 Cashflow | T7: =-$T$4*$U$5 -> 1360000
A8: =A7+1 -> 4 | B8: =B7+5000 -> 125000 | C8: =(B8/B7)-1 -> 0.041666667 | G8: =G7+1 -> 4 | H8: =H7+5000 -> 125000 | I8: =(H8/H7)-1 -> 0.041666667 | R8: =R7+365 -> 46752 | S8: Year 4 Cashflow | T8: =-$T$4*$U$5 -> 1360000
A9: =A8+1 -> 5 | B9: =B8+5000 -> 130000 | C9: =(B9/B8)-1 -> 0.04 | G9: =G8+1 -> 5 | H9: =H8+5000 -> 130000 | I9: =(H9/H8)-1 -> 0.04 | R9: =R8+365 -> 47117 | S9: Year 5 Cashflow | T9: =-$T$4*$U$5 -> 1360000
A10: =A9+1 -> 6 | B10: =B9+5000 -> 135000 | C10: =(B10/B9)-1 -> 0.038461538 | R10: =R9+365 -> 47482 | S10: 6 | T10: =-T4*(1+U10)^S10 -> 14813534 | U10: 0.097 | V10: Assumed Appreciation
A11: =A10+1 -> 7 | B11: =B10+5000 -> 140000 | C11: =(B11/B10)-1 -> 0.037037037 | I11: =(H9-H4)/H4 -> 0.3 | J11: ROI
A12: =A11+1 -> 8 | B12: =B11+5000 -> 145000 | C12: =(B12/B11)-1 -> 0.035714286 | I12: =SUM(I5:I9)/COUNT(I5:I9) -> 0.055813853 | J12: AAR
A13: =A12+1 -> 9 | B13: =B12+5000 -> 150000 | C13: =(B13/B12)-1 -> 0.034482759 | I13: =(H9/H4)^(1/COUNT(I4:I9))-1 -> 0.053873952 | J13: CAGR | M13: 0.105 | N13: projected Cash On Cash Return
A14: =A13+1 -> 10 | B14: =B13+5000 -> 155000 | C14: =(B14/B13)-1 -> 0.033333333 | I14: =H9/H4 -> 1.3 | J14: Equity Multiplier | M14: 8500000 | N14: initial investment
M15: =O15*12 -> 60 | N15: hold period | O15: 5
C16: =(B14-B4)/B4 -> 0.55 | D16: ROI
C17: =SUM(C5:C14)/COUNT(C5:C14) -> 0.045809822 | D17: AAR | M17: Future | N17: =M14*(1+M13/12)^(M15) -> 14336125 | O17: =N17/M14 -> 1.686603 | P17: Equity Multiple
C18: =(B14/B4)^(1/COUNT(C4:C14))-1 -> 0.044800014 | D18: CAGR | M18: CAGR | N18: =(N17/M14)^(1/(O15*4))-1 -> 0.026480357
C19: =B14/B4 -> 1.55 | D19: Equity Multiplier

Sheet STR Calculator
H1: Heloc Down Payment | I1: 0.0825
A2: 915 Sanctuary Shores Way - 3bd / 4bath - 3240 sqft | B2: 3240 | C2: sqft | D2: =A3/B2 -> 231.48148 | E2: per sqft | H2: Heloc Loan Terms | I2: 20 | J2: yrs
A3: =B5 -> 750000 | B3: asking price | H3: HELOC Amount | I3: =SUM(B7+B6-C5-C4) -> 20000
C4: 5000 | D4: earnest money | H4: HELOC P&I Payment | I4: =-PMT($I$1/12,$I$2*12,I3) -> 170.41313 | J4: =I4*12 -> 2044.9576 | L4: IRR | M4: =IRR(M5:M11) -> 0.033020744
A5: Purchase Price | B5: 750000 | C5: 50000 | D5: cash | H5: HELOC Principle Payment | I5: =-PPMT($I$1/12,1,$I$2*12,I3) -> 32.91313 | J5: =I5*12 -> 394.95757 | L5: Initial Investment | M5: =-B5 -> -750000
A6: Closing Costs (4%) | B6: 0 | C6: $B$5*0.04 | H6: HELOC Interest Only Payment | I6: =-IPMT($I$1/12,1,$I$2*12,I3) -> 137.5 | J6: =I6*12 -> 1650 | L6: Year 1 Cashflow | M6: ='STR 10 Year'!B39 -> 9987.2708
A7: Down Payment | B7: =B5*C7 -> 75000 | C7: 0.1 | D7: downpayment | L7: Year 2 Cashflow | M7: ='STR 10 Year'!C39 -> 11253.271
A8: Total Loan Amount | B8: =B5-B7 -> 675000 | H8: Conventional Loan Interest Rate | I8: =IF(C7=0.1,0.08062,0.0775) -> 0.08062 | J8: IF(C7=0.1,0.08062,0.0775) | L8: Year 3 Cashflow | M8: ='STR 10 Year'!D39 -> 12225.871
H9: Loan Term | I9: 30 | J9: yrs | L9: Year 4 Cashflow | M9: ='STR 10 Year'!E39 -> 13205.019
H10: Monthly Payment on Purchase Price | I10: =-PMT($I$8/12,$I$9*12,$B$8) -> 4982.1163 | L10: Year 5 Cashflow | M10: ='STR 10 Year'!F39 -> 14190.658
A11: All In Price (Purchase+Repairs) | B11: =SUM(B5) -> 750000 | H11: Monthly Interest Payment on Purchase Price | I11: =-IPMT($I$8/12,1,$I$9*12,$B$8) -> 4534.875 | L11: 6 | M11: =$B$5*(1+0.02)^L11 -> 844621.81 | N11: assumes 2%/yr appreciation
A12: Estimated ARV (After Repair Value) | B12: =B5 -> 750000 | H12: Monthly Principle Payment on Purchase Price | I12: =-PPMT($I$8/12,1,$I$9*12,$B$8) -> 447.24132 | J12: =I12*12 -> 5366.8959
B14: Nightly | C14: Monthly | D14: Annually | H14: Financials
A15: Average Rent | B15: 300 | C15: =B15*30.5 -> 9150 | D15: =C15*12 -> 109800 | H15: Cash On Cash Return (CoC) | I15: =C48/SUM($B$6:$B$7) -> 0.13316361
A16: Occupancy Rate | B16: 1 | C16: =-C15*(1-B16) -> 0 | D16: =C16*12 -> 0 | H16: ROE (Return on Equity) | I16: =C48/B7 -> 0.13316361
A17: Additional Income (Laundry/Storage etc) | C17: 0 | D17: =C17*12 -> 0 | H17: AAR
H18: Mortgage Pay Down yr 1 | I18: =PPMT($I$8/12,1,$I$9*12,$B$8)*12 -> -5366.8959
A19: Calculated Gross Revenue | C19: =SUM(C15:C17) -> 9150 | D19: =C19*12 -> 109800 | H19: Tax Savings at 25% | I19: =C48*0.25 -> 2496.8177
H21: Rules of Thumb
A22: Estimated Expenses | B22: Monthly | C22: Annually | H22: 50% Rule
A23: Management Fees | B23: =C15*D23 -> 0 | C23: =B23*12 -> 0 | D23: 0 | E23: =IF(D23=0,1,0) -> 1 | H23: 2% Rule | I23: =$C$15/$B$5 -> 0.0122
A24: Subscriptions (AirDnA/Pricelabs/Guesty) | B24: 50 | C24: =B24*12 -> 600 | H24: DSCR | I24: =B44/(B46+B45+B47) -> 1.1535667
A25: AirBnB / VRBO Fee (3% of nightly) | B25: 0 | C25: =B25*12 -> 0
A26: Property Taxes / Year | B26: 200 | C26: =B26*12 -> 2400 | D26: =C26/B5 -> 0.0032
A27: Insurance / Year | B27: 200 | C27: =B27*12 -> 2400 | D27: =C27/B5 -> 0.0032
A28: Cleaners (per stay, average 6/month) - Trash included. Soap/Toilet Paper/Detergent etc. | B28: =D28*6 -> 1500 | C28: =B28*12 -> 18000 | D28: 250 | H28: Emergency Fund Needed (6 months) | I28: =B42*$J$28+SUM(B45:B46)*$J$28 -> 48106.365 | J28: 6 | K28: months
A29: Handyman | B29: 250 | C29: =B29*12 -> 3000 | I29: =I28/2 -> 24053.182 | J29: =J28/2 -> 3 | K29: months
A30: HOA / year | B30: 100 | C30: =B30*12 -> 1200 | D30: =C30/B5 -> 0.0016
A31: Electricity | B31: 250 | C31: =B31*12 -> 3000
A32: Nat Gas(~$2k for large tank, for ~1.5yrs) | B32: =2000/18 -> 111.11111 | C32: =B32*12 -> 1333.3333
A33: WIFI / Cable | B33: 150 | C33: =B33*12 -> 1800
A34: Pool Service (bi-weekly = 2xmonth) | B34: 0 | C34: =B34*12 -> 0
A35: Water/Sewer ($0 for well/septic) | B35: 0 | C35: =B35*12 -> 0
A36: Building Maintenance | B36: =C36/12 -> 0 | C36: =B5*D36 -> 0 | D36: 0
A37: Capex (Future Repairs) | B37: =C37/12 -> 0 | C37: =D37*B5 -> 0 | D37: 0
A38: Grounds Cleanup/Services Maintenance/Snow Removal | B38: 0 | C38: =B38*12 -> 0 | H38: Ask cleaners what is included vs not - Linens/soaps/shampoos/coffee/creamer
A39: City Permit Fees | B39: 25 | C39: =B39*12 -> 300
A40: Incidentals (Coffee/Creamer etc) | B40: 25 | C40: =B40*12 -> 300
A41: Umbrella Insurance (Allstate Anchorage) | B41: 37 | C41: =B41*12 -> 444
A42: Totals | B42: =SUM(B23:B41) -> 2898.1111 | C42: =SUM(C23:C41) -> 34777.333
...

Sheet Interest Rate Comparison
A1: Purchase Price | C1: 0.1 | D1: 0.15 | E1: 0.2 | F1: 0.25 | H1: 5% Increase in Down Payment | I1: Time to recoup
A2: ='STR Calculator'!B5 -> 750000 | B2: Down Payment | C2: =$A$2*C1 -> 75000 | D2: =$A$2*D1 -> 112500 | E2: =$A$2*E1 -> 150000 | F2: =$A$2*F1 -> 187500 | H2: =D2-C2 -> 37500
A3: 30 | B3: 0.0825 | C3: =PMT($B$3/12,$A$3*12,($A$2-C2)) -> -5071.0496 | D3: =PMT($B$3/12,$A$3*12,($A$2-D2)) -> -4789.3246 | E3: =PMT($B$3/12,$A$3*12,($A$2-E2)) -> -4507.5996 | F3: =PMT($B$3/12,$A$3*12,($A$2-F2)) -> -4225.8746 | G3: =B3 -> 0.0825 | H3: =D3-C3 -> 281.72498 | I3: =$H$2/H3/12 -> 11.092378
B4: 0.08 | C4: =PMT($B$4/12,$A$3*12,($A$2-C2)) -> -4952.9109 | D4: =PMT($B$4/12,$A$3*12,($A$2-D2)) -> -4677.7492 | E4: =PMT($B$4/12,$A$3*12,($A$2-E2)) -> -4402.5874 | F4: =PMT($B$4/12,$A$3*12,($A$2-F2)) -> -4127.4257 | G4: =B4 -> 0.08 | H4: =D4-C4 -> 275.16172 | I4: =$H$2/H4/12 -> 11.356958
B5: 0.0775 | C5: =PMT($B$5/12,$A$3*12,($A$2-C2)) -> -4835.7827 | D5: =PMT($B$5/12,$A$3*12,($A$2-D2)) -> -4567.1281 | E5: =PMT($B$5/12,$A$3*12,($A$2-E2)) -> -4298.4735 | F5: =PMT($B$5/12,$A$3*12,($A$2-F2)) -> -4029.8189 | G5: =B5 -> 0.0775 | H5: =D5-C5 -> 268.65459 | I5: =$H$2/H5/12 -> 11.632036
B6: 0.075 | C6: =PMT($B$6/12,$A$3*12,($A$2-C2)) -> -4719.6979 | D6: =PMT($B$6/12,$A$3*12,($A$2-D2)) -> -4457.4925 | E6: =PMT($B$6/12,$A$3*12,($A$2-E2)) -> -4195.2871 | F6: =PMT($B$6/12,$A$3*12,($A$2-F2)) -> -3933.0816 | G6: =B6 -> 0.075 | H6: =D6-C6 -> 262.20544 | I6: =$H$2/H6/12 -> 11.918136
B7: 0.0725 | C7: =PMT($B$7/12,$A$3*12,($A$2-C2)) -> -4604.6899 | D7: =PMT($B$7/12,$A$3*12,($A$2-D2)) -> -4348.8738 | E7: =PMT($B$7/12,$A$3*12,($A$2-E2)) -> -4093.0577 | F7: =PMT($B$7/12,$A$3*12,($A$2-F2)) -> -3837.2416 | G7: =B7 -> 0.0725 | H7: =D7-C7 -> 255.81611 | I7: =$H$2/H7/12 -> 12.215806
B8: 0.07 | C8: =PMT($B$8/12,$A$3*12,($A$2-C2)) -> -4490.7918 | D8: =PMT($B$8/12,$A$3*12,($A$2-D2)) -> -4241.3034 | E8: =PMT($B$8/12,$A$3*12,($A$2-E2)) -> -3991.815 | F8: =PMT($B$8/12,$A$3*12,($A$2-F2)) -> -3742.3265 | G8: =B8 -> 0.07 | H8: =D8-C8 -> 249.48844 | I8: =$H$2/H8/12 -> 12.525631
G9: Higher delta between P&I payment at higher interest rate compared to lower = shorter payout, when factoring in increased down payment for lower rate
A12: Down Payment % | B12: Down Payment | C12: Interest Rate | D12: ="Interest Paid on Down Payment by Year "&ROUND(I4,0) -> Interest Paid on Down Payment by Year 11 | E12: Down Payment Difference | F12: ="Interest Paid Difference @ year "&ROUND(I4,0) -> Interest Paid Difference @ year 11 | G12: Down Payment vs Interest Paid | H12: =ROUND(I4,0)&"yr FV of down payment saved @ 8%" -> 11yr FV of down payment saved @ 8% | I12: NPV of Interest Saved/Lost | J12: ="Cum Interest Paid Year "&ROUND(I4,0) -> Cum Interest Paid Year 11 | K12: Interest Saved Compared to 10% Loan | L12: Total Interest Paid - Life of Loan
A13: =C1 -> 0.1 | B13: =$A$2*A13 -> 75000 | C13: =B4 -> 0.08 | D13: =B13*(1+C13)^$I$4 -> 179743.6 | E13: 0 | F13: 0 | G13: =F13-E13 -> 0 | H13: 0 | I13: 0 | J13: =VLOOKUP($I$4*12,'Amoritization Scenario 10% DP'!$W$8:$AH$367,10) -> 573823.03 | K13: 0 | L13: 1270301
A14: =D1 -> 0.15 | B14: =$A$2*A14 -> 112500 | C14: =B4 -> 0.08 | D14: =B14*(1+C14)^$I$4 -> 269615.41 | E14: =B14-B13 -> 37500 | F14: =D14-D13 -> 89871.802 | G14: =F14-E14 -> 52371.802 | H14: =E14*(1+0.08)^I4 -> 89871.802 | I14: =G14/(1+C14)^I4 -> 21852.712 | J14: =VLOOKUP($I$4*12,'Amoritization Scenario 15% DP'!$W$8:$AH$367,10) -> 541943.97 | K14: =J13-J14 -> 31879.057 | L14: 1199728 | M14: =L14+H14 -> 1289599.8
A15: =E1 -> 0.2 | B15: =$A$2*A15 -> 150000 | C15: =B5 -> 0.0775 | D15: =B15*(1+C15)^$I$4 -> 350149.03 | E15: =B15-B13 -> 75000 | F15: =D15-D13 -> 170405.43 | G15: =F15-E15 -> 95405.426 | H15: =E15*(1+0.08)^I4 -> 179743.6 | I15: =G15/(1+C15)^I4 -> 40870.637 | J15: =VLOOKUP($I$4*12,'Amoritization Scenario 20% DP'!$AJ$8:$AU$367,10) -> 492787.9 | K15: =J13-J15 -> 81035.128 | L15: 1034105 | M15: =L15+H15 -> 1213848.6
K17: Present Value=Future Value /( 1+i)^n

Sheet STR 10 Year
A1: Year | B1: 1 | C1: 2 | D1: 3 | E1: 4 | F1: 5 | G1: 6 | H1: 7 | I1: 8 | J1: 9 | K1: 10
A2: Property Income | L2: Desired Return | M2: 0.08 | N2: match stock market
A3: Yearly Revenue | B3: ='STR Calculator'!D15 -> 109800 | C3: =B3*(1+C5) -> 110898 | D3: =C3*(1+D5) -> 112006.98 | E3: =D3*(1+E5) -> 113127.05 | F3: =E3*(1+F5) -> 114258.32 | G3: =F3*(1+G5) -> 115400.9 | H3: =G3*(1+H5) -> 116554.91 | I3: =H3*(1+I5) -> 117720.46 | J3: =I3*(1+J5) -> 118897.67 | K3: =J3*(1+K5) -> 120086.64
A4: Monthly Revenue | B4: =B3/12 -> 9150 | C4: =C3/12 -> 9241.5 | D4: =D3/12 -> 9333.915 | E4: =E3/12 -> 9427.2541 | F4: =F3/12 -> 9521.5267 | G4: =G3/12 -> 9616.742 | H4: =H3/12 -> 9712.9094 | I4: =I3/12 -> 9810.0385 | ... K4: =K3/12 -> 10007.22 | M4: IRR | P4: NPV
A5: Rent Appreciation | B5: 0.01 | C5: =$B$5 -> 0.01 | D5: =$B$5 -> 0.01 | E5: =$B$5 -> 0.01 | F5: =$B$5 -> 0.01 | G5: =$B$5 -> 0.01 | H5: =$B$5 -> 0.01 | I5: =$B$5 -> 0.01 | J5: =$B$5 -> 0.01 | K5: =$B$5 -> 0.01 | M5: 45536 | N5: 0 | O5: =-SUM('STR Calculator'!B6:B7) -> -75000 | P5: =O5 -> -75000
A6: ="Vacancy Loss (Occupancy rate "&'STR Calculator'!$B$16&"%)" -> Vacancy Loss (Occupancy rate 1%) | B6: =B3*(1-'STR Calculator'!$B$16) -> 0 | C6: =C3*(1-'STR Calculator'!$B$16) -> 0 | D6: =D3*(1-'STR Calculator'!$B$16) -> 0 | E6: =E3*(1-'STR Calculator'!$B$16) -> 0 | F6: =F3*(1-'STR Calculator'!$B$16) -> 0 | G6: =G3*(1-'STR Calculator'!$B$16) -> 0 | H6: =H3*(1-'STR Calculator'!$B$16) -> 0 | I6: =I3*(1-'STR Calculator'!$B$16) -> 0 | ... K6: =K3*(1-'STR Calculator'!$B$16) -> 0 | M6: 45901 | N6: 1 | O6: =B39 -> 9987.2708 | P6: =O6/(1+$M$2)^N6 -> 9247.473
M7: 46266 | N7: 2 | O7: =C39 -> 11253.271 | P7: =O7/(1+$M$2)^N7 -> 9647.8659
A8: Operating Income | B8: =B3-B6 -> 109800 | C8: =C3-C6 -> 110898 | D8: =D3-D6 -> 112006.98 | E8: =E3-E6 -> 113127.05 | F8: =F3-F6 -> 114258.32 | G8: =G3-G6 -> 115400.9 | H8: =H3-H6 -> 116554.91 | I8: =I3-I6 -> 117720.46 | ... K8: =K3-K6 -> 120086.64 | M8: 46631 | N8: 3 | O8: =D39 -> 12225.871 | P8: =O8/(1+$M$2)^N8 -> 9705.2904
M9: 46997 | N9: 4 | O9: =E39 -> 13205.019 | P9: =O9/(1+$M$2)^N9 -> 9706.0831
A10: Property Expenses | M10: 47362 | N10: 5 | O10: =F39 -> 14190.658 | P10: =O10/(1+$M$2)^N10 -> 9657.9234
A11: Management Fee | B11: ='STR Calculator'!$C$23 -> 0 | C11: =$B$11 -> 0 | D11: =$B$11 -> 0 | E11: =$B$11 -> 0 | F11: =$B$11 -> 0 | G11: =$B$11 -> 0 | H11: =$B$11 -> 0 | I11: =$B$11 -> 0 | J11: =$B$11 -> 0 | K11: =$B$11 -> 0 | M11: 47727 | N11: 6 | O11: =G39 -> 15182.726 | P11: =O11/(1+$M$2)^N11 -> 9567.6926
A12: Subscriptions | B12: ='STR Calculator'!$C$24 -> 600 | C12: ='STR Calculator'!$C$24 -> 600 | D12: ='STR Calculator'!$C$24 -> 600 | E12: ='STR Calculator'!$C$24 -> 600 | F12: ='STR Calculator'!$C$24 -> 600 | G12: ='STR Calculator'!$C$24 -> 600 | H12: ='STR Calculator'!$C$24 -> 600 | I12: ='STR Calculator'!$C$24 -> 600 | ... K12: ='STR Calculator'!$C$24 -> 600 | M12: 48092 | N12: 7 | O12: =H39 -> 16181.154 | P12: =O12/(1+$M$2)^N12 -> 9441.5479
A13: AirBnB/VRBO Fee (3% of nightly- Passed to guest) | B13: ='STR Calculator'!$C$25 -> 0 | C13: ='STR Calculator'!$C$25 -> 0 | D13: ='STR Calculator'!$C$25 -> 0 | E13: ='STR Calculator'!$C$25 -> 0 | F13: ='STR Calculator'!$C$25 -> 0 | G13: ='STR Calculator'!$C$25 -> 0 | H13: ='STR Calculator'!$C$25 -> 0 | I13: ='STR Calculator'!$C$25 -> 0 | ... K13: ='STR Calculator'!$C$25 -> 0 | M13: 48458 | N13: 8 | O13: =I39 -> 17185.868 | P13: =O13/(1+$M$2)^N13 -> 9284.99
A14: Property Taxes (1.5%) | B14: ='STR Calculator'!$C$26 -> 2400 | C14: =B44*($B$14/'STR Calculator'!$B$5) -> 2496 | D14: =C44*($B$14/'STR Calculator'!$B$5) -> 2595.84 | E14: =D44*($B$14/'STR Calculator'!$B$5) -> 2699.6736 | F14: =E44*($B$14/'STR Calculator'!$B$5) -> 2807.6605 | G14: =F44*($B$14/'STR Calculator'!$B$5) -> 2919.967 | H14: =G44*($B$14/'STR Calculator'!$B$5) -> 3036.7656 | I14: =H44*($B$14/'STR Calculator'!$B$5) -> 3158.2363 | J14: =I44*($B$14/'STR Calculator'!$B$5) -> 3284.5657 | K14: =J44*($B$14/'STR Calculator'!$B$5) -> 3415.9483 | M14: 48823 | N14: 9 | O14: =J39 -> 18196.789 | P14: =O14/(1+$M$2)^N14 -> 9102.925
A15: Insurance (1.5%) | B15: ='STR Calculator'!$C$27 -> 2400 | C15: =B15+(B15*0.015) -> 2436 | D15: =C15+(C15*0.015) -> 2472.54 | E15: =D15+(D15*0.015) -> 2509.6281 | F15: =E15+(E15*0.015) -> 2547.2725 | G15: =F15+(F15*0.015) -> 2585.4816 | H15: =G15+(G15*0.015) -> 2624.2638 | I15: =H15+(H15*0.015) -> 2663.6278 | J15: =I15+(I15*0.015) -> 2703.5822 | K15: =J15+(J15*0.015) -> 2744.1359 | M15: 49188 | N15: 10 | O15: =K39+K44-('STR Calculator'!B8-SUM('STR 10 Year'!B46:K46)) -> 537255.29 | P15: =O15/(1+$M$2)^N15 -> 248853.15
A16: Cleaners/Handyman | B16: =SUM('STR Calculator'!$C$28:$C$29) -> 21000 | C16: =SUM('STR Calculator'!$C$28:$C$29) -> 21000 | D16: =SUM('STR Calculator'!$C$28:$C$29) -> 21000 | E16: =SUM('STR Calculator'!$C$28:$C$29) -> 21000 | F16: =SUM('STR Calculator'!$C$28:$C$29) -> 21000 | G16: =SUM('STR Calculator'!$C$28:$C$29) -> 21000 | H16: =SUM('STR Calculator'!$C$28:$C$29) -> 21000 | I16: =SUM('STR Calculator'!$C$28:$C$29) -> 21000 | ... K16: =SUM('STR Calculator'!$C$28:$C$29) -> 21000
A17: HOA Fees | B17: ='STR Calculator'!$C$30 -> 1200 | C17: ='STR Calculator'!$C$30 -> 1200 | D17: ='STR Calculator'!$C$30 -> 1200 | E17: ='STR Calculator'!$C$30 -> 1200 | F17: ='STR Calculator'!$C$30 -> 1200 | G17: ='STR Calculator'!$C$30 -> 1200 | H17: ='STR Calculator'!$C$30 -> 1200 | I17: ='STR Calculator'!$C$30 -> 1200 | ... K17: ='STR Calculator'!$C$30 -> 1200 | O17: =XIRR(O5:O15,M5:M15) -> 0.30445239 | P17: =SUM(P5:P15) -> 259214.94
A18: Electricity | B18: ='STR Calculator'!$C$31 -> 3000 | C18: ='STR Calculator'!$C$31 -> 3000 | D18: ='STR Calculator'!$C$31 -> 3000 | E18: ='STR Calculator'!$C$31 -> 3000 | F18: ='STR Calculator'!$C$31 -> 3000 | G18: ='STR Calculator'!$C$31 -> 3000 | H18: ='STR Calculator'!$C$31 -> 3000 | I18: ='STR Calculator'!$C$31 -> 3000 | ... K18: ='STR Calculator'!$C$31 -> 3000
A19: Natural Gas | B19: ='STR Calculator'!$C$32 -> 1333.3333 | C19: ='STR Calculator'!$C$32 -> 1333.3333 | D19: ='STR Calculator'!$C$32 -> 1333.3333 | E19: ='STR Calculator'!$C$32 -> 1333.3333 | F19: ='STR Calculator'!$C$32 -> 1333.3333 | G19: ='STR Calculator'!$C$32 -> 1333.3333 | H19: ='STR Calculator'!$C$32 -> 1333.3333 | I19: ='STR Calculator'!$C$32 -> 1333.3333 | ... K19: ='STR Calculator'!$C$32 -> 1333.3333
A20: WIFI/Cable | B20: ='STR Calculator'!$C$33 -> 1800 | C20: ='STR Calculator'!$C$33 -> 1800 | D20: ='STR Calculator'!$C$33 -> 1800 | E20: ='STR Calculator'!$C$33 -> 1800 | F20: ='STR Calculator'!$C$33 -> 1800 | G20: ='STR Calculator'!$C$33 -> 1800 | H20: ='STR Calculator'!$C$33 -> 1800 | I20: ='STR Calculator'!$C$33 -> 1800 | ... K20: ='STR Calculator'!$C$33 -> 1800
A21: Water/Sewer ($0 if septic/well) | B21: ='STR Calculator'!$C$35 -> 0 | C21: ='STR Calculator'!$C$35 -> 0 | D21: ='STR Calculator'!$C$35 -> 0 | E21: ='STR Calculator'!$C$35 -> 0 | F21: ='STR Calculator'!$C$35 -> 0 | G21: ='STR Calculator'!$C$35 -> 0 | H21: ='STR Calculator'!$C$35 -> 0 | I21: ='STR Calculator'!$C$35 -> 0 | ... K21: ='STR Calculator'!$C$35 -> 0
A22: Pool Service ($75/each x biweekly) | B22: ='STR Calculator'!$C$34 -> 0 | C22: ='STR Calculator'!$C$34 -> 0 | D22: ='STR Calculator'!$C$34 -> 0 | E22: ='STR Calculator'!$C$34 -> 0 | F22: ='STR Calculator'!$C$34 -> 0 | G22: ='STR Calculator'!$C$34 -> 0 | H22: ='STR Calculator'!$C$34 -> 0 | I22: ='STR Calculator'!$C$34 -> 0 | ... K22: ='STR Calculator'!$C$34 -> 0
A23: Building Maintenance (1%) | B23: ='STR Calculator'!$C$36 -> 0 | C23: ='STR Calculator'!$B$5*'STR Calculator'!$D$37 -> 0 | D23: ='STR Calculator'!$B$5*'STR Calculator'!$D$37 -> 0 | E23: ='STR Calculator'!$B$5*'STR Calculator'!$D$37 -> 0 | F23: ='STR Calculator'!$B$5*'STR Calculator'!$D$37 -> 0 | G23: ='STR Calculator'!$B$5*'STR Calculator'!$D$37 -> 0 | H23: ='STR Calculator'!$B$5*'STR Calculator'!$D$37 -> 0 | I23: ='STR Calculator'!$B$5*'STR Calculator'!$D$37 -> 0 | J23: ='STR Calculator'!$B$5*'STR Calculator'!$D$37 -> 0 | K23: ='STR Calculator'!$B$5*'STR Calculator'!$D$37 -> 0
A24: Capex (1%) | B24: ='STR Calculator'!$C$37 -> 0 | C24: ='STR Calculator'!$C$37 -> 0 | D24: ='STR Calculator'!$C$37 -> 0 | E24: ='STR Calculator'!$C$37 -> 0 | F24: ='STR Calculator'!$C$37 -> 0 | G24: ='STR Calculator'!$C$37 -> 0 | H24: ='STR Calculator'!$C$37 -> 0 | I24: ='STR Calculator'!$C$37 -> 0 | ... K24: ='STR Calculator'!$C$37 -> 0
A25: Grounds Cleanup/Services/Snow Removal | B25: ='STR Calculator'!$C$38 -> 0 | C25: ='STR Calculator'!$C$38 -> 0 | D25: ='STR Calculator'!$C$38 -> 0 | E25: ='STR Calculator'!$C$38 -> 0 | F25: ='STR Calculator'!$C$38 -> 0 | G25: ='STR Calculator'!$C$38 -> 0 | H25: ='STR Calculator'!$C$38 -> 0 | I25: ='STR Calculator'!$C$38 -> 0 | ... K25: ='STR Calculator'!$C$38 -> 0
A26: City Permit Fee | B26: 300 | C26: 0 | D26: 0 | E26: 0 | F26: 0 | G26: 0 | H26: 0 | I26: 0 | J26: 0 | K26: 0
A27: Incidentals (Coffee/Creamer etc) | B27: ='STR Calculator'!$C$40 -> 300 | C27: ='STR Calculator'!$C$40 -> 300 | D27: ='STR Calculator'!$C$40 -> 300 | E27: ='STR Calculator'!$C$40 -> 300 | F27: ='STR Calculator'!$C$40 -> 300 | G27: ='STR Calculator'!$C$40 -> 300 | H27: ='STR Calculator'!$C$40 -> 300 | I27: ='STR Calculator'!$C$40 -> 300 | ... K27: ='STR Calculator'!$C$40 -> 300
A28: Umbrella Insurance | B28: ='STR Calculator'!$C$41 -> 444 | C28: ='STR Calculator'!$C$41 -> 444 | D28: ='STR Calculator'!$C$41 -> 444 | E28: ='STR Calculator'!$C$41 -> 444 | F28: ='STR Calculator'!$C$41 -> 444 | G28: ='STR Calculator'!$C$41 -> 444 | H28: ='STR Calculator'!$C$41 -> 444 | I28: ='STR Calculator'!$C$41 -> 444 | ... K28: ='STR Calculator'!$C$41 -> 444
A30: Operating Expenses | B30: =SUM(B12:B28) -> 34777.333 | C30: =SUM(C12:C28) -> 34609.333 | D30: =SUM(D12:D28) -> 34745.713 | E30: =SUM(E12:E28) -> 34886.635 | F30: =SUM(F12:F28) -> 35032.266 | G30: =SUM(G12:G28) -> 35182.782 | H30: =SUM(H12:H28) -> 35338.363 | I30: =SUM(I12:I28) -> 35499.197 | ... K30: =SUM(K12:K28) -> 35837.418
A32: Net Operating Income (NOI) | B32: =B8-B30 -> 75022.667 | C32: =C8-C30 -> 76288.667 | D32: =D8-D30 -> 77261.267 | E32: =E8-E30 -> 78240.415 | F32: =F8-F30 -> 79226.054 | G32: =G8-G30 -> 80218.122 | H32: =H8-H30 -> 81216.55 | I32: =I8-I30 -> 82221.264 | ... K32: =K8-K30 -> 84249.225
A33: Capitalization Rate (CAP Rate) | B33: =B32/'STR Calculator'!$B$5 -> 0.10003022 | C33: =C32/'STR Calculator'!$B$5 -> 0.10171822 | D33: =D32/'STR Calculator'!$B$5 -> 0.10301502 | E33: =E32/'STR Calculator'!$B$5 -> 0.10432055 | F33: =F32/'STR Calculator'!$B$5 -> 0.10563474 | G33: =G32/'STR Calculator'!$B$5 -> 0.1069575 | H33: =H32/'STR Calculator'!$B$5 -> 0.10828873 | I33: =I32/'STR Calculator'!$B$5 -> 0.10962835 | ... K33: =K32/'STR Calculator'!$B$5 -> 0.1123323
A35: Key Investment Indicators
A36: Mortgage Payment | B36: =PMT('STR Calculator'!$I$8/12, 'STR Calculator'!$I$9*12,'STR Calculator'!$B$8)*12 -> -59785.396 | C36: =PMT('STR Calculator'!$I$8/12, 'STR Calculator'!$I$9*12,'STR Calculator'!$B$8)*12 -> -59785.396 | D36: =PMT('STR Calculator'!$I$8/12, 'STR Calculator'!$I$9*12,'STR Calculator'!$B$8)*12 -> -59785.396 | E36: =PMT('STR Calculator'!$I$8/12, 'STR Calculator'!$I$9*12,'STR Calculator'!$B$8)*12 -> -59785.396 | F36: =PMT('STR Calculator'!$I$8/12, 'STR Calculator'!$I$9*12,'STR Calculator'!$B$8)*12 -> -59785.396 | G36: =PMT('STR Calculator'!$I$8/12, 'STR Calculator'!$I$9*12,'STR Calculator'!$B$8)*12 -> -59785.396 | H36: =PMT('STR Calculator'!$I$8/12, 'STR Calculator'!$I$9*12,'STR Calculator'!$B$8)*12 -> -59785.396 | I36: =PMT('STR Calculator'!$I$8/12, 'STR Calculator'!$I$9*12,'STR Calculator'!$B$8)*12 -> -59785.396 | ... K36: =PMT('STR Calculator'!$I$8/12, 'STR Calculator'!$I$9*12,'STR Calculator'!$B$8)*12 -> -59785.396
A37: ="HELOC Payment ($"& 'STR Calculator'!I3&")" -> HELOC Payment ($20000) | B37: =-'STR Calculator'!$C$45 -> -1650 | C37: =-'STR Calculator'!$C$45 -> -1650 | D37: =-'STR Calculator'!$C$45 -> -1650 | E37: =-'STR Calculator'!$C$45 -> -1650 | F37: =-'STR Calculator'!$C$45 -> -1650 | G37: =-'STR Calculator'!$C$45 -> -1650 | H37: =-'STR Calculator'!$C$45 -> -1650 | I37: =-'STR Calculator'!$C$45 -> -1650 | ... K37: =-'STR Calculator'!$C$45 -> -1650
A38: PMI if Down Payment less than 20% | B38: =-'STR Calculator'!$C$47 -> -3600 | C38: =-'STR Calculator'!$C$47 -> -3600 | D38: =-'STR Calculator'!$C$47 -> -3600 | E38: =-'STR Calculator'!$C$47 -> -3600 | F38: =-'STR Calculator'!$C$47 -> -3600 | G38: =-'STR Calculator'!$C$47 -> -3600 | H38: =-'STR Calculator'!$C$47 -> -3600 | I38: =-'STR Calculator'!$C$47 -> -3600 | ... K38: =-'STR Calculator'!$C$47 -> -3600
A39: Net Cash Flow | B39: =B32+B36+B37+B38 -> 9987.2708 | C39: =C32+C36+C37+C38 -> 11253.271 | D39: =D32+D36+D37+D38 -> 12225.871 | E39: =E32+E36+E37+E38 -> 13205.019 | F39: =F32+F36+F37+F38 -> 14190.658 | G39: =G32+G36+G37+G38 -> 15182.726 | H39: =H32+H36+H37+H38 -> 16181.154 | I39: =I32+I36+I37+I38 -> 17185.868 | ... K39: =K32+K36+K37+K38 -> 19213.829 | L39: =SUM(B39:K39) -> 146822.46 | M39: FV of all cash flows
A40: Monthly Cash Flow | B40: =B39/12 -> 832.27257 | C40: =C39/12 -> 937.77257 | D40: =D39/12 -> 1018.8226 | E40: =E39/12 -> 1100.4182 | F40: =F39/12 -> 1182.5548 | G40: =G39/12 -> 1265.2271 | H40: =H39/12 -> 1348.4295 | I40: =I39/12 -> 1432.1557 | ... K40: =K39/12 -> 1601.1525
A41: ="Discounted Cash Flow (DCF) @ "&M2&"% return" -> Discounted Cash Flow (DCF) @ 0.08% return | B41: =B39/(1+$M$2)^B1 -> 9247.473 | C41: =C39/(1+$M$2)^C1 -> 9647.8659 | D41: =D39/(1+$M$2)^D1 -> 9705.2904 | E41: =E39/(1+$M$2)^E1 -> 9706.0831 | F41: =F39/(1+$M$2)^F1 -> 9657.9234 | G41: =G39/(1+$M$2)^G1 -> 9567.6926 | H41: =H39/(1+$M$2)^H1 -> 9441.5479 | I41: =I39/(1+$M$2)^I1 -> 9284.99 | ... K41: =K39/(1+$M$2)^K1 -> 8899.7207 | L41: =SUM(B41:K41) -> 94261.512 | M41: PV of all cash flows
A42: Cash on Cash ROI | B42: =B39/(SUM('STR Calculator'!$B$7,'STR Calculator'!$B$6)) -> 0.13316361 | C42: =C39/(SUM('STR Calculator'!$B$7,'STR Calculator'!$B$6)) -> 0.15004361 | D42: =D39/(SUM('STR Calculator'!$B$7,'STR Calculator'!$B$6)) -> 0.16301161 | E42: =E39/(SUM('STR Calculator'!$B$7,'STR Calculator'!$B$6)) -> 0.17606692 | F42: =F39/(SUM('STR Calculator'!$B$7,'STR Calculator'!$B$6)) -> 0.18920877 | G42: =G39/(SUM('STR Calculator'!$B$7,'STR Calculator'!$B$6)) -> 0.20243634 | H42: =H39/(SUM('STR Calculator'!$B$7,'STR Calculator'!$B$6)) -> 0.21574872 | I42: =I39/(SUM('STR Calculator'!$B$7,'STR Calculator'!$B$6)) -> 0.22914491 | ... K42: =K39/(SUM('STR Calculator'!$B$7,'STR Calculator'!$B$6)) -> 0.25618439
A43: Property Appreciation | B43: 0.04 | C43: =$B$43 -> 0.04 | D43: =$B$43 -> 0.04 | E43: =$B$43 -> 0.04 | F43: =$B$43 -> 0.04 | G43: =$B$43 -> 0.04 | H43: =$B$43 -> 0.04 | I43: =$B$43 -> 0.04 | J43: =$B$43 -> 0.04 | K43: =$B$43 -> 0.04
...

Sheet STR 7yr IRR Financing
A1: ='STR Calculator'!A2 &" - FINANCING CALCULATIONS" -> 915 Sanctuary Shores Way - 3bd / 4bath - 3240 sqft - FINANCING CALCULATIONS
B4: Year 1 | C4: Year 2 | D4: Year 3 | E4: Year 4 | F4: Year 5 | G4: Year 6 | H4: Year 7
A5: Maintenance | B5: 0.01 | C5: 0.01 | D5: 0.01 | E5: 0.01 | F5: 0.01 | G5: 0.01 | H5: 0.01
A6: Property Appreciation | B6: 0.02 | C6: 0.02 | D6: 0.02 | E6: 0.02 | F6: 0.02 | G6: 0.02 | H6: 0.02
A7: Rental Appreciation | B7: 0.01 | C7: 0.01 | D7: 0.01 | E7: 0.01 | F7: 0.01 | G7: 0.01 | H7: 0.01
A8: Tax/Insurance/HOA Appreciation | B8: 0.015 | C8: 0.015 | D8: 0.015 | E8: 0.015 | F8: 0.015 | G8: 0.015 | H8: 0.015
A9: Vacancy | B9: =1-'STR Calculator'!$B$16 -> 0 | C9: =1-'STR Calculator'!$B$16 -> 0 | D9: =1-'STR Calculator'!$B$16 -> 0 | E9: =1-'STR Calculator'!$B$16 -> 0 | F9: =1-'STR Calculator'!$B$16 -> 0 | G9: =1-'STR Calculator'!$B$16 -> 0 | H9: =1-'STR Calculator'!$B$16 -> 0
B11: Year 1 | C11: Year 2 | D11: Year 3 | E11: Year 4 | F11: Year 5 | G11: Year 6 | H11: Year 7
A12: Revenues
A13: Rental Income | B13: ='STR Calculator'!D15 -> 109800 | C13: =SUM(B$13+(C$7*B$13)) -> 110898 | D13: =SUM(C$13+(D$7*C$13)) -> 112006.98 | E13: =SUM(D$13+(E$7*D$13)) -> 113127.05 | F13: =SUM(E$13+(F$7*E$13)) -> 114258.32 | G13: =SUM(F$13+(G$7*F$13)) -> 115400.9 | H13: =SUM(G$13+(H$7*G$13)) -> 116554.91
A14: Monthly Revenue | B14: =B13/12 -> 9150 | C14: =C13/12 -> 9241.5 | D14: =D13/12 -> 9333.915 | E14: =E13/12 -> 9427.2541 | F14: =F13/12 -> 9521.5267 | G14: =G13/12 -> 9616.742 | H14: =H13/12 -> 9712.9094
A15: Vacancy Rate | B15: ='STR Calculator'!D16 -> 0 | C15: =-(C13*C9) -> 0 | D15: =-(D13*D9) -> 0 | E15: =-(E13*E9) -> 0 | F15: =-(F13*F9) -> 0 | G15: =-(G13*G9) -> 0 | H15: =-(H13*H9) -> 0
A16: Net Revenue | B16: =SUM(B13,B15) -> 109800 | C16: =SUM(C13,C15) -> 110898 | D16: =SUM(D13,D15) -> 112006.98 | E16: =SUM(E13,E15) -> 113127.05 | F16: =SUM(F13,F15) -> 114258.32 | G16: =SUM(G13,G15) -> 115400.9 | H16: =SUM(H13,H15) -> 116554.91
A18: Expenses
A19: Management Fees | B19: 0 | C19: 0 | D19: 0 | E19: 0 | F19: 0 | G19: 0 | H19: 0
A20: Subscriptions | B20: ='STR Calculator'!$C$24 -> 600 | C20: ='STR Calculator'!$C$24 -> 600 | D20: ='STR Calculator'!$C$24 -> 600 | E20: ='STR Calculator'!$C$24 -> 600 | F20: ='STR Calculator'!$C$24 -> 600 | G20: ='STR Calculator'!$C$24 -> 600 | H20: ='STR Calculator'!$C$24 -> 600
A21: Property Taxes | B21: ='STR Calculator'!$C$26 -> 2400 | C21: =B$21+(B$21*C$8) -> 2436 | D21: =C$21+(C$21*D$8) -> 2472.54 | E21: =D$21+(D$21*E$8) -> 2509.6281 | F21: =E$21+(E$21*F$8) -> 2547.2725 | G21: =F$21+(F$21*G$8) -> 2585.4816 | H21: =G$21+(G$21*H$8) -> 2624.2638
A22: Insurance | B22: =('STR Calculator'!$C$27) -> 2400 | C22: =('STR Calculator'!$B$5+B48)*($B$22/'STR Calculator'!$B$5) -> 2448 | D22: =('STR Calculator'!$B$5+C48)*($B$22/'STR Calculator'!$B$5) -> 2448.96 | E22: =('STR Calculator'!$B$5+D48)*($B$22/'STR Calculator'!$B$5) -> 2448.9792 | F22: =('STR Calculator'!$B$5+E48)*($B$22/'STR Calculator'!$B$5) -> 2448.9796 | G22: =('STR Calculator'!$B$5+F48)*($B$22/'STR Calculator'!$B$5) -> 2448.9796 | H22: =('STR Calculator'!$B$5+G48)*($B$22/'STR Calculator'!$B$5) -> 2448.9796
A23: Cleaners/Handyman | B23: =SUM('STR Calculator'!$C$28:$C$29) -> 21000 | C23: =SUM('STR Calculator'!$C$28:$C$29) -> 21000 | D23: =SUM('STR Calculator'!$C$28:$C$29) -> 21000 | E23: =SUM('STR Calculator'!$C$28:$C$29) -> 21000 | F23: =SUM('STR Calculator'!$C$28:$C$29) -> 21000 | G23: =SUM('STR Calculator'!$C$28:$C$29) -> 21000 | H23: =SUM('STR Calculator'!$C$28:$C$29) -> 21000
A24: Electricity | B24: ='STR Calculator'!$C$31 -> 3000 | C24: ='STR Calculator'!$C$31 -> 3000 | D24: ='STR Calculator'!$C$31 -> 3000 | E24: ='STR Calculator'!$C$31 -> 3000 | F24: ='STR Calculator'!$C$31 -> 3000 | G24: ='STR Calculator'!$C$31 -> 3000 | H24: ='STR Calculator'!$C$31 -> 3000
A25: Natural Gas | B25: ='STR Calculator'!$C$32 -> 1333.3333 | C25: ='STR Calculator'!$C$32 -> 1333.3333 | D25: ='STR Calculator'!$C$32 -> 1333.3333 | E25: ='STR Calculator'!$C$32 -> 1333.3333 | F25: ='STR Calculator'!$C$32 -> 1333.3333 | G25: ='STR Calculator'!$C$32 -> 1333.3333 | H25: ='STR Calculator'!$C$32 -> 1333.3333
A26: WIFI/Cable | B26: ='STR Calculator'!$C$33 -> 1800 | C26: ='STR Calculator'!$C$33 -> 1800 | D26: ='STR Calculator'!$C$33 -> 1800 | E26: ='STR Calculator'!$C$33 -> 1800 | F26: ='STR Calculator'!$C$33 -> 1800 | G26: ='STR Calculator'!$C$33 -> 1800 | H26: ='STR Calculator'!$C$33 -> 1800
A27: Water/Sewer | B27: ='STR Calculator'!$C$35 -> 0 | C27: ='STR Calculator'!$C$35 -> 0 | D27: ='STR Calculator'!$C$35 -> 0 | E27: ='STR Calculator'!$C$35 -> 0 | F27: ='STR Calculator'!$C$35 -> 0 | G27: ='STR Calculator'!$C$35 -> 0 | H27: ='STR Calculator'!$C$35 -> 0
A28: Pool Service | B28: ='STR Calculator'!$C$34 -> 0 | C28: ='STR Calculator'!$C$34 -> 0 | D28: ='STR Calculator'!$C$34 -> 0 | E28: ='STR Calculator'!$C$34 -> 0 | F28: ='STR Calculator'!$C$34 -> 0 | G28: ='STR Calculator'!$C$34 -> 0 | H28: ='STR Calculator'!$C$34 -> 0
A29: HOA | B29: ='STR Calculator'!$C$30 -> 1200 | C29: =B29+(B29*C8) -> 1218 | D29: =C29+(C29*D8) -> 1236.27 | E29: =D29+(D29*E8) -> 1254.814 | F29: =E29+(E29*F8) -> 1273.6363 | G29: =F29+(F29*G8) -> 1292.7408 | H29: =G29+(G29*H8) -> 1312.1319
A30: Maintenance & Repairs | B30: ='STR Calculator'!$C$36 -> 0 | C30: ='STR Calculator'!$B$5*C5 -> 7500 | D30: ='STR Calculator'!$B$5*D5 -> 7500 | E30: ='STR Calculator'!$B$5*E5 -> 7500 | F30: ='STR Calculator'!$B$5*F5 -> 7500 | G30: ='STR Calculator'!$B$5*G5 -> 7500 | H30: ='STR Calculator'!$B$5*H5 -> 7500
A31: Capex | B31: ='STR Calculator'!$C$37 -> 0 | C31: ='STR Calculator'!$C$37 -> 0 | D31: ='STR Calculator'!$C$37 -> 0 | E31: ='STR Calculator'!$C$37 -> 0 | F31: ='STR Calculator'!$C$37 -> 0 | G31: ='STR Calculator'!$C$37 -> 0 | H31: ='STR Calculator'!$C$37 -> 0
A32: City Permit | B32: ='STR Calculator'!C39 -> 300 | C32: 0 | D32: 0 | E32: 0 | F32: 0 | G32: 0 | H32: 0
A33: Incidentals (Coffee, etc) | B33: ='STR Calculator'!$C$40 -> 300 | C33: ='STR Calculator'!$C$40 -> 300 | D33: ='STR Calculator'!$C$40 -> 300 | E33: ='STR Calculator'!$C$40 -> 300 | F33: ='STR Calculator'!$C$40 -> 300 | G33: ='STR Calculator'!$C$40 -> 300 | H33: ='STR Calculator'!$C$40 -> 300
A34: Umbrella Insurance | B34: ='STR Calculator'!$C$41 -> 444 | C34: ='STR Calculator'!$C$41 -> 444 | D34: ='STR Calculator'!$C$41 -> 444 | E34: ='STR Calculator'!$C$41 -> 444 | F34: ='STR Calculator'!$C$41 -> 444 | G34: ='STR Calculator'!$C$41 -> 444 | H34: ='STR Calculator'!$C$41 -> 444
A35: Total Expenses | B35: =SUM(B20:B34) -> 34777.333 | C35: =SUM(C20:C34) -> 42079.333 | D35: =SUM(D20:D34) -> 42135.103 | E35: =SUM(E20:E34) -> 42190.755 | F35: =SUM(F20:F34) -> 42247.222 | G35: =SUM(G20:G34) -> 42304.535 | H35: =SUM(H20:H34) -> 42362.709
A37: Net Operating Income (NOI) | B37: =SUM(B16-B35) -> 75022.667 | C37: =SUM(C16-C35) -> 68818.667 | D37: =SUM(D16-D35) -> 69871.877 | E37: =SUM(E16-E35) -> 70936.295 | F37: =SUM(F16-F35) -> 72011.099 | G37: =SUM(G16-G35) -> 73096.368 | H37: =SUM(H16-H35) -> 74192.204
A39: Cash Flow
A40: NOI (Cash Available) | B40: =B37 -> 75022.667 | C40: =C37 -> 68818.667 | D40: =D37 -> 69871.877 | E40: =E37 -> 70936.295 | F40: =F37 -> 72011.099 | G40: =G37 -> 73096.368 | H40: =H37 -> 74192.204
A41: Conventional Mortgage | B41: ='STR Calculator'!$C$46 -> 59785.396 | C41: ='STR Calculator'!$C$46 -> 59785.396 | D41: ='STR Calculator'!$C$46 -> 59785.396 | E41: ='STR Calculator'!$C$46 -> 59785.396 | F41: ='STR Calculator'!$C$46 -> 59785.396 | G41: ='STR Calculator'!$C$46 -> 59785.396 | H41: ='STR Calculator'!$C$46 -> 59785.396
A42: HELOC Mortgage | B42: ='STR Calculator'!$C$45 -> 1650 | C42: ='STR Calculator'!$C$45 -> 1650 | D42: ='STR Calculator'!$C$45 -> 1650 | E42: ='STR Calculator'!$C$45 -> 1650 | F42: ='STR Calculator'!$C$45 -> 1650 | G42: ='STR Calculator'!$C$45 -> 1650 | H42: ='STR Calculator'!$C$45 -> 1650
A43: PMI if Down Payment less than 20% | B43: ='STR Calculator'!$C$47 -> 3600 | C43: ='STR Calculator'!$C$47 -> 3600 | D43: ='STR Calculator'!$C$47 -> 3600 | E43: ='STR Calculator'!$C$47 -> 3600 | F43: ='STR Calculator'!$C$47 -> 3600 | G43: ='STR Calculator'!$C$47 -> 3600 | H43: ='STR Calculator'!$C$47 -> 3600
A44: Total Cash Flow | B44: =SUM(B40-B41-B42-B43) -> 9987.2708 | C44: =SUM(C40-C41-C42-C43) -> 3783.2708 | D44: =SUM(D40-D41-D42-D43) -> 4836.4808 | E44: =SUM(E40-E41-E42-E43) -> 5900.8993 | F44: =SUM(F40-F41-F42-F43) -> 6975.7027 | G44: =SUM(G40-G41-G42-G43) -> 8060.9723 | H44: =SUM(H40-H41-H42-H43) -> 9156.808
A45: Monthly Cash Flow | B45: =B44/12 -> 832.27257 | C45: =C44/12 -> 315.27257 | D45: =D44/12 -> 403.04007 | E45: =E44/12 -> 491.7416 | F45: =F44/12 -> 581.30856 | G45: =G44/12 -> 671.74769 | H45: =H44/12 -> 763.06733
A46: DSCR | B46: =B40/SUM(B41:B43) -> 1.1535667 | C46: =C40/SUM(C41:C43) -> 1.0581725 | D46: =D40/SUM(D41:D43) -> 1.0743669 | E46: =E40/SUM(E41:E43) -> 1.0907337 | F46: =F40/SUM(F41:F43) -> 1.1072601 | G46: =G40/SUM(G41:G43) -> 1.1239475 | H46: =H40/SUM(H41:H43) -> 1.1407973
...

Sheet Amoritization Scenario 10% DP
A1: If deciding between different Down Payment % and Interest Rates, compare Cumulative Interest Payment over duration to recoup additional Down Payment Lump Sum, to see which is better. NPV / PV/FV money calculation
C3: sqft | J3: Interest | K3: ='Interest Rate Comparison'!B3 -> 0.0825 | N3: =K3/12 -> 0.006875 | O3: r | W3: Interest | X3: ='Interest Rate Comparison'!B4 -> 0.08 | AA3: =X3/12 -> 0.0066666667 | AB3: r | AJ3: Interest | AK3: ='Interest Rate Comparison'!B5 -> 0.0775 | AN3: =AK3/12 -> 0.0064583333 | AO3: r | AW3: Interest | AX3: ='Interest Rate Comparison'!B6 -> 0.075 | BA3: =AX3/12 -> 0.00625 | BB3: r | BJ3: Interest | BK3: ='Interest Rate Comparison'!B7 -> 0.0725 | BN3: =BK3/12 -> 0.0060416667 | BO3: r | BW3: Interest | BX3: ='Interest Rate Comparison'!B8 -> 0.07 | CA3: =BX3/12 -> 0.0058333333 | CB3: r
C4: $/sqft Market Estimate | J4: Term | K4: =$L$4*12 -> 360 | L4: ='STR Calculator'!I9 -> 30 | M4: years | N4: =(1+N3)^K4 -> 11.781506 | O4: (1+r)^n | W4: Term | X4: =$L$4*12 -> 360 | Y4: 30 | Z4: years | AA4: =(1+AA3)^X4 -> 10.93573 | AB4: (1+r)^n | AJ4: Term | AK4: =$L$4*12 -> 360 | AL4: 30 | AM4: years | AN4: =(1+AN3)^AK4 -> 10.150514 | AO4: (1+r)^n | AW4: Term | AX4: =$L$4*12 -> 360 | AY4: 30 | AZ4: years | BA4: =(1+BA3)^AX4 -> 9.4215339 | BB4: (1+r)^n | BJ4: Term | BK4: =$L$4*12 -> 360 | BL4: 30 | BM4: years | BN4: =(1+BN3)^BK4 -> 8.744772 | BO4: (1+r)^n | BW4: Term | BX4: =$L$4*12 -> 360 | BY4: 30 | BZ4: years | CA4: =(1+CA3)^BX4 -> 8.1164975 | CB4: (1+r)^n
A5: Original Purchase Price | B5: ='STR Calculator'!B5 -> 750000 | C5: =B5/B3 -> #DIV/0! | D5: sqft | J5: Monthly Payment | W5: Monthly Payment | AJ5: Monthly Payment | AW5: Monthly Payment | BJ5: Monthly Payment | BW5: Monthly Payment
A6: Down Payment | B6: 0.1
A7: Current Loan Balance | B7: =B5-(B5*B6) -> 675000 | C7: as of 11/13/22 | J7: paymentNumber | K7: paymentDate | L7: startingBalance | M7: Monthly Payment | N7: principalPayment | O7: Principle Pay Down | P7: interestPayment | Q7: Interest Percent | R7: cumulativePrincipal | S7: cumulativeInterest | T7: endingBalance | U7: Total Paid End of Loan | W7: paymentNumber | X7: paymentDate | Y7: startingBalance | Z7: Monthly Payment | AA7: principalPayment | AB7: Principle Pay Down | AC7: interestPayment | AD7: Interest Percent | AE7: cumulativePrincipal | AF7: cumulativeInterest | AG7: endingBalance | AH7: Total Paid End of Loan | AJ7: paymentNumber | AK7: paymentDate | AL7: startingBalance | AM7: Monthly Payment | AN7: principalPayment | AO7: Principle Pay Down | AP7: interestPayment | AQ7: Interest Percent | AR7: cumulativePrincipal | AS7: cumulativeInterest | AT7: endingBalance | AU7: Total Paid End of Loan | AW7: paymentNumber | AX7: paymentDate | AY7: startingBalance | AZ7: Monthly Payment | BA7: principalPayment | BB7: Principle Pay Down | BC7: interestPayment | BD7: Interest Percent | BE7: cumulativePrincipal | BF7: cumulativeInterest | BG7: endingBalance | BH7: Total Paid End of Loan | BJ7: paymentNumber | BK7: paymentDate | BL7: startingBalance | BM7: Monthly Payment | BN7: principalPayment | BO7: Principle Pay Down | BP7: interestPayment | BQ7: Interest Percent | BR7: cumulativePrincipal | BS7: cumulativeInterest | BT7: endingBalance | BU7: Total Paid End of Loan | BW7: paymentNumber | BX7: paymentDate | BY7: startingBalance | BZ7: Monthly Payment | CA7: principalPayment | CB7: Principle Pay Down | CC7: interestPayment | CD7: Interest Percent | CE7: cumulativePrincipal | CF7: cumulativeInterest | CG7: endingBalance | CH7: Total Paid End of Loan
A8: Current Equity | B8: =B5-B7 -> 75000 | J8: 1 | K8: 44866 | L8: ='Amoritization Scenario 10% DP'!$B$7 -> 675000 | M8: =$L$8/((($N$4)-1)/($N$3*$N$4)) -> 5071.0496 | N8: =M8-P8 -> 430.42458 | O8: =(N8/L8)*12 -> 0.0076519925 | P8: =L8*($K$3/12) -> 4640.625 | Q8: =(P8/L8)*12 -> 0.0825 | R8: =N8 -> 430.42458 | S8: =P8 -> 4640.625 | T8: =L8-N8 -> 674569.58 | U8: =R8+S8 -> 5071.0496 | W8: 1 | X8: 44866 | Y8: ='Amoritization Scenario 10% DP'!$B$7 -> 675000 | Z8: =$Y$8/((($AA$4)-1)/($AA$3*$AA$4)) -> 4952.9109 | AA8: =Z8-AC8 -> 452.91087 | AB8: =(AA8/Y8)*12 -> 0.0080517489 | AC8: =Y8*($X$3/12) -> 4500 | AD8: =(AC8/Y8)*12 -> 0.08 | AE8: =AA8 -> 452.91087 | AF8: =AC8 -> 4500 | AG8: =Y8-AA8 -> 674547.09 | AH8: =AE8+AF8 -> 4952.9109 | AJ8: 1 | AK8: 44866 | AL8: ='Amoritization Scenario 10% DP'!$B$7 -> 675000 | AM8: =$AL$8/((($AN$4)-1)/($AN$3*$AN$4)) -> 4835.7827 | AN8: =AM8-AP8 -> 476.40766 | AO8: =(AN8/AL8)*12 -> 0.0084694695 | AP8: =AL8*($AK$3/12) -> 4359.375 | AQ8: =(AP8/AL8)*12 -> 0.0775 | AR8: =AN8 -> 476.40766 | AS8: =AP8 -> 4359.375 | AT8: =AL8-AN8 -> 674523.59 | AU8: =AR8+AS8 -> 4835.7827 | AW8: 1 | AX8: 44866 | AY8: ='Amoritization Scenario 10% DP'!$B$7 -> 675000 | AZ8: =$AY$8/((($BA$4)-1)/($BA$3*$BA$4)) -> 4719.6979 | BA8: =AZ8-BC8 -> 500.94793 | BB8: =(BA8/AY8)*12 -> 0.008905741 | BC8: =AY8*($AX$3/12) -> 4218.75 | BD8: =(BC8/AY8)*12 -> 0.075 | BE8: =BA8 -> 500.94793 | BF8: =BC8 -> 4218.75 | BG8: =AY8-BA8 -> 674499.05 | BH8: =BE8+BF8 -> 4719.6979 | BJ8: 1 | BK8: 44866 | BL8: ='Amoritization Scenario 10% DP'!$B$7 -> 675000 | BM8: =$BL$8/((($BN$4)-1)/($BN$3*$BN$4)) -> 4604.6899 | BN8: =BM8-BP8 -> 526.56489 | BO8: =(BN8/BL8)*12 -> 0.0093611536 | BP8: =BL8*($BK$3/12) -> 4078.125 | BQ8: =(BP8/BL8)*12 -> 0.0725 | BR8: =BN8 -> 526.56489 | BS8: =BP8 -> 4078.125 | BT8: =BL8-BN8 -> 674473.44 | BU8: =BR8+BS8 -> 4604.6899 | BW8: 1 | BX8: 44866 | BY8: ='Amoritization Scenario 10% DP'!$B$7 -> 675000 | BZ8: =$BY$8/((($CA$4)-1)/($CA$3*$CA$4)) -> 4490.7918 | CA8: =BZ8-CC8 -> 553.29184 | CB8: =(CA8/BY8)*12 -> 0.0098362994 | CC8: =BY8*($BX$3/12) -> 3937.5 | CD8: =(CC8/BY8)*12 -> 0.07 | CE8: =CA8 -> 553.29184 | CF8: =CC8 -> 3937.5 | CG8: =BY8-CA8 -> 674446.71 | CH8: =CE8+CF8 -> 4490.7918
J9: 2 | K9: 44896 | L9: =T8 -> 674569.58 | M9: =$L$8/((($N$4)-1)/($N$3*$N$4)) -> 5071.0496 | N9: =M9-P9 -> 433.38375 | O9: =(N9/L9)*12 -> 0.007709516 | P9: =L9*($K$3/12) -> 4637.6658 | Q9: =(P9/L9)*12 -> 0.0825 | R9: =R8+N9 -> 863.80832 | S9: =S8+P9 -> 9278.2908 | T9: =L9-N9 -> 674136.19 | U9: =R9+S9 -> 10142.099 | W9: 2 | X9: 44896 | Y9: =AG8 -> 674547.09 | Z9: =Z8 -> 4952.9109 | AA9: =Z9-AC9 -> 455.93028 | AB9: =(AA9/Y9)*12 -> 0.0081108694 | AC9: =Y9*($X$3/12) -> 4496.9806 | AD9: =(AC9/Y9)*12 -> 0.08 | AE9: =AE8+AA9 -> 908.84115 | AF9: =AF8+AC9 -> 8996.9806 | AG9: =Y9-AA9 -> 674091.16 | AH9: =AE9+AF9 -> 9905.8217 | AJ9: 2 | AK9: 44896 | AL9: =AT8 -> 674523.59 | AM9: =AM8 -> 4835.7827 | AN9: =AM9-AP9 -> 479.48446 | AO9: =(AN9/AL9)*12 -> 0.0085301886 | AP9: =AL9*($AK$3/12) -> 4356.2982 | AQ9: =(AP9/AL9)*12 -> 0.0775 | AR9: =AR8+AN9 -> 955.89211 | AS9: =AS8+AP9 -> 8715.6732 | AT9: =AL9-AN9 -> 674044.11 | AU9: =AR9+AS9 -> 9671.5653 | AW9: 2 | AX9: 44896 | AY9: =BG8 -> 674499.05 | AZ9: =AZ8 -> 4719.6979 | BA9: =AZ9-BC9 -> 504.07886 | BB9: =(BA9/AY9)*12 -> 0.0089680575 | BC9: =AY9*($AX$3/12) -> 4215.6191 | BD9: =(BC9/AY9)*12 -> 0.075 | BE9: =BE8+BA9 -> 1005.0268 | BF9: =BF8+BC9 -> 8434.3691 | BG9: =AY9-BA9 -> 673994.97 | BH9: =BE9+BF9 -> 9439.3959 | BJ9: 2 | BK9: 44896 | BL9: =BT8 -> 674473.44 | BM9: =BM8 -> 4604.6899 | BN9: =BM9-BP9 -> 529.74622 | BO9: =(BN9/BL9)*12 -> 0.009425063 | BP9: =BL9*($BK$3/12) -> 4074.9437 | BQ9: =(BP9/BL9)*12 -> 0.0725 | BR9: =BR8+BN9 -> 1056.3111 | BS9: =BS8+BP9 -> 8153.0687 | BT9: =BL9-BN9 -> 673943.69 | BU9: =BR9+BS9 -> 9209.3798 | BW9: 2 | BX9: 44896 | BY9: =CG8 -> 674446.71 | BZ9: =BZ8 -> 4490.7918 | CA9: =BZ9-CC9 -> 556.51938 | CB9: =(CA9/BY9)*12 -> 0.0099017943 | CC9: =BY9*($BX$3/12) -> 3934.2725 | CD9: =(CC9/BY9)*12 -> 0.07 | CE9: =CE8+CA9 -> 1109.8112 | CF9: =CF8+CC9 -> 7871.7725 | CG9: =BY9-CA9 -> 673890.19 | CH9: =CE9+CF9 -> 8981.5837
A10: Year | B10: ="Cum Interest @ "&K3&"%" -> Cum Interest @ 0.0825% | C10: ="Cum Interest @ "&X3&"%" -> Cum Interest @ 0.08% | D10: ="Cum Interest @ "&AK3&"%" -> Cum Interest @ 0.0775% | E10: ="Cum Interest @ "&AX3&"%" -> Cum Interest @ 0.075% | F10: ="Cum Interest @ "&BK3&"%" -> Cum Interest @ 0.0725% | G10: ="Cum Interest @ "&BX3&"%" -> Cum Interest @ 0.07% | J10: 3 | K10: 44927 | L10: =T9 -> 674136.19 | M10: =$L$8/((($N$4)-1)/($N$3*$N$4)) -> 5071.0496 | N10: =M10-P10 -> 436.36326 | O10: =(N10/L10)*12 -> 0.0077675093 | P10: =L10*($K$3/12) -> 4634.6863 | Q10: =(P10/L10)*12 -> 0.0825 | R10: =R9+N10 -> 1300.1716 | S10: =S9+P10 -> 13912.977 | T10: =L10-N10 -> 673699.83 | U10: =R10+S10 -> 15213.149 | W10: 3 | X10: 44927 | Y10: =AG9 -> 674091.16 | Z10: =Z9 -> 4952.9109 | AA10: =Z10-AC10 -> 458.96981 | AB10: =(AA10/Y10)*12 -> 0.0081704643 | AC10: =Y10*($X$3/12) -> 4493.9411 | AD10: =(AC10/Y10)*12 -> 0.08 | AE10: =AE9+AA10 -> 1367.811 | AF10: =AF9+AC10 -> 13490.922 | AG10: =Y10-AA10 -> 673632.19 | AH10: =AE10+AF10 -> 14858.733 | AJ10: 3 | AK10: 44927 | AL10: =AT9 -> 674044.11 | AM10: =AM9 -> 4835.7827 | AN10: =AM10-AP10 -> 482.58113 | AO10: =(AN10/AL10)*12 -> 0.0085913866 | AP10: =AL10*($AK$3/12) -> 4353.2015 | AQ10: =(AP10/AL10)*12 -> 0.0775 | AR10: =AR9+AN10 -> 1438.4732 | AS10: =AS9+AP10 -> 13068.875 | AT10: =AL10-AN10 -> 673561.53 | AU10: =AR10+AS10 -> 14507.348 | AW10: 3 | AX10: 44927 | AY10: =BG9 -> 673994.97 | AZ10: =AZ9 -> 4719.6979 | BA10: =AZ10-BC10 -> 507.22935 | BB10: =(BA10/AY10)*12 -> 0.009030857 | BC10: =AY10*($AX$3/12) -> 4212.4686 | BD10: =(BC10/AY10)*12 -> 0.075 | BE10: =BE9+BA10 -> 1512.2561 | BF10: =BF9+BC10 -> 12646.838 | BG10: =AY10-BA10 -> 673487.74 | BH10: =BE10+BF10 -> 14159.094 | BJ10: 3 | BK10: 44927 | BL10: =BT9 -> 673943.69 | BM10: =BM9 -> 4604.6899 | BN10: =BM10-BP10 -> 532.94677 | BO10: =(BN10/BL10)*12 -> 0.0094894594 | BP10: =BL10*($BK$3/12) -> 4071.7431 | BQ10: =(BP10/BL10)*12 -> 0.0725 | BR10: =BR9+BN10 -> 1589.2579 | BS10: =BS9+BP10 -> 12224.812 | BT10: =BL10-BN10 -> 673410.74 | BU10: =BR10+BS10 -> 13814.07 | BW10: 3 | BX10: 44927 | BY10: =CG9 -> 673890.19 | BZ10: =BZ9 -> 4490.7918 | CA10: =BZ10-CC10 -> 559.76574 | CB10: =(CA10/BY10)*12 -> 0.0099677796 | CC10: =BY10*($BX$3/12) -> 3931.0261 | CD10: =(CC10/BY10)*12 -> 0.07 | CE10: =CE9+CA10 -> 1669.577 | CF10: =CF9+CC10 -> 11802.799 | CG10: =BY10-CA10 -> 673330.42 | CH10: =CE10+CF10 -> 13472.376
A11: 1 | B11: =VLOOKUP($A$11*12,$J$7:$U$367,10) -> 55487.649 | C11: =VLOOKUP(A11*12,$W$7:$AH$367,10) -> 53796.224 | D11: =VLOOKUP(A11*12,$AJ$7:$AU$367,10) -> 52104.995 | E11: =VLOOKUP(A11*12,$AW$7:$BH$367,10) -> 50413.993 | F11: =VLOOKUP(A11*12,$BJ$7:$BU$367,10) -> 48723.246 | G11: =VLOOKUP(A11*12,$BW$7:$CH$367,10) -> 47032.786 | J11: 4 | K11: 44958 | L11: =T10 -> 673699.83 | M11: =$L$8/((($N$4)-1)/($N$3*$N$4)) -> 5071.0496 | N11: =M11-P11 -> 439.36326 | O11: =(N11/L11)*12 -> 0.0078259766 | P11: =L11*($K$3/12) -> 4631.6863 | Q11: =(P11/L11)*12 -> 0.0825 | R11: =R10+N11 -> 1739.5348 | S11: =S10+P11 -> 18544.663 | T11: =L11-N11 -> 673260.47 | U11: =R11+S11 -> 20284.198 | W11: 4 | X11: 44958 | Y11: =AG10 -> 673632.19 | Z11: =Z10 -> 4952.9109 | AA11: =Z11-AC11 -> 462.02961 | AB11: =(AA11/Y11)*12 -> 0.008230538 | AC11: =Y11*($X$3/12) -> 4490.8813 | AD11: =(AC11/Y11)*12 -> 0.08 | AE11: =AE10+AA11 -> 1829.8406 | AF11: =AF10+AC11 -> 17981.803 | AG11: =Y11-AA11 -> 673170.16 | AH11: =AE11+AF11 -> 19811.643 | AJ11: 4 | AK11: 44958 | AL11: =AT10 -> 673561.53 | AM11: =AM10 -> 4835.7827 | AN11: =AM11-AP11 -> 485.6978 | AO11: =(AN11/AL11)*12 -> 0.0086530678 | AP11: =AL11*($AK$3/12) -> 4350.0849 | AQ11: =(AP11/AL11)*12 -> 0.0775 | AR11: =AR10+AN11 -> 1924.171 | AS11: =AS10+AP11 -> 17418.96 | AT11: =AL11-AN11 -> 673075.83 | AU11: =AR11+AS11 -> 19343.131 | AW11: 4 | AX11: 44958 | AY11: =BG10 -> 673487.74 | AZ11: =AZ10 -> 4719.6979 | BA11: =AZ11-BC11 -> 510.39953 | BB11: =(BA11/AY11)*12 -> 0.0090941438 | BC11: =AY11*($AX$3/12) -> 4209.2984 | BD11: =(BC11/AY11)*12 -> 0.075 | BE11: =BE10+BA11 -> 2022.6557 | BF11: =BF10+BC11 -> 16856.136 | BG11: =AY11-BA11 -> 672977.34 | BH11: =BE11+BF11 -> 18878.792 | BJ11: 4 | BK11: 44958 | BL11: =BT10 -> 673410.74 | BM11: =BM10 -> 4604.6899 | BN11: =BM11-BP11 -> 536.16666 | BO11: =(BN11/BL11)*12 -> 0.009554347 | BP11: =BL11*($BK$3/12) -> 4068.5232 | BQ11: =(BP11/BL11)*12 -> 0.0725 | BR11: =BR10+BN11 -> 2125.4245 | BS11: =BS10+BP11 -> 16293.335 | BT11: =BL11-BN11 -> 672874.58 | BU11: =BR11+BS11 -> 18418.76 | BW11: 4 | BX11: 44958 | BY11: =CG10 -> 673330.42 | BZ11: =BZ10 -> 4490.7918 | CA11: =BZ11-CC11 -> 563.03104 | CB11: =(CA11/BY11)*12 -> 0.01003426 | CC11: =BY11*($BX$3/12) -> 3927.7608 | CD11: =(CC11/BY11)*12 -> 0.07 | CE11: =CE10+CA11 -> 2232.608 | CF11: =CF10+CC11 -> 15730.559 | CG11: =BY11-CA11 -> 672767.39 | CH11: =CE11+CF11 -> 17963.167
A12: =A11+1 -> 2 | B12: =VLOOKUP(A12*12,$J$7:$U$367,10) -> 110515.56 | C12: =VLOOKUP(A12*12,$W$7:$AH$367,10) -> 107124.44 | D12: =VLOOKUP(A12*12,$AJ$7:$AU$367,10) -> 103734.18 | E12: =VLOOKUP(A12*12,$AW$7:$BH$367,10) -> 100344.93 | F12: =VLOOKUP(A12*12,$BJ$7:$BU$367,10) -> 96956.786 | G12: =VLOOKUP(A12*12,$BW$7:$CH$367,10) -> 93569.899 | J12: 5 | K12: 44986 | L12: =T11 -> 673260.47 | M12: =$L$8/((($N$4)-1)/($N$3*$N$4)) -> 5071.0496 | N12: =M12-P12 -> 442.38388 | O12: =(N12/L12)*12 -> 0.0078849224 | P12: =L12*($K$3/12) -> 4628.6657 | Q12: =(P12/L12)*12 -> 0.0825 | R12: =R11+N12 -> 2181.9187 | S12: =S11+P12 -> 23173.329 | T12: =L12-N12 -> 672818.08 | U12: =R12+S12 -> 25355.248 | W12: 5 | X12: 44986 | Y12: =AG11 -> 673170.16 | Z12: =Z11 -> 4952.9109 | AA12: =Z12-AC12 -> 465.10981 | AB12: =(AA12/Y12)*12 -> 0.008291095 | AC12: =Y12*($X$3/12) -> 4487.8011 | AD12: =(AC12/Y12)*12 -> 0.08 | AE12: =AE11+AA12 -> 2294.9504 | AF12: =AF11+AC12 -> 22469.604 | AG12: =Y12-AA12 -> 672705.05 | AH12: =AE12+AF12 -> 24764.554 | AJ12: 5 | AK12: 44986 | AL12: =AT11 -> 673075.83 | AM12: =AM11 -> 4835.7827 | AN12: =AM12-AP12 -> 488.8346 | AO12: =(AN12/AL12)*12 -> 0.0087152367 | AP12: =AL12*($AK$3/12) -> 4346.9481 | AQ12: =(AP12/AL12)*12 -> 0.0775 | AR12: =AR11+AN12 -> 2413.0056 | AS12: =AS11+AP12 -> 21765.908 | AT12: =AL12-AN12 -> 672586.99 | AU12: =AR12+AS12 -> 24178.913 | AW12: 5 | AX12: 44986 | AY12: =BG11 -> 672977.34 | AZ12: =AZ11 -> 4719.6979 | BA12: =AZ12-BC12 -> 513.58953 | BB12: =(BA12/AY12)*12 -> 0.0091579225 | BC12: =AY12*($AX$3/12) -> 4206.1084 | BD12: =(BC12/AY12)*12 -> 0.075 | BE12: =BE11+BA12 -> 2536.2452 | BF12: =BF11+BC12 -> 21062.244 | BG12: =AY12-BA12 -> 672463.75 | BH12: =BE12+BF12 -> 23598.49 | BJ12: 5 | BK12: 44986 | BL12: =BT11 -> 672874.58 | BM12: =BM11 -> 4604.6899 | BN12: =BM12-BP12 -> 539.406 | BO12: =(BN12/BL12)*12 -> 0.0096197303 | BP12: =BL12*($BK$3/12) -> 4065.2839 | BQ12: =(BP12/BL12)*12 -> 0.0725 | BR12: =BR11+BN12 -> 2664.8305 | BS12: =BS11+BP12 -> 20358.619 | BT12: =BL12-BN12 -> 672335.17 | BU12: =BR12+BS12 -> 23023.449 | BW12: 5 | BX12: 44986 | BY12: =CG11 -> 672767.39 | BZ12: =BZ11 -> 4490.7918 | CA12: =BZ12-CC12 -> 566.31539 | CB12: =(CA12/BY12)*12 -> 0.01010124 | CC12: =BY12*($BX$3/12) -> 3924.4765 | CD12: =(CC12/BY12)*12 -> 0.07 | CE12: =CE11+CA12 -> 2798.9234 | CF12: =CF11+CC12 -> 19655.036 | CG12: =BY12-CA12 -> 672201.08 | CH12: =CE12+CF12 -> 22453.959
A13: =A12+1 -> 3 | B13: =VLOOKUP(A13*12,$J$7:$U$367,10) -> 165044.35 | C13: =VLOOKUP(A13*12,$W$7:$AH$367,10) -> 159945.8 | D13: =VLOOKUP(A13*12,$AJ$7:$AU$367,10) -> 154849.35 | E13: =VLOOKUP(A13*12,$AW$7:$BH$367,10) -> 149755.3 | F13: =VLOOKUP(A13*12,$BJ$7:$BU$367,10) -> 144663.91 | G13: =VLOOKUP(A13*12,$BW$7:$CH$367,10) -> 139575.51 | J13: 6 | K13: 45017 | L13: =T12 -> 672818.08 | M13: =$L$8/((($N$4)-1)/($N$3*$N$4)) -> 5071.0496 | N13: =M13-P13 -> 445.42527 | O13: =(N13/L13)*12 -> 0.0079443513 | P13: =L13*($K$3/12) -> 4625.6243 | Q13: =(P13/L13)*12 -> 0.0825 | R13: =R12+N13 -> 2627.344 | S13: =S12+P13 -> 27798.953 | T13: =L13-N13 -> 672372.66 | U13: =R13+S13 -> 30426.297 | W13: 6 | X13: 45017 | Y13: =AG12 -> 672705.05 | Z13: =Z12 -> 4952.9109 | AA13: =Z13-AC13 -> 468.21054 | AB13: =(AA13/Y13)*12 -> 0.0083521396 | AC13: =Y13*($X$3/12) -> 4484.7003 | AD13: =(AC13/Y13)*12 -> 0.08 | AE13: =AE12+AA13 -> 2763.1609 | AF13: =AF12+AC13 -> 26954.304 | AG13: =Y13-AA13 -> 672236.84 | AH13: =AE13+AF13 -> 29717.465 | AJ13: 6 | AK13: 45017 | AL13: =AT12 -> 672586.99 | AM13: =AM12 -> 4835.7827 | AN13: =AM13-AP13 -> 491.99165 | AO13: =(AN13/AL13)*12 -> 0.0087778977 | AP13: =AL13*($AK$3/12) -> 4343.791 | AQ13: =(AP13/AL13)*12 -> 0.0775 | AR13: =AR12+AN13 -> 2904.9973 | AS13: =AS12+AP13 -> 26109.699 | AT13: =AL13-AN13 -> 672095 | AU13: =AR13+AS13 -> 29014.696 | AW13: 6 | AX13: 45017 | AY13: =BG12 -> 672463.75 | AZ13: =AZ12 -> 4719.6979 | BA13: =AZ13-BC13 -> 516.79947 | BB13: =(BA13/AY13)*12 -> 0.0092221975 | BC13: =AY13*($AX$3/12) -> 4202.8985 | BD13: =(BC13/AY13)*12 -> 0.075 | BE13: =BE12+BA13 -> 3053.0447 | BF13: =BF12+BC13 -> 25265.143 | BG13: =AY13-BA13 -> 671946.96 | BH13: =BE13+BF13 -> 28318.188 | BJ13: 6 | BK13: 45017 | BL13: =BT12 -> 672335.17 | BM13: =BM12 -> 4604.6899 | BN13: =BM13-BP13 -> 542.66491 | BO13: =(BN13/BL13)*12 -> 0.009685614 | BP13: =BL13*($BK$3/12) -> 4062.025 | BQ13: =(BP13/BL13)*12 -> 0.0725 | BR13: =BR12+BN13 -> 3207.4954 | BS13: =BS12+BP13 -> 24420.644 | BT13: =BL13-BN13 -> 671792.5 | BU13: =BR13+BS13 -> 27628.139 | BW13: 6 | BX13: 45017 | BY13: =CG12 -> 672201.08 | BZ13: =BZ12 -> 4490.7918 | CA13: =BZ13-CC13 -> 569.6189 | CB13: =(CA13/BY13)*12 -> 0.010168723 | CC13: =BY13*($BX$3/12) -> 3921.1729 | CD13: =(CC13/BY13)*12 -> 0.07 | CE13: =CE12+CA13 -> 3368.5423 | CF13: =CF12+CC13 -> 23576.209 | CG13: =BY13-CA13 -> 671631.46 | CH13: =CE13+CF13 -> 26944.751
A14: =A13+1 -> 4 | B14: =VLOOKUP(A14*12,$J$7:$U$367,10) -> 219031.24 | C14: =VLOOKUP(A14*12,$W$7:$AH$367,10) -> 212218.23 | D14: =VLOOKUP(A14*12,$AJ$7:$AU$367,10) -> 205409.22 | E14: =VLOOKUP(A14*12,$AW$7:$BH$367,10) -> 198604.7 | F14: =VLOOKUP(A14*12,$BJ$7:$BU$367,10) -> 191805.17 | G14: =VLOOKUP(A14*12,$BW$7:$CH$367,10) -> 185011.19 | J14: 7 | K14: 45047 | L14: =T13 -> 672372.66 | M14: =$L$8/((($N$4)-1)/($N$3*$N$4)) -> 5071.0496 | N14: =M14-P14 -> 448.48757 | O14: =(N14/L14)*12 -> 0.0080042678 | P14: =L14*($K$3/12) -> 4622.562 | Q14: =(P14/L14)*12 -> 0.0825 | R14: =R13+N14 -> 3075.8316 | S14: =S13+P14 -> 32421.515 | T14: =L14-N14 -> 671924.17 | U14: =R14+S14 -> 35497.347 | W14: 7 | X14: 45047 | Y14: =AG13 -> 672236.84 | Z14: =Z13 -> 4952.9109 | AA14: =Z14-AC14 -> 471.33195 | AB14: =(AA14/Y14)*12 -> 0.0084136766 | AC14: =Y14*($X$3/12) -> 4481.5789 | AD14: =(AC14/Y14)*12 -> 0.08 | AE14: =AE13+AA14 -> 3234.4929 | AF14: =AF13+AC14 -> 31435.883 | AG14: =Y14-AA14 -> 671765.51 | AH14: =AE14+AF14 -> 34670.376 | AJ14: 7 | AK14: 45047 | AL14: =AT13 -> 672095 | AM14: =AM13 -> 4835.7827 | AN14: =AM14-AP14 -> 495.1691 | AO14: =(AN14/AL14)*12 -> 0.0088410554 | AP14: =AL14*($AK$3/12) -> 4340.6136 | AQ14: =(AP14/AL14)*12 -> 0.0775 | AR14: =AR13+AN14 -> 3400.1664 | AS14: =AS13+AP14 -> 30450.312 | AT14: =AL14-AN14 -> 671599.83 | AU14: =AR14+AS14 -> 33850.479 | AW14: 7 | AX14: 45047 | AY14: =BG13 -> 671946.96 | AZ14: =AZ13 -> 4719.6979 | BA14: =AZ14-BC14 -> 520.02946 | BB14: =(BA14/AY14)*12 -> 0.0092869735 | BC14: =AY14*($AX$3/12) -> 4199.6685 | BD14: =(BC14/AY14)*12 -> 0.075 | BE14: =BE13+BA14 -> 3573.0741 | BF14: =BF13+BC14 -> 29464.811 | BG14: =AY14-BA14 -> 671426.93 | BH14: =BE14+BF14 -> 33037.886 | BJ14: 7 | BK14: 45047 | BL14: =BT13 -> 671792.5 | BM14: =BM13 -> 4604.6899 | BN14: =BM14-BP14 -> 545.94351 | BO14: =(BN14/BL14)*12 -> 0.0097520024 | BP14: =BL14*($BK$3/12) -> 4058.7464 | BQ14: =(BP14/BL14)*12 -> 0.0725 | BR14: =BR13+BN14 -> 3753.439 | BS14: =BS13+BP14 -> 28479.39 | BT14: =BL14-BN14 -> 671246.56 | BU14: =BR14+BS14 -> 32232.829 | BW14: 7 | BX14: 45047 | BY14: =CG13 -> 671631.46 | BZ14: =BZ13 -> 4490.7918 | CA14: =BZ14-CC14 -> 572.94167 | CB14: =(CA14/BY14)*12 -> 0.010236715 | CC14: =BY14*($BX$3/12) -> 3917.8502 | CD14: =(CC14/BY14)*12 -> 0.07 | CE14: =CE13+CA14 -> 3941.484 | CF14: =CF13+CC14 -> 27494.059 | CG14: =BY14-CA14 -> 671058.52 | CH14: =CE14+CF14 -> 31435.543
A15: =A14+1 -> 5 | B15: =VLOOKUP(A15*12,$J$7:$U$367,10) -> 272429.78 | C15: =VLOOKUP(A15*12,$W$7:$AH$367,10) -> 263896.19 | D15: =VLOOKUP(A15*12,$AJ$7:$AU$367,10) -> 255369.19 | E15: =VLOOKUP(A15*12,$AW$7:$BH$367,10) -> 246849.57 | F15: =VLOOKUP(A15*12,$BJ$7:$BU$367,10) -> 238338.14 | G15: =VLOOKUP(A15*12,$BW$7:$CH$367,10) -> 229835.74 | J15: 8 | K15: 45078 | L15: =T14 -> 671924.17 | M15: =$L$8/((($N$4)-1)/($N$3*$N$4)) -> 5071.0496 | N15: =M15-P15 -> 451.57092 | O15: =(N15/L15)*12 -> 0.0080646765 | P15: =L15*($K$3/12) -> 4619.4787 | Q15: =(P15/L15)*12 -> 0.0825 | R15: =R14+N15 -> 3527.4025 | S15: =S14+P15 -> 37040.994 | T15: =L15-N15 -> 671472.6 | U15: =R15+S15 -> 40568.397 | W15: 8 | X15: 45078 | Y15: =AG14 -> 671765.51 | Z15: =Z14 -> 4952.9109 | AA15: =Z15-AC15 -> 474.47416 | AB15: =(AA15/Y15)*12 -> 0.0084757104 | AC15: =Y15*($X$3/12) -> 4478.4367 | AD15: =(AC15/Y15)*12 -> 0.08 | AE15: =AE14+AA15 -> 3708.967 | AF15: =AF14+AC15 -> 35914.32 | AG15: =Y15-AA15 -> 671291.03 | AH15: =AE15+AF15 -> 39623.287 | AJ15: 8 | AK15: 45078 | AL15: =AT14 -> 671599.83 | AM15: =AM14 -> 4835.7827 | AN15: =AM15-AP15 -> 498.36707 | AO15: =(AN15/AL15)*12 -> 0.0089047145 | AP15: =AL15*($AK$3/12) -> 4337.4156 | AQ15: =(AP15/AL15)*12 -> 0.0775 | AR15: =AR14+AN15 -> 3898.5335 | AS15: =AS14+AP15 -> 34787.728 | AT15: =AL15-AN15 -> 671101.47 | AU15: =AR15+AS15 -> 38686.261 | AW15: 8 | AX15: 45078 | AY15: =BG14 -> 671426.93 | AZ15: =AZ14 -> 4719.6979 | BA15: =AZ15-BC15 -> 523.27965 | BB15: =(BA15/AY15)*12 -> 0.0093522549 | BC15: =AY15*($AX$3/12) -> 4196.4183 | BD15: =(BC15/AY15)*12 -> 0.075 | BE15: =BE14+BA15 -> 4096.3538 | BF15: =BF14+BC15 -> 33661.23 | BG15: =AY15-BA15 -> 670903.65 | BH15: =BE15+BF15 -> 37757.583 | BJ15: 8 | BK15: 45078 | BL15: =BT14 -> 671246.56 | BM15: =BM14 -> 4604.6899 | BN15: =BM15-BP15 -> 549.24192 | BO15: =(BN15/BL15)*12 -> 0.0098189002 | BP15: =BL15*($BK$3/12) -> 4055.448 | BQ15: =(BP15/BL15)*12 -> 0.0725 | BR15: =BR14+BN15 -> 4302.6809 | BS15: =BS14+BP15 -> 32534.838 | BT15: =BL15-BN15 -> 670697.32 | BU15: =BR15+BS15 -> 36837.519 | BW15: 8 | BX15: 45078 | BY15: =CG14 -> 671058.52 | BZ15: =BZ14 -> 4490.7918 | CA15: =BZ15-CC15 -> 576.28383 | CB15: =(CA15/BY15)*12 -> 0.010305221 | CC15: =BY15*($BX$3/12) -> 3914.508 | CD15: =(CC15/BY15)*12 -> 0.07 | CE15: =CE14+CA15 -> 4517.7678 | CF15: =CF14+CC15 -> 31408.567 | CG15: =BY15-CA15 -> 670482.23 | CH15: =CE15+CF15 -> 35926.335
A16: =A15+1 -> 6 | B16: =VLOOKUP(A16*12,$J$7:$U$367,10) -> 325189.58 | C16: =VLOOKUP(A16*12,$W$7:$AH$367,10) -> 314930.31 | D16: =VLOOKUP(A16*12,$AJ$7:$AU$367,10) -> 304681.08 | E16: =VLOOKUP(A16*12,$AW$7:$BH$367,10) -> 294442.99 | F16: =VLOOKUP(A16*12,$BJ$7:$BU$367,10) -> 284217.22 | G16: =VLOOKUP(A16*12,$BW$7:$CH$367,10) -> 274004.99 | J16: 9 | K16: 45108 | L16: =T15 -> 671472.6 | M16: =$L$8/((($N$4)-1)/($N$3*$N$4)) -> 5071.0496 | N16: =M16-P16 -> 454.67547 | O16: =(N16/L16)*12 -> 0.008125582 | P16: =L16*($K$3/12) -> 4616.3741 | Q16: =(P16/L16)*12 -> 0.0825 | R16: =R15+N16 -> 3982.0779 | S16: =S15+P16 -> 41657.368 | T16: =L16-N16 -> 671017.92 | U16: =R16+S16 -> 45639.446 | W16: 9 | X16: 45108 | Y16: =AG15 -> 671291.03 | Z16: =Z15 -> 4952.9109 | AA16: =Z16-AC16 -> 477.63732 | AB16: =(AA16/Y16)*12 -> 0.0085382458 | AC16: =Y16*($X$3/12) -> 4475.2736 | AD16: =(AC16/Y16)*12 -> 0.08 | AE16: =AE15+AA16 -> 4186.6044 | AF16: =AF15+AC16 -> 40389.594 | AG16: =Y16-AA16 -> 670813.4 | AH16: =AE16+AF16 -> 44576.198 | AJ16: 9 | AK16: 45108 | AL16: =AT15 -> 671101.47 | AM16: =AM15 -> 4835.7827 | AN16: =AM16-AP16 -> 501.58569 | AO16: =(AN16/AL16)*12 -> 0.0089688796 | AP16: =AL16*($AK$3/12) -> 4334.197 | AQ16: =(AP16/AL16)*12 -> 0.0775 | AR16: =AR15+AN16 -> 4400.1191 | AS16: =AS15+AP16 -> 39121.925 | AT16: =AL16-AN16 -> 670599.88 | AU16: =AR16+AS16 -> 43522.044 | AW16: 9 | AX16: 45108 | AY16: =BG15 -> 670903.65 | AZ16: =AZ15 -> 4719.6979 | BA16: =AZ16-BC16 -> 526.55014 | BB16: =(BA16/AY16)*12 -> 0.0094180465 | BC16: =AY16*($AX$3/12) -> 4193.1478 | BD16: =(BC16/AY16)*12 -> 0.075 | BE16: =BE15+BA16 -> 4622.9039 | BF16: =BF15+BC16 -> 37854.377 | BG16: =AY16-BA16 -> 670377.1 | BH16: =BE16+BF16 -> 42477.281 | BJ16: 9 | BK16: 45108 | BL16: =BT15 -> 670697.32 | BM16: =BM15 -> 4604.6899 | BN16: =BM16-BP16 -> 552.56025 | BO16: =(BN16/BL16)*12 -> 0.0098863121 | BP16: =BL16*($BK$3/12) -> 4052.1296 | BQ16: =(BP16/BL16)*12 -> 0.0725 | BR16: =BR15+BN16 -> 4855.2411 | BS16: =BS15+BP16 -> 36586.968 | BT16: =BL16-BN16 -> 670144.76 | BU16: =BR16+BS16 -> 41442.209 | BW16: 9 | BX16: 45108 | BY16: =CG15 -> 670482.23 | BZ16: =BZ15 -> 4490.7918 | CA16: =BZ16-CC16 -> 579.64549 | CB16: =(CA16/BY16)*12 -> 0.010374243 | CC16: =BY16*($BX$3/12) -> 3911.1464 | CD16: =(CC16/BY16)*12 -> 0.07 | CE16: =CE15+CA16 -> 5097.4133 | CF16: =CF15+CC16 -> 35319.713 | CG16: =BY16-CA16 -> 669902.59 | CH16: =CE16+CF16 -> 40417.127
