Workbook
Name If: #REF!
Name If: #REF!

Sheet Calculators
A3: Year | C3: Annual ROI | G3: Year | I3: Annual ROI | S3: IRR | T3: =XIRR(T4:T10,R4:R10) -> 0.21632629
A4: 0 | B4: 100000 | G4: 0 | H4: 100000 | M4: Present Value=Future Value /( 1+i)^n | R4: 45292 | S4: Initial Investment | T4: -8500000
A5: =A4+1 -> 1 | B5: 110000 | C5: =(B5/B4)-1 -> 0.1 | G5: =G4+1 -> 1 | H5: 110000 | I5: =(H5/H4)-1 -> 0.1 | M5: interest | N5: 0.08 | R5: =R4+365 -> 45657 | S5: Year 1 Cashflow | T5: =-$T$4*$U$5 -> 1360000 | U5: 0.16 | V5: Cash On Cash
A6: =A5+1 -> 2 | B6: 105000 | C6: =(B6/B5)-1 -> -0.045454545 | G6: =G5+1 -> 2 | H6: 105000 | I6: =(H6/H5)-1 -> -0.045454545 | M6: time (yrs) | N6: 5 | O6: =N6*12 -> 60 | R6: =R5+365 -> 46022 | S6: Year 2 Cashflow | T6: =-$T$4*$U$5 -> 1360000
A7: =A6+1 -> 3 | B7: 120000 | C7: =(B7/B6)-1 -> 0.14285714 | G7: =G6+1 -> 3 | H7: 120000 | I7: =(H7/H6)-1 -> 0.14285714 | R7: =R6+365 -> 46387 | S7: Year 3 Cashflow | T7: =-$T$4*$U$5 -> 1360000
A8: =A7+1 -> 4 | B8: =B7+5000 -> 125000 | C8: =(B8/B7)-1 -> 0.041666667 | G8: =G7+1 -> 4 | H8: =H7+5000 -> 125000 | I8: =(H8/H7)-1 -> 0.041666667 | R8: =R7+365 -> 46752 | S8: Year 4 Cashflow | T8: =-$T$4*$U$5 -> 1360000
A9: =A8+1 -> 5 | B9: =B8+5000 -> 130000 | C9: =(B9/B8)-1 -> 0.04 | G9: =G8+1 -> 5 | H9: =H8+5000 -> 130000 | I9: =(H9/H8)-1 -> 0.04 | R9: =R8+365 -> 47117 | S9: Year 5 Cashflow | T9: =-$T$4*$U$5 -> 1360000
A10: =A9+1 -> 6 | B10: =B9+5000 -> 135000 | C10: =(B10/B9)-1 -> 0.038461538 | R10: =R9+365 -> 47482 | S10: 6 | T10: =-T4*(1+U10)^S10 -> 14813534 | U10: 0.097 | V10: Assumed Appreciation
A11: =A10+1 -> 7 | B11: =B10+5000 -> 140000 | C11: =(B11/B10)-1 -> 0.037037037 | I11: =(H9-H4)/H4 -> 0.3 | J11: ROI
A12: =A11+1 -> 8 | B12: =B11+5000 -> 145000 | C12: =(B12/B11)-1 -> 0.035714286 | I12: =SUM(I5:I9)/COUNT(I5:I9) -> 0.055813853 | J12: AAR
A13: =A12+1 -> 9 | B13: =B12+5000 -> 150000 | C13: =(B13/B12)-1 -> 0.034482759 | I13: =(H9/H4)^(1/COUNT(I4:I9))-1 -> 0.053873952 | J13: CAGR | M13: 0.105 | N13: projected Cash On Cash Return
A14: =A13+1 -> 10 | B14: =B13+5000 -> 155000 | C14: =(B14/B13)-1 -> 0.033333333 | I14: =H9/H4 -> 1.3 | J14: Equity Multiplier | M14: 8500000 | N14: initial investment
M15: =O15*12 -> 60 | N15: hold period | O15: 5
C16: =(B14-B4)/B4 -> 0.55 | D16: ROI
C17: =SUM(C5:C14)/COUNT(C5:C14) -> 0.045809822 | D17: AAR | M17: Future | N17: =M14*(1+M13/12)^(M15) -> 14336125 | O17: =N17/M14 -> 1.686603 | P17: Equity Multiple
C18: =(B14/B4)^(1/COUNT(C4:C14))-1 -> 0.044800014 | D18: CAGR | M18: CAGR | N18: =(N17/M14)^(1/(O15*4))-1 -> 0.026480357
C19: =B14/B4 -> 1.55 | D19: Equity Multiplier

Sheet STR Calculator
A1: https://www.zillow.com/homedetails/2615-Whippoorwill-Hill-Way-Sevierville-TN-37862/42506804_zpid/ | H1: Heloc Down Payment | I1: 0.0825
A2: 2615 Whippor Will Way - 1bd / 3bath - 1617 sqft | B2: 1617 | C2: sqft | D2: =A3/B2 -> 370.43908 | E2: per sqft | H2: Heloc Loan Terms | I2: 20 | J2: yrs
A3: =B5 -> 599000 | B3: asking price | H3: HELOC Amount | I3: =SUM(B7+B6-C5-C4) -> 64800
C4: 5000 | D4: earnest money | H4: HELOC P&I Payment | I4: =-PMT($I$1/12,$I$2*12,I3) -> 552.13854 | J4: =I4*12 -> 6625.6625 | L4: IRR | M4: =IRR(M5:M11) -> 0.036890162
A5: Purchase Price | B5: 599000 | C5: 50000 | D5: cash | H5: HELOC Principle Payment | I5: =-PPMT($I$1/12,1,$I$2*12,I3) -> 106.63854 | J5: =I5*12 -> 1279.6625 | L5: Initial Investment | M5: =-B5 -> -599000
A6: Closing Costs (4%) | B6: 0 | C6: $B$5*0.04 | H6: HELOC Interest Only Payment | I6: =-IPMT($I$1/12,1,$I$2*12,I3) -> 445.5 | J6: =I6*12 -> 5346 | L6: Year 1 Cashflow | M6: ='STR 10 Year'!B39 -> 10780.097
A7: Down Payment | B7: =B5*C7 -> 119800 | C7: 0.2 | D7: downpayment | L7: Year 2 Cashflow | M7: ='STR 10 Year'!C39 -> 11854.097
A8: Total Loan Amount | B8: =B5-B7 -> 479200 | H8: Conventional Loan Interest Rate | I8: =IF(C7=0.1,0.08062,0.0775) -> 0.0775 | J8: IF(C7=0.1,0.08062,0.0775) | L8: Year 3 Cashflow | M8: ='STR 10 Year'!D39 -> 12632.732
H9: Loan Term | I9: 30 | J9: yrs | L9: Year 4 Cashflow | M9: ='STR 10 Year'!E39 -> 13415.93
B10: Nightly | C10: Monthly | D10: Annually | H10: Monthly Payment on Purchase Price | I10: =-PMT($I$8/12,$I$9*12,$B$8) -> 3433.0475 | L10: Year 5 Cashflow | M10: ='STR 10 Year'!F39 -> 14203.613
A11: Average Rent | B11: 250 | C11: =B11*30.5 -> 7625 | D11: =C11*12 -> 91500 | H11: Monthly Interest Payment on Purchase Price | I11: =-IPMT($I$8/12,1,$I$9*12,$B$8) -> 3094.8333 | L11: 6 | M11: =$B$5*(1+0.02)^L11 -> 674571.29 | N11: assumes 2%/yr appreciation
A12: Occupancy Rate | B12: 1 | C12: =-C11*(1-B12) -> 0 | D12: =C12*12 -> 0 | H12: Monthly Principle Payment on Purchase Price | I12: =-PPMT($I$8/12,1,$I$9*12,$B$8) -> 338.21415 | J12: =I12*12 -> 4058.5698
A13: Additional Income (Laundry/Storage etc) | C13: 0 | D13: =C13*12 -> 0
H14: Financials
A15: Calculated Gross Revenue | C15: =SUM(C11:C13) -> 7625 | D15: =C15*12 -> 91500 | H15: Cash On Cash Return (CoC) | I15: =C44/SUM($B$6:$B$7) -> 0.087980775 | L15: Desired Return | M15: 0.08
H16: ROE (Return on Equity) | I16: =C44/B7 -> 0.087980775
A17: Estimated Expenses | B17: Monthly | C17: Annually | H17: AAR | I17: ='STR 10 Year'!L50 -> 0.20744104 | L17: IRR | O17: NPV
A18: Management Fees | B18: =C11*D18 -> 0 | C18: =B18*12 -> 0 | D18: 0 | E18: =IF(D18=0,1,0) -> 1 | H18: Mortgage Pay Down yr 1 | I18: =PPMT($I$8/12,1,$I$9*12,$B$8)*12 -> -4058.5698 | L18: 45536 | M18: 0 | N18: =-SUM('STR Calculator'!B6:B7) -> -119800 | O18: =N18 -> -119800
A19: Subscriptions (AirDnA/Pricelabs/Guesty) | B19: 50 | C19: =B19*12 -> 600 | H19: Tax Savings at 25% | I19: =C44*0.25 -> 2635.0242 | L19: 45901 | M19: 1 | N19: ='STR 10 Year'!B39 -> 10780.097 | O19: =N19/(1+$M$15)^M19 -> 9981.5712
A20: AirBnB / VRBO Fee (3% of nightly) | B20: 0 | C20: =B20*12 -> 0 | L20: 46266 | M20: 2 | N20: ='STR 10 Year'!C39 -> 11854.097 | O20: =N20/(1+$M$15)^M20 -> 10162.977
A21: Property Taxes / Year | B21: 200 | C21: =B21*12 -> 2400 | D21: =C21/B5 -> 0.0040066778 | H21: Rules of Thumb | L21: 46631 | M21: 3 | N21: ='STR 10 Year'!D39 -> 12632.732 | O21: =N21/(1+$M$15)^M21 -> 10028.27
A22: Insurance / Year | B22: 250 | C22: =B22*12 -> 3000 | D22: =C22/B5 -> 0.0050083472 | H22: 50% Rule | L22: 46997 | M22: 4 | N22: ='STR 10 Year'!E39 -> 13415.93 | O22: =N22/(1+$M$15)^M22 -> 9861.1088
A23: Cleaners (per stay, average 6/month) - Trash included. Soap/Toilet Paper/Detergent etc. | B23: =D23*6 -> 1500 | C23: =B23*12 -> 18000 | D23: 250 | H23: 2% Rule | I23: =$C$11/$B$5 -> 0.012729549 | L23: 47362 | M23: 5 | N23: ='STR 10 Year'!F39 -> 14203.613 | O23: =N23/(1+$M$15)^M23 -> 9666.7401
A24: Handyman | B24: 250 | C24: =B24*12 -> 3000 | H24: DSCR | I24: =B40/(B42+B41+B43) -> 1.2264614 | L24: 47727 | M24: 6 | N24: ='STR 10 Year'!G39 -> 14995.698 | O24: =N24/(1+$M$15)^M24 -> 9449.8331
A25: HOA / year | B25: 0 | C25: =B25*12 -> 0 | D25: =C25/B5 -> 0 | L25: 48092 | M25: 7 | N25: ='STR 10 Year'!H39 -> 15792.095 | O25: =N25/(1+$M$15)^M25 -> 9214.5359
A26: Electricity | B26: 250 | C26: =B26*12 -> 3000 | L26: 48458 | M26: 8 | N26: ='STR 10 Year'!I39 -> 16592.711 | O26: =N26/(1+$M$15)^M26 -> 8964.5253
A27: Nat Gas(~$2k for large tank, for ~1.5yrs) | B27: =2000/18 -> 111.11111 | C27: =B27*12 -> 1333.3333 | L27: 48823 | M27: 9 | N27: ='STR 10 Year'!J39 -> 17397.442 | O27: =N27/(1+$M$15)^M27 -> 8703.0524
A28: WIFI / Cable | B28: 150 | C28: =B28*12 -> 1800 | H28: Emergency Fund Needed (6 months) | I28: =B38*$J$28+SUM(B41:B42)*$J$28 -> 40479.952 | J28: 6 | K28: months | L28: 49188 | M28: 10 | N28: ='STR 10 Year'!K39+'STR 10 Year'!K44-('STR Calculator'!B8-SUM('STR 10 Year'!B46:K46)) -> 491848.63 | O28: =N28/(1+$M$15)^M28 -> 227821.08
A29: Pool Service (bi-weekly = 2xmonth) | B29: 0 | C29: =B29*12 -> 0 | I29: =I28/2 -> 20239.976 | J29: =J28/2 -> 3 | K29: months
A30: Water/Sewer ($0 for well/septic) | B30: 0 | C30: =B30*12 -> 0 | N30: =XIRR(N18:N28,L18:L28) -> 0.2162627 | O30: =SUM(O18:O28) -> 194053.7
A31: Building Maintenance | B31: =C31/12 -> 0 | C31: =B5*D31 -> 0 | D31: 0
A32: Capex (Future Repairs) | B32: =C32/12 -> 0 | C32: =D32*B5 -> 0 | D32: 0
A33: Grounds Cleanup/Services Maintenance/Snow Removal | B33: 0 | C33: =B33*12 -> 0
A34: City Permit Fees | B34: 25 | C34: =B34*12 -> 300
A35: Fire Marshal Permit | B35: 20 | C35: =B35*12 -> 240
A36: Incidentals (Coffee/Creamer etc) | B36: 25 | C36: =B36*12 -> 300
A37: Umbrella Insurance (Allstate Anchorage) | B37: 37 | C37: =B37*12 -> 444
A38: Totals | B38: =SUM(B18:B37) -> 2868.1111 | C38: =SUM(C18:C37) -> 34417.333 | H38: Ask cleaners what is included vs not - Linens/soaps/shampoos/coffee/creamer
A40: Net Operating Income | B40: =C15-B38 -> 4756.8889 | C40: =D15-C38 -> 57082.667 | D40: DSCR | E40: =B40/(B42+B41+B43) -> 1.2264614
A41: HELOC Payment (Interest Only) | B41: =IF(I6<0,0,I6) -> 445.5 | C41: =B41*12 -> 5346 | D41: =IF(B41=I6,1,0) -> 1
...

Sheet Interest Rate Comparison
A1: Purchase Price | C1: 0.1 | D1: 0.15 | E1: 0.2 | F1: 0.25 | H1: 5% Increase in Down Payment | I1: Time to recoup
A2: ='STR Calculator'!B5 -> 599000 | B2: Down Payment | C2: =$A$2*C1 -> 59900 | D2: =$A$2*D1 -> 89850 | E2: =$A$2*E1 -> 119800 | F2: =$A$2*F1 -> 149750 | H2: =D2-C2 -> 29950
A3: 30 | B3: 0.0825 | C3: =PMT($B$3/12,$A$3*12,($A$2-C2)) -> -4050.0783 | D3: =PMT($B$3/12,$A$3*12,($A$2-D2)) -> -3825.0739 | E3: =PMT($B$3/12,$A$3*12,($A$2-E2)) -> -3600.0696 | F3: =PMT($B$3/12,$A$3*12,($A$2-F2)) -> -3375.0652 | G3: =B3 -> 0.0825 | H3: =D3-C3 -> 225.00435 | I3: =$H$2/H3/12 -> 11.092378
B4: 0.08 | C4: =PMT($B$4/12,$A$3*12,($A$2-C2)) -> -3955.7248 | D4: =PMT($B$4/12,$A$3*12,($A$2-D2)) -> -3735.9623 | E4: =PMT($B$4/12,$A$3*12,($A$2-E2)) -> -3516.1998 | F4: =PMT($B$4/12,$A$3*12,($A$2-F2)) -> -3296.4373 | G4: =B4 -> 0.08 | H4: =D4-C4 -> 219.76249 | I4: =$H$2/H4/12 -> 11.356958
B5: 0.0775 | C5: =PMT($B$5/12,$A$3*12,($A$2-C2)) -> -3862.1784 | D5: =PMT($B$5/12,$A$3*12,($A$2-D2)) -> -3647.6129 | E5: =PMT($B$5/12,$A$3*12,($A$2-E2)) -> -3433.0475 | F5: =PMT($B$5/12,$A$3*12,($A$2-F2)) -> -3218.482 | G5: =B5 -> 0.0775 | H5: =D5-C5 -> 214.56547 | I5: =$H$2/H5/12 -> 11.632036
B6: 0.075 | C6: =PMT($B$6/12,$A$3*12,($A$2-C2)) -> -3769.4654 | D6: =PMT($B$6/12,$A$3*12,($A$2-D2)) -> -3560.0507 | E6: =PMT($B$6/12,$A$3*12,($A$2-E2)) -> -3350.6359 | F6: =PMT($B$6/12,$A$3*12,($A$2-F2)) -> -3141.2212 | G6: =B6 -> 0.075 | H6: =D6-C6 -> 209.41475 | I6: =$H$2/H6/12 -> 11.918136
B7: 0.0725 | C7: =PMT($B$7/12,$A$3*12,($A$2-C2)) -> -3677.6123 | D7: =PMT($B$7/12,$A$3*12,($A$2-D2)) -> -3473.3005 | E7: =PMT($B$7/12,$A$3*12,($A$2-E2)) -> -3268.9887 | F7: =PMT($B$7/12,$A$3*12,($A$2-F2)) -> -3064.6769 | G7: =B7 -> 0.0725 | H7: =D7-C7 -> 204.3118 | I7: =$H$2/H7/12 -> 12.215806
B8: 0.07 | C8: =PMT($B$8/12,$A$3*12,($A$2-C2)) -> -3586.6458 | D8: =PMT($B$8/12,$A$3*12,($A$2-D2)) -> -3387.3877 | E8: =PMT($B$8/12,$A$3*12,($A$2-E2)) -> -3188.1296 | F8: =PMT($B$8/12,$A$3*12,($A$2-F2)) -> -2988.8715 | G8: =B8 -> 0.07 | H8: =D8-C8 -> 199.2581 | I8: =$H$2/H8/12 -> 12.525631
G9: Higher delta between P&I payment at higher interest rate compared to lower = shorter payout, when factoring in increased down payment for lower rate
A12: Down Payment % | B12: Down Payment | C12: Interest Rate | D12: ="Interest Paid on Down Payment by Year "&ROUND(I4,0) -> Interest Paid on Down Payment by Year 11 | E12: Down Payment Difference | F12: ="Interest Paid Difference @ year "&ROUND(I4,0) -> Interest Paid Difference @ year 11 | G12: Down Payment vs Interest Paid | H12: =ROUND(I4,0)&"yr FV of down payment saved @ 8%" -> 11yr FV of down payment saved @ 8% | I12: NPV of Interest Saved/Lost | J12: ="Cum Interest Paid Year "&ROUND(I4,0) -> Cum Interest Paid Year 11 | K12: Interest Saved Compared to 10% Loan | L12: Total Interest Paid - Life of Loan
A13: =C1 -> 0.1 | B13: =$A$2*A13 -> 59900 | C13: =B4 -> 0.08 | D13: =B13*(1+C13)^$I$4 -> 143555.23 | E13: 0 | F13: 0 | G13: =F13-E13 -> 0 | H13: 0 | I13: 0 | J13: =VLOOKUP($I$4*12,'Amoritization Scenario 10% DP'!$W$8:$AH$367,10) -> 458293.33 | K13: 0 | L13: 1270301
A14: =D1 -> 0.15 | B14: =$A$2*A14 -> 89850 | C14: =B4 -> 0.08 | D14: =B14*(1+C14)^$I$4 -> 215332.84 | E14: =B14-B13 -> 29950 | F14: =D14-D13 -> 71777.613 | G14: =F14-E14 -> 41827.613 | H14: =E14*(1+0.08)^I4 -> 71777.613 | I14: =G14/(1+C14)^I4 -> 17453.032 | J14: =VLOOKUP($I$4*12,'Amoritization Scenario 15% DP'!$W$8:$AH$367,10) -> 432832.59 | K14: =J13-J14 -> 25460.74 | L14: 1199728 | M14: =L14+H14 -> 1271505.6
A15: =E1 -> 0.2 | B15: =$A$2*A15 -> 119800 | C15: =B5 -> 0.0775 | D15: =B15*(1+C15)^$I$4 -> 279652.36 | E15: =B15-B13 -> 59900 | F15: =D15-D13 -> 136097.13 | G15: =F15-E15 -> 76197.134 | H15: =E15*(1+0.08)^I4 -> 143555.23 | I15: =G15/(1+C15)^I4 -> 32642.016 | J15: =VLOOKUP($I$4*12,'Amoritization Scenario 20% DP'!$AJ$8:$AU$367,10) -> 393573.27 | K15: =J13-J15 -> 64720.056 | L15: 1034105 | M15: =L15+H15 -> 1177660.2
K17: Present Value=Future Value /( 1+i)^n

Sheet STR 10 Year
A1: Year | B1: 1 | C1: 2 | D1: 3 | E1: 4 | F1: 5 | G1: 6 | H1: 7 | I1: 8 | J1: 9 | K1: 10
A2: Property Income | L2: Desired Return | M2: 0.08 | N2: match stock market
A3: Yearly Revenue | B3: ='STR Calculator'!D11 -> 91500 | C3: =B3*(1+C5) -> 92415 | D3: =C3*(1+D5) -> 93339.15 | E3: =D3*(1+E5) -> 94272.541 | F3: =E3*(1+F5) -> 95215.267 | G3: =F3*(1+G5) -> 96167.42 | H3: =G3*(1+H5) -> 97129.094 | I3: =H3*(1+I5) -> 98100.385 | J3: =I3*(1+J5) -> 99081.389 | K3: =J3*(1+K5) -> 100072.2
A4: Monthly Revenue | B4: =B3/12 -> 7625 | C4: =C3/12 -> 7701.25 | D4: =D3/12 -> 7778.2625 | E4: =E3/12 -> 7856.0451 | F4: =F3/12 -> 7934.6056 | G4: =G3/12 -> 8013.9516 | H4: =H3/12 -> 8094.0911 | I4: =I3/12 -> 8175.0321 | ... K4: =K3/12 -> 8339.3502 | M4: IRR | P4: NPV
A5: Rent Appreciation | B5: 0.01 | C5: =$B$5 -> 0.01 | D5: =$B$5 -> 0.01 | E5: =$B$5 -> 0.01 | F5: =$B$5 -> 0.01 | G5: =$B$5 -> 0.01 | H5: =$B$5 -> 0.01 | I5: =$B$5 -> 0.01 | J5: =$B$5 -> 0.01 | K5: =$B$5 -> 0.01 | M5: 45536 | N5: 0 | O5: =-SUM('STR Calculator'!B6:B7) -> -119800 | P5: =O5 -> -119800
A6: ="Vacancy Loss (Occupancy rate "&'STR Calculator'!$B$12&"%)" -> Vacancy Loss (Occupancy rate 1%) | B6: =B3*(1-'STR Calculator'!$B$12) -> 0 | C6: =C3*(1-'STR Calculator'!$B$12) -> 0 | D6: =D3*(1-'STR Calculator'!$B$12) -> 0 | E6: =E3*(1-'STR Calculator'!$B$12) -> 0 | F6: =F3*(1-'STR Calculator'!$B$12) -> 0 | G6: =G3*(1-'STR Calculator'!$B$12) -> 0 | H6: =H3*(1-'STR Calculator'!$B$12) -> 0 | I6: =I3*(1-'STR Calculator'!$B$12) -> 0 | ... K6: =K3*(1-'STR Calculator'!$B$12) -> 0 | M6: 45901 | N6: 1 | O6: =B39 -> 10780.097 | P6: =O6/(1+$M$2)^N6 -> 9981.5712
M7: 46266 | N7: 2 | O7: =C39 -> 11854.097 | P7: =O7/(1+$M$2)^N7 -> 10162.977
A8: Operating Income | B8: =B3-B6 -> 91500 | C8: =C3-C6 -> 92415 | D8: =D3-D6 -> 93339.15 | E8: =E3-E6 -> 94272.541 | F8: =F3-F6 -> 95215.267 | G8: =G3-G6 -> 96167.42 | H8: =H3-H6 -> 97129.094 | I8: =I3-I6 -> 98100.385 | ... K8: =K3-K6 -> 100072.2 | M8: 46631 | N8: 3 | O8: =D39 -> 12632.732 | P8: =O8/(1+$M$2)^N8 -> 10028.27
M9: 46997 | N9: 4 | O9: =E39 -> 13415.93 | P9: =O9/(1+$M$2)^N9 -> 9861.1088
A10: Property Expenses | M10: 47362 | N10: 5 | O10: =F39 -> 14203.613 | P10: =O10/(1+$M$2)^N10 -> 9666.7401
A11: Management Fee | B11: ='STR Calculator'!$C$18 -> 0 | C11: =$B$11 -> 0 | D11: =$B$11 -> 0 | E11: =$B$11 -> 0 | F11: =$B$11 -> 0 | G11: =$B$11 -> 0 | H11: =$B$11 -> 0 | I11: =$B$11 -> 0 | J11: =$B$11 -> 0 | K11: =$B$11 -> 0 | M11: 47727 | N11: 6 | O11: =G39 -> 14995.698 | P11: =O11/(1+$M$2)^N11 -> 9449.8331
A12: Subscriptions | B12: ='STR Calculator'!$C$19 -> 600 | C12: ='STR Calculator'!$C$19 -> 600 | D12: ='STR Calculator'!$C$19 -> 600 | E12: ='STR Calculator'!$C$19 -> 600 | F12: ='STR Calculator'!$C$19 -> 600 | G12: ='STR Calculator'!$C$19 -> 600 | H12: ='STR Calculator'!$C$19 -> 600 | I12: ='STR Calculator'!$C$19 -> 600 | ... K12: ='STR Calculator'!$C$19 -> 600 | M12: 48092 | N12: 7 | O12: =H39 -> 15792.095 | P12: =O12/(1+$M$2)^N12 -> 9214.5359
A13: AirBnB/VRBO Fee (3% of nightly- Passed to guest) | B13: ='STR Calculator'!$C$20 -> 0 | C13: ='STR Calculator'!$C$20 -> 0 | D13: ='STR Calculator'!$C$20 -> 0 | E13: ='STR Calculator'!$C$20 -> 0 | F13: ='STR Calculator'!$C$20 -> 0 | G13: ='STR Calculator'!$C$20 -> 0 | H13: ='STR Calculator'!$C$20 -> 0 | I13: ='STR Calculator'!$C$20 -> 0 | ... K13: ='STR Calculator'!$C$20 -> 0 | M13: 48458 | N13: 8 | O13: =I39 -> 16592.711 | P13: =O13/(1+$M$2)^N13 -> 8964.5253
A14: Property Taxes (1.5%) | B14: ='STR Calculator'!$C$21 -> 2400 | C14: =B44*($B$14/'STR Calculator'!$B$5) -> 2496 | D14: =C44*($B$14/'STR Calculator'!$B$5) -> 2595.84 | E14: =D44*($B$14/'STR Calculator'!$B$5) -> 2699.6736 | F14: =E44*($B$14/'STR Calculator'!$B$5) -> 2807.6605 | G14: =F44*($B$14/'STR Calculator'!$B$5) -> 2919.967 | H14: =G44*($B$14/'STR Calculator'!$B$5) -> 3036.7656 | I14: =H44*($B$14/'STR Calculator'!$B$5) -> 3158.2363 | J14: =I44*($B$14/'STR Calculator'!$B$5) -> 3284.5657 | K14: =J44*($B$14/'STR Calculator'!$B$5) -> 3415.9483 | M14: 48823 | N14: 9 | O14: =J39 -> 17397.442 | P14: =O14/(1+$M$2)^N14 -> 8703.0524
A15: Insurance (1.5%) | B15: ='STR Calculator'!$C$22 -> 3000 | C15: =B15+(B15*0.015) -> 3045 | D15: =C15+(C15*0.015) -> 3090.675 | E15: =D15+(D15*0.015) -> 3137.0351 | F15: =E15+(E15*0.015) -> 3184.0907 | G15: =F15+(F15*0.015) -> 3231.852 | H15: =G15+(G15*0.015) -> 3280.3298 | I15: =H15+(H15*0.015) -> 3329.5347 | J15: =I15+(I15*0.015) -> 3379.4778 | K15: =J15+(J15*0.015) -> 3430.1699 | M15: 49188 | N15: 10 | O15: =K39+K44-('STR Calculator'!B8-SUM('STR 10 Year'!B46:K46)) -> 491848.63 | P15: =O15/(1+$M$2)^N15 -> 227821.08
A16: Cleaners/Handyman | B16: =SUM('STR Calculator'!$C$23:$C$24) -> 21000 | C16: =SUM('STR Calculator'!$C$23:$C$24) -> 21000 | D16: =SUM('STR Calculator'!$C$23:$C$24) -> 21000 | E16: =SUM('STR Calculator'!$C$23:$C$24) -> 21000 | F16: =SUM('STR Calculator'!$C$23:$C$24) -> 21000 | G16: =SUM('STR Calculator'!$C$23:$C$24) -> 21000 | H16: =SUM('STR Calculator'!$C$23:$C$24) -> 21000 | I16: =SUM('STR Calculator'!$C$23:$C$24) -> 21000 | ... K16: =SUM('STR Calculator'!$C$23:$C$24) -> 21000
A17: HOA Fees | B17: ='STR Calculator'!$C$25 -> 0 | C17: ='STR Calculator'!$C$25 -> 0 | D17: ='STR Calculator'!$C$25 -> 0 | E17: ='STR Calculator'!$C$25 -> 0 | F17: ='STR Calculator'!$C$25 -> 0 | G17: ='STR Calculator'!$C$25 -> 0 | H17: ='STR Calculator'!$C$25 -> 0 | I17: ='STR Calculator'!$C$25 -> 0 | ... K17: ='STR Calculator'!$C$25 -> 0 | O17: =XIRR(O5:O15,M5:M15) -> 0.2162627 | P17: =SUM(P5:P15) -> 194053.7
A18: Electricity | B18: ='STR Calculator'!$C$26 -> 3000 | C18: ='STR Calculator'!$C$26 -> 3000 | D18: ='STR Calculator'!$C$26 -> 3000 | E18: ='STR Calculator'!$C$26 -> 3000 | F18: ='STR Calculator'!$C$26 -> 3000 | G18: ='STR Calculator'!$C$26 -> 3000 | H18: ='STR Calculator'!$C$26 -> 3000 | I18: ='STR Calculator'!$C$26 -> 3000 | ... K18: ='STR Calculator'!$C$26 -> 3000
A19: Natural Gas | B19: ='STR Calculator'!$C$27 -> 1333.3333 | C19: ='STR Calculator'!$C$27 -> 1333.3333 | D19: ='STR Calculator'!$C$27 -> 1333.3333 | E19: ='STR Calculator'!$C$27 -> 1333.3333 | F19: ='STR Calculator'!$C$27 -> 1333.3333 | G19: ='STR Calculator'!$C$27 -> 1333.3333 | H19: ='STR Calculator'!$C$27 -> 1333.3333 | I19: ='STR Calculator'!$C$27 -> 1333.3333 | ... K19: ='STR Calculator'!$C$27 -> 1333.3333
A20: WIFI/Cable | B20: ='STR Calculator'!$C$28 -> 1800 | C20: ='STR Calculator'!$C$28 -> 1800 | D20: ='STR Calculator'!$C$28 -> 1800 | E20: ='STR Calculator'!$C$28 -> 1800 | F20: ='STR Calculator'!$C$28 -> 1800 | G20: ='STR Calculator'!$C$28 -> 1800 | H20: ='STR Calculator'!$C$28 -> 1800 | I20: ='STR Calculator'!$C$28 -> 1800 | ... K20: ='STR Calculator'!$C$28 -> 1800
A21: Water/Sewer ($0 if septic/well) | B21: ='STR Calculator'!$C$30 -> 0 | C21: ='STR Calculator'!$C$30 -> 0 | D21: ='STR Calculator'!$C$30 -> 0 | E21: ='STR Calculator'!$C$30 -> 0 | F21: ='STR Calculator'!$C$30 -> 0 | G21: ='STR Calculator'!$C$30 -> 0 | H21: ='STR Calculator'!$C$30 -> 0 | I21: ='STR Calculator'!$C$30 -> 0 | ... K21: ='STR Calculator'!$C$30 -> 0
A22: Pool Service ($75/each x biweekly) | B22: ='STR Calculator'!$C$29 -> 0 | C22: ='STR Calculator'!$C$29 -> 0 | D22: ='STR Calculator'!$C$29 -> 0 | E22: ='STR Calculator'!$C$29 -> 0 | F22: ='STR Calculator'!$C$29 -> 0 | G22: ='STR Calculator'!$C$29 -> 0 | H22: ='STR Calculator'!$C$29 -> 0 | I22: ='STR Calculator'!$C$29 -> 0 | ... K22: ='STR Calculator'!$C$29 -> 0
A23: Building Maintenance (1%) | B23: ='STR Calculator'!$C$31 -> 0 | C23: ='STR Calculator'!$B$5*'STR Calculator'!$D$31 -> 0 | D23: ='STR Calculator'!$B$5*'STR Calculator'!$D$31 -> 0 | E23: ='STR Calculator'!$B$5*'STR Calculator'!$D$31 -> 0 | F23: ='STR Calculator'!$B$5*'STR Calculator'!$D$31 -> 0 | G23: ='STR Calculator'!$B$5*'STR Calculator'!$D$31 -> 0 | H23: ='STR Calculator'!$B$5*'STR Calculator'!$D$31 -> 0 | I23: ='STR Calculator'!$B$5*'STR Calculator'!$D$31 -> 0 | J23: ='STR Calculator'!$B$5*'STR Calculator'!$D$31 -> 0 | K23: ='STR Calculator'!$B$5*'STR Calculator'!$D$31 -> 0
A24: Capex (1%) | B24: ='STR Calculator'!$C$32 -> 0 | C24: ='STR Calculator'!$C$32 -> 0 | D24: ='STR Calculator'!$C$32 -> 0 | E24: ='STR Calculator'!$C$32 -> 0 | F24: ='STR Calculator'!$C$32 -> 0 | G24: ='STR Calculator'!$C$32 -> 0 | H24: ='STR Calculator'!$C$32 -> 0 | I24: ='STR Calculator'!$C$32 -> 0 | ... K24: ='STR Calculator'!$C$32 -> 0
A25: Grounds Cleanup/Services/Snow Removal | B25: ='STR Calculator'!$C$33 -> 0 | C25: ='STR Calculator'!$C$33 -> 0 | D25: ='STR Calculator'!$C$33 -> 0 | E25: ='STR Calculator'!$C$33 -> 0 | F25: ='STR Calculator'!$C$33 -> 0 | G25: ='STR Calculator'!$C$33 -> 0 | H25: ='STR Calculator'!$C$33 -> 0 | I25: ='STR Calculator'!$C$33 -> 0 | ... K25: ='STR Calculator'!$C$33 -> 0
A26: City Permit Fee | B26: 300 | C26: 0 | D26: 0 | E26: 0 | F26: 0 | G26: 0 | H26: 0 | I26: 0 | J26: 0 | K26: 0
A27: Incidentals (Coffee/Creamer etc) | B27: ='STR Calculator'!$C$36 -> 300 | C27: ='STR Calculator'!$C$36 -> 300 | D27: ='STR Calculator'!$C$36 -> 300 | E27: ='STR Calculator'!$C$36 -> 300 | F27: ='STR Calculator'!$C$36 -> 300 | G27: ='STR Calculator'!$C$36 -> 300 | H27: ='STR Calculator'!$C$36 -> 300 | I27: ='STR Calculator'!$C$36 -> 300 | ... K27: ='STR Calculator'!$C$36 -> 300
A28: Umbrella Insurance | B28: ='STR Calculator'!$C$37 -> 444 | C28: ='STR Calculator'!$C$37 -> 444 | D28: ='STR Calculator'!$C$37 -> 444 | E28: ='STR Calculator'!$C$37 -> 444 | F28: ='STR Calculator'!$C$37 -> 444 | G28: ='STR Calculator'!$C$37 -> 444 | H28: ='STR Calculator'!$C$37 -> 444 | I28: ='STR Calculator'!$C$37 -> 444 | ... K28: ='STR Calculator'!$C$37 -> 444
A30: Operating Expenses | B30: =SUM(B12:B28) -> 34177.333 | C30: =SUM(C12:C28) -> 34018.333 | D30: =SUM(D12:D28) -> 34163.848 | E30: =SUM(E12:E28) -> 34314.042 | F30: =SUM(F12:F28) -> 34469.085 | G30: =SUM(G12:G28) -> 34629.152 | H30: =SUM(H12:H28) -> 34794.429 | I30: =SUM(I12:I28) -> 34965.104 | ... K30: =SUM(K12:K28) -> 35323.452
A32: Net Operating Income (NOI) | B32: =B8-B30 -> 57322.667 | C32: =C8-C30 -> 58396.667 | D32: =D8-D30 -> 59175.302 | E32: =E8-E30 -> 59958.499 | F32: =F8-F30 -> 60746.182 | G32: =G8-G30 -> 61538.267 | H32: =H8-H30 -> 62334.665 | I32: =I8-I30 -> 63135.28 | ... K32: =K8-K30 -> 64748.751
A33: Capitalization Rate (CAP Rate) | B33: =B32/'STR Calculator'!$B$5 -> 0.095697273 | C33: =C32/'STR Calculator'!$B$5 -> 0.097490262 | D33: =D32/'STR Calculator'!$B$5 -> 0.098790153 | E33: =E32/'STR Calculator'!$B$5 -> 0.10009766 | F33: =F32/'STR Calculator'!$B$5 -> 0.10141266 | G33: =G32/'STR Calculator'!$B$5 -> 0.102735 | H33: =H32/'STR Calculator'!$B$5 -> 0.10406455 | I33: =I32/'STR Calculator'!$B$5 -> 0.10540114 | ... K33: =K32/'STR Calculator'!$B$5 -> 0.10809474
A35: Key Investment Indicators
A36: Mortgage Payment | B36: =PMT('STR Calculator'!$I$8/12, 'STR Calculator'!$I$9*12,'STR Calculator'!$B$8)*12 -> -41196.57 | C36: =PMT('STR Calculator'!$I$8/12, 'STR Calculator'!$I$9*12,'STR Calculator'!$B$8)*12 -> -41196.57 | D36: =PMT('STR Calculator'!$I$8/12, 'STR Calculator'!$I$9*12,'STR Calculator'!$B$8)*12 -> -41196.57 | E36: =PMT('STR Calculator'!$I$8/12, 'STR Calculator'!$I$9*12,'STR Calculator'!$B$8)*12 -> -41196.57 | F36: =PMT('STR Calculator'!$I$8/12, 'STR Calculator'!$I$9*12,'STR Calculator'!$B$8)*12 -> -41196.57 | G36: =PMT('STR Calculator'!$I$8/12, 'STR Calculator'!$I$9*12,'STR Calculator'!$B$8)*12 -> -41196.57 | H36: =PMT('STR Calculator'!$I$8/12, 'STR Calculator'!$I$9*12,'STR Calculator'!$B$8)*12 -> -41196.57 | I36: =PMT('STR Calculator'!$I$8/12, 'STR Calculator'!$I$9*12,'STR Calculator'!$B$8)*12 -> -41196.57 | ... K36: =PMT('STR Calculator'!$I$8/12, 'STR Calculator'!$I$9*12,'STR Calculator'!$B$8)*12 -> -41196.57
A37: ="HELOC Payment ($"& 'STR Calculator'!I3&")" -> HELOC Payment ($64800) | B37: =-'STR Calculator'!$C$41 -> -5346 | C37: =-'STR Calculator'!$C$41 -> -5346 | D37: =-'STR Calculator'!$C$41 -> -5346 | E37: =-'STR Calculator'!$C$41 -> -5346 | F37: =-'STR Calculator'!$C$41 -> -5346 | G37: =-'STR Calculator'!$C$41 -> -5346 | H37: =-'STR Calculator'!$C$41 -> -5346 | I37: =-'STR Calculator'!$C$41 -> -5346 | ... K37: =-'STR Calculator'!$C$41 -> -5346
A38: PMI if Down Payment less than 20% | B38: =-'STR Calculator'!$C$43 -> 0 | C38: =-'STR Calculator'!$C$43 -> 0 | D38: =-'STR Calculator'!$C$43 -> 0 | E38: =-'STR Calculator'!$C$43 -> 0 | F38: =-'STR Calculator'!$C$43 -> 0 | G38: =-'STR Calculator'!$C$43 -> 0 | H38: =-'STR Calculator'!$C$43 -> 0 | I38: =-'STR Calculator'!$C$43 -> 0 | ... K38: =-'STR Calculator'!$C$43 -> 0
A39: Net Cash Flow | B39: =B32+B36+B37+B38 -> 10780.097 | C39: =C32+C36+C37+C38 -> 11854.097 | D39: =D32+D36+D37+D38 -> 12632.732 | E39: =E32+E36+E37+E38 -> 13415.93 | F39: =F32+F36+F37+F38 -> 14203.613 | G39: =G32+G36+G37+G38 -> 14995.698 | H39: =H32+H36+H37+H38 -> 15792.095 | I39: =I32+I36+I37+I38 -> 16592.711 | ... K39: =K32+K36+K37+K38 -> 18206.181 | L39: =SUM(B39:K39) -> 145870.59 | M39: FV of all cash flows
A40: Monthly Cash Flow | B40: =B39/12 -> 898.34141 | C40: =C39/12 -> 987.84141 | D40: =D39/12 -> 1052.7277 | E40: =E39/12 -> 1117.9941 | F40: =F39/12 -> 1183.6344 | G40: =G39/12 -> 1249.6415 | H40: =H39/12 -> 1316.0079 | I40: =I39/12 -> 1382.7259 | ... K40: =K39/12 -> 1517.1818
A41: ="Discounted Cash Flow (DCF) @ "&M2&"% return" -> Discounted Cash Flow (DCF) @ 0.08% return | B41: =B39/(1+$M$2)^B1 -> 9981.5712 | C41: =C39/(1+$M$2)^C1 -> 10162.977 | D41: =D39/(1+$M$2)^D1 -> 10028.27 | E41: =E39/(1+$M$2)^E1 -> 9861.1088 | F41: =F39/(1+$M$2)^F1 -> 9666.7401 | G41: =G39/(1+$M$2)^G1 -> 9449.8331 | H41: =H39/(1+$M$2)^H1 -> 9214.5359 | I41: =I39/(1+$M$2)^I1 -> 8964.5253 | ... K41: =K39/(1+$M$2)^K1 -> 8432.9845 | L41: =SUM(B41:K41) -> 94465.599 | M41: PV of all cash flows
A42: Cash on Cash ROI | B42: =B39/(SUM('STR Calculator'!$B$7,'STR Calculator'!$B$6)) -> 0.089984114 | C42: =C39/(SUM('STR Calculator'!$B$7,'STR Calculator'!$B$6)) -> 0.098949056 | D42: =D39/(SUM('STR Calculator'!$B$7,'STR Calculator'!$B$6)) -> 0.10544851 | E42: =E39/(SUM('STR Calculator'!$B$7,'STR Calculator'!$B$6)) -> 0.11198606 | F42: =F39/(SUM('STR Calculator'!$B$7,'STR Calculator'!$B$6)) -> 0.11856104 | G42: =G39/(SUM('STR Calculator'!$B$7,'STR Calculator'!$B$6)) -> 0.12517277 | H42: =H39/(SUM('STR Calculator'!$B$7,'STR Calculator'!$B$6)) -> 0.13182049 | I42: =I39/(SUM('STR Calculator'!$B$7,'STR Calculator'!$B$6)) -> 0.13850343 | ... K42: =K39/(SUM('STR Calculator'!$B$7,'STR Calculator'!$B$6)) -> 0.15197146
A43: Property Appreciation | B43: 0.04 | C43: =$B$43 -> 0.04 | D43: =$B$43 -> 0.04 | E43: =$B$43 -> 0.04 | F43: =$B$43 -> 0.04 | G43: =$B$43 -> 0.04 | H43: =$B$43 -> 0.04 | I43: =$B$43 -> 0.04 | J43: =$B$43 -> 0.04 | K43: =$B$43 -> 0.04
...

Sheet STR 7yr IRR Financing
A1: ='STR Calculator'!A2 &" - FINANCING CALCULATIONS" -> 2615 Whippor Will Way - 1bd / 3bath - 1617 sqft - FINANCING CALCULATIONS
B4: Year 1 | C4: Year 2 | D4: Year 3 | E4: Year 4 | F4: Year 5 | G4: Year 6 | H4: Year 7
A5: Maintenance | B5: 0.01 | C5: 0.01 | D5: 0.01 | E5: 0.01 | F5: 0.01 | G5: 0.01 | H5: 0.01
A6: Property Appreciation | B6: 0.02 | C6: 0.02 | D6: 0.02 | E6: 0.02 | F6: 0.02 | G6: 0.02 | H6: 0.02
A7: Rental Appreciation | B7: 0.01 | C7: 0.01 | D7: 0.01 | E7: 0.01 | F7: 0.01 | G7: 0.01 | H7: 0.01
A8: Tax/Insurance/HOA Appreciation | B8: 0.015 | C8: 0.015 | D8: 0.015 | E8: 0.015 | F8: 0.015 | G8: 0.015 | H8: 0.015
A9: Vacancy | B9: =1-'STR Calculator'!$B$12 -> 0 | C9: =1-'STR Calculator'!$B$12 -> 0 | D9: =1-'STR Calculator'!$B$12 -> 0 | E9: =1-'STR Calculator'!$B$12 -> 0 | F9: =1-'STR Calculator'!$B$12 -> 0 | G9: =1-'STR Calculator'!$B$12 -> 0 | H9: =1-'STR Calculator'!$B$12 -> 0
B11: Year 1 | C11: Year 2 | D11: Year 3 | E11: Year 4 | F11: Year 5 | G11: Year 6 | H11: Year 7
A12: Revenues
A13: Rental Income | B13: ='STR Calculator'!D11 -> 91500 | C13: =SUM(B$13+(C$7*B$13)) -> 92415 | D13: =SUM(C$13+(D$7*C$13)) -> 93339.15 | E13: =SUM(D$13+(E$7*D$13)) -> 94272.541 | F13: =SUM(E$13+(F$7*E$13)) -> 95215.267 | G13: =SUM(F$13+(G$7*F$13)) -> 96167.42 | H13: =SUM(G$13+(H$7*G$13)) -> 97129.094
A14: Monthly Revenue | B14: =B13/12 -> 7625 | C14: =C13/12 -> 7701.25 | D14: =D13/12 -> 7778.2625 | E14: =E13/12 -> 7856.0451 | F14: =F13/12 -> 7934.6056 | G14: =G13/12 -> 8013.9516 | H14: =H13/12 -> 8094.0911
A15: Vacancy Rate | B15: ='STR Calculator'!D12 -> 0 | C15: =-(C13*C9) -> 0 | D15: =-(D13*D9) -> 0 | E15: =-(E13*E9) -> 0 | F15: =-(F13*F9) -> 0 | G15: =-(G13*G9) -> 0 | H15: =-(H13*H9) -> 0
A16: Net Revenue | B16: =SUM(B13,B15) -> 91500 | C16: =SUM(C13,C15) -> 92415 | D16: =SUM(D13,D15) -> 93339.15 | E16: =SUM(E13,E15) -> 94272.541 | F16: =SUM(F13,F15) -> 95215.267 | G16: =SUM(G13,G15) -> 96167.42 | H16: =SUM(H13,H15) -> 97129.094
A18: Expenses
A19: Management Fees | B19: 0 | C19: 0 | D19: 0 | E19: 0 | F19: 0 | G19: 0 | H19: 0
A20: Subscriptions | B20: ='STR Calculator'!$C$19 -> 600 | C20: ='STR Calculator'!$C$19 -> 600 | D20: ='STR Calculator'!$C$19 -> 600 | E20: ='STR Calculator'!$C$19 -> 600 | F20: ='STR Calculator'!$C$19 -> 600 | G20: ='STR Calculator'!$C$19 -> 600 | H20: ='STR Calculator'!$C$19 -> 600
A21: Property Taxes | B21: ='STR Calculator'!$C$21 -> 2400 | C21: =B$21+(B$21*C$8) -> 2436 | D21: =C$21+(C$21*D$8) -> 2472.54 | E21: =D$21+(D$21*E$8) -> 2509.6281 | F21: =E$21+(E$21*F$8) -> 2547.2725 | G21: =F$21+(F$21*G$8) -> 2585.4816 | H21: =G$21+(G$21*H$8) -> 2624.2638
A22: Insurance | B22: =('STR Calculator'!$C$22) -> 3000 | C22: =('STR Calculator'!$B$5+B48)*($B$22/'STR Calculator'!$B$5) -> 3060 | D22: =('STR Calculator'!$B$5+C48)*($B$22/'STR Calculator'!$B$5) -> 3061.2 | E22: =('STR Calculator'!$B$5+D48)*($B$22/'STR Calculator'!$B$5) -> 3061.224 | F22: =('STR Calculator'!$B$5+E48)*($B$22/'STR Calculator'!$B$5) -> 3061.2245 | G22: =('STR Calculator'!$B$5+F48)*($B$22/'STR Calculator'!$B$5) -> 3061.2245 | H22: =('STR Calculator'!$B$5+G48)*($B$22/'STR Calculator'!$B$5) -> 3061.2245
A23: Cleaners/Handyman | B23: =SUM('STR Calculator'!$C$23:$C$24) -> 21000 | C23: =SUM('STR Calculator'!$C$23:$C$24) -> 21000 | D23: =SUM('STR Calculator'!$C$23:$C$24) -> 21000 | E23: =SUM('STR Calculator'!$C$23:$C$24) -> 21000 | F23: =SUM('STR Calculator'!$C$23:$C$24) -> 21000 | G23: =SUM('STR Calculator'!$C$23:$C$24) -> 21000 | H23: =SUM('STR Calculator'!$C$23:$C$24) -> 21000
A24: Electricity | B24: ='STR Calculator'!$C$26 -> 3000 | C24: ='STR Calculator'!$C$26 -> 3000 | D24: ='STR Calculator'!$C$26 -> 3000 | E24: ='STR Calculator'!$C$26 -> 3000 | F24: ='STR Calculator'!$C$26 -> 3000 | G24: ='STR Calculator'!$C$26 -> 3000 | H24: ='STR Calculator'!$C$26 -> 3000
A25: Natural Gas | B25: ='STR Calculator'!$C$27 -> 1333.3333 | C25: ='STR Calculator'!$C$27 -> 1333.3333 | D25: ='STR Calculator'!$C$27 -> 1333.3333 | E25: ='STR Calculator'!$C$27 -> 1333.3333 | F25: ='STR Calculator'!$C$27 -> 1333.3333 | G25: ='STR Calculator'!$C$27 -> 1333.3333 | H25: ='STR Calculator'!$C$27 -> 1333.3333
A26: WIFI/Cable | B26: ='STR Calculator'!$C$28 -> 1800 | C26: ='STR Calculator'!$C$28 -> 1800 | D26: ='STR Calculator'!$C$28 -> 1800 | E26: ='STR Calculator'!$C$28 -> 1800 | F26: ='STR Calculator'!$C$28 -> 1800 | G26: ='STR Calculator'!$C$28 -> 1800 | H26: ='STR Calculator'!$C$28 -> 1800
A27: Water/Sewer | B27: ='STR Calculator'!$C$30 -> 0 | C27: ='STR Calculator'!$C$30 -> 0 | D27: ='STR Calculator'!$C$30 -> 0 | E27: ='STR Calculator'!$C$30 -> 0 | F27: ='STR Calculator'!$C$30 -> 0 | G27: ='STR Calculator'!$C$30 -> 0 | H27: ='STR Calculator'!$C$30 -> 0
A28: Pool Service | B28: ='STR Calculator'!$C$29 -> 0 | C28: ='STR Calculator'!$C$29 -> 0 | D28: ='STR Calculator'!$C$29 -> 0 | E28: ='STR Calculator'!$C$29 -> 0 | F28: ='STR Calculator'!$C$29 -> 0 | G28: ='STR Calculator'!$C$29 -> 0 | H28: ='STR Calculator'!$C$29 -> 0
A29: HOA | B29: ='STR Calculator'!$C$25 -> 0 | C29: =B29+(B29*C8) -> 0 | D29: =C29+(C29*D8) -> 0 | E29: =D29+(D29*E8) -> 0 | F29: =E29+(E29*F8) -> 0 | G29: =F29+(F29*G8) -> 0 | H29: =G29+(G29*H8) -> 0
A30: Maintenance & Repairs | B30: ='STR Calculator'!$C$31 -> 0 | C30: ='STR Calculator'!$B$5*C5 -> 5990 | D30: ='STR Calculator'!$B$5*D5 -> 5990 | E30: ='STR Calculator'!$B$5*E5 -> 5990 | F30: ='STR Calculator'!$B$5*F5 -> 5990 | G30: ='STR Calculator'!$B$5*G5 -> 5990 | H30: ='STR Calculator'!$B$5*H5 -> 5990
A31: Capex | B31: ='STR Calculator'!$C$32 -> 0 | C31: ='STR Calculator'!$C$32 -> 0 | D31: ='STR Calculator'!$C$32 -> 0 | E31: ='STR Calculator'!$C$32 -> 0 | F31: ='STR Calculator'!$C$32 -> 0 | G31: ='STR Calculator'!$C$32 -> 0 | H31: ='STR Calculator'!$C$32 -> 0
A32: City Permit | B32: ='STR Calculator'!C34 -> 300 | C32: 0 | D32: 0 | E32: 0 | F32: 0 | G32: 0 | H32: 0
A33: Incidentals (Coffee, etc) | B33: ='STR Calculator'!$C$36 -> 300 | C33: ='STR Calculator'!$C$36 -> 300 | D33: ='STR Calculator'!$C$36 -> 300 | E33: ='STR Calculator'!$C$36 -> 300 | F33: ='STR Calculator'!$C$36 -> 300 | G33: ='STR Calculator'!$C$36 -> 300 | H33: ='STR Calculator'!$C$36 -> 300
A34: Umbrella Insurance | B34: ='STR Calculator'!$C$37 -> 444 | C34: ='STR Calculator'!$C$37 -> 444 | D34: ='STR Calculator'!$C$37 -> 444 | E34: ='STR Calculator'!$C$37 -> 444 | F34: ='STR Calculator'!$C$37 -> 444 | G34: ='STR Calculator'!$C$37 -> 444 | H34: ='STR Calculator'!$C$37 -> 444
A35: Total Expenses | B35: =SUM(B20:B34) -> 34177.333 | C35: =SUM(C20:C34) -> 39963.333 | D35: =SUM(D20:D34) -> 40001.073 | E35: =SUM(E20:E34) -> 40038.185 | F35: =SUM(F20:F34) -> 40075.83 | G35: =SUM(G20:G34) -> 40114.039 | H35: =SUM(H20:H34) -> 40152.822
A37: Net Operating Income (NOI) | B37: =SUM(B16-B35) -> 57322.667 | C37: =SUM(C16-C35) -> 52451.667 | D37: =SUM(D16-D35) -> 53338.077 | E37: =SUM(E16-E35) -> 54234.356 | F37: =SUM(F16-F35) -> 55139.437 | G37: =SUM(G16-G35) -> 56053.38 | H37: =SUM(H16-H35) -> 56976.272
A39: Cash Flow
A40: NOI (Cash Available) | B40: =B37 -> 57322.667 | C40: =C37 -> 52451.667 | D40: =D37 -> 53338.077 | E40: =E37 -> 54234.356 | F40: =F37 -> 55139.437 | G40: =G37 -> 56053.38 | H40: =H37 -> 56976.272
A41: Conventional Mortgage | B41: ='STR Calculator'!$C$42 -> 41196.57 | C41: ='STR Calculator'!$C$42 -> 41196.57 | D41: ='STR Calculator'!$C$42 -> 41196.57 | E41: ='STR Calculator'!$C$42 -> 41196.57 | F41: ='STR Calculator'!$C$42 -> 41196.57 | G41: ='STR Calculator'!$C$42 -> 41196.57 | H41: ='STR Calculator'!$C$42 -> 41196.57
A42: HELOC Mortgage | B42: ='STR Calculator'!$C$41 -> 5346 | C42: ='STR Calculator'!$C$41 -> 5346 | D42: ='STR Calculator'!$C$41 -> 5346 | E42: ='STR Calculator'!$C$41 -> 5346 | F42: ='STR Calculator'!$C$41 -> 5346 | G42: ='STR Calculator'!$C$41 -> 5346 | H42: ='STR Calculator'!$C$41 -> 5346
A43: PMI if Down Payment less than 20% | B43: ='STR Calculator'!$C$43 -> 0 | C43: ='STR Calculator'!$C$43 -> 0 | D43: ='STR Calculator'!$C$43 -> 0 | E43: ='STR Calculator'!$C$43 -> 0 | F43: ='STR Calculator'!$C$43 -> 0 | G43: ='STR Calculator'!$C$43 -> 0 | H43: ='STR Calculator'!$C$43 -> 0
A44: Total Cash Flow | B44: =SUM(B40-B41-B42-B43) -> 10780.097 | C44: =SUM(C40-C41-C42-C43) -> 5909.0969 | D44: =SUM(D40-D41-D42-D43) -> 6795.5069 | E44: =SUM(E40-E41-E42-E43) -> 7691.7863 | F44: =SUM(F40-F41-F42-F43) -> 8596.8668 | G44: =SUM(G40-G41-G42-G43) -> 9510.8104 | H44: =SUM(H40-H41-H42-H43) -> 10433.702
A45: Monthly Cash Flow | B45: =B44/12 -> 898.34141 | C45: =C44/12 -> 492.42474 | D45: =D44/12 -> 566.29224 | E45: =E44/12 -> 640.98219 | F45: =F44/12 -> 716.40557 | G45: =G44/12 -> 792.56753 | H45: =H44/12 -> 869.4752
A46: DSCR | B46: =B40/SUM(B41:B43) -> 1.231618 | C46: =C40/SUM(C41:C43) -> 1.1269611 | D46: =D40/SUM(D41:D43) -> 1.1460063 | E46: =E40/SUM(E41:E43) -> 1.1652635 | F46: =F40/SUM(F41:F43) -> 1.1847098 | G46: =G40/SUM(G41:G43) -> 1.2043465 | H46: =H40/SUM(H41:H43) -> 1.2241755
...

Sheet Amoritization Scenario 10% DP
A1: If deciding between different Down Payment % and Interest Rates, compare Cumulative Interest Payment over duration to recoup additional Down Payment Lump Sum, to see which is better. NPV / PV/FV money calculation
C3: sqft | J3: Interest | K3: ='Interest Rate Comparison'!B3 -> 0.0825 | N3: =K3/12 -> 0.006875 | O3: r | W3: Interest | X3: ='Interest Rate Comparison'!B4 -> 0.08 | AA3: =X3/12 -> 0.0066666667 | AB3: r | AJ3: Interest | AK3: ='Interest Rate Comparison'!B5 -> 0.0775 | AN3: =AK3/12 -> 0.0064583333 | AO3: r | AW3: Interest | AX3: ='Interest Rate Comparison'!B6 -> 0.075 | BA3: =AX3/12 -> 0.00625 | BB3: r | BJ3: Interest | BK3: ='Interest Rate Comparison'!B7 -> 0.0725 | BN3: =BK3/12 -> 0.0060416667 | BO3: r | BW3: Interest | BX3: ='Interest Rate Comparison'!B8 -> 0.07 | CA3: =BX3/12 -> 0.0058333333 | CB3: r
C4: $/sqft Market Estimate | J4: Term | K4: =$L$4*12 -> 360 | L4: ='STR Calculator'!I9 -> 30 | M4: years | N4: =(1+N3)^K4 -> 11.781506 | O4: (1+r)^n | W4: Term | X4: =$L$4*12 -> 360 | Y4: 30 | Z4: years | AA4: =(1+AA3)^X4 -> 10.93573 | AB4: (1+r)^n | AJ4: Term | AK4: =$L$4*12 -> 360 | AL4: 30 | AM4: years | AN4: =(1+AN3)^AK4 -> 10.150514 | AO4: (1+r)^n | AW4: Term | AX4: =$L$4*12 -> 360 | AY4: 30 | AZ4: years | BA4: =(1+BA3)^AX4 -> 9.4215339 | BB4: (1+r)^n | BJ4: Term | BK4: =$L$4*12 -> 360 | BL4: 30 | BM4: years | BN4: =(1+BN3)^BK4 -> 8.744772 | BO4: (1+r)^n | BW4: Term | BX4: =$L$4*12 -> 360 | BY4: 30 | BZ4: years | CA4: =(1+CA3)^BX4 -> 8.1164975 | CB4: (1+r)^n
A5: Original Purchase Price | B5: ='STR Calculator'!B5 -> 599000 | C5: =B5/B3 -> #DIV/0! | D5: sqft | J5: Monthly Payment | W5: Monthly Payment | AJ5: Monthly Payment | AW5: Monthly Payment | BJ5: Monthly Payment | BW5: Monthly Payment
A6: Down Payment | B6: 0.1
A7: Current Loan Balance | B7: =B5-(B5*B6) -> 539100 | C7: as of 11/13/22 | J7: paymentNumber | K7: paymentDate | L7: startingBalance | M7: Monthly Payment | N7: principalPayment | O7: Principle Pay Down | P7: interestPayment | Q7: Interest Percent | R7: cumulativePrincipal | S7: cumulativeInterest | T7: endingBalance | U7: Total Paid End of Loan | W7: paymentNumber | X7: paymentDate | Y7: startingBalance | Z7: Monthly Payment | AA7: principalPayment | AB7: Principle Pay Down | AC7: interestPayment | AD7: Interest Percent | AE7: cumulativePrincipal | AF7: cumulativeInterest | AG7: endingBalance | AH7: Total Paid End of Loan | AJ7: paymentNumber | AK7: paymentDate | AL7: startingBalance | AM7: Monthly Payment | AN7: principalPayment | AO7: Principle Pay Down | AP7: interestPayment | AQ7: Interest Percent | AR7: cumulativePrincipal | AS7: cumulativeInterest | AT7: endingBalance | AU7: Total Paid End of Loan | AW7: paymentNumber | AX7: paymentDate | AY7: startingBalance | AZ7: Monthly Payment | BA7: principalPayment | BB7: Principle Pay Down | BC7: interestPayment | BD7: Interest Percent | BE7: cumulativePrincipal | BF7: cumulativeInterest | BG7: endingBalance | BH7: Total Paid End of Loan | BJ7: paymentNumber | BK7: paymentDate | BL7: startingBalance | BM7: Monthly Payment | BN7: principalPayment | BO7: Principle Pay Down | BP7: interestPayment | BQ7: Interest Percent | BR7: cumulativePrincipal | BS7: cumulativeInterest | BT7: endingBalance | BU7: Total Paid End of Loan | BW7: paymentNumber | BX7: paymentDate | BY7: startingBalance | BZ7: Monthly Payment | CA7: principalPayment | CB7: Principle Pay Down | CC7: interestPayment | CD7: Interest Percent | CE7: cumulativePrincipal | CF7: cumulativeInterest | CG7: endingBalance | CH7: Total Paid End of Loan
A8: Current Equity | B8: =B5-B7 -> 59900 | J8: 1 | K8: 44866 | L8: ='Amoritization Scenario 10% DP'!$B$7 -> 539100 | M8: =$L$8/((($N$4)-1)/($N$3*$N$4)) -> 4050.0783 | N8: =M8-P8 -> 343.76576 | O8: =(N8/L8)*12 -> 0.0076519925 | P8: =L8*($K$3/12) -> 3706.3125 | Q8: =(P8/L8)*12 -> 0.0825 | R8: =N8 -> 343.76576 | S8: =P8 -> 3706.3125 | T8: =L8-N8 -> 538756.23 | U8: =R8+S8 -> 4050.0783 | W8: 1 | X8: 44866 | Y8: ='Amoritization Scenario 10% DP'!$B$7 -> 539100 | Z8: =$Y$8/((($AA$4)-1)/($AA$3*$AA$4)) -> 3955.7248 | AA8: =Z8-AC8 -> 361.72482 | AB8: =(AA8/Y8)*12 -> 0.0080517489 | AC8: =Y8*($X$3/12) -> 3594 | AD8: =(AC8/Y8)*12 -> 0.08 | AE8: =AA8 -> 361.72482 | AF8: =AC8 -> 3594 | AG8: =Y8-AA8 -> 538738.28 | AH8: =AE8+AF8 -> 3955.7248 | AJ8: 1 | AK8: 44866 | AL8: ='Amoritization Scenario 10% DP'!$B$7 -> 539100 | AM8: =$AL$8/((($AN$4)-1)/($AN$3*$AN$4)) -> 3862.1784 | AN8: =AM8-AP8 -> 380.49092 | AO8: =(AN8/AL8)*12 -> 0.0084694695 | AP8: =AL8*($AK$3/12) -> 3481.6875 | AQ8: =(AP8/AL8)*12 -> 0.0775 | AR8: =AN8 -> 380.49092 | AS8: =AP8 -> 3481.6875 | AT8: =AL8-AN8 -> 538719.51 | AU8: =AR8+AS8 -> 3862.1784 | AW8: 1 | AX8: 44866 | AY8: ='Amoritization Scenario 10% DP'!$B$7 -> 539100 | AZ8: =$AY$8/((($BA$4)-1)/($BA$3*$BA$4)) -> 3769.4654 | BA8: =AZ8-BC8 -> 400.09042 | BB8: =(BA8/AY8)*12 -> 0.008905741 | BC8: =AY8*($AX$3/12) -> 3369.375 | BD8: =(BC8/AY8)*12 -> 0.075 | BE8: =BA8 -> 400.09042 | BF8: =BC8 -> 3369.375 | BG8: =AY8-BA8 -> 538699.91 | BH8: =BE8+BF8 -> 3769.4654 | BJ8: 1 | BK8: 44866 | BL8: ='Amoritization Scenario 10% DP'!$B$7 -> 539100 | BM8: =$BL$8/((($BN$4)-1)/($BN$3*$BN$4)) -> 3677.6123 | BN8: =BM8-BP8 -> 420.54983 | BO8: =(BN8/BL8)*12 -> 0.0093611536 | BP8: =BL8*($BK$3/12) -> 3257.0625 | BQ8: =(BP8/BL8)*12 -> 0.0725 | BR8: =BN8 -> 420.54983 | BS8: =BP8 -> 3257.0625 | BT8: =BL8-BN8 -> 538679.45 | BU8: =BR8+BS8 -> 3677.6123 | BW8: 1 | BX8: 44866 | BY8: ='Amoritization Scenario 10% DP'!$B$7 -> 539100 | BZ8: =$BY$8/((($CA$4)-1)/($CA$3*$CA$4)) -> 3586.6458 | CA8: =BZ8-CC8 -> 441.89575 | CB8: =(CA8/BY8)*12 -> 0.0098362994 | CC8: =BY8*($BX$3/12) -> 3144.75 | CD8: =(CC8/BY8)*12 -> 0.07 | CE8: =CA8 -> 441.89575 | CF8: =CC8 -> 3144.75 | CG8: =BY8-CA8 -> 538658.1 | CH8: =CE8+CF8 -> 3586.6458
J9: 2 | K9: 44896 | L9: =T8 -> 538756.23 | M9: =$L$8/((($N$4)-1)/($N$3*$N$4)) -> 4050.0783 | N9: =M9-P9 -> 346.12915 | O9: =(N9/L9)*12 -> 0.007709516 | P9: =L9*($K$3/12) -> 3703.9491 | Q9: =(P9/L9)*12 -> 0.0825 | R9: =R8+N9 -> 689.89491 | S9: =S8+P9 -> 7410.2616 | T9: =L9-N9 -> 538410.11 | U9: =R9+S9 -> 8100.1565 | W9: 2 | X9: 44896 | Y9: =AG8 -> 538738.28 | Z9: =Z8 -> 3955.7248 | AA9: =Z9-AC9 -> 364.13632 | AB9: =(AA9/Y9)*12 -> 0.0081108694 | AC9: =Y9*($X$3/12) -> 3591.5885 | AD9: =(AC9/Y9)*12 -> 0.08 | AE9: =AE8+AA9 -> 725.86113 | AF9: =AF8+AC9 -> 7185.5885 | AG9: =Y9-AA9 -> 538374.14 | AH9: =AE9+AF9 -> 7911.4496 | AJ9: 2 | AK9: 44896 | AL9: =AT8 -> 538719.51 | AM9: =AM8 -> 3862.1784 | AN9: =AM9-AP9 -> 382.94825 | AO9: =(AN9/AL9)*12 -> 0.0085301886 | AP9: =AL9*($AK$3/12) -> 3479.2302 | AQ9: =(AP9/AL9)*12 -> 0.0775 | AR9: =AR8+AN9 -> 763.43917 | AS9: =AS8+AP9 -> 6960.9177 | AT9: =AL9-AN9 -> 538336.56 | AU9: =AR9+AS9 -> 7724.3568 | AW9: 2 | AX9: 44896 | AY9: =BG8 -> 538699.91 | AZ9: =AZ8 -> 3769.4654 | BA9: =AZ9-BC9 -> 402.59098 | BB9: =(BA9/AY9)*12 -> 0.0089680575 | BC9: =AY9*($AX$3/12) -> 3366.8744 | BD9: =(BC9/AY9)*12 -> 0.075 | BE9: =BE8+BA9 -> 802.6814 | BF9: =BF8+BC9 -> 6736.2494 | BG9: =AY9-BA9 -> 538297.32 | BH9: =BE9+BF9 -> 7538.9308 | BJ9: 2 | BK9: 44896 | BL9: =BT8 -> 538679.45 | BM9: =BM8 -> 3677.6123 | BN9: =BM9-BP9 -> 423.09065 | BO9: =(BN9/BL9)*12 -> 0.009425063 | BP9: =BL9*($BK$3/12) -> 3254.5217 | BQ9: =(BP9/BL9)*12 -> 0.0725 | BR9: =BR8+BN9 -> 843.64047 | BS9: =BS8+BP9 -> 6511.5842 | BT9: =BL9-BN9 -> 538256.36 | BU9: =BR9+BS9 -> 7355.2247 | BW9: 2 | BX9: 44896 | BY9: =CG8 -> 538658.1 | BZ9: =BZ8 -> 3586.6458 | CA9: =BZ9-CC9 -> 444.47348 | CB9: =(CA9/BY9)*12 -> 0.0099017943 | CC9: =BY9*($BX$3/12) -> 3142.1723 | CD9: =(CC9/BY9)*12 -> 0.07 | CE9: =CE8+CA9 -> 886.36923 | CF9: =CF8+CC9 -> 6286.9223 | CG9: =BY9-CA9 -> 538213.63 | CH9: =CE9+CF9 -> 7173.2915
A10: Year | B10: ="Cum Interest @ "&K3&"%" -> Cum Interest @ 0.0825% | C10: ="Cum Interest @ "&X3&"%" -> Cum Interest @ 0.08% | D10: ="Cum Interest @ "&AK3&"%" -> Cum Interest @ 0.0775% | E10: ="Cum Interest @ "&AX3&"%" -> Cum Interest @ 0.075% | F10: ="Cum Interest @ "&BK3&"%" -> Cum Interest @ 0.0725% | G10: ="Cum Interest @ "&BX3&"%" -> Cum Interest @ 0.07% | J10: 3 | K10: 44927 | L10: =T9 -> 538410.11 | M10: =$L$8/((($N$4)-1)/($N$3*$N$4)) -> 4050.0783 | N10: =M10-P10 -> 348.50879 | O10: =(N10/L10)*12 -> 0.0077675093 | P10: =L10*($K$3/12) -> 3701.5695 | Q10: =(P10/L10)*12 -> 0.0825 | R10: =R9+N10 -> 1038.4037 | S10: =S9+P10 -> 11111.831 | T10: =L10-N10 -> 538061.6 | U10: =R10+S10 -> 12150.235 | W10: 3 | X10: 44927 | Y10: =AG9 -> 538374.14 | Z10: =Z9 -> 3955.7248 | AA10: =Z10-AC10 -> 366.56389 | AB10: =(AA10/Y10)*12 -> 0.0081704643 | AC10: =Y10*($X$3/12) -> 3589.1609 | AD10: =(AC10/Y10)*12 -> 0.08 | AE10: =AE9+AA10 -> 1092.425 | AF10: =AF9+AC10 -> 10774.749 | AG10: =Y10-AA10 -> 538007.57 | AH10: =AE10+AF10 -> 11867.174 | AJ10: 3 | AK10: 44927 | AL10: =AT9 -> 538336.56 | AM10: =AM9 -> 3862.1784 | AN10: =AM10-AP10 -> 385.42146 | AO10: =(AN10/AL10)*12 -> 0.0085913866 | AP10: =AL10*($AK$3/12) -> 3476.757 | AQ10: =(AP10/AL10)*12 -> 0.0775 | AR10: =AR9+AN10 -> 1148.8606 | AS10: =AS9+AP10 -> 10437.675 | AT10: =AL10-AN10 -> 537951.14 | AU10: =AR10+AS10 -> 11586.535 | AW10: 3 | AX10: 44927 | AY10: =BG9 -> 538297.32 | AZ10: =AZ9 -> 3769.4654 | BA10: =AZ10-BC10 -> 405.10717 | BB10: =(BA10/AY10)*12 -> 0.009030857 | BC10: =AY10*($AX$3/12) -> 3364.3582 | BD10: =(BC10/AY10)*12 -> 0.075 | BE10: =BE9+BA10 -> 1207.7886 | BF10: =BF9+BC10 -> 10100.608 | BG10: =AY10-BA10 -> 537892.21 | BH10: =BE10+BF10 -> 11308.396 | BJ10: 3 | BK10: 44927 | BL10: =BT9 -> 538256.36 | BM10: =BM9 -> 3677.6123 | BN10: =BM10-BP10 -> 425.64682 | BO10: =(BN10/BL10)*12 -> 0.0094894594 | BP10: =BL10*($BK$3/12) -> 3251.9655 | BQ10: =(BP10/BL10)*12 -> 0.0725 | BR10: =BR9+BN10 -> 1269.2873 | BS10: =BS9+BP10 -> 9763.5497 | BT10: =BL10-BN10 -> 537830.71 | BU10: =BR10+BS10 -> 11032.837 | BW10: 3 | BX10: 44927 | BY10: =CG9 -> 538213.63 | BZ10: =BZ9 -> 3586.6458 | CA10: =BZ10-CC10 -> 447.06624 | CB10: =(CA10/BY10)*12 -> 0.0099677796 | CC10: =BY10*($BX$3/12) -> 3139.5795 | CD10: =(CC10/BY10)*12 -> 0.07 | CE10: =CE9+CA10 -> 1333.4355 | CF10: =CF9+CC10 -> 9426.5018 | CG10: =BY10-CA10 -> 537766.56 | CH10: =CE10+CF10 -> 10759.937
A11: 1 | B11: =VLOOKUP($A$11*12,$J$7:$U$367,10) -> 44316.136 | C11: =VLOOKUP(A11*12,$W$7:$AH$367,10) -> 42965.251 | D11: =VLOOKUP(A11*12,$AJ$7:$AU$367,10) -> 41614.523 | E11: =VLOOKUP(A11*12,$AW$7:$BH$367,10) -> 40263.976 | F11: =VLOOKUP(A11*12,$BJ$7:$BU$367,10) -> 38913.632 | G11: =VLOOKUP(A11*12,$BW$7:$CH$367,10) -> 37563.518 | J11: 4 | K11: 44958 | L11: =T10 -> 538061.6 | M11: =$L$8/((($N$4)-1)/($N$3*$N$4)) -> 4050.0783 | N11: =M11-P11 -> 350.90479 | O11: =(N11/L11)*12 -> 0.0078259766 | P11: =L11*($K$3/12) -> 3699.1735 | Q11: =(P11/L11)*12 -> 0.0825 | R11: =R10+N11 -> 1389.3085 | S11: =S10+P11 -> 14811.005 | T11: =L11-N11 -> 537710.69 | U11: =R11+S11 -> 16200.313 | W11: 4 | X11: 44958 | Y11: =AG10 -> 538007.57 | Z11: =Z10 -> 3955.7248 | AA11: =Z11-AC11 -> 369.00765 | AB11: =(AA11/Y11)*12 -> 0.008230538 | AC11: =Y11*($X$3/12) -> 3586.7172 | AD11: =(AC11/Y11)*12 -> 0.08 | AE11: =AE10+AA11 -> 1461.4327 | AF11: =AF10+AC11 -> 14361.467 | AG11: =Y11-AA11 -> 537638.57 | AH11: =AE11+AF11 -> 15822.899 | AJ11: 4 | AK11: 44958 | AL11: =AT10 -> 537951.14 | AM11: =AM10 -> 3862.1784 | AN11: =AM11-AP11 -> 387.91064 | AO11: =(AN11/AL11)*12 -> 0.0086530678 | AP11: =AL11*($AK$3/12) -> 3474.2678 | AQ11: =(AP11/AL11)*12 -> 0.0775 | AR11: =AR10+AN11 -> 1536.7713 | AS11: =AS10+AP11 -> 13911.942 | AT11: =AL11-AN11 -> 537563.23 | AU11: =AR11+AS11 -> 15448.714 | AW11: 4 | AX11: 44958 | AY11: =BG10 -> 537892.21 | AZ11: =AZ10 -> 3769.4654 | BA11: =AZ11-BC11 -> 407.63909 | BB11: =(BA11/AY11)*12 -> 0.0090941438 | BC11: =AY11*($AX$3/12) -> 3361.8263 | BD11: =(BC11/AY11)*12 -> 0.075 | BE11: =BE10+BA11 -> 1615.4277 | BF11: =BF10+BC11 -> 13462.434 | BG11: =AY11-BA11 -> 537484.57 | BH11: =BE11+BF11 -> 15077.862 | BJ11: 4 | BK11: 44958 | BL11: =BT10 -> 537830.71 | BM11: =BM10 -> 3677.6123 | BN11: =BM11-BP11 -> 428.21844 | BO11: =(BN11/BL11)*12 -> 0.009554347 | BP11: =BL11*($BK$3/12) -> 3249.3939 | BQ11: =(BP11/BL11)*12 -> 0.0725 | BR11: =BR10+BN11 -> 1697.5057 | BS11: =BS10+BP11 -> 13012.944 | BT11: =BL11-BN11 -> 537402.49 | BU11: =BR11+BS11 -> 14710.449 | BW11: 4 | BX11: 44958 | BY11: =CG10 -> 537766.56 | BZ11: =BZ10 -> 3586.6458 | CA11: =BZ11-CC11 -> 449.67413 | CB11: =(CA11/BY11)*12 -> 0.01003426 | CC11: =BY11*($BX$3/12) -> 3136.9716 | CD11: =(CC11/BY11)*12 -> 0.07 | CE11: =CE10+CA11 -> 1783.1096 | CF11: =CF10+CC11 -> 12563.473 | CG11: =BY11-CA11 -> 537316.89 | CH11: =CE11+CF11 -> 14346.583
A12: =A11+1 -> 2 | B12: =VLOOKUP(A12*12,$J$7:$U$367,10) -> 88265.098 | C12: =VLOOKUP(A12*12,$W$7:$AH$367,10) -> 85556.717 | D12: =VLOOKUP(A12*12,$AJ$7:$AU$367,10) -> 82849.036 | E12: =VLOOKUP(A12*12,$AW$7:$BH$367,10) -> 80142.147 | F12: =VLOOKUP(A12*12,$BJ$7:$BU$367,10) -> 77436.153 | G12: =VLOOKUP(A12*12,$BW$7:$CH$367,10) -> 74731.159 | J12: 5 | K12: 44986 | L12: =T11 -> 537710.69 | M12: =$L$8/((($N$4)-1)/($N$3*$N$4)) -> 4050.0783 | N12: =M12-P12 -> 353.31726 | O12: =(N12/L12)*12 -> 0.0078849224 | P12: =L12*($K$3/12) -> 3696.761 | Q12: =(P12/L12)*12 -> 0.0825 | R12: =R11+N12 -> 1742.6258 | S12: =S11+P12 -> 18507.766 | T12: =L12-N12 -> 537357.37 | U12: =R12+S12 -> 20250.391 | W12: 5 | X12: 44986 | Y12: =AG11 -> 537638.57 | Z12: =Z11 -> 3955.7248 | AA12: =Z12-AC12 -> 371.4677 | AB12: =(AA12/Y12)*12 -> 0.008291095 | AC12: =Y12*($X$3/12) -> 3584.2571 | AD12: =(AC12/Y12)*12 -> 0.08 | AE12: =AE11+AA12 -> 1832.9004 | AF12: =AF11+AC12 -> 17945.724 | AG12: =Y12-AA12 -> 537267.1 | AH12: =AE12+AF12 -> 19778.624 | AJ12: 5 | AK12: 44986 | AL12: =AT11 -> 537563.23 | AM12: =AM11 -> 3862.1784 | AN12: =AM12-AP12 -> 390.4159 | AO12: =(AN12/AL12)*12 -> 0.0087152367 | AP12: =AL12*($AK$3/12) -> 3471.7625 | AQ12: =(AP12/AL12)*12 -> 0.0775 | AR12: =AR11+AN12 -> 1927.1872 | AS12: =AS11+AP12 -> 17383.705 | AT12: =AL12-AN12 -> 537172.81 | AU12: =AR12+AS12 -> 19310.892 | AW12: 5 | AX12: 44986 | AY12: =BG11 -> 537484.57 | AZ12: =AZ11 -> 3769.4654 | BA12: =AZ12-BC12 -> 410.18684 | BB12: =(BA12/AY12)*12 -> 0.0091579225 | BC12: =AY12*($AX$3/12) -> 3359.2786 | BD12: =(BC12/AY12)*12 -> 0.075 | BE12: =BE11+BA12 -> 2025.6145 | BF12: =BF11+BC12 -> 16821.713 | BG12: =AY12-BA12 -> 537074.39 | BH12: =BE12+BF12 -> 18847.327 | BJ12: 5 | BK12: 44986 | BL12: =BT11 -> 537402.49 | BM12: =BM11 -> 3677.6123 | BN12: =BM12-BP12 -> 430.80559 | BO12: =(BN12/BL12)*12 -> 0.0096197303 | BP12: =BL12*($BK$3/12) -> 3246.8067 | BQ12: =(BP12/BL12)*12 -> 0.0725 | BR12: =BR11+BN12 -> 2128.3113 | BS12: =BS11+BP12 -> 16259.75 | BT12: =BL12-BN12 -> 536971.69 | BU12: =BR12+BS12 -> 18388.062 | BW12: 5 | BX12: 44986 | BY12: =CG11 -> 537316.89 | BZ12: =BZ11 -> 3586.6458 | CA12: =BZ12-CC12 -> 452.29722 | CB12: =(CA12/BY12)*12 -> 0.01010124 | CC12: =BY12*($BX$3/12) -> 3134.3485 | CD12: =(CC12/BY12)*12 -> 0.07 | CE12: =CE11+CA12 -> 2235.4068 | CF12: =CF11+CC12 -> 15697.822 | CG12: =BY12-CA12 -> 536864.59 | CH12: =CE12+CF12 -> 17933.229
A13: =A12+1 -> 3 | B13: =VLOOKUP(A13*12,$J$7:$U$367,10) -> 131815.42 | C13: =VLOOKUP(A13*12,$W$7:$AH$367,10) -> 127743.38 | D13: =VLOOKUP(A13*12,$AJ$7:$AU$367,10) -> 123673.02 | E13: =VLOOKUP(A13*12,$AW$7:$BH$367,10) -> 119604.56 | F13: =VLOOKUP(A13*12,$BJ$7:$BU$367,10) -> 115538.25 | G13: =VLOOKUP(A13*12,$BW$7:$CH$367,10) -> 111474.31 | J13: 6 | K13: 45017 | L13: =T12 -> 537357.37 | M13: =$L$8/((($N$4)-1)/($N$3*$N$4)) -> 4050.0783 | N13: =M13-P13 -> 355.74631 | O13: =(N13/L13)*12 -> 0.0079443513 | P13: =L13*($K$3/12) -> 3694.3319 | Q13: =(P13/L13)*12 -> 0.0825 | R13: =R12+N13 -> 2098.3721 | S13: =S12+P13 -> 22202.098 | T13: =L13-N13 -> 537001.63 | U13: =R13+S13 -> 24300.47 | W13: 6 | X13: 45017 | Y13: =AG12 -> 537267.1 | Z13: =Z12 -> 3955.7248 | AA13: =Z13-AC13 -> 373.94415 | AB13: =(AA13/Y13)*12 -> 0.0083521396 | AC13: =Y13*($X$3/12) -> 3581.7807 | AD13: =(AC13/Y13)*12 -> 0.08 | AE13: =AE12+AA13 -> 2206.8445 | AF13: =AF12+AC13 -> 21527.504 | AG13: =Y13-AA13 -> 536893.16 | AH13: =AE13+AF13 -> 23734.349 | AJ13: 6 | AK13: 45017 | AL13: =AT12 -> 537172.81 | AM13: =AM12 -> 3862.1784 | AN13: =AM13-AP13 -> 392.93733 | AO13: =(AN13/AL13)*12 -> 0.0087778977 | AP13: =AL13*($AK$3/12) -> 3469.2411 | AQ13: =(AP13/AL13)*12 -> 0.0775 | AR13: =AR12+AN13 -> 2320.1245 | AS13: =AS12+AP13 -> 20852.946 | AT13: =AL13-AN13 -> 536779.88 | AU13: =AR13+AS13 -> 23173.07 | AW13: 6 | AX13: 45017 | AY13: =BG12 -> 537074.39 | AZ13: =AZ12 -> 3769.4654 | BA13: =AZ13-BC13 -> 412.75051 | BB13: =(BA13/AY13)*12 -> 0.0092221975 | BC13: =AY13*($AX$3/12) -> 3356.7149 | BD13: =(BC13/AY13)*12 -> 0.075 | BE13: =BE12+BA13 -> 2438.365 | BF13: =BF12+BC13 -> 20178.427 | BG13: =AY13-BA13 -> 536661.63 | BH13: =BE13+BF13 -> 22616.792 | BJ13: 6 | BK13: 45017 | BL13: =BT12 -> 536971.69 | BM13: =BM12 -> 3677.6123 | BN13: =BM13-BP13 -> 433.40837 | BO13: =(BN13/BL13)*12 -> 0.009685614 | BP13: =BL13*($BK$3/12) -> 3244.204 | BQ13: =(BP13/BL13)*12 -> 0.0725 | BR13: =BR12+BN13 -> 2561.7197 | BS13: =BS12+BP13 -> 19503.954 | BT13: =BL13-BN13 -> 536538.28 | BU13: =BR13+BS13 -> 22065.674 | BW13: 6 | BX13: 45017 | BY13: =CG12 -> 536864.59 | BZ13: =BZ12 -> 3586.6458 | CA13: =BZ13-CC13 -> 454.93562 | CB13: =(CA13/BY13)*12 -> 0.010168723 | CC13: =BY13*($BX$3/12) -> 3131.7101 | CD13: =(CC13/BY13)*12 -> 0.07 | CE13: =CE12+CA13 -> 2690.3424 | CF13: =CF12+CC13 -> 18829.532 | CG13: =BY13-CA13 -> 536409.66 | CH13: =CE13+CF13 -> 21519.875
A14: =A13+1 -> 4 | B14: =VLOOKUP(A14*12,$J$7:$U$367,10) -> 174932.95 | C14: =VLOOKUP(A14*12,$W$7:$AH$367,10) -> 169491.63 | D14: =VLOOKUP(A14*12,$AJ$7:$AU$367,10) -> 164053.5 | E14: =VLOOKUP(A14*12,$AW$7:$BH$367,10) -> 158618.95 | F14: =VLOOKUP(A14*12,$BJ$7:$BU$367,10) -> 153188.4 | G14: =VLOOKUP(A14*12,$BW$7:$CH$367,10) -> 147762.27 | J14: 7 | K14: 45047 | L14: =T13 -> 537001.63 | M14: =$L$8/((($N$4)-1)/($N$3*$N$4)) -> 4050.0783 | N14: =M14-P14 -> 358.19207 | O14: =(N14/L14)*12 -> 0.0080042678 | P14: =L14*($K$3/12) -> 3691.8862 | Q14: =(P14/L14)*12 -> 0.0825 | R14: =R13+N14 -> 2456.5641 | S14: =S13+P14 -> 25893.984 | T14: =L14-N14 -> 536643.44 | U14: =R14+S14 -> 28350.548 | W14: 7 | X14: 45047 | Y14: =AG13 -> 536893.16 | Z14: =Z13 -> 3955.7248 | AA14: =Z14-AC14 -> 376.43711 | AB14: =(AA14/Y14)*12 -> 0.0084136766 | AC14: =Y14*($X$3/12) -> 3579.2877 | AD14: =(AC14/Y14)*12 -> 0.08 | AE14: =AE13+AA14 -> 2583.2816 | AF14: =AF13+AC14 -> 25106.792 | AG14: =Y14-AA14 -> 536516.72 | AH14: =AE14+AF14 -> 27690.074 | AJ14: 7 | AK14: 45047 | AL14: =AT13 -> 536779.88 | AM14: =AM13 -> 3862.1784 | AN14: =AM14-AP14 -> 395.47505 | AO14: =(AN14/AL14)*12 -> 0.0088410554 | AP14: =AL14*($AK$3/12) -> 3466.7034 | AQ14: =(AP14/AL14)*12 -> 0.0775 | AR14: =AR13+AN14 -> 2715.5996 | AS14: =AS13+AP14 -> 24319.649 | AT14: =AL14-AN14 -> 536384.4 | AU14: =AR14+AS14 -> 27035.249 | AW14: 7 | AX14: 45047 | AY14: =BG13 -> 536661.63 | AZ14: =AZ13 -> 3769.4654 | BA14: =AZ14-BC14 -> 415.3302 | BB14: =(BA14/AY14)*12 -> 0.0092869735 | BC14: =AY14*($AX$3/12) -> 3354.1352 | BD14: =(BC14/AY14)*12 -> 0.075 | BE14: =BE13+BA14 -> 2853.6952 | BF14: =BF13+BC14 -> 23532.563 | BG14: =AY14-BA14 -> 536246.3 | BH14: =BE14+BF14 -> 26386.258 | BJ14: 7 | BK14: 45047 | BL14: =BT13 -> 536538.28 | BM14: =BM13 -> 3677.6123 | BN14: =BM14-BP14 -> 436.02688 | BO14: =(BN14/BL14)*12 -> 0.0097520024 | BP14: =BL14*($BK$3/12) -> 3241.5854 | BQ14: =(BP14/BL14)*12 -> 0.0725 | BR14: =BR13+BN14 -> 2997.7466 | BS14: =BS13+BP14 -> 22745.54 | BT14: =BL14-BN14 -> 536102.25 | BU14: =BR14+BS14 -> 25743.286 | BW14: 7 | BX14: 45047 | BY14: =CG13 -> 536409.66 | BZ14: =BZ13 -> 3586.6458 | CA14: =BZ14-CC14 -> 457.58942 | CB14: =(CA14/BY14)*12 -> 0.010236715 | CC14: =BY14*($BX$3/12) -> 3129.0563 | CD14: =(CC14/BY14)*12 -> 0.07 | CE14: =CE13+CA14 -> 3147.9319 | CF14: =CF13+CC14 -> 21958.588 | CG14: =BY14-CA14 -> 535952.07 | CH14: =CE14+CF14 -> 25106.52
A15: =A14+1 -> 5 | B15: =VLOOKUP(A15*12,$J$7:$U$367,10) -> 217580.59 | C15: =VLOOKUP(A15*12,$W$7:$AH$367,10) -> 210765.09 | D15: =VLOOKUP(A15*12,$AJ$7:$AU$367,10) -> 203954.86 | E15: =VLOOKUP(A15*12,$AW$7:$BH$367,10) -> 197150.53 | F15: =VLOOKUP(A15*12,$BJ$7:$BU$367,10) -> 190352.73 | G15: =VLOOKUP(A15*12,$BW$7:$CH$367,10) -> 183562.15 | J15: 8 | K15: 45078 | L15: =T14 -> 536643.44 | M15: =$L$8/((($N$4)-1)/($N$3*$N$4)) -> 4050.0783 | N15: =M15-P15 -> 360.65464 | O15: =(N15/L15)*12 -> 0.0080646765 | P15: =L15*($K$3/12) -> 3689.4236 | Q15: =(P15/L15)*12 -> 0.0825 | R15: =R14+N15 -> 2817.2188 | S15: =S14+P15 -> 29583.407 | T15: =L15-N15 -> 536282.78 | U15: =R15+S15 -> 32400.626 | W15: 8 | X15: 45078 | Y15: =AG14 -> 536516.72 | Z15: =Z14 -> 3955.7248 | AA15: =Z15-AC15 -> 378.9467 | AB15: =(AA15/Y15)*12 -> 0.0084757104 | AC15: =Y15*($X$3/12) -> 3576.7781 | AD15: =(AC15/Y15)*12 -> 0.08 | AE15: =AE14+AA15 -> 2962.2283 | AF15: =AF14+AC15 -> 28683.57 | AG15: =Y15-AA15 -> 536137.77 | AH15: =AE15+AF15 -> 31645.799 | AJ15: 8 | AK15: 45078 | AL15: =AT14 -> 536384.4 | AM15: =AM14 -> 3862.1784 | AN15: =AM15-AP15 -> 398.02916 | AO15: =(AN15/AL15)*12 -> 0.0089047145 | AP15: =AL15*($AK$3/12) -> 3464.1493 | AQ15: =(AP15/AL15)*12 -> 0.0775 | AR15: =AR14+AN15 -> 3113.6287 | AS15: =AS14+AP15 -> 27783.799 | AT15: =AL15-AN15 -> 535986.37 | AU15: =AR15+AS15 -> 30897.427 | AW15: 8 | AX15: 45078 | AY15: =BG14 -> 536246.3 | AZ15: =AZ14 -> 3769.4654 | BA15: =AZ15-BC15 -> 417.92601 | BB15: =(BA15/AY15)*12 -> 0.0093522549 | BC15: =AY15*($AX$3/12) -> 3351.5394 | BD15: =(BC15/AY15)*12 -> 0.075 | BE15: =BE14+BA15 -> 3271.6212 | BF15: =BF14+BC15 -> 26884.102 | BG15: =AY15-BA15 -> 535828.38 | BH15: =BE15+BF15 -> 30155.723 | BJ15: 8 | BK15: 45078 | BL15: =BT14 -> 536102.25 | BM15: =BM14 -> 3677.6123 | BN15: =BM15-BP15 -> 438.66121 | BO15: =(BN15/BL15)*12 -> 0.0098189002 | BP15: =BL15*($BK$3/12) -> 3238.9511 | BQ15: =(BP15/BL15)*12 -> 0.0725 | BR15: =BR14+BN15 -> 3436.4078 | BS15: =BS14+BP15 -> 25984.491 | BT15: =BL15-BN15 -> 535663.59 | BU15: =BR15+BS15 -> 29420.899 | BW15: 8 | BX15: 45078 | BY15: =CG14 -> 535952.07 | BZ15: =BZ14 -> 3586.6458 | CA15: =BZ15-CC15 -> 460.25869 | CB15: =(CA15/BY15)*12 -> 0.010305221 | CC15: =BY15*($BX$3/12) -> 3126.3871 | CD15: =(CC15/BY15)*12 -> 0.07 | CE15: =CE14+CA15 -> 3608.1905 | CF15: =CF14+CC15 -> 25084.975 | CG15: =BY15-CA15 -> 535491.81 | CH15: =CE15+CF15 -> 28693.166
