Workbook
Name Cash_beginning: 'BONUS Cashflow Tracker (Monthly'!$C$7
Name Cash_minimum: 'BONUS Cashflow Tracker (Monthly'!$C$4
Name Company_name: 'BONUS Cashflow Tracker (Monthly'!$B$2
Name Start_date: 'BONUS Cashflow Tracker (Monthly'!$C$3

Sheet INSTRUCTIONS
A1: How to Use The Contrarian Deal Analysis Sheet
A2: 1 | B2: Make a copy of this document if you haven't already.
A3: 2 | B3: Add your Deal Box requirements to the Deal Box tab. You can also copy what you have from the Contrarian Deal Box sheet.
A4: 3 | B4: (Optional) Complete the SDE Calculation worksheet
A5: 4 | B5: Use the Deal Calculator to quickly assess if the deal is right for you.
A6: 5 | B6: Sign an NDA to get 3 years of P&Ls or other financials.
A7: 6 | B7: Rerun the Deal Calculator to confirm if the cashflow requirements are met.
A8: 7 | B8: Hire your deal team to draft an LOI with an initial offer.
A9: 8 | B9: Once accepted, go into formal due diligence.
A10: 9 | B10: Use the documents from due diligence to assess the Contrarian Value Markers of the business.
A11: 10 | B11: If all looks good, continue through closing.
A12: 11 | B12: Use the day 0 checklist to get your bases covered for ownership.
A15: VERSION HISTORY
A16: 1 | B16: Initial launch | H16: 45362
A17: 1.1 | B17: Added Maintenance CapX as expense. Updated DSCR & purchase price formula. | H17: 45363
A18: 1.2 | B18: Significant update to Deal Calculator with additional expenses and calculations | H18: 45395
A19: 1.3 | B19: Added a simple working capital calculator | H19: 45395
A20: 1.4 | B20: Updated deal calculator, closing checklist, DD checklist, Day 0 checklist (minor) | H20: 45396
A21: 1.5 | B21: Added the monthly and weekly cashflow trackers. | H21: 45418
A22: 1.6 | B22: Converted deal calculator to annual numbers plus error fix | H22: 45442
A23: 1.7 | B23: Fixed SDE calculation formula | H23: 45443
A24: 1.8 | B24: Added field for Included Working Capital other than inventory in Calculator | H24: 45460
B25: Added default SBA guarantee fees for additional fees added to loan in Calculator
A26: 1.9 | B26: Updated formula in deal calculator for Minimum Cash Flow | H26: 45461
A27: 1.1 | B27: Updated deal box estimated debt service from .33 of cash flow to .43 of cash flow | H27: 45517
A28: 1.11 | B28: Updated drop in revenue for break even calculation to reflect gross margin | H28: 45543
B29: Added an item for salary NEEDED by owner for basic living expenses that impacts DSCR
A30: 1.12 | B30: Updated SBA guarantee fee; Moved personal salary NEEDED for clarity | H30: 45595
A31: 1.13 | B31: Moved SDE Calculation to Step 2 | H31: 45608
A32: 1.14 | B32: Updated SBA guarantee fee | H32: 45743
A34: © 2024 Contrarian Thinking, LLC. All rights reserved.

Sheet Step 1 Deal Box
A1: My Contrarian Deal Box
A2: Anything marked with * is a formula, do not edit those cells.
C3: My Deal Box | D3: Business A | E3: Business B | F3: Business C | G3: Business D | H3: Business E | I3: Business F | J3: Business G
A4: Purchase Price & Cashflow Requirements
A5: Minimum Annual Cashflow | B5: This is the minimum cashflow (your income) you have to make to move forward on a deal. | C5: 100000 | D5: 0 | E5: 0 | F5: 0 | G5: 0 | H5: 0 | I5: 0 | J5: 0
A6: Operator Salary | B6: This is what you'd have to pay the operator, if you choose to have one. If you don't know whether this is necessary at this point, you can leave this at $0. Just keep in mind that when you start seriously looking at a business, you will need to increase the target cashflow if you need to pay an operator. | C6: 0 | D6: 0 | E6: 0 | F6: 0 | G6: 0 | H6: 0 | I6: 0 | J6: 0
A7: Financing | B7: Are you going to be financing the acquisition? | C7: TRUE | D7: FALSE | E7: FALSE | F7: FALSE | G7: FALSE | H7: FALSE | I7: FALSE | J7: FALSE
A8: Estimated Debt Service Cost* | B8: If you are going to use financing, the number at the right will be the very estimated cost of debt service. You'll want to get a precise number in a future step. | C8: =IF(C7=TRUE,((C5+C6)*0.43),0) -> 43000 | D8: =IF(D7=TRUE,((D5+D6)*0.43),0) -> 0 | E8: =IF(E7=TRUE,((E5+E6)*0.43),0) -> 0 | F8: =IF(F7=TRUE,((F5+F6)*0.43),0) -> 0 | G8: =IF(G7=TRUE,((G5+G6)*0.43),0) -> 0 | H8: =IF(H7=TRUE,((H5+H6)*0.43),0) -> 0 | I8: =IF(I7=TRUE,((I5+I6)*0.43),0) -> 0 | J8: =IF(J7=TRUE,((J5+J6)*0.43),0) -> 0
A9: Total Cashflow Needed* | B9: This is the cashflow you must have from the business in order to meet your income goals, pay your operator's salary and pay for any debt service. | C9: =C8+C6+C5 -> 143000 | D9: =D8+D6+D5 -> 0 | E9: =E8+E6+E5 -> 0 | F9: =F8+F6+F5 -> 0 | G9: =G8+G6+G5 -> 0 | H9: =H8+H6+H5 -> 0 | I9: =I8+I6+I5 -> 0 | J9: =J8+J6+J5 -> 0
A10: Minimum Purchase Price* | B10: This is the minimum price you'd likely pay for your business using a 2x multiple. Do not focus on this number, this is negotiable and cashflow is most important. | C10: =C9*2 -> 286000 | D10: =D9*2 -> 0 | E10: =E9*2 -> 0 | F10: =F9*2 -> 0 | G10: =G9*2 -> 0 | H10: =H9*2 -> 0 | I10: =I9*2 -> 0 | J10: =J9*2 -> 0
A11: Maximum Purchase Price* | B11: This is the maximum price you'd likely pay for your business using a 4x multiple. Do not focus on this number, this is negotiable and cashflow is most important. | C11: =C9*4 -> 572000 | D11: =D9*4 -> 0 | E11: =E9*4 -> 0 | F11: =F9*4 -> 0 | G11: =G9*4 -> 0 | H11: =H9*4 -> 0 | I11: =I9*4 -> 0 | J11: =J9*4 -> 0
A13: Is this the right business for me?
A14: Must-Haves | B14: What are the must-haves in your future business? Operator-only? Remote? What's best for you? Ideally max 3. | C14: Insert here.
A15: Can't Stands | B15: What are the things you'd HATE in your future business? If you were the operator? If you had to work in a specific industry? Put what you definitely DONT want here. Ideally max 3. | C15: Insert here.
A16: Financing Options | B16: Are you only working with deals that are seller-financed? Or SBA is fine too? Put your ideal financing options here. | C16: Insert here.
A17: Sector/Industry | B17: Do you have a specific industry you're interested in buying like plumbing or HVAC? If not, can leave blank. | C17: Insert here.
A18: Location | B18: Does this have to be remote? Or specific to your current town or state? If not, can leave blank. | C18: Insert here.
A19: Employees | B19: Do you want to work with a small or big team? Any preference? | C19: Insert here.
A20: # Years in Business | B20: Do you have a set number of years you're willing to work with? For example, if it's less than 3 years, you wouldn't buy it? | C20: Insert here.
A21: Operator | B21: Do you want an operator in place? Or will you be the operator? If you're indifferent, can leave blank. | C21: Insert here.
A22: Contrarian Truths Check | C22: Insert here. | D22: Make sure all of these are checked.
A23: Profitability | B23: Does business profit cover debt service/financing costs? | D23: FALSE | E23: FALSE | F23: FALSE | G23: FALSE | H23: FALSE | I23: FALSE | J23: FALSE
B24: Does business profit cover operator salary? | D24: FALSE
B25: Does business profit cover growth capital/working capital? | D25: FALSE
B26: Does business profit cover my earnings/income?
A27: Contrarian Truths Check | D27: Make sure NONE of these are checked.
A28: Gross Defects | B28: High failure rate | D28: FALSE | E28: FALSE | F28: FALSE | G28: FALSE | H28: FALSE | I28: FALSE | J28: FALSE
B29: Net operating loss | C29: FALSE
B30: Asymmetric risk | C30: FALSE
B31: Debt/Equity \> 1 | C31: FALSE
B32: High expense | C32: FALSE | D32: FALSE | E32: FALSE | F32: FALSE | G32: FALSE | H32: FALSE | I32: FALSE | J32: FALSE
B33: Low transferability | C33: FALSE
A34: SOWS & BRIT Test | D34: The more of these boxes are checked, the better. It's not required to move forward.
A35: SOWS | B35: Stale - is there minimal innovation? | C35: FALSE
B36: Old - long standing business? | C36: FALSE
B37: Weak - poor competition? | C37: FALSE
B38: Simple - simple business model, but needed. | C38: FALSE
A39: BRIT | B39: Buy - buy businesses that cashflow. Make sure it covers your cashflow requirements. | C39: FALSE
B40: Resist - in recession-resistant sectors. Is the industry recession-proof? | C40: FALSE
B41: Increase - with an ability to raise their prices. Can you add more value to increase revenue? | C41: FALSE
...

Sheet Step 2 SDE Calculation
A1: BONUS: SDE Calculation | N1: Watch the lesson in the Main Street Accelerator on calculating SDE
A2: Use the worksheet below to calculate SDE. SDE is a more accurate reflection of profits for Main Street businesses that are typically owner-operated. Do not edit black cells. They are formulas.
B4: WEIGHTING FOR AVERAGE | D4: 0.2 | E4: 0.3 | F4: 0.5 | G4: 0 | H4: 1998 | I4: 1997 | J4: =IF(SUM(D4:G4)=100%,"","*** WEIGHTING <> 100% ***")
D5: 20___ | E5: 20___ | F5: 20___ | G5: YTD 20___ | H5: 1998 | I5: 1997 | J5: Weighted Average | N5: Other SDE Addback Examples:
A6: 1 | B6: Sales | D6: 0 | E6: 0 | F6: 0 | G6: 0 | J6: =SUMPRODUCT(D6:G6,D$4:G$4) -> 0 | N6: Inventory written off to increase COGS in previous years
A7: 2 | B7: Less Cost of Sales | D7: 0 | E7: 0 | F7: 0 | G7: 0 | J7: =SUMPRODUCT(D7:G7,D$4:G$4) -> 0 | N7: Child Care provided by company (or its employees)
A8: 3 | B8: Less Operating Expenses | D8: 0 | E8: 0 | F8: 0 | G8: 0 | J8: =SUMPRODUCT(D8:G8,D$4:G$4) -> 0 | N8: Other family members on payroll but not working in the company
A9: 4 | B9: Equals Net Income Before Taxes | D9: =D6-(D7+D8) -> 0 | E9: =E6-(E7+E8) -> 0 | F9: =F6-(F7+F8) -> 0 | G9: =G6-(G7+G8) -> 0 | J9: =SUMPRODUCT(D9:G9,D$4:G$4) -> 0 | N9: Gains or losses on disposal of assets
A10: 5 | B10: Plus Depreciation & Amortization | D10: 0 | E10: 0 | F10: 0 | G10: 0 | J10: =SUMPRODUCT(D10:G10,D$4:G$4) -> 0 | N10: Laundry or dry cleaning for owner/owner's family
A11: 6 | B11: Plus Interest on Loans to Business | D11: 0 | E11: 0 | F11: 0 | G11: 0 | J11: =SUMPRODUCT(D11:G11,D$4:G$4) -> 0 | N11: Excessive (or under) market rate rental and/or lease amounts
A12: 7 | B12: Plus Corporate / LLC Taxes | D12: 0 | E12: 0 | F12: 0 | G12: 0 | J12: =SUMPRODUCT(D12:G12,D$4:G$4) -> 0 | N12: Personal Banking Charges
A13: 8 | B13: Plus Salary for One Owner | D13: 0 | E13: 0 | F13: 0 | G13: 0 | J13: =SUMPRODUCT(D13:G13,D$4:G$4) -> 0 | N13: Household repairs or services paid by company
A14: 9 | B14: Plus Payroll Taxes on Owner's Salary | D14: 0 | E14: 0 | F14: 0 | G14: 0 | J14: =SUMPRODUCT(D14:G14,D$4:G$4) -> 0 | N14: Home Office rent paid to owner by company
A15: 10 | B15: Equals Basic Discretionary Earnings | D15: =SUM(D9:D14) -> 0 | E15: =SUM(E9:E14) -> 0 | F15: =SUM(F9:F14) -> 0 | G15: =SUM(G9:G14) -> 0 | H15: =H14+#REF! -> #REF! | I15: =I14+#REF! -> #REF! | J15: =SUMPRODUCT(D15:G15,D$4:G$4) -> 0 | N15: Insurance premiums for owner's health, life, etc.
A16: Seller's Discretionary Earnings will sometimes include the following additions/deletions - line items indicating "cash flowing" to or from the company to the owner | N16: Personal Home Internet Service
A17: 11 | B17: Salaries to Non-Working Family Members | D17: 0 | E17: 0 | F17: 0 | G17: 0 | J17: =SUMPRODUCT(D17:G17,D$4:G$4) -> 0 | N17: Maid / Housecleaning services
A18: 12 | B18: Salary Adjustments for Other Owners & Family Members | D18: 0 | E18: 0 | F18: 0 | G18: 0 | J18: =SUMPRODUCT(D18:G18,D$4:G$4) -> 0 | N18: Memberships (Equipment or Health, Country or Golf Clubs)
A19: 13 | B19: Payroll Tax Additions/Deletions For 10 & 11 Above | D19: 0 | E19: 0 | F19: 0 | G19: 0 | J19: =SUMPRODUCT(D19:G19,D$4:G$4) -> 0 | N19: Non-Business Postage/Shipping
A20: 14 | B20: Auto Lease/Payments for Owner's Benefit | D20: 0 | E20: 0 | F20: 0 | G20: 0 | J20: =SUMPRODUCT(D20:G20,D$4:G$4) -> 0 | N20: Unique payroll benefits paid to owner
A21: 15 | B21: Auto Insurance for Owner's Benefit | D21: 0 | E21: 0 | F21: 0 | G21: 0 | J21: =SUMPRODUCT(D21:G21,D$4:G$4) -> 0 | N21: Personal Credit Cards paid by business
A22: 16 | B22: Auto Repairs & Maintenance for Owner's Benefit | D22: 0 | E22: 0 | F22: 0 | G22: 0 | J22: =SUMPRODUCT(D22:G22,D$4:G$4) -> 0 | N22: Personal or Owner Family Products Purchased/Services Used (Provided by or paid for by company)
A23: 17 | B23: Contributions and Donations | D23: 0 | E23: 0 | F23: 0 | G23: 0 | J23: =SUMPRODUCT(D23:G23,D$4:G$4) -> 0 | N23: Non-Business Professional Services (Legal/Accounting/Tax)
A24: 18 | B24: Fair Market Rent Additions/Deletions | D24: 0 | E24: 0 | F24: 0 | G24: 0 | J24: =SUMPRODUCT(D24:G24,D$4:G$4) -> 0 | N24: Retirement plan contributions
A25: 19 | B25: Insurance Premiums for Owner's Health, Life, etc. | D25: 0 | E25: 0 | F25: 0 | G25: 0 | J25: =SUMPRODUCT(D25:G25,D$4:G$4) -> 0 | N25: Subscriptions to Personal Magazine, newspapers, etc.
A26: 20 | B26: Non-Business Professional Services (legal / accounting / tax) | D26: 0 | E26: 0 | F26: 0 | G26: 0 | J26: =SUMPRODUCT(D26:G26,D$4:G$4) -> 0
A27: 21 | B27: Retirement Plan Contributions | D27: 0 | E27: 0 | F27: 0 | G27: 0 | J27: =SUMPRODUCT(D27:G27,D$4:G$4) -> 0
A28: 22 | B28: Non-Business Meals & Entertainment | D28: 0 | E28: 0 | F28: 0 | G28: 0 | J28: =SUMPRODUCT(D28:G28,D$4:G$4) -> 0
A29: 23 | B29: Non-Business Travel | D29: 0 | E29: 0 | F29: 0 | G29: 0 | J29: =SUMPRODUCT(D29:G29,D$4:G$4) -> 0
A30: 24 | B30: Non-Business Telephone, Internet & Cell Phone expenses | D30: 0 | E30: 0 | F30: 0 | G30: 0 | J30: =SUMPRODUCT(D30:G30,D$4:G$4) -> 0
A31: 25 | B31: One Time Non-Recurring Charges or (Income) | D31: 0 | E31: 0 | F31: 0 | G31: 0 | J31: =SUMPRODUCT(D31:G31,D$4:G$4) -> 0
A32: 26 | B32: Inventory Adjustments | D32: 0 | E32: 0 | F32: 0 | G32: 0 | J32: =SUMPRODUCT(D32:G32,D$4:G$4) -> 0
A33: 27 | B33: Supplier Rebates | D33: 0 | E33: 0 | F33: 0 | G33: 0 | J33: =SUMPRODUCT(D33:G33,D$4:G$4) -> 0
A34: 28 | B34: Maintenance CapX (enter a negative number) | D34: 0 | E34: 0 | F34: 0 | G34: 0 | J34: =SUMPRODUCT(D34:G34,D$4:G$4) -> 0
A35: 29 | B35: Add others here | D35: 0 | E35: 0 | F35: 0 | G35: 0 | J35: =SUMPRODUCT(D35:G35,D$4:G$4) -> 0
A36: 30 | B36: Add others here | D36: 0 | E36: 0 | F36: 0 | G36: 0 | J36: =SUMPRODUCT(D36:G36,D$4:G$4) -> 0
A37: 31 | B37: Add others here | D37: 0 | E37: 0 | F37: 0 | G37: 0 | J37: =SUMPRODUCT(D37:G37,D$4:G$4) -> 0
... A40: 34 | B40: Add others here | D40: 0 | E40: 0 | F40: 0 | G40: 0 | J40: =SUMPRODUCT(D40:G40,D$4:G$4) -> 0
A41: 35 | B41: Sum of Discretionary Earnings Additions/Deletions | D41: =SUM(D17:D40) -> 0 | E41: =SUM(E17:E40) -> 0 | F41: =SUM(F17:F40) -> 0 | G41: =SUM(G17:G40) -> 0 | H41: =SUM(H14:H40) -> #REF! | I41: =SUM(I14:I40) -> #REF! | J41: =SUMPRODUCT(D41:G41,D$4:G$4) -> 0
A42: 36 | B42: Total Seller Discretionary Earnings (SDE) | D42: =D15+D41 -> 0 | E42: =E15+E41 -> 0 | F42: =F15+F41 -> 0 | G42: =G15+G41 -> 0 | H42: =#REF!+H41 -> #REF! | I42: =#REF!+I41 -> #REF! | J42: =SUMPRODUCT(D42:G42,D$4:G$4) -> 0

Sheet Step 3 Deal Calculator
B1: ANNUAL CASHFLOW YEAR 1 | H1: Watch a walkthrough of how to use the Deal Calculator in the MSA here.
H2: Contrarian Action Items
B3: Editable Cells Are Black | H3: FALSE | I3: Use the deal calculator to do a quick glance if this deal meets your deal box.
H4: FALSE | I4: Reach out to seller/broker
B5: LOAN PAYMENT CALCULATOR | E5: EXPENSES (MONEY OUT) | H5: FALSE | I5: Sign NDA
B6: Purchase Price | C6: 1000000 | H6: FALSE | I6: Get 3 years of recast earnings or P&Ls
B7: Down payment | C7: 100000 | H7: FALSE | I7: Move to step 3 to make an offer
B8: Loan Amount #1 | C8: 800000
B9: Loan #1 Additional Fees Added To Loan (Default is SBA upfront guarantee fee) | C9: =IF(C8<=150000,C8*0.02,IF(C8<=700000,C8*0.03,IF(C8<=1000000,C8*0.035,35000+((C8-1000000)*0.0375)))) -> 28000
B10: Interest Rate (Annual) | C10: 0.1
B11: Term (Years) | C11: 10 | H11: Notes From P&L
B12: Loan Amount #2 | C12: =C6-C7-C8 -> 100000
B13: Interest Rate (Annual) | C13: 0.05 | H13: You can write any notes here about the business. Anything interesting from the P&L? Important caveats?
B14: Term (Years) | C14: 5
B15: Debt Service Coverage Ratio | C15: =(C36+C26-C37)/C26 -> 2.1110688
B16: Monthly Loan Payment | C16: =PMT(C13/12, C14*12, -C12)+(PMT(C10/12, C11*12, -C8-C9)) -> 12829.204
B18: REVENUE (MONEY IN - ANNUAL)
B19: Money In (Annual Business Revenue) | C19: 1500000
B20: Total Annual Income | C20: =C19 -> 1500000
B22: EXPENSES (MONEY OUT - ANNUAL)
B23: Operating Expenses | C23: 1050000
B24: Cost of Goods Sold | C24: 200000
B25: Maintenance CapX | C25: 0 | H25: Salary NEEDED From Biz
B26: Annual Loan Payments | C26: =C16*12 -> 153950.45 | E26: ADDITIONAL CALCULATIONS
B27: Operator Salary + Benefits (Annual - New Hire / Not Current Employee) | C27: 0 | E27: Gross Profit Margin | F27: =(C20-C24)/C20 -> 0.86666667 | H27: Only put a value here if you NEED income from this business to pay your basic living expenses. If you have income from another W2, investments, spousal income, etc. that covers basic expenses, leave this at $0. The only impact this number has is on the DSCR - it will lower the DSCR because if you NEED income from the business, then part of the cash flow the business is generating is not available to pay off debt because you NEED it. This is how a lender underwrites a loan. If you're relying on the business for basic expenses, they will usually assume some reasonable amount based upon where you live (usually up to $100,000). We're talking basic expenses here, nothing fancy.
B28: Total Annual Expenses | C28: =SUM(C23:C27) -> 1403950.5 | E28: Net Profit Margin | F28: =(C36+C26)/C20 -> 0.21666667
E29: Cash on Cash Return (Annual Cash Flow / Cash Invested) | F29: =C36/C7 -> 1.7104955
B30: ADDBACKS & WORKING CAPITAL INCLUDED IN PURCHASE PRICE | E30: Estimated Revenue Drop Before Loan Under Water | F30: =(C19-((C23+C25+C26+C27-C31)/F27))/C19 -> 0.13157657
B31: Annual Addbacks (Owner Benefits + Depreciation + Interest + Taxes | C31: 75000
B32: Cash + Accounts Receivable + Cash Equivalents - Accounts Payable (Affects Multiple) | C32: 0 | E32: TOTAL RETURN ON INITIAL INVESTMENT (BASED ON ZERO GROWTH)
E33: YEAR 1 | F33: =((C36)-C7)/C7 -> 0.71049547
B34: CASH FLOW (INCOME - TOTAL ANNUAL EXPENSES + ADDBACKS + YOUR SALARY) | E34: YEAR 2 | F34: =((C36*2)-C7)/C7 -> 2.4209909
B35: Monthly Cashflow | C35: =(C20-C28+C31)/12 -> 14254.129 | E35: YEAR 3* | F35: =((C36*3)-C7)/C7 -> 4.1314864
B36: Annual Cashflow | C36: =(C20-C28+C31) -> 171049.55 | E36: * This is a cumalative return over the 3-year period.
B37: Your Salary NEEDED From This Business (See right sidebar for more details) | C37: 0
B38: Seller Discretionary Earnings (Rev - OpEx - COGS - MCapX + Addbacks) | C38: =C20-C23-C24-C25+C31 -> 325000
E39: MY DEAL BOX REQUIREMENTS (Fills in automatically from other tab)
B40: MULTIPLE CHART (SDE = OPERATING INCOME + ADDBACKS) | E40: Minimum Desired Annual Cashflow | F40: ='Step 1 Deal Box'!C5 -> 100000
B41: Purchase Price | C41: Multiple of SDE | E41: Deal Annual Cashflow | F41: =C36 -> 171049.55
B42: ="Asking Price Of "&TEXT(C6,"$0,000") & IF(C32>0," With "&TEXT(C32,"$0,000") & " of Working Capital","") -> Asking Price Of $1,000,000 | C42: =(C6-C32)/C38 -> 3.0769231 | E42: Max Purchase Price | F42: ='Step 1 Deal Box'!C11 -> 572000
...

Sheet Step 4 Offer Checklist
A1: Step 3: Make the seller an offer.
A2: Use the checklist below to cover most of your bases in the LOI and APA. Remember: everything is negotiable. You'll come back to this after due diligence to edit & tweak your offer after getting all the docs.
A4: Category | B4: Questions To Answer | C4: Answers | D4: Notes | E4: Added to LOI? | F4: Added to PA? | H4: Contrarian Action Items
A5: Accounts Payable | B5: Will you ask to include accounts payable? | D5: Typically not included but you could take these over (would make the purchase price lower). | E5: FALSE | F5: FALSE | H5: FALSE | I5: Determine offer price range (using deal calculator)
A6: Accounts Receivable | B6: Will you ask to include accounts receivable? | D6: The standard asset purchase agreement does not come with accounts receivable. You may want to include some because you'll need working capital. That would be a separate cash infusion, loan, AR, or a combo of all. | E6: FALSE | F6: FALSE | H6: FALSE | I6: Hire deal team to help draft LOI
A7: Broker Information | B7: Who's the broker? What's their fee? How will they be paid? | E7: FALSE | F7: FALSE | H7: FALSE | I7: Send LOI to broker/seller and review
A8: Close Date | B8: When will the deal close? | E8: FALSE | F8: FALSE | H8: FALSE | I8: Negotiate terms and price
A9: Confidentiality | B9: A clause for confidentiality for both parties until the deal is completed. | D9: We include verbiage in our LOI that protects our negotiation period for a set amount of time. That gives us time to take the next step and get under the hood of the business we’re interested in buying. This is typically not possible during the NDA stage, and it may cost some money to lock it down for this period. So the devil is in the details on how long of an exclusivity period we get. We often ask for 30 days. | E9: FALSE | F9: FALSE | H9: FALSE | I9: Have lawyer draft your PA
A10: Contingencies | B10: Business performance? | D10: In general - if there’s anything you’re concerned about, talk to your attorney - and add it into the agreement under contingencies. | E10: FALSE | F10: FALSE | H10: FALSE | I10: Get APA signed by seller
A11: Contingencies | B11: Lease? | D11: In general - if there’s anything you’re concerned about, talk to your attorney - and add it into the agreement under contingencies. | E11: FALSE | F11: FALSE
A12: Contingencies | B12: Financing? | D12: In general - if there’s anything you’re concerned about, talk to your attorney - and add it into the agreement under contingencies. | E12: FALSE | F12: FALSE | H12: Links
A13: Contingencies | B13: Timeline for DD? | D13: In general - if there’s anything you’re concerned about, talk to your attorney - and add it into the agreement under contingencies. | E13: FALSE | F13: FALSE | H13: LOI TEMPLATE
A14: Contingencies | B14: Add other contingencies that are relevant to your deal here. | D14: There are dozens of other contingencies you can add to your agreements. Your lawyer will likely know what to add. | E14: FALSE | F14: FALSE | H14: APA TEMPLATE (coming soon!)
A15: Contingencies | B15: Add other contingencies that are relevant to your deal here. | D15: There are dozens of other contingencies you can add to your agreements. Your lawyer will likely know what to add. | E15: FALSE | F15: FALSE
A16: Contingencies | B16: Add other contingencies that are relevant to your deal here. | D16: There are dozens of other contingencies you can add to your agreements. Your lawyer will likely know what to add. | E16: FALSE | F16: FALSE
A17: Contingencies | B17: Add other contingencies that are relevant to your deal here. | D17: There are dozens of other contingencies you can add to your agreements. Your lawyer will likely know what to add. | E17: FALSE | F17: FALSE
A18: Escrow | B18: Who to use, when escrow is opened, and any other relevant details. | D18: This is usually more addressed in the closing stage, so you may not have all the details yet. | E18: FALSE | F18: FALSE
A19: Financing | B19: How much will you include in your down payment? | D19: Your total down payment is.... Earnest deposit + deposit upon signing + additional cash during escrow + cash payments from 3rd party financing. Make sure to specify these amounts. | E19: FALSE | F19: FALSE
A20: Financing | B20: How much will be seller financed? | D20: Include percentage, payment period, and monthly payment amount. | E20: FALSE | F20: FALSE
A21: Financing | B21: Are you including earn-outs in the deal? | E21: FALSE | F21: FALSE
A22: Financing | B22: Are you going to borrow from any third parties? | D22: Specify who the parties are, what the potential interest rate would be, monthly payments, etc. | E22: FALSE | F22: FALSE
A23: Financing | B23: Are you bringing in equity partners? | E23: FALSE | F23: FALSE
A24: Inventory | B24: What is the amount of inventory that will be included in this sale? | D24: Get specifics on what inventory means as well. | E24: FALSE | F24: FALSE
A25: Non-compete | B25: Length of time, and distance that the owner will not compete. | E25: FALSE | F25: FALSE
A26: Non-recruit | B26: The owner will not recruit employees. | E26: FALSE | F26: FALSE
A27: Non-solicit | B27: The owner will not take clients away from the business. | E27: FALSE | F27: FALSE
A28: Termination | B28: When will the agreement expire? | E28: FALSE | F28: FALSE
A29: Transition Period | B29: How long will the owner stay on? | D29: Maybe you could ask for more (that you don’t really need) so you can give it back during negotiation. Example: ask for a training period of 8 weeks. Still make it fair, but lean into this. | E29: FALSE | F29: FALSE
A30: Transition Period | B30: What tasks are required of the owner? How much training will they provide? | E30: FALSE | F30: FALSE
A31: Work In Process | B31: Is there any outstanding deposits for work to be completed that should be included? | D31: Example: A business received $100K deposit for work to be done, but it’s not completed yet. That's a liability of the company. The buyer is going to have to take that on, and they should get that cash back - because it's a deposit, and they still have to do the work. | E31: FALSE | F31: FALSE

Sheet Step 5 Due Diligence Checklist
A1: Step 4: Due Diligence
A2: After they accept your initial offer, you'll need to go into proper due diligence. This is where you'll fact check the P&L and get other documents to answer important questions before signing the APA. You'll mark which documents you feel are required in order to close the deal. We added in our recommendations.
A4: Document Name | B4: Category | C4: Importance | D4: Notes | E4: Status | F4: Links | H4: Contrarian Action Items
A5: Three Years of P&Ls | B5: Finances | D5: If it’s a brokered deal, you’ll usually get a recast earnings statement. That’s a P&L with addbacks to arrive at SDE. You may get that instead of a P&L - either works. | H5: FALSE | I5: Gather necessary documents.
A6: Three Years of Tax Returns Tax Returns for at least the past three years | B6: Finances | D6: 4506-T is a document that gives you the ability to reach out to the IRS and get copies of returns directly from them. A lender will require this. Still helpful for you to have to verify accuracy of tax returns. | H6: FALSE | I6: Gather nice-to-have documents that you feel are important to the deal.
A7: YTD P&L | B7: Finances | H7: FALSE | I7: Use the documents to verify accuracy of your sales price, catch any red flags, and look for Contrarian Value Markers.
A8: Three Years of Balance Sheets | B8: Finances | H8: FALSE | I8: If all is looking good, adjust your initial offer. Send an APA.
A9: 1-3 Years of Bank Statements | B9: Finances | D9: If you’re doing any kind of bank financing, you’ll need bank statements. You’ll likely need to hire an an accountant to help sort through the bank statements to confirm the accuracy of the P&L. | H9: FALSE | I9: Use the closing checklist to close the deal!
A10: Equipment List, Inventory of All Products, Equipment, and Real Estate | B10: Assets | D10: You aren’t getting a valuation. You could ask for year and condition but a valuation requires resources most owners aren’t going to bring like an appraisal that costs $$.
A11: Current leases and titles | B11: Assets | D11: ADA and similar laws are all compliant with all properties
A12: Full inventory of all property including automobiles, boats, equipment, real estate, and inventory | B12: Assets | D12: Also list essential items currently being used by the business that will not be included in the sale
A13: Get any required inspections done (health, fire, etc) | B13: Assets
A14: Office & warehouse locations | B14: Assets
A15: All products and services, including cost and margins | B15: Operations & Business Structure
A16: Company names & trademarks, patents & other IP. Also any fictitious business names used by the company. | B16: Operations & Business Structure | D16: All company’s patents, trademarks, and copyrights. Product inventions, formulas, recipes, or technical know-how. All rights owned data and digital information. Get confirmation on who developed the IP.
A17: Copy of all operating licenses with any city, county, or state agency | B17: Operations & Business Structure | D17: All permits for the conduct of business, including licenses, franchises and concessions, including any current or pending governmental permits, licenses, grants and tax concessions or certificates.
A18: Insurance coverage & policies | B18: Operations & Business Structure | D18: Also get any historic claims made against insurance
A19: All former citations within the past 3 years for failure by the Company to comply with applicable local, state and federal laws | B19: Legal
A20: All nondisclosure or non-compete agreements | B20: Legal
A21: Any pending litigations or threats | B21: Legal | D21: Pro tip: Have the seller sign off that no legal issues currently exist in your contract so you have a back-out provision if something goes wrong later. Your lawyer can write this up for you.
A22: Contracts between officers, directors, or principals of the company. | B22: Legal
A23: Distribution agreements, sales agreements, subscription agreements | B23: Legal
A24: LOI’s, contracts, closing transcripts from mergers or acquisitions | B24: Legal | D24: Would only apply if the company has former acquisitions or mergers.
A25: Partnerships & JV’s | B25: Legal
A26: Details of payments made during the last 12 months including 1099 and other contractor/consultant payments | B26: Legal
A27: Warranty and Guarantee Policies | B27: Customer
A28: Quality of Earnings Report | B28: Finances | D28: Typically only done on larger deals. Usually starting at about $10k.
A29: Three Years of Cash Flow Statements | B29: Finances | D29: Not the same as a P&L. Not all businesses will have this. Great if they do.
A30: Accounts Payable and Receivable | B30: Finances | D30: Only ask for this if you’re trying to buy the working capital or if they have a large amount of AR.
A31: Credit Report | B31: Finances | D31: Only applicable for stock or member interest purchases where you’ll own the current legal entity.
A32: List of ALL Debts | B32: Finances | D32: Only applicable for stock or member interest purchases. If applicable, also get the terms, existing loan agreements, lines of credit, equipment leases or any other debt.
A33: Sales Tax Reports | B33: Finances | D33: Only applies if the business sells retail and has to file such reports.
A34: Federal Payroll Tax Forms (Form 941) | B34: Finances
A35: State Payroll Tax Forms (Forms Vary) | B35: Finances | D35: See what forms are required for your state.
A36: Profit & Loss Broken Down By Month & Annual of Current Year | B36: Finances | D36: Good to see if it’s a seasonal business.
A37: See The Business IRL | D37: Look up photos of the business (or just their website). Then go to the business IRL. Pose as a customer. Don’t say you’re loking to buy. Get a feel for how it’s currently managed. Is it clean and well-maintained? Did you have a good experience using their services? This may seem minor, but it can make a huge difference on the bottom line later.
A38: Marketing plans including advertising programs, marketing programs, and events | B38: Growth | D38: Identify any marketing-related costs. Customer lead acquisition report across all channels. Any customer loyalty programs?
A39: List all major competitors and their pricing | B39: Industry | D39: Can ask the seller for any industry trends or intel they have on competitors. But most of this research will be done yourself.
A40: Data security - confirm all data is secure | B40: Assets | D40: - Confirm how they use personal information
A41: - Procedures around customer policy
...

Sheet Step 6 Contrarian Value Markers
A1: Step 5: Contrarian Business Value Markers
A2: Get answers to the questions below with everything you've gotten so far. This will answer the question "Is this risk acceptable to me?" Remember: The answers are not deal-breakers. These are nice-to-haves. More is better. More risk --> adjust your sale price or terms.
A4: Category | B4: Questions To Ask | C4: Answers | D4: Notes | E4: Risk Level | G4: Risk Ranking
A5: Financial Viability | B5: Does the business have increasing revenue streams to demonstrate the ability to generate income over time? | G5: The risk rank is a formula that is automatically calculated based on your answers at left. Do not edit.
A6: Financial Viability | B6: Does the business have professional bookkeeping and detailed financial records to ensure accuracy, transparency, and accountability? | G6: Financial Viability | H6: =_xludf.IFS(COUNTIF(E5:E7, "Somewhat Risky") > COUNTIF(E5:E7, "Looks Good") + COUNTIF(E5:E7, "Not Good"), "Somewhat Risky", COUNTIF(E5:E7, "Looks Good") > COUNTIF(E5:E7, "Somewhat Risky") + COUNTIF(E5:E7, "Not Good"), "Looks Good", COUNTIF(E5:E7, "Not Good") > COUNTIF(E5:E7, "Looks Good") + COUNTIF(E5:E7, "Somewhat Risky"), "Not Good", COUNTIF(E5:E7, "Looks Good") = COUNTIF(E5:E7, "Not Good"), "Somewhat Risky", COUNTIF(E5:E7, "Looks Good") = COUNTIF(E5:E7, "Somewhat Risky"), "Somewhat Risky", COUNTIF(E5:E7, "Not Good") = COUNTIF(E5:E7, "Somewhat Risky"), "Somewhat Risky", AND(COUNTIF(E5:E7, "Looks Good") = 0, COUNTIF(E5:E7, "Somewhat Risky") = 0, COUNTIF(E5:E7, "Not Good") = 0), "") -> #NAME?
A7: Financial Viability | B7: Are profit margins healthy compared to industry peers? | G7: Diversification | H7: =_xludf.IFS(COUNTIF(E8:E13, "Somewhat Risky") > COUNTIF(E8:E13, "Looks Good") + COUNTIF(E8:E13, "Not Good"), "Somewhat Risky", COUNTIF(E8:E13, "Looks Good") > COUNTIF(E8:E13, "Somewhat Risky") + COUNTIF(E8:E13, "Not Good"), "Looks Good", COUNTIF(E8:E13, "Not Good") > COUNTIF(E8:E13, "Looks Good") + COUNTIF(E8:E13, "Somewhat Risky"), "Not Good", COUNTIF(E8:E13, "Looks Good") = COUNTIF(E8:E13, "Not Good"), "Somewhat Risky", COUNTIF(E8:E13, "Looks Good") = COUNTIF(E8:E13, "Somewhat Risky"), "Somewhat Risky", COUNTIF(E8:E13, "Not Good") = COUNTIF(E8:E13, "Somewhat Risky"), "Somewhat Risky", AND(COUNTIF(E8:E13, "Looks Good") = 0, COUNTIF(E8:E13, "Somewhat Risky") = 0, COUNTIF(E8:E13, "Not Good") = 0), "") -> #NAME?
A8: Diversification | B8: Does the business have a diverse customer base to minimize reliance on a single client or market segment? | G8: Employee-Centric Risk | H8: =_xludf.IFS(COUNTIF(E14:E17, "Somewhat Risky") > COUNTIF(E14:E17, "Looks Good") + COUNTIF(E14:E17, "Not Good"), "Somewhat Risky", COUNTIF(E14:E17, "Looks Good") > COUNTIF(E14:E17, "Somewhat Risky") + COUNTIF(E14:E17, "Not Good"), "Looks Good", COUNTIF(E14:E17, "Not Good") > COUNTIF(E14:E17, "Looks Good") + COUNTIF(E14:E17, "Somewhat Risky"), "Not Good", COUNTIF(E14:E17, "Looks Good") = COUNTIF(E14:E17, "Not Good"), "Somewhat Risky", COUNTIF(E14:E17, "Looks Good") = COUNTIF(E14:E17, "Somewhat Risky"), "Somewhat Risky", COUNTIF(E14:E17, "Not Good") = COUNTIF(E14:E17, "Somewhat Risky"), "Somewhat Risky", AND(COUNTIF(E14:E17, "Looks Good") = 0, COUNTIF(E14:E17, "Somewhat Risky") = 0, COUNTIF(E14:E17, "Not Good") = 0), "") -> #NAME?
A9: Diversification | B9: Would it be a huge impact losing the largest customer have on this business? | G9: Cashflow vs Cashsuck | H9: =_xludf.IFS(COUNTIF(E18:E22, "Somewhat Risky") > COUNTIF(E18:E22, "Looks Good") + COUNTIF(E18:E22, "Not Good"), "Somewhat Risky", COUNTIF(E18:E22, "Looks Good") > COUNTIF(E18:E22, "Somewhat Risky") + COUNTIF(E18:E22, "Not Good"), "Looks Good", COUNTIF(E18:E22, "Not Good") > COUNTIF(E18:E22, "Looks Good") + COUNTIF(E18:E22, "Somewhat Risky"), "Not Good", COUNTIF(E18:E22, "Looks Good") = COUNTIF(E18:E22, "Not Good"), "Somewhat Risky", COUNTIF(E18:E22, "Looks Good") = COUNTIF(E18:E22, "Somewhat Risky"), "Somewhat Risky", COUNTIF(E18:E22, "Not Good") = COUNTIF(E18:E22, "Somewhat Risky"), "Somewhat Risky", AND(COUNTIF(E18:E22, "Looks Good") = 0, COUNTIF(E18:E22, "Somewhat Risky") = 0, COUNTIF(E18:E22, "Not Good") = 0), "") -> #NAME?
A10: Diversification | B10: What percentage of the business's total revenue was generated by its largest customer last year? | G10: Unfair Advantage | H10: =_xludf.IFS(COUNTIF(E23:E28, "Somewhat Risky") > COUNTIF(E23:E28, "Looks Good") + COUNTIF(E23:E28, "Not Good"), "Somewhat Risky", COUNTIF(E23:E28, "Looks Good") > COUNTIF(E23:E28, "Somewhat Risky") + COUNTIF(E23:E28, "Not Good"), "Looks Good", COUNTIF(E23:E28, "Not Good") > COUNTIF(E23:E28, "Looks Good") + COUNTIF(E23:E28, "Somewhat Risky"), "Not Good", COUNTIF(E23:E28, "Looks Good") = COUNTIF(E23:E28, "Not Good"), "Somewhat Risky", COUNTIF(E23:E28, "Looks Good") = COUNTIF(E23:E28, "Somewhat Risky"), "Somewhat Risky", COUNTIF(E23:E28, "Not Good") = COUNTIF(E23:E28, "Somewhat Risky"), "Somewhat Risky", AND(COUNTIF(E23:E28, "Looks Good") = 0, COUNTIF(E23:E28, "Somewhat Risky") = 0, COUNTIF(E23:E28, "Not Good") = 0), "") -> #NAME?
A11: Diversification | B11: How feasible would it be to find an alternative supplier for the business's most crucial external provider? | G11: Happy Customers | H11: =_xludf.IFS(COUNTIF(E29:E34, "Somewhat Risky") > COUNTIF(E29:E34, "Looks Good") + COUNTIF(E29:E34, "Not Good"), "Somewhat Risky", COUNTIF(E29:E34, "Looks Good") > COUNTIF(E29:E34, "Somewhat Risky") + COUNTIF(E29:E34, "Not Good"), "Looks Good", COUNTIF(E29:E34, "Not Good") > COUNTIF(E29:E34, "Looks Good") + COUNTIF(E29:E34, "Somewhat Risky"), "Not Good", COUNTIF(E29:E34, "Looks Good") = COUNTIF(E29:E34, "Not Good"), "Somewhat Risky", COUNTIF(E29:E34, "Looks Good") = COUNTIF(E29:E34, "Somewhat Risky"), "Somewhat Risky", COUNTIF(E29:E34, "Not Good") = COUNTIF(E29:E34, "Somewhat Risky"), "Somewhat Risky", AND(COUNTIF(E29:E34, "Looks Good") = 0, COUNTIF(E29:E34, "Somewhat Risky") = 0, COUNTIF(E29:E34, "Not Good") = 0), "") -> #NAME?
A12: Diversification | B12: Are there multiple revenue streams within the business to spread risk and ensure stability? | G12: Recurring Revenue | H12: =_xludf.IFS(COUNTIF(E35:E39, "Somewhat Risky") > COUNTIF(E35:E39, "Looks Good") + COUNTIF(E35:E39, "Not Good"), "Somewhat Risky", COUNTIF(E35:E39, "Looks Good") > COUNTIF(E35:E39, "Somewhat Risky") + COUNTIF(E35:E39, "Not Good"), "Looks Good", COUNTIF(E35:E39, "Not Good") > COUNTIF(E35:E39, "Looks Good") + COUNTIF(E35:E39, "Somewhat Risky"), "Not Good", COUNTIF(E35:E39, "Looks Good") = COUNTIF(E35:E39, "Not Good"), "Somewhat Risky", COUNTIF(E35:E39, "Looks Good") = COUNTIF(E35:E39, "Somewhat Risky"), "Somewhat Risky", COUNTIF(E35:E39, "Not Good") = COUNTIF(E35:E39, "Somewhat Risky"), "Somewhat Risky", AND(COUNTIF(E35:E39, "Looks Good") = 0, COUNTIF(E35:E39, "Somewhat Risky") = 0, COUNTIF(E35:E39, "Not Good") = 0), "") -> #NAME?
A13: Diversification | B13: Does the business operate in multiple geographical locations or markets to reduce exposure to regional economic fluctuations? | G13: Owner-Centric Risk | H13: =_xludf.IFS(COUNTIF(E40:E43, "Somewhat Risky") > COUNTIF(E40:E43, "Looks Good") + COUNTIF(E40:E43, "Not Good"), "Somewhat Risky", COUNTIF(E40:E43, "Looks Good") > COUNTIF(E40:E43, "Somewhat Risky") + COUNTIF(E40:E43, "Not Good"), "Looks Good", COUNTIF(E40:E43, "Not Good") > COUNTIF(E40:E43, "Looks Good") + COUNTIF(E40:E43, "Somewhat Risky"), "Not Good", COUNTIF(E40:E43, "Looks Good") = COUNTIF(E40:E43, "Not Good"), "Somewhat Risky", COUNTIF(E40:E43, "Looks Good") = COUNTIF(E40:E43, "Somewhat Risky"), "Somewhat Risky", COUNTIF(E40:E43, "Not Good") = COUNTIF(E40:E43, "Somewhat Risky"), "Somewhat Risky", AND(COUNTIF(E40:E43, "Looks Good") = 0, COUNTIF(E40:E43, "Somewhat Risky") = 0, COUNTIF(E40:E43, "Not Good") = 0), "") -> #NAME?
A14: Employee-Centric Risk | B14: How difficult would it be to replace the employee responsible for sales and marketing? product or service delivery? customer support? | G14: Upside Potential | H14: =_xludf.IFS(COUNTIF(E44:E50, "Somewhat Risky") > COUNTIF(E44:E50, "Looks Good") + COUNTIF(E44:E50, "Not Good"), "Somewhat Risky", COUNTIF(E44:E50, "Looks Good") > COUNTIF(E44:E50, "Somewhat Risky") + COUNTIF(E44:E50, "Not Good"), "Looks Good", COUNTIF(E44:E50, "Not Good") > COUNTIF(E44:E50, "Looks Good") + COUNTIF(E44:E50, "Somewhat Risky"), "Not Good", COUNTIF(E44:E50, "Looks Good") = COUNTIF(E44:E50, "Not Good"), "Somewhat Risky", COUNTIF(E44:E50, "Looks Good") = COUNTIF(E44:E50, "Somewhat Risky"), "Somewhat Risky", COUNTIF(E44:E50, "Not Good") = COUNTIF(E44:E50, "Somewhat Risky"), "Somewhat Risky", AND(COUNTIF(E44:E50, "Looks Good") = 0, COUNTIF(E44:E50, "Somewhat Risky") = 0, COUNTIF(E44:E50, "Not Good") = 0), "") -> #NAME?
A15: Employee-Centric Risk | B15: What happens when the key employee takes a vacation? | G15: Repeatable Processes & Documentation | H15: =_xludf.IFS(COUNTIF(E51:E54, "Somewhat Risky") > COUNTIF(E51:E54, "Looks Good") + COUNTIF(E51:E54, "Not Good"), "Somewhat Risky", COUNTIF(E51:E54, "Looks Good") > COUNTIF(E51:E54, "Somewhat Risky") + COUNTIF(E51:E54, "Not Good"), "Looks Good", COUNTIF(E51:E54, "Not Good") > COUNTIF(E51:E54, "Looks Good") + COUNTIF(E51:E54, "Somewhat Risky"), "Not Good", COUNTIF(E51:E54, "Looks Good") = COUNTIF(E51:E54, "Not Good"), "Somewhat Risky", COUNTIF(E51:E54, "Looks Good") = COUNTIF(E51:E54, "Somewhat Risky"), "Somewhat Risky", COUNTIF(E51:E54, "Not Good") = COUNTIF(E51:E54, "Somewhat Risky"), "Somewhat Risky", AND(COUNTIF(E51:E54, "Looks Good") = 0, COUNTIF(E51:E54, "Somewhat Risky") = 0, COUNTIF(E51:E54, "Not Good") = 0), "") -> #NAME?
A16: Employee-Centric Risk | B16: Are there incentives or retention plans to motivate the key employee to stay with the business for the long term?
A17: Employee-Centric Risk | B17: Are strategies in place to establish a pool of potential hires for vital positions in case of key employee turnover?
A18: Cashflow vs Cash-Suck | B18: Does the business have a history of maintaining positive cash flow to cover operating expenses, debt obligations, and investments?
A19: Cashflow vs Cash-Suck | B19: Are there any outstanding debts or overdue payments that could indicate cash flow issues?
A20: Cashflow vs Cash-Suck | B20: Are there any seasonal fluctuations in cash flow, and if so, how does the business manage these fluctuations?
A21: Cashflow vs Cash-Suck | B21: Does the business charge for services or goods up-front first, and then provide service? Or is payment received after service is performed?
A22: Cashflow vs Cash-Suck | B22: Can the business extend the payment terms with certain vendors to manage cash flow more effectively?
A23: Unfair Advantage | B23: What distinguishes the business from others in the market, and how can it leverage that uniqueness?
A24: Unfair Advantage | B24: What motivates customers to choose this business over others?
A25: Unfair Advantage | B25: Does the business have a strong brand reputation that competitors find difficult to replicate?
A26: Unfair Advantage | B26: Are there any regulatory barriers or high entry costs that deter competitors from entering the market?
A27: Unfair Advantage | B27: Does the business have any patents, trademarks, or proprietary technology that sets it apart from competitors?
... A54: Repeatable Processes & Documentation | B54: Can the business provide evidence of repeatable sales or marketing processes that consistently generate leads and conversions?

Sheet Step 7 Closing Checklist
A1: Step 6: Close the deal.
A2: Use the checklist below to know what next steps are for the deal to close. These are not in chronological order. Disclaimer: Every transaction is unique so this list is not comprehensive. There are items that may be specific to your deal. You can add them below.
A4: Category | B4: Action Item | C4: Who's Responsible | D4: Notes | E4: Date Due | F4: Status | G4: Links (where applicable)
A5: Business Performance | B5: Request information (due diligence) | C5: Buyer
A6: Business Performance | B6: Provide information (due diligence) | C6: Seller
A7: Business Performance | B7: Review information | C7: Buyer
A8: Business Performance | B8: Remove business performance contingency | C8: Buyer
A9: Cash Deposits | B9: Earnest deposit upon acceptance sent to escrow | C9: Buyer
A10: Cash Deposits | B10: Earnest deposit upon escrow instructions sent to escrow | C10: Buyer
A11: Cash Deposits | B11: Balance of cash deposit sent to escrow | C11: Buyer
A12: Escrow Checks | B12: Sign escrow instructions | C12: Buyer & Seller
A13: Escrow Checks | B13: Bulk sale compliance (depending upon state) | C13: Escrow Holder
A14: Escrow Checks | B14: Obtain state tax release (depending upon state) | C14: Escrow Holder
A15: Escrow Checks | B15: Obtain sales tax release (depending upon state and if applicable) | C15: Escrow Holder
A16: Escrow Checks | B16: Obtain state lien search report | C16: Escrow Holder
... A51: Signed Documents | B51: Employment or Consulting Agreement (if required with prior owner continuing as employee) | C51: Buyer & Seller

Sheet Step 8 Day 0 Checklist
A1: Step 7: Start running the business.
A2: Use the checklist below to cover most of your bases for starting on day 0. Disclaimer: Every business is different so not all of these will be required. And we highly recommend adding in your own items below.
A4: Category | B4: Action Item | C4: Who's Responsible | D4: Notes | E4: Date Due | F4: Status | H4: Stock vs Asset Purchases
A5: Customers | B5: Transfer CRM and all other software | C5: Buyer | H5: Most of the time when buying a business, you're buying the asset itself - aka the business. This means the old company no longer exists. So you'll have to recreate the LLC, payroll, rehire employees, etc. The checklist at left is based on an asset purchase. If you are purchasing the stock, you are purchasing the business as a whole - and not recreating it. So you'll carry over all the existing items.
A6: Customers | B6: Get customer lists | C6: Buyer
A7: Customers | B7: Get vendor lists | C7: Buyer
A8: Customers | B8: Copies of standard communications and correspondence | C8: Buyer
A9: Customers | B9: Any customer research data, white papers, or research | C9: Buyer & Seller
A10: Employees | B10: An organization chart showing all employee contact info, bios on employees, job descriptions | C10: Buyer & Seller
A11: Employees | B11: Setup payroll service | C11: Buyer
A12: Employees | B12: Re-hire employees | C12: Buyer
A13: Employees | B13: Establish employee benefits | C13: Buyer
A14: Employees | B14: Create employee manual | C14: Buyer
A15: Employees | B15: Meet with employees | C15: Buyer
A16: Employees | B16: Optional: Assess if you want to give employees a raise or bonus. Sometimes this is expected because you are new to the business. | C16: Buyer
A17: Financial | B17: Establish bank account | C17: Buyer
... A29: Owner Transition | B29: Set plan for transfer of knowledge (systems, passwords, SOPs, etc) | C29: Buyer & Seller
A30: Owner Transition | B30: Create a plan for training, if included in your agreement | C30: Buyer & Seller | D30: This is applicable if you included any sort of transition or offboarding in your PA.
A31: Misc | B31: Inspect equipment and other assets | C31: Buyer | D31: Use the list of assets as your guide for what you need to transfer over if you're unsure of everything needed.
A32: Misc | B32: Agree on final inventory amount | C32: Buyer & Seller
A33: Misc | B33: Conduct phase 1 environmental report (if required) | C33: Buyer
A34: Misc | B34: Arrange insurance (property, liability, worker’s com, etc.) | C34: Buyer
A35: Misc | B35: Transfer telephone number | C35: Buyer
A36: Misc | B36: Switch gas & electric | C36: Buyer
A37: Misc | B37: Switch water | C37: Buyer
A38: Misc | B38: Switch garbage | C38: Buyer
A39: Misc | B39: Get the keys! | C39: Buyer
A40: Misc | B40: Access to security and alarm systems | C40: Buyer
A41: Misc | B41: Optional: Pay an employee a bonus to help with the transition. Spend your time on important tasks and not on chasing down misc items. | C41: Buyer
A42: Misc | B42: Transfer website, domain, and other IP | C42: Buyer
A43: Misc | B43: Finalize assignment of third-party contracts | C43: Buyer
... A50: Misc | B50: Add your own here | C50: Buyer

Sheet BONUS Cashflow Tracker (Weekly)
B2: 13 Weekly Cash Flow Projection
B3: [Company Name]
C4: Current Week | D4: Week 2 | E4: Week 3 | F4: Week 4 | G4: Week 5 | H4: Week 6 | I4: Week 7 | J4: Week 8 | K4: Week 9 | L4: Week 10 | M4: Week 11 | N4: Week 12 | O4: Week 13
C5: 45240 | D5: =C5+7 -> 45247 | E5: =D5+7 -> 45254 | F5: =E5+7 -> 45261 | G5: =F5+7 -> 45268 | H5: =G5+7 -> 45275 | I5: =H5+7 -> 45282 | J5: =I5+7 -> 45289 | K5: =J5+7 -> 45296 | ... O5: =N5+7 -> 45324
C6: Projected | D6: Projected | E6: Projected | F6: Projected | G6: Projected | H6: Projected | I6: Projected | J6: Projected | K6: Projected | L6: Projected | M6: Projected | N6: Projected | O6: Projected
B7: Cash on hand (beginning of month) | D7: =C53 -> 0 | E7: =D53 -> 0 | F7: =E53 -> 0 | G7: =F53 -> 0 | H7: =G53 -> 0 | I7: =H53 -> 0 | J7: =I53 -> 0 | K7: =J53 -> 0 | ... O7: =N53 -> 0
B8: CASH RECEIPTS
B9: Cash sales
B10: Returns and allowances
B11: Collections on accounts receivable
B12: Interest, other income
B13: Loan proceeds
B14: Owner contributions
B15: TOTAL CASH RECEIPTS | C15: =SUM(C9,C11:C14,(C10*-1)) -> 0 | D15: =SUM(D9,D11:D14,(D10*-1)) -> 0 | E15: =SUM(E9,E11:E14,(E10*-1)) -> 0 | F15: =SUM(F9,F11:F14,(F10*-1)) -> 0 | G15: =SUM(G9,G11:G14,(G10*-1)) -> 0 | H15: =SUM(H9,H11:H14,(H10*-1)) -> 0 | I15: =SUM(I9,I11:I14,(I10*-1)) -> 0 | J15: =SUM(J9,J11:J14,(J10*-1)) -> 0 | ... O15: =SUM(O9,O11:O14,(O10*-1)) -> 0
B16: Total cash available | C16: =C7+C15 -> 0 | D16: =D7+D15 -> 0 | E16: =E7+E15 -> 0 | F16: =F7+F15 -> 0 | G16: =G7+G15 -> 0 | H16: =H7+H15 -> 0 | I16: =I7+I15 -> 0 | J16: =J7+J15 -> 0 | ... O16: =O7+O15 -> 0
B18: CASH PAID OUT
B19: Advertising
B20: Commissions and fees
B21: Contract labor
B22: Employee benefit programs
B23: Insurance (other than health)
B24: Interest expense
B25: Materials and supplies (in COGS)
B26: Meals and entertainment
B27: Mortgage interest
B28: Office expense
B29: Other interest expense
... B43: Miscellaneous
B44: SUBTOTAL | C44: =SUM(C19:C43) -> 0 | D44: =SUM(D19:D43) -> 0 | E44: =SUM(E19:E43) -> 0 | F44: =SUM(F19:F43) -> 0 | G44: =SUM(G19:G43) -> 0 | H44: =SUM(H19:H43) -> 0 | I44: =SUM(I19:I43) -> 0 | J44: =SUM(J19:J43) -> 0 | ... O44: =SUM(O19:O43) -> 0
B45: OTHER CASH PAID OUT
B46: Loan principal payment
B47: Capital purchases
B48: Other startup costs
B49: To reserve and/or escrow
B50: Owners' withdrawal
B51: SUBTOTAL | C51: =SUM(C46:C50) -> 0 | D51: =SUM(D46:D50) -> 0 | E51: =SUM(E46:E50) -> 0 | F51: =SUM(F46:F50) -> 0 | G51: =SUM(G46:G50) -> 0 | H51: =SUM(H46:H50) -> 0 | I51: =SUM(I46:I50) -> 0 | J51: =SUM(J46:J50) -> 0 | ... O51: =SUM(O46:O50) -> 0
B52: TOTAL CASH PAID OUT | C52: =C44+C51 -> 0 | D52: =D44+D51 -> 0 | E52: =E44+E51 -> 0 | F52: =F44+F51 -> 0 | G52: =G44+G51 -> 0 | H52: =H44+H51 -> 0 | I52: =I44+I51 -> 0 | J52: =J44+J51 -> 0 | ... O52: =O44+O51 -> 0
B53: Cash on hand (end of month) | C53: =C16-C52 -> 0 | D53: =D16-D52 -> 0 | E53: =E16-E52 -> 0 | F53: =F16-F52 -> 0 | G53: =G16-G52 -> 0 | H53: =H16-H52 -> 0 | I53: =I16-I52 -> 0 | J53: =J16-J52 -> 0 | ... O53: =O16-O52 -> 0

Sheet BONUS Cashflow Tracker (Monthly
B1: MONTHLY Cash Flow Projection
B2: Company Name
B3: Starting date | C3: 45240
B4: Cash balance alert minimum | C4: =C7 -> 0 | E4: ='BONUS Cashflow Tracker (Monthly'!Cash_minimum -> 0 | F4: ='BONUS Cashflow Tracker (Monthly'!Cash_minimum -> 0 | G4: ='BONUS Cashflow Tracker (Monthly'!Cash_minimum -> 0 | H4: ='BONUS Cashflow Tracker (Monthly'!Cash_minimum -> 0 | I4: ='BONUS Cashflow Tracker (Monthly'!Cash_minimum -> 0 | J4: ='BONUS Cashflow Tracker (Monthly'!Cash_minimum -> 0 | K4: ='BONUS Cashflow Tracker (Monthly'!Cash_minimum -> 0 | L4: ='BONUS Cashflow Tracker (Monthly'!Cash_minimum -> 0 | ... O4: ='BONUS Cashflow Tracker (Monthly'!Cash_minimum -> 0
C6: Beginning | D6: 45322 | E6: 45323 | F6: 45352 | G6: 45383 | H6: 45413 | I6: 45444 | J6: 45474 | K6: 45505 | L6: 45536 | M6: 45566 | N6: 45597 | O6: 45627 | P6: Total
B7: Cash on hand (beginning of month) | C7: 0 | D7: =C54 -> 0 | E7: =D54 -> 0 | F7: =E54 -> 0 | G7: =F54 -> 0 | H7: =G54 -> 0 | I7: =H54 -> 0 | J7: =I54 -> 0 | K7: =J54 -> 0 | ... O7: =N54 -> 0 | P7: =SUM(C7:O7) -> 0
B9: CASH RECEIPTS | D9: =D6 -> 45322 | E9: =E6 -> 45323 | F9: =F6 -> 45352 | G9: =G6 -> 45383 | H9: =H6 -> 45413 | I9: =I6 -> 45444 | J9: =J6 -> 45474 | K9: =K6 -> 45505 | ... O9: =O6 -> 45627 | P9: Total
B10: Cash sales | P10: =SUM(D10:O10) -> 0
B11: Returns and allowances | P11: =SUM(D11:O11) -> 0
B12: Collections on accounts receivable | P12: =SUM(D12:O12) -> 0
B13: Interest, other income | P13: =SUM(D13:O13) -> 0
B14: Loan proceeds | P14: =SUM(D14:O14) -> 0
B15: Owner contributions | P15: =SUM(D15:O15) -> 0
B16: TOTAL CASH RECEIPTS | D16: =SUM(D10,D12:D15,(D11*-1)) -> 0 | E16: =SUM(E10,E12:E15,(E11*-1)) -> 0 | F16: =SUM(F10,F12:F15,(F11*-1)) -> 0 | G16: =SUM(G10,G12:G15,(G11*-1)) -> 0 | H16: =SUM(H10,H12:H15,(H11*-1)) -> 0 | I16: =SUM(I10,I12:I15,(I11*-1)) -> 0 | J16: =SUM(J10,J12:J15,(J11*-1)) -> 0 | K16: =SUM(K10,K12:K15,(K11*-1)) -> 0 | ... O16: =SUM(O10,O12:O15,(O11*-1)) -> 0 | P16: =SUM(D16:O16) -> 0
B17: Total cash available | C17: =(C7+'BONUS Cashflow Tracker (Monthly'!$C$16) -> 0 | D17: =(D7+'BONUS Cashflow Tracker (Monthly'!$D$16) -> 0 | E17: =(E7+'BONUS Cashflow Tracker (Monthly'!$E$16) -> 0 | F17: =(F7+'BONUS Cashflow Tracker (Monthly'!$F$16) -> 0 | G17: =(G7+'BONUS Cashflow Tracker (Monthly'!$G$16) -> 0 | H17: =(H7+'BONUS Cashflow Tracker (Monthly'!$H$16) -> 0 | I17: =(I7+'BONUS Cashflow Tracker (Monthly'!$I$16) -> 0 | J17: =(J7+'BONUS Cashflow Tracker (Monthly'!$J$16) -> 0 | K17: =(K7+'BONUS Cashflow Tracker (Monthly'!$K$16) -> 0 | L17: =(L7+'BONUS Cashflow Tracker (Monthly'!$L$16) -> 0 | M17: =(M7+'BONUS Cashflow Tracker (Monthly'!$M$16) -> 0 | N17: =(N7+'BONUS Cashflow Tracker (Monthly'!$N$16) -> 0 | O17: =(O7+'BONUS Cashflow Tracker (Monthly'!$O$16) -> 0 | P17: =SUM(D17:O17) -> 0
B19: CASH PAID OUT | D19: =D9 -> 45322 | E19: =E9 -> 45323 | F19: =F9 -> 45352 | G19: =G9 -> 45383 | H19: =H9 -> 45413 | I19: =I9 -> 45444 | J19: =J9 -> 45474 | K19: =K9 -> 45505 | ... O19: =O9 -> 45627 | P19: Total
B20: Advertising | P20: =SUM(D20:O20) -> 0
B21: Commissions and fees | P21: =SUM(D21:O21) -> 0
B22: Contract labor | P22: =SUM(D22:O22) -> 0
B23: Employee benefit programs | P23: =SUM(D23:O23) -> 0
B24: Insurance (other than health) | P24: =SUM(D24:O24) -> 0
B25: Interest expense | P25: =SUM(D25:O25) -> 0
B26: Materials and supplies (in COGS) | P26: =SUM(D26:O26) -> 0
B27: Meals and entertainment | P27: =SUM(D27:O27) -> 0
B28: Mortgage interest | P28: =SUM(D28:O28) -> 0
B29: Office expense | P29: =SUM(D29:O29) -> 0
B30: Other interest expense | P30: =SUM(D30:O30) -> 0
B31: Pension and profit-sharing plan | P31: =SUM(D31:O31) -> 0
... B44: Miscellaneous | P44: =SUM(D44:O44) -> 0
B45: SUBTOTAL | D45: =SUBTOTAL(109,'BONUS Cashflow Tracker (Monthly'!$D$20:$D$44) -> 0 | E45: =SUBTOTAL(109,'BONUS Cashflow Tracker (Monthly'!$E$20:$E$44) -> 0 | F45: =SUBTOTAL(109,'BONUS Cashflow Tracker (Monthly'!$F$20:$F$44) -> 0 | G45: =SUBTOTAL(109,'BONUS Cashflow Tracker (Monthly'!$G$20:$G$44) -> 0 | H45: =SUBTOTAL(109,'BONUS Cashflow Tracker (Monthly'!$H$20:$H$44) -> 0 | I45: =SUBTOTAL(109,'BONUS Cashflow Tracker (Monthly'!$I$20:$I$44) -> 0 | J45: =SUBTOTAL(109,'BONUS Cashflow Tracker (Monthly'!$J$20:$J$44) -> 0 | K45: =SUBTOTAL(109,'BONUS Cashflow Tracker (Monthly'!$K$20:$K$44) -> 0 | L45: =SUBTOTAL(109,'BONUS Cashflow Tracker (Monthly'!$L$20:$L$44) -> 0 | M45: =SUBTOTAL(109,'BONUS Cashflow Tracker (Monthly'!$M$20:$M$44) -> 0 | N45: =SUBTOTAL(109,'BONUS Cashflow Tracker (Monthly'!$N$20:$N$44) -> 0 | O45: =SUBTOTAL(109,'BONUS Cashflow Tracker (Monthly'!$O$20:$O$44) -> 0 | P45: =SUBTOTAL(109,'BONUS Cashflow Tracker (Monthly'!$P$20:$P$44) -> 0
B46: OTHER CASH PAID OUT
B47: Loan principal payment | P47: =SUM(D47:O47) -> 0
B48: Capital purchases | P48: =SUM(D48:O48) -> 0
B49: Other startup costs | P49: =SUM(D49:O49) -> 0
B50: To reserve and/or escrow | P50: =SUM(D50:O50) -> 0
B51: Owners' withdrawal | P51: =SUM(D51:O51) -> 0
B52: SUBTOTAL | D52: =SUM(D47:D51) -> 0 | E52: =SUM(E47:E51) -> 0 | F52: =SUM(F47:F51) -> 0 | G52: =SUM(G47:G51) -> 0 | H52: =SUM(H47:H51) -> 0 | I52: =SUM(I47:I51) -> 0 | J52: =SUM(J47:J51) -> 0 | K52: =SUM(K47:K51) -> 0 | ... P52: =SUM(P47:P51) -> 0
B53: TOTAL CASH PAID OUT | D53: ='BONUS Cashflow Tracker (Monthly'!$D$45+SUBTOTAL(109,'BONUS Cashflow Tracker (Monthly'!$D$47:$D$51) -> 0 | E53: ='BONUS Cashflow Tracker (Monthly'!$E$45+SUBTOTAL(109,'BONUS Cashflow Tracker (Monthly'!$E$47:$E$51) -> 0 | F53: ='BONUS Cashflow Tracker (Monthly'!$F$45+SUBTOTAL(109,'BONUS Cashflow Tracker (Monthly'!$F$47:$F$51) -> 0 | G53: ='BONUS Cashflow Tracker (Monthly'!$G$45+SUBTOTAL(109,'BONUS Cashflow Tracker (Monthly'!$G$47:$G$51) -> 0 | H53: ='BONUS Cashflow Tracker (Monthly'!$H$45+SUBTOTAL(109,'BONUS Cashflow Tracker (Monthly'!$H$47:$H$51) -> 0 | I53: ='BONUS Cashflow Tracker (Monthly'!$I$45+SUBTOTAL(109,'BONUS Cashflow Tracker (Monthly'!$I$47:$I$51) -> 0 | J53: ='BONUS Cashflow Tracker (Monthly'!$J$45+SUBTOTAL(109,'BONUS Cashflow Tracker (Monthly'!$J$47:$J$51) -> 0 | K53: ='BONUS Cashflow Tracker (Monthly'!$K$45+SUBTOTAL(109,'BONUS Cashflow Tracker (Monthly'!$K$47:$K$51) -> 0 | L53: ='BONUS Cashflow Tracker (Monthly'!$L$45+SUBTOTAL(109,'BONUS Cashflow Tracker (Monthly'!$L$47:$L$51) -> 0 | M53: ='BONUS Cashflow Tracker (Monthly'!$M$45+SUBTOTAL(109,'BONUS Cashflow Tracker (Monthly'!$M$47:$M$51) -> 0 | N53: ='BONUS Cashflow Tracker (Monthly'!$N$45+SUBTOTAL(109,'BONUS Cashflow Tracker (Monthly'!$N$47:$N$51) -> 0 | O53: ='BONUS Cashflow Tracker (Monthly'!$O$45+SUBTOTAL(109,'BONUS Cashflow Tracker (Monthly'!$O$47:$O$51) -> 0 | P53: =SUM(D53:O53) -> 0
B54: Cash on hand (end of month) | C54: =C17 -> 0 | D54: =D17-'BONUS Cashflow Tracker (Monthly'!$D$53 -> 0 | E54: =E17-'BONUS Cashflow Tracker (Monthly'!$E$53 -> 0 | F54: =F17-'BONUS Cashflow Tracker (Monthly'!$F$53 -> 0 | G54: =G17-'BONUS Cashflow Tracker (Monthly'!$G$53 -> 0 | H54: =H17-'BONUS Cashflow Tracker (Monthly'!$H$53 -> 0 | I54: =I17-'BONUS Cashflow Tracker (Monthly'!$I$53 -> 0 | J54: =J17-'BONUS Cashflow Tracker (Monthly'!$J$53 -> 0 | K54: =K17-'BONUS Cashflow Tracker (Monthly'!$K$53 -> 0 | L54: =L17-'BONUS Cashflow Tracker (Monthly'!$L$53 -> 0 | M54: =M17-'BONUS Cashflow Tracker (Monthly'!$M$53 -> 0 | N54: =N17-'BONUS Cashflow Tracker (Monthly'!$N$53 -> 0 | O54: =O17-'BONUS Cashflow Tracker (Monthly'!$O$53 -> 0
B56: OTHER OPERATING DATA | D56: =D19 -> 45322 | E56: =E19 -> 45323 | F56: =F19 -> 45352 | G56: =G19 -> 45383 | H56: =H19 -> 45413 | I56: =I19 -> 45444 | J56: =J19 -> 45474 | K56: =K19 -> 45505 | ... O56: =O19 -> 45627 | P56: Total
...

Sheet BONUS Working Capital Needs
A1: BONUS: Working Capital Needs
A2: Use the worksheet below to calculate your working capital needs. If you do not have sufficient working capital, you will run out of money quickly. Please note that this spreadsheet is in Beta and fairly simplistic. Consult with your professional financial advisors to be sure.
A4: Acquired Cash | B4: 0 | D4: Standard Payment Terms | G4: Net 30
A5: Acquired Accounts Receivable | B5: 0 | D5: Starting Month | G5: 45413
A6: Acquired Accounts Payable | B6: 0 | D6: Immediate Cash Infusion | G6: 25000
B9: =G5 -> 45413 | C9: =EDATE(B9,1) -> 45444 | D9: =EDATE(C9,1) -> 45474 | E9: =EDATE(D9,1) -> 45505 | F9: =EDATE(E9,1) -> 45536 | G9: =EDATE(F9,1) -> 45566 | H9: =EDATE(G9,1) -> 45597 | I9: =EDATE(H9,1) -> 45627 | J9: =EDATE(I9,1) -> 45658 | ... M9: =EDATE(L9,1) -> 45748
A10: Starting Cash | B10: =B4+G6 -> 25000 | C10: =B16 -> 5000 | D10: =C16 -> 15000 | E10: =D16 -> 25000 | F10: =E16 -> 35000 | G10: =F16 -> 45000 | H10: =G16 -> 55000 | I10: =H16 -> 65000 | J10: =I16 -> 75000 | ... M10: =L16 -> 105000
A11: Total Monthly Cash Outflow | B11: 20000 | C11: 20000 | D11: 20000 | E11: 20000 | F11: 20000 | G11: 20000 | H11: 20000 | I11: 20000 | J11: 20000 | K11: 20000 | L11: 20000 | M11: 20000
