Workbook
Name If: #REF!
Name If: #REF!

Sheet Quick HELOC Loan Calc
A1: 2811 Cordell Memphis TN | G1: Heloc Down Payment | H1: 0.0875
G2: Heloc Loan Terms | H2: 20 | I2: yrs
A3: =B5 -> 179400 | B3: asking price | G3: HELOC Amount | H3: =SUM(B7+B6-C5-C4) -> 3858
C4: 5000 | D4: earnest money | G4: HELOC P&I Payment | H4: =-PMT($H$1/12,$H$2*12,H3) -> 34.093559 | I4: =H4*12 -> 409.12271 | K4: IRR | L4: =IRR(L5:L11) -> 0.025517791
A5: Purchase Price | B5: 179400 | C5: 47026 | D5: cash | G5: HELOC Interest Only Payment | H5: =-IPMT($H$1/12,1,$H$2*12,H3) -> 28.13125 | I5: =H5*12 -> 337.575 | K5: Initial Investment | L5: =-B5 -> -179400
A6: Closing Costs (4%) | B6: 11034 | I6: =H4-H5 -> 5.9623091 | K6: Year 1 Cashflow | L6: ='10 Year'!B30 -> 613.53922
A7: Down Payment (20%) - HELOC | B7: =B5*C7 -> 44850 | C7: 0.25 | D7: downpayment | G7: Conventional Loan Interest Rate | H7: 0.06625 | K7: Year 2 Cashflow | L7: ='10 Year'!C30 -> 1038.9272
A8: Total Loan Amount | B8: =B5-B7 -> 134550 | G8: Loan Term | H8: 30 | I8: yrs | K8: Year 3 Cashflow | L8: ='10 Year'!D30 -> 981.75409
A9: Down Payment - Cash | B9: =B5 -> 179400 | G9: Monthly Interest Payment on Purchase Price | H9: =-IPMT($H$7/12,1,$H$8*12,$B$8) -> 742.82812 | K9: Year 4 Cashflow | L9: ='10 Year'!E30 -> 1690.5974
K10: Year 5 Cashflow | L10: ='10 Year'!F30 -> 1916.1118
A11: All In Price (Purchase+Repairs) | B11: =SUM(B5) -> 179400 | G11: Financials | K11: 6 | L11: =B5*(1+0.02)^K11 -> 202033.54 | M11: assumes 2%/yr appreciation
A12: Estimated ARV (After Repair Value) | B12: =B5 -> 179400 | G12: Cash On Cash Return (CoC) | H12: =C38/SUM(B6:B7) -> 0.010191454
G13: ROI (Return on Investment) | H13: =(SUM($B$6:$B$7)/B5) -> 0.31150502
B14: Monthly | C14: Annually | G14: ROE (Return on Equity) | H14: =C38/B7 -> 0.012698756
A15: Average Rent | B15: 1350 | C15: =B15*12 -> 16200 | G15: Mortgage Pay Down yr 1 | H15: =PPMT(H7/12,1,H8*12,B8)*12 -> -1424.5233
A16: Less 4% Vacancy | B16: =B15*-0.04 -> -54 | C16: =B16*12 -> -648 | G16: Tax Savings at 33% | H16: =C38*0.33 -> 187.94794
A17: Additional Income (Laundry) | B17: 0 | C17: =B17*12 -> 0
A18: Calculated Gross Revenue | B18: =SUM(B15:B17) -> 1296 | C18: =B18*12 -> 15552 | G18: Rules of Thumb
G19: 50% Rule
G20: 2% Rule | H20: =$B$15/$B$5 -> 0.0075250836
A21: Estimated Expenses | B21: Monthly | C21: Annually | G21: DSCR | H21: =B35/(B37+B36) -> 1.0550894
A22: Management Fees | B22: =B15*D22 -> 108 | C22: =B22*12 -> 1296 | D22: 0.08 | E22: =IF(D22=0,1,0) -> 0
A23: Property Taxes / Year | B23: 107 | C23: =B23*12 -> 1284 | D23: 0.0108
A24: Insurance / Year | B24: 73 | C24: =B24*12 -> 876 | D24: =C24/B5 -> 0.0048829431
A25: HOA / year | G25: Emergency Fund Needed (6 months) | H25: =B33*$I$25+SUM(B36:B37)*$I$25 -> 7491.2304 | I25: 6 | J25: months
A26: Electricity | C26: =B26*12 -> 0 | H26: =H25/2 -> 3745.6152 | I26: =I25/2 -> 3 | J26: months
A27: Nat Gas | C27: =B27*12 -> 0
A28: Water/Sewer | C28: =B28*12 -> 0
A29: Building Maintenance | B29: 54 | C29: =B29*12 -> 648 | D29: =C29/C15 -> 0.04
A30: Grounds Cleanup/Services Maintenance/Snow Removal | C30: =B30*12 -> 0
A31: Yearly Safety Inspection | B31: 8 | C31: =B31*12 -> 96
A32: Umbrella Insurance (Allstate Anchorage) | B32: 37 | C32: =B32*12 -> 444
A33: Totals | B33: =SUM(B22:B32) -> 387 | C33: =SUM(C22:C32) -> 4644
A35: Net Operating Income | B35: =B18-B33 -> 909 | C35: =C18-C33 -> 10908 | D35: DSCR | E35: =B35/(B37+B36) -> 1.0550894
A36: HELOC Payment | C36: =B36*12 -> 0 | D36: =IF(B36=H5,1,0) -> 0
A37: Conventional Loan Payment | B37: =-PMT($H$7/12,$H$8*12,$B$8) -> 861.5384 | C37: =B37*12 -> 10338.461 | D37: Cap Rate | E37: =C35/B5 -> 0.060802676 | G37: NOI/value
A38: Cash Flow | B38: =B35-B37-B36 -> 47.461602 | C38: =B38*12 -> 569.53922
A41: Estimated CapEx | B41: Timeline of Repair (yrs) | C41: Cost per Unit | D41: Total Cost | E41: Monthly Cost
A42: Roof | B42: 5 | C42: 7000 | D42: =C42 -> 7000 | E42: =D42/B42/12 -> 116.66667
A43: Master Bath | B43: 10 | D43: =C43 -> 0 | E43: =D43/B43/12 -> 0
...

Sheet 7yr IRR Financing
A1: ='Quick HELOC Loan Calc'!$A$1 &" FINANCING CALCULATIONS" -> 2811 Cordell Memphis TN FINANCING CALCULATIONS
B4: Year 1 | C4: Year 2 | D4: Year 3 | E4: Year 4 | F4: Year 5 | G4: Year 6 | H4: Year 7
A5: Maintenance | B5: 0.04 | C5: 0.04 | D5: 0.04 | E5: 0.04 | F5: 0.04 | G5: 0.04 | H5: 0.04
A6: Property Appreciation | B6: 0.04 | C6: 0.04 | D6: 0.04 | E6: 0.04 | F6: 0.04 | G6: 0.04 | H6: 0.04
A7: Rental Appreciation | B7: 0.03 | C7: 0.03 | D7: 0.03 | E7: 0.03 | F7: 0.03 | G7: 0.03 | H7: 0.03
A8: Tax/Insurance/HOA Appreciation | B8: 0.015 | C8: 0.015 | D8: 0.015 | E8: 0.015 | F8: 0.015 | G8: 0.015 | H8: 0.015
A9: Vacancy | B9: 0.04 | C9: 0.04 | D9: 0.04 | E9: 0.04 | F9: 0.04 | G9: 0.04 | H9: 0.04
B11: Year 1 | C11: Year 2 | D11: Year 3 | E11: Year 4 | F11: Year 5 | G11: Year 6 | H11: Year 7
A12: Revenues
A13: Rental Income | B13: ='Quick HELOC Loan Calc'!C15 -> 16200 | C13: =SUM(B$13+(C$7*B$13)) -> 16686 | D13: =SUM(C$13+(D$7*C$13)) -> 17186.58 | E13: =SUM(D$13+(E$7*D$13)) -> 17702.177 | F13: =SUM(E$13+(F$7*E$13)) -> 18233.243 | G13: =SUM(F$13+(G$7*F$13)) -> 18780.24 | H13: =SUM(G$13+(H$7*G$13)) -> 19343.647
B14: =B13/12 -> 1350 | C14: =C13/12 -> 1390.5 | D14: =D13/12 -> 1432.215 | E14: =E13/12 -> 1475.1815 | F14: =F13/12 -> 1519.4369 | G14: =G13/12 -> 1565.02 | H14: =H13/12 -> 1611.9706
A15: Vacancy Rate | B15: =-(B13*B9) -> -648 | C15: =-(C13*C9) -> -667.44 | D15: =-(D13*D9) -> -687.4632 | E15: =-(E13*E9) -> -708.0871 | F15: =-(F13*F9) -> -729.32971 | G15: =-(G13*G9) -> -751.2096 | H15: =-(H13*H9) -> -773.74589
A16: Net Rental Income | B16: =SUM(B13,B15) -> 15552 | C16: =SUM(C13,C15) -> 16018.56 | D16: =SUM(D13,D15) -> 16499.117 | E16: =SUM(E13,E15) -> 16994.09 | F16: =SUM(F13,F15) -> 17503.913 | G16: =SUM(G13,G15) -> 18029.03 | H16: =SUM(H13,H15) -> 18569.901
A18: Expenses
A19: Property Taxes | B19: ='Quick HELOC Loan Calc'!C23 -> 1284 | C19: =B$19+(B$19*C$8) -> 1303.26 | D19: =C$19+(C$19*D$8) -> 1322.8089 | E19: =D$19+(D$19*E$8) -> 1342.651 | F19: =E$19+(E$19*F$8) -> 1362.7908 | G19: =F$19+(F$19*G$8) -> 1383.2327 | H19: =G$19+(G$19*H$8) -> 1403.9812
A20: Insurance | B20: ='Quick HELOC Loan Calc'!C24 -> 876 | C20: =B20+(B20*C8) -> 889.14 | D20: =C20+(C20*D8) -> 902.4771 | E20: =D20+(D20*E8) -> 916.01426 | F20: =E20+(E20*F8) -> 929.75447 | G20: =F20+(F20*G8) -> 943.70079 | H20: =G20+(G20*H8) -> 957.8563
A21: Property Mgmt | C21: =C13*0.08 -> 1334.88 | D21: =D13*0.08 -> 1374.9264 | E21: =E13*0.08 -> 1416.1742 | F21: =F13*0.08 -> 1458.6594 | G21: =G13*0.08 -> 1502.4192 | H21: =H13*0.08 -> 1547.4918 | I21: $5000 management credit
A22: Lease Fee | B22: 0 | C22: 0 | D22: 250 | E22: 0 | F22: 250 | G22: 0 | H22: 250
A23: Management Renewal Fee | D23: 250 | E23: 250 | F23: 250 | H23: 250
A24: HOA | B24: ='[1]Input Info'!B14 -> 0 | C24: =B24+(B24*C8) -> 0 | D24: =C24+(C24*D8) -> 0 | E24: =D24+(D24*E8) -> 0 | F24: =E24+(E24*F8) -> 0 | G24: =F24+(F24*G8) -> 0 | H24: =G24+(G24*H8) -> 0
A25: Maintenance & Repairs | B25: =B13*B5 -> 648 | C25: =C13*C5 -> 667.44 | D25: =D13*D5 -> 687.4632 | E25: =E13*E5 -> 708.0871 | F25: =F13*F5 -> 729.32971 | G25: =G13*G5 -> 751.2096 | H25: =H13*H5 -> 773.74589
A26: Yearly Inspection | B26: 100 | C26: 100 | D26: 100 | E26: 100 | F26: 100 | G26: 100 | H26: 100
A27: Umbrella Insurance | B27: =33*12 -> 396 | C27: =33*12 -> 396 | D27: =33*12 -> 396 | E27: =33*12 -> 396 | F27: =33*12 -> 396 | G27: =33*12 -> 396 | H27: =33*12 -> 396
A28: Total Expenses | B28: =SUM(B19:B27) -> 3304 | C28: =SUM(C19:C27) -> 4690.72 | D28: =SUM(D19:D27) -> 5283.6756 | E28: =SUM(E19:E27) -> 5128.9266 | F28: =SUM(F19:F27) -> 5476.5344 | G28: =SUM(G19:G27) -> 5076.5622 | H28: =SUM(H19:H27) -> 5679.0751
A30: Net Operating Income (NOI) | B30: =SUM(B16-B28) -> 12248 | C30: =SUM(C16-C28) -> 11327.84 | D30: =SUM(D16-D28) -> 11215.441 | E30: =SUM(E16-E28) -> 11865.164 | F30: =SUM(F16-F28) -> 12027.379 | G30: =SUM(G16-G28) -> 12952.468 | H30: =SUM(H16-H28) -> 12890.826
A32: Cash Flow
A33: NOI (Cash Available) | B33: =B30 -> 12248 | C33: =C30 -> 11327.84 | D33: =D30 -> 11215.441 | E33: =E30 -> 11865.164 | F33: =F30 -> 12027.379 | G33: =G30 -> 12952.468 | H33: =H30 -> 12890.826
A34: Conventional Mortgage | B34: =SUM('Quick HELOC Loan Calc'!$B$37*12) -> 10338.461 | C34: =SUM('Quick HELOC Loan Calc'!$B$37*12) -> 10338.461 | D34: =SUM('Quick HELOC Loan Calc'!$B$37*12) -> 10338.461 | E34: =SUM('Quick HELOC Loan Calc'!$B$37*12) -> 10338.461 | F34: =SUM('Quick HELOC Loan Calc'!$B$37*12) -> 10338.461 | G34: =SUM('Quick HELOC Loan Calc'!$B$37*12) -> 10338.461 | H34: =SUM('Quick HELOC Loan Calc'!$B$37*12) -> 10338.461
A35: HELOC Mortgage | B35: ='Quick HELOC Loan Calc'!C36 -> 0 | I35: Interest Only - Pay off on 1 year anniversary
A36: Total Cash Flow | B36: =SUM(B33-B34-B35) -> 1909.5392 | C36: =SUM(C33-C34-C35) -> 989.37922 | D36: =SUM(D33-D34-D35) -> 876.98042 | E36: =SUM(E33-E34-E35) -> 1526.7029 | F36: =SUM(F33-F34-F35) -> 1688.9178 | G36: =SUM(G33-G34-G35) -> 2614.0074 | H36: =SUM(H33-H34-H35) -> 2552.3654
A37: Monthly Cash Flow | B37: =B36/12 -> 159.12827 | C37: =C36/12 -> 82.448269 | D37: =D36/12 -> 73.081702 | E37: =E36/12 -> 127.22525 | F37: =F36/12 -> 140.74315 | G37: =G36/12 -> 217.83395 | H37: =H36/12 -> 212.69712
A38: DSCR | B38: =B33/SUM(B34:B35) -> 1.1847025 | C38: =C33/SUM(C34:C35) -> 1.0956989 | D38: =D33/SUM(D34:D35) -> 1.084827 | E38: =E33/SUM(E34:E35) -> 1.1476722 | F38: =F33/SUM(F34:F35) -> 1.1633626 | G38: =G33/SUM(G34:G35) -> 1.252843 | H38: =H33/SUM(H34:H35) -> 1.2468806
A39: Equity Accrued | B39: =-CUMPRINC('Quick HELOC Loan Calc'!$H$7/12,'Quick HELOC Loan Calc'!$H$8*12,'Quick HELOC Loan Calc'!$B$8,1,12,0) -> 1468.5843 | C39: =-CUMPRINC('Quick HELOC Loan Calc'!$H$7/12,'Quick HELOC Loan Calc'!$H$8*12,'Quick HELOC Loan Calc'!$B$8,13,24,0) -> 1568.8874 | D39: =-CUMPRINC('Quick HELOC Loan Calc'!$H$7/12,'Quick HELOC Loan Calc'!$H$8*12,'Quick HELOC Loan Calc'!$B$8,25,36,0) -> 1676.041 | E39: =-CUMPRINC('Quick HELOC Loan Calc'!$H$7/12,'Quick HELOC Loan Calc'!$H$8*12,'Quick HELOC Loan Calc'!$B$8,37,48,0) -> 1790.5132 | F39: =-CUMPRINC('Quick HELOC Loan Calc'!$H$7/12,'Quick HELOC Loan Calc'!$H$8*12,'Quick HELOC Loan Calc'!$B$8,49,60,0) -> 1912.8037 | G39: =-CUMPRINC('Quick HELOC Loan Calc'!$H$7/12,'Quick HELOC Loan Calc'!$H$8*12,'Quick HELOC Loan Calc'!$B$8,61,72,0) -> 2043.4465 | H39: =-CUMPRINC('Quick HELOC Loan Calc'!$H$7/12,'Quick HELOC Loan Calc'!$H$8*12,'Quick HELOC Loan Calc'!$B$8,73,84,0) -> 2183.0122
A40: Appreciation | B40: =SUM(B6*'Quick HELOC Loan Calc'!$B$5) -> 7176 | C40: =(SUM(B40)+'Quick HELOC Loan Calc'!$B$5)*C$6 -> 7463.04 | D40: =('Quick HELOC Loan Calc'!$B$5+C40+B40)*D$6 -> 7761.5616 | E40: =('Quick HELOC Loan Calc'!$B$5+D40+C40+B40)*E$6 -> 8072.0241 | F40: =('Quick HELOC Loan Calc'!$B$5+E40+D40+C40+B40)*F$6 -> 8394.905 | G40: =('Quick HELOC Loan Calc'!$B$5+F40+E40+D40+C40+B40)*G$6 -> 8730.7012 | H40: =('Quick HELOC Loan Calc'!$B$5+G40+F40+E40+D40+C40+B40)*H$6 -> 9079.9293
A41: Total Return | B41: =SUM(B36+B39+B40) -> 10554.124 | C41: =SUM(C36+C39+C40) -> 10021.307 | D41: =SUM(D36+D39+D40) -> 10314.583 | E41: =SUM(E36+E39+E40) -> 11389.24 | F41: =SUM(F36+F39+F40) -> 11996.627 | G41: =SUM(G36+G39+G40) -> 13388.155 | H41: =SUM(H36+H39+H40) -> 13815.307
A42: Total ROI | B42: =SUM(B41/'[1]Input Info'!$B$18) -> 0.25128866 | C42: =SUM(C41/'[1]Input Info'!$B$18) -> 0.23860254 | D42: =SUM(D41/'[1]Input Info'!$B$18) -> 0.24558531 | E42: =SUM(E41/'[1]Input Info'!$B$18) -> 0.27117239 | F42: =SUM(F41/'[1]Input Info'!$B$18) -> 0.28563397 | G42: =SUM(G41/'[1]Input Info'!$B$18) -> 0.3187656 | H42: =SUM(H41/'[1]Input Info'!$B$18) -> 0.32893588
A43: Average ROI | G43: =AVERAGE(B42:H42) -> 0.27714062
A44: Estimated Value at Year 7 | G44: ='[1]Input Info'!B5+(SUM('7yr IRR Financing'!B40:H40)) -> 196678.16
A45: Loan Paid Down over 7 Years | G45: =SUM(B39:H39) -> 12643.288
A46: Total returns are based on calculations of external data and is subject to change. Estimated returns are estimated, and may not factor in all scenarios or costs. REI Nation, LLC and Premier Property Management Group, LLC have offered this estimator of returns in good faith. We realize that there are alternate methods to calculate return, and that some assumptions may not be applicable for your calculations. Data provided for the calculation is the user’s responsibility. We do not make any representations or warranties of any kind on the information provided. We also disclaim any liability or responsibility for the accuracy, correctness, or completeness of any information provided. *All calculations include estimated maintenance, estimated vacancy, estimated property management fees, estimated equity accrual, estimated property taxes, estimated insurance and estimated appreciation.

Sheet 10 Year
A1: Year | B1: 1 | C1: 2 | D1: 3 | E1: 4 | F1: 5 | G1: 6 | H1: 7 | I1: 8 | J1: 9 | K1: 10
A2: Property Income | L2: Desired Return | M2: 0.08 | N2: match stock market
A3: Rent | B3: ='Quick HELOC Loan Calc'!C15 -> 16200 | C3: =B3*(1+C5) -> 16783.2 | D3: =C3*(1+D5) -> 17387.395 | E3: =D3*(1+E5) -> 18013.341 | F3: =E3*(1+F5) -> 18661.822 | G3: =F3*(1+G5) -> 19333.647 | H3: =G3*(1+H5) -> 20029.659 | I3: =H3*(1+I5) -> 20750.726 | J3: =I3*(1+J5) -> 21497.752 | K3: =J3*(1+K5) -> 22271.672
A4: Monthly Rent | B4: =B3/12 -> 1350 | C4: =C3/12 -> 1398.6 | D4: =D3/12 -> 1448.9496 | E4: =E3/12 -> 1501.1118 | F4: =F3/12 -> 1555.1518 | G4: =G3/12 -> 1611.1373 | H4: =H3/12 -> 1669.1382 | I4: =I3/12 -> 1729.2272 | ... K4: =K3/12 -> 1855.9726 | M4: IRR | P4: NPV
A5: Rent Appreciation | B5: 0.036 | C5: =$B$5 -> 0.036 | D5: =$B$5 -> 0.036 | E5: =$B$5 -> 0.036 | F5: =$B$5 -> 0.036 | G5: =$B$5 -> 0.036 | H5: =$B$5 -> 0.036 | I5: =$B$5 -> 0.036 | J5: =$B$5 -> 0.036 | K5: =$B$5 -> 0.036 | M5: 45536 | N5: 0 | O5: =-SUM('Quick HELOC Loan Calc'!B6:B7) -> -55884 | P5: =O5 -> -55884
A6: Vacancy Loss | B6: 0.04 | C6: =$B$6 -> 0.04 | D6: =$B$6 -> 0.04 | E6: =$B$6 -> 0.04 | F6: =$B$6 -> 0.04 | G6: =$B$6 -> 0.04 | H6: =$B$6 -> 0.04 | I6: =$B$6 -> 0.04 | J6: =$B$6 -> 0.04 | K6: =$B$6 -> 0.04 | M6: 45901 | N6: 1 | O6: =B30 -> 613.53922 | P6: =O6/(1+$M$2)^N6 -> 568.09187
M7: 46266 | N7: 2 | O7: =C30 -> 1038.9272 | P7: =O7/(1+$M$2)^N7 -> 890.71264
A8: Operating Income | B8: =B3*(1-B6) -> 15552 | C8: =C3*(1-C6) -> 16111.872 | D8: =D3*(1-D6) -> 16691.899 | E8: =E3*(1-E6) -> 17292.808 | F8: =F3*(1-F6) -> 17915.349 | G8: =G3*(1-G6) -> 18560.301 | H8: =H3*(1-H6) -> 19228.472 | I8: =I3*(1-I6) -> 19920.697 | ... K8: =K3*(1-K6) -> 21380.805 | M8: 46631 | N8: 3 | O8: =D30 -> 981.75409 | P8: =O8/(1+$M$2)^N8 -> 779.34805
M9: 46997 | N9: 4 | O9: =E30 -> 1690.5974 | P9: =O9/(1+$M$2)^N9 -> 1242.6395
A10: Property Expenses | M10: 47362 | N10: 5 | O10: =F30 -> 1916.1118 | P10: =O10/(1+$M$2)^N10 -> 1304.0735
A11: Management Fee | B11: =0.08 -> 0.08 | C11: =$B$11 -> 0.08 | D11: =$B$11 -> 0.08 | E11: =$B$11 -> 0.08 | F11: =$B$11 -> 0.08 | G11: =$B$11 -> 0.08 | H11: =$B$11 -> 0.08 | I11: =$B$11 -> 0.08 | J11: =$B$11 -> 0.08 | K11: =$B$11 -> 0.08 | M11: 47727 | N11: 6 | O11: =G30 -> 2908.8936 | P11: =O11/(1+$M$2)^N11 -> 1833.0964
A12: Management Fees | B12: =IF('Quick HELOC Loan Calc'!$E$22=1,"Waived",'Quick HELOC Loan Calc'!$C$22) -> 1296 | C12: =C3*C11 -> 1342.656 | D12: =D3*D11 -> 1390.9916 | E12: =E3*E11 -> 1441.0673 | F12: =F3*F11 -> 1492.9457 | G12: =G3*G11 -> 1546.6918 | H12: =H3*H11 -> 1602.3727 | I12: =I3*I11 -> 1660.0581 | J12: =J3*J11 -> 1719.8202 | K12: =K3*K11 -> 1781.7337 | M12: 48092 | N12: 7 | O12: =H30 -> 2919.5634 | P12: =O12/(1+$M$2)^N12 -> 1703.5372
A13: Property Taxes (1.5%) | B13: ='Quick HELOC Loan Calc'!C23 -> 1284 | C13: =B36*($B$13/'Quick HELOC Loan Calc'!$B$5) -> 1335.36 | D13: =C36*($B$13/'Quick HELOC Loan Calc'!$B$5) -> 1386.72 | E13: =D36*($B$13/'Quick HELOC Loan Calc'!$B$5) -> 1440.1344 | F13: =E36*($B$13/'Quick HELOC Loan Calc'!$B$5) -> 1495.6032 | G13: =F36*($B$13/'Quick HELOC Loan Calc'!$B$5) -> 1553.2086 | H13: =G36*($B$13/'Quick HELOC Loan Calc'!$B$5) -> 1613.0327 | I13: =H36*($B$13/'Quick HELOC Loan Calc'!$B$5) -> 1675.161 | J13: =I36*($B$13/'Quick HELOC Loan Calc'!$B$5) -> 1739.6824 | K13: =J36*($B$13/'Quick HELOC Loan Calc'!$B$5) -> 1806.6888 | M13: 48458 | N13: 8 | O13: =I30 -> 3948.7641 | P13: =O13/(1+$M$2)^N13 -> 2133.3944
A14: Insurance (1.5%) | B14: ='Quick HELOC Loan Calc'!C24 -> 876 | C14: =B14+(B14*0.015) -> 889.14 | D14: =C14+(C14*0.015) -> 902.4771 | E14: =D14+(D14*0.015) -> 916.01426 | F14: =E14+(E14*0.015) -> 929.75447 | G14: =F14+(F14*0.015) -> 943.70079 | H14: =G14+(G14*0.015) -> 957.8563 | I14: =H14+(H14*0.015) -> 972.22414 | J14: =I14+(I14*0.015) -> 986.80751 | K14: =J14+(J14*0.015) -> 1001.6096 | M14: 48823 | N14: 9 | O14: =J30 -> 3997.1614 | P14: =O14/(1+$M$2)^N14 -> 1999.5759
A15: Maintenance/Repairs (4%) | B15: =IF('Quick HELOC Loan Calc'!$C$29=0,"Seller Covered",'Quick HELOC Loan Calc'!$C$29) -> 648 | C15: =C3*0.04 -> 671.328 | D15: =D3*0.04 -> 695.49581 | E15: =E3*0.04 -> 720.53366 | F15: =F3*0.04 -> 746.47287 | G15: =G3*0.04 -> 773.34589 | H15: =H3*0.04 -> 801.18634 | I15: =I3*0.04 -> 830.02905 | J15: =J3*0.04 -> 859.9101 | K15: =K3*0.04 -> 890.86686 | M15: 49188 | N15: 10 | O15: =K30+K36-('Quick HELOC Loan Calc'!B8-SUM('10 Year'!B38:K38)) -> 152546.38 | P15: =O15/(1+$M$2)^N15 -> 70658.49
A16: Leasing Fee | B16: 0 | C16: 0 | D16: 250 | E16: 0 | F16: 250 | G16: 0 | H16: 250 | I16: 0 | J16: 250 | K16: 0 | O16: =XIRR(O5:O15,M5:M15) -> 0.12688131 | P16: =SUM(P5:P15) -> 27228.959
A17: Annual Safety Inspection | B17: 100 | C17: 100 | D17: 100 | E17: 100 | F17: 100 | G17: 100 | H17: 100 | I17: 100 | J17: 100 | K17: 100
A18: Management Renewal Fee | D18: 250 | E18: 250 | F18: 250 | H18: 250 | J18: 250 | K18: 250
A19: HOA Fees | B19: 0 | C19: 0 | D19: 0 | E19: 0 | F19: 0 | G19: 0 | H19: 0 | I19: 0 | J19: 0 | K19: 0
A20: Umbrella Insurance | B20: =33*12 -> 396 | C20: =33*12 -> 396 | D20: =33*12 -> 396 | E20: =33*12 -> 396 | F20: =33*12 -> 396 | G20: =33*12 -> 396 | H20: =33*12 -> 396 | I20: =33*12 -> 396 | ... K20: =33*12 -> 396
A22: Operating Expenses | B22: =SUM(B12:B20) -> 4600 | C22: =SUM(C12:C20) -> 4734.484 | D22: =SUM(D12:D20) -> 5371.6845 | E22: =SUM(E12:E20) -> 5263.7496 | F22: =SUM(F12:F20) -> 5660.7763 | G22: =SUM(G12:G20) -> 5312.947 | H22: =SUM(H12:H20) -> 5970.448 | I22: =SUM(I12:I20) -> 5633.4723 | ... K22: =SUM(K12:K20) -> 6226.899
A24: Net Operating Income (NOI) | B24: =B8-B22 -> 10952 | C24: =C8-C22 -> 11377.388 | D24: =D8-D22 -> 11320.215 | E24: =E8-E22 -> 12029.058 | F24: =F8-F22 -> 12254.573 | G24: =G8-G22 -> 13247.354 | H24: =H8-H22 -> 13258.024 | I24: =I8-I22 -> 14287.225 | ... K24: =K8-K22 -> 15153.906
A25: Capitalization Rate (CAP Rate) | B25: =B24/'Quick HELOC Loan Calc'!$B$5 -> 0.061047938 | C25: =C24/'Quick HELOC Loan Calc'!$B$5 -> 0.063419108 | D25: =D24/'Quick HELOC Loan Calc'!$B$5 -> 0.063100417 | E25: =E24/'Quick HELOC Loan Calc'!$B$5 -> 0.067051606 | F25: =F24/'Quick HELOC Loan Calc'!$B$5 -> 0.068308654 | G25: =G24/'Quick HELOC Loan Calc'!$B$5 -> 0.073842555 | H25: =H24/'Quick HELOC Loan Calc'!$B$5 -> 0.07390203 | I25: =I24/'Quick HELOC Loan Calc'!$B$5 -> 0.079638935 | ... K25: =K24/'Quick HELOC Loan Calc'!$B$5 -> 0.084469931
A27: Key Investment Indicators
A28: Mortgage Payment | B28: =PMT('Quick HELOC Loan Calc'!$H$7/12, 'Quick HELOC Loan Calc'!$H$8*12,'Quick HELOC Loan Calc'!$B$8)*12 -> -10338.461 | C28: =PMT('Quick HELOC Loan Calc'!$H$7/12, 'Quick HELOC Loan Calc'!$H$8*12,'Quick HELOC Loan Calc'!$B$8)*12 -> -10338.461 | D28: =PMT('Quick HELOC Loan Calc'!$H$7/12, 'Quick HELOC Loan Calc'!$H$8*12,'Quick HELOC Loan Calc'!$B$8)*12 -> -10338.461 | E28: =PMT('Quick HELOC Loan Calc'!$H$7/12, 'Quick HELOC Loan Calc'!$H$8*12,'Quick HELOC Loan Calc'!$B$8)*12 -> -10338.461 | F28: =PMT('Quick HELOC Loan Calc'!$H$7/12, 'Quick HELOC Loan Calc'!$H$8*12,'Quick HELOC Loan Calc'!$B$8)*12 -> -10338.461 | G28: =PMT('Quick HELOC Loan Calc'!$H$7/12, 'Quick HELOC Loan Calc'!$H$8*12,'Quick HELOC Loan Calc'!$B$8)*12 -> -10338.461 | H28: =PMT('Quick HELOC Loan Calc'!$H$7/12, 'Quick HELOC Loan Calc'!$H$8*12,'Quick HELOC Loan Calc'!$B$8)*12 -> -10338.461 | I28: =PMT('Quick HELOC Loan Calc'!$H$7/12, 'Quick HELOC Loan Calc'!$H$8*12,'Quick HELOC Loan Calc'!$B$8)*12 -> -10338.461 | ... K28: =PMT('Quick HELOC Loan Calc'!$H$7/12, 'Quick HELOC Loan Calc'!$H$8*12,'Quick HELOC Loan Calc'!$B$8)*12 -> -10338.461
A29: ="HELOC Payment ($"& SUM('Quick HELOC Loan Calc'!B6,'Quick HELOC Loan Calc'!B7)-('Quick HELOC Loan Calc'!$C$5)&")" -> HELOC Payment ($8858) | B29: =-'Quick HELOC Loan Calc'!$C$36 -> 0
A30: Net Cash Flow | B30: =B24+B28+B29 -> 613.53922 | C30: =C24+C28+C29 -> 1038.9272 | D30: =D24+D28+D29 -> 981.75409 | E30: =E24+E28+E29 -> 1690.5974 | F30: =F24+F28+F29 -> 1916.1118 | G30: =G24+G28+G29 -> 2908.8936 | H30: =H24+H28+H29 -> 2919.5634 | I30: =I24+I28+I29 -> 3948.7641 | ... K30: =K24+K28+K29 -> 4815.4449 | L30: =SUM(B30:K30) -> 24830.757 | M30: FV of all cash flows
A31: Monthly Cash Flow | B31: =B30/12 -> 51.128269 | C31: =C30/12 -> 86.577269 | D31: =D30/12 -> 81.812841 | E31: =E30/12 -> 140.88311 | F31: =F30/12 -> 159.67598 | G31: =G30/12 -> 242.4078 | H31: =H30/12 -> 243.29695 | I31: =I30/12 -> 329.06368 | ... K31: =K30/12 -> 401.28708
A32: ="Discounted Cash Flow (DCF) @"&M2&"% return" -> Discounted Cash Flow (DCF) @0.08% return | B32: =B30/(1+$M$2)^B1 -> 568.09187 | C32: =C30/(1+$M$2)^C1 -> 890.71264 | D32: =D30/(1+$M$2)^D1 -> 779.34805 | E32: =E30/(1+$M$2)^E1 -> 1242.6395 | F32: =F30/(1+$M$2)^F1 -> 1304.0735 | G32: =G30/(1+$M$2)^G1 -> 1833.0964 | H32: =H30/(1+$M$2)^H1 -> 1703.5372 | I32: =I30/(1+$M$2)^I1 -> 2133.3944 | ... K32: =K30/(1+$M$2)^K1 -> 2230.4827 | L32: =SUM(B32:K32) -> 14684.952 | M32: PV of all cash flows
A33: Cash on Cash ROI | B33: =B30/(SUM('Quick HELOC Loan Calc'!$B$7,'Quick HELOC Loan Calc'!$B$6)) -> 0.010978799 | C33: =C30/(SUM('Quick HELOC Loan Calc'!$B$7,'Quick HELOC Loan Calc'!$B$6)) -> 0.018590781 | D33: =D30/(SUM('Quick HELOC Loan Calc'!$B$7,'Quick HELOC Loan Calc'!$B$6)) -> 0.017567713 | E33: =E30/(SUM('Quick HELOC Loan Calc'!$B$7,'Quick HELOC Loan Calc'!$B$6)) -> 0.030251903 | F33: =F30/(SUM('Quick HELOC Loan Calc'!$B$7,'Quick HELOC Loan Calc'!$B$6)) -> 0.034287306 | G33: =G30/(SUM('Quick HELOC Loan Calc'!$B$7,'Quick HELOC Loan Calc'!$B$6)) -> 0.052052351 | H33: =H30/(SUM('Quick HELOC Loan Calc'!$B$7,'Quick HELOC Loan Calc'!$B$6)) -> 0.05224328 | I33: =I30/(SUM('Quick HELOC Loan Calc'!$B$7,'Quick HELOC Loan Calc'!$B$6)) -> 0.070660012 | ... K33: =K30/(SUM('Quick HELOC Loan Calc'!$B$7,'Quick HELOC Loan Calc'!$B$6)) -> 0.08616858
A35: Property Appreciation | B35: 0.04 | C35: =$B$35 -> 0.04 | D35: =$B$35 -> 0.04 | E35: =$B$35 -> 0.04 | F35: =$B$35 -> 0.04 | G35: =$B$35 -> 0.04 | H35: =$B$35 -> 0.04 | I35: =$B$35 -> 0.04 | J35: =$B$35 -> 0.04 | K35: =$B$35 -> 0.04
A36: Property Value | B36: ='Quick HELOC Loan Calc'!$B$5*(1+'10 Year'!B35) -> 186576 | C36: =B36+B37 -> 193752 | D36: =C36+C37 -> 201215.04 | E36: =D36+D37 -> 208965.12 | F36: =E36+E37 -> 217013.72 | G36: =F36+F37 -> 225372.33 | H36: =G36+G37 -> 234052.88 | I36: =H36+H37 -> 243067.77 | J36: =I36+I37 -> 252429.88 | K36: =J36+J37 -> 262152.59
A37: Property Appreciation | B37: ='Quick HELOC Loan Calc'!$B$5*B35 -> 7176 | C37: =B36*C35 -> 7463.04 | D37: =C36*D35 -> 7750.08 | E37: =D36*E35 -> 8048.6016 | F37: =E36*F35 -> 8358.6048 | G37: =F36*G35 -> 8680.5489 | H37: =G36*H35 -> 9014.8931 | I37: =H36*I35 -> 9362.115 | J37: =I36*J35 -> 9722.7107 | K37: =J36*K35 -> 10097.195
A38: Mortgage Principle Reduction | B38: =-CUMPRINC('Quick HELOC Loan Calc'!$H$7/12,'Quick HELOC Loan Calc'!$H$8*12,'Quick HELOC Loan Calc'!$B$8,1,12,0) -> 1468.5843 | C38: =-CUMPRINC('Quick HELOC Loan Calc'!$H$7/12,'Quick HELOC Loan Calc'!$H$8*12,'Quick HELOC Loan Calc'!$B$8,13,24,0) -> 1568.8874 | D38: =-CUMPRINC('Quick HELOC Loan Calc'!$H$7/12,'Quick HELOC Loan Calc'!$H$8*12,'Quick HELOC Loan Calc'!$B$8,25,36,0) -> 1676.041 | E38: =-CUMPRINC('Quick HELOC Loan Calc'!$H$7/12,'Quick HELOC Loan Calc'!$H$8*12,'Quick HELOC Loan Calc'!$B$8,37,48,0) -> 1790.5132 | F38: =-CUMPRINC('Quick HELOC Loan Calc'!$H$7/12,'Quick HELOC Loan Calc'!$H$8*12,'Quick HELOC Loan Calc'!$B$8,49,60,0) -> 1912.8037 | G38: =-CUMPRINC('Quick HELOC Loan Calc'!$H$7/12,'Quick HELOC Loan Calc'!$H$8*12,'Quick HELOC Loan Calc'!$B$8,61,72,0) -> 2043.4465 | H38: =-CUMPRINC('Quick HELOC Loan Calc'!$H$7/12,'Quick HELOC Loan Calc'!$H$8*12,'Quick HELOC Loan Calc'!$B$8,73,84,0) -> 2183.0122 | I38: =-CUMPRINC('Quick HELOC Loan Calc'!$H$7/12,'Quick HELOC Loan Calc'!$H$8*12,'Quick HELOC Loan Calc'!$B$8,85,96,0) -> 2332.11 | J38: =-CUMPRINC('Quick HELOC Loan Calc'!$H$7/12,'Quick HELOC Loan Calc'!$H$8*12,'Quick HELOC Loan Calc'!$B$8,97,108,0) -> 2491.3911 | K38: =-CUMPRINC('Quick HELOC Loan Calc'!$H$7/12,'Quick HELOC Loan Calc'!$H$8*12,'Quick HELOC Loan Calc'!$B$8,109,120,0) -> 2661.551
A39: Net Tax Savings (33% Bracket) | B39: =B30*0.25 -> 153.38481 | C39: =C30*0.25 -> 259.73181 | D39: =D30*0.25 -> 245.43852 | E39: =E30*0.25 -> 422.64934 | F39: =F30*0.25 -> 479.02795 | G39: =G30*0.25 -> 727.2234 | H39: =H30*0.25 -> 729.89086 | I39: =I30*0.25 -> 987.19103 | ... K39: =K30*0.25 -> 1203.8612
A40: Tax ROI | B40: =B39/SUM('Quick HELOC Loan Calc'!$B$6:$B$7) -> 0.0027446998 | C40: =C39/SUM('Quick HELOC Loan Calc'!$B$6:$B$7) -> 0.0046476953 | D40: =D39/SUM('Quick HELOC Loan Calc'!$B$6:$B$7) -> 0.0043919283 | E40: =E39/SUM('Quick HELOC Loan Calc'!$B$6:$B$7) -> 0.0075629758 | F40: =F39/SUM('Quick HELOC Loan Calc'!$B$6:$B$7) -> 0.0085718264 | G40: =G39/SUM('Quick HELOC Loan Calc'!$B$6:$B$7) -> 0.013013088 | H40: =H39/SUM('Quick HELOC Loan Calc'!$B$6:$B$7) -> 0.01306082 | I40: =I39/SUM('Quick HELOC Loan Calc'!$B$6:$B$7) -> 0.017665003 | ... K40: =K39/SUM('Quick HELOC Loan Calc'!$B$6:$B$7) -> 0.021542145
A41: Total Return (Not counting appreciation) | B41: =SUM(B30,B38,B39) -> 2235.5084 | C41: =SUM(C30,C38,C39) -> 2867.5464 | D41: =SUM(D30,D38,D39) -> 2903.2336 | E41: =SUM(E30,E38,E39) -> 3903.7599 | F41: =SUM(F30,F38,F39) -> 4307.9434 | G41: =SUM(G30,G38,G39) -> 5679.5635 | H41: =SUM(H30,H38,H39) -> 5832.4665 | I41: =SUM(I30,I38,I39) -> 7268.0652 | ... K41: =SUM(K30,K38,K39) -> 8680.8571
A42: Total ROI | B42: =B41/SUM('Quick HELOC Loan Calc'!$B$6:$B$7) -> 0.040002655 | C42: =C41/SUM('Quick HELOC Loan Calc'!$B$6:$B$7) -> 0.051312476 | D42: =D41/SUM('Quick HELOC Loan Calc'!$B$6:$B$7) -> 0.051951071 | E42: =E41/SUM('Quick HELOC Loan Calc'!$B$6:$B$7) -> 0.069854697 | F42: =F41/SUM('Quick HELOC Loan Calc'!$B$6:$B$7) -> 0.077087242 | G42: =G41/SUM('Quick HELOC Loan Calc'!$B$6:$B$7) -> 0.1016313 | H42: =H41/SUM('Quick HELOC Loan Calc'!$B$6:$B$7) -> 0.10436738 | I42: =I41/SUM('Quick HELOC Loan Calc'!$B$6:$B$7) -> 0.13005628 | ... K42: =K41/SUM('Quick HELOC Loan Calc'!$B$6:$B$7) -> 0.15533708 | L42: =SUM(B42:K42)/K1 -> 0.09155892 | M42: AAR
L43: =('10 Year'!K36/'Quick HELOC Loan Calc'!B5)^(1/'10 Year'!K1)-1 -> 0.038659439 | M43: CAGR
A45: Total Property Equity (not counting appreciation) | B45: =SUM('Quick HELOC Loan Calc'!$B$7,'10 Year'!B38) -> 46318.584 | C45: =B45+C38 -> 47887.472 | D45: =C45+D38 -> 49563.513 | E45: =D45+E38 -> 51354.026 | F45: =E45+F38 -> 53266.83 | G45: =F45+G38 -> 55310.276 | H45: =G45+H38 -> 57493.288 | I45: =H45+I38 -> 59825.398 | J45: =I45+J38 -> 62316.789 | K45: =J45+K38 -> 64978.34
...

Sheet Calculators
A3: Year | C3: Annual ROI | G3: Year | I3: Annual ROI | S3: IRR | T3: =XIRR(T4:T10,R4:R10) -> 0.21632629
A4: 0 | B4: 100000 | G4: 0 | H4: 100000 | M4: Present Value=Future Value /( 1+i)^n | R4: 45292 | S4: Initial Investment | T4: -8500000
A5: =A4+1 -> 1 | B5: 110000 | C5: =(B5/B4)-1 -> 0.1 | G5: =G4+1 -> 1 | H5: 110000 | I5: =(H5/H4)-1 -> 0.1 | M5: interest | N5: 0.08 | R5: =R4+365 -> 45657 | S5: Year 1 Cashflow | T5: =-$T$4*$U$5 -> 1360000 | U5: 0.16 | V5: Cash On Cash
A6: =A5+1 -> 2 | B6: 105000 | C6: =(B6/B5)-1 -> -0.045454545 | G6: =G5+1 -> 2 | H6: 105000 | I6: =(H6/H5)-1 -> -0.045454545 | M6: time (yrs) | N6: 5 | O6: =N6*12 -> 60 | R6: =R5+365 -> 46022 | S6: Year 2 Cashflow | T6: =-$T$4*$U$5 -> 1360000
A7: =A6+1 -> 3 | B7: 120000 | C7: =(B7/B6)-1 -> 0.14285714 | G7: =G6+1 -> 3 | H7: 120000 | I7: =(H7/H6)-1 -> 0.14285714 | R7: =R6+365 -> 46387 | S7: Year 3 Cashflow | T7: =-$T$4*$U$5 -> 1360000
A8: =A7+1 -> 4 | B8: =B7+5000 -> 125000 | C8: =(B8/B7)-1 -> 0.041666667 | G8: =G7+1 -> 4 | H8: =H7+5000 -> 125000 | I8: =(H8/H7)-1 -> 0.041666667 | R8: =R7+365 -> 46752 | S8: Year 4 Cashflow | T8: =-$T$4*$U$5 -> 1360000
A9: =A8+1 -> 5 | B9: =B8+5000 -> 130000 | C9: =(B9/B8)-1 -> 0.04 | G9: =G8+1 -> 5 | H9: =H8+5000 -> 130000 | I9: =(H9/H8)-1 -> 0.04 | R9: =R8+365 -> 47117 | S9: Year 5 Cashflow | T9: =-$T$4*$U$5 -> 1360000
A10: =A9+1 -> 6 | B10: =B9+5000 -> 135000 | C10: =(B10/B9)-1 -> 0.038461538 | R10: =R9+365 -> 47482 | S10: 6 | T10: =-T4*(1+U10)^S10 -> 14813534 | U10: 0.097 | V10: Assumed Appreciation
A11: =A10+1 -> 7 | B11: =B10+5000 -> 140000 | C11: =(B11/B10)-1 -> 0.037037037 | I11: =(H9-H4)/H4 -> 0.3 | J11: ROI
A12: =A11+1 -> 8 | B12: =B11+5000 -> 145000 | C12: =(B12/B11)-1 -> 0.035714286 | I12: =SUM(I5:I9)/COUNT(I5:I9) -> 0.055813853 | J12: AAR
A13: =A12+1 -> 9 | B13: =B12+5000 -> 150000 | C13: =(B13/B12)-1 -> 0.034482759 | I13: =(H9/H4)^(1/COUNT(I4:I9))-1 -> 0.053873952 | J13: CAGR | M13: 0.105 | N13: projected Cash On Cash Return
A14: =A13+1 -> 10 | B14: =B13+5000 -> 155000 | C14: =(B14/B13)-1 -> 0.033333333 | I14: =H9/H4 -> 1.3 | J14: Equity Multiplier | M14: 8500000 | N14: initial investment
M15: =O15*12 -> 60 | N15: hold period | O15: 5
C16: =(B14-B4)/B4 -> 0.55 | D16: ROI
C17: =SUM(C5:C14)/COUNT(C5:C14) -> 0.045809822 | D17: AAR | M17: Future | N17: =M14*(1+M13/12)^(M15) -> 14336125 | O17: =N17/M14 -> 1.686603 | P17: Equity Multiple
C18: =(B14/B4)^(1/COUNT(C4:C14))-1 -> 0.044800014 | D18: CAGR | M18: CAGR | N18: =(N17/M14)^(1/(M15))-1 -> 0.00875
C19: =B14/B4 -> 1.55 | D19: Equity Multiplier
