Workbook
Name If: #REF!
Name If: #REF!
Name If: #REF!

Sheet Quick HELOC Loan Calc
G1: Heloc Down Payment | H1: 0.08
G2: Heloc Loan Terms | H2: 20 | I2: yrs
A3: =B5 -> 1000000 | B3: asking price | G3: HELOC Amount | H3: =SUM(B7+B6-C5-C4) -> 87974
C4: 5000 | D4: earnest money | G4: HELOC P&I Payment | H4: =-PMT($H$1/12,$H$2*12,H3) -> 735.84979 | I4: =H4*12 -> 8830.1974 | K4: IRR | L4: =IRR(L5:L11) -> -0.025857971
A5: Purchase Price | B5: 1000000 | C5: 47026 | D5: cash | G5: HELOC Interest Only Payment | H5: =-IPMT($H$1/12,1,$H$2*12,H3) -> 586.49333 | I5: =H5*12 -> 7037.92 | K5: Initial Investment | L5: =-B5 -> -1000000
A6: Closing Costs (4%) | B6: =B5*0.04 -> 40000 | I6: =H4-H5 -> 149.35645 | K6: Year 1 Cashflow | L6: ='10 Year'!B30 -> -64027.504
A7: Down Payment (20%) - HELOC | B7: =B5*C7 -> 100000 | C7: 0.1 | D7: downpayment | G7: Conventional Loan Interest Rate | H7: 0.06625 | K7: Year 2 Cashflow | L7: ='10 Year'!C30 -> -57861.456
A8: Total Loan Amount | B8: =B5-B7 -> 900000 | G8: Loan Term | H8: 30 | I8: yrs | K8: Year 3 Cashflow | L8: ='10 Year'!D30 -> -57919.908
A9: Down Payment - Cash | B9: =B5 -> 1000000 | G9: Monthly Interest Payment on Purchase Price | H9: =-PMT($H$7/12,$H$8*12,$B$8) -> 5762.7986 | K9: Year 4 Cashflow | L9: ='10 Year'!E30 -> -57212.363
G10: Monthly Interest Payment on Purchase Price | H10: =-IPMT($H$7/12,1,$H$8*12,$B$8) -> 4968.75 | K10: Year 5 Cashflow | L10: ='10 Year'!F30 -> -56988.166
A11: All In Price (Purchase+Repairs) | B11: =SUM(B5) -> 1000000 | K11: 6 | L11: =B5*(1+0.02)^K11 -> 1126162.4 | M11: assumes 2%/yr appreciation
A12: Estimated ARV (After Repair Value) | B12: =B5 -> 1000000 | G12: Financials
G13: Cash On Cash Return (CoC) | H13: =C38/SUM(B6:B7) -> -0.4576536
B14: Monthly | C14: Annually | G14: ROI (Return on Investment) | H14: =(SUM($B$6:$B$7)/B5) -> 0.14
A15: Average Rent | B15: 1350 | C15: =B15*12 -> 16200 | G15: ROE (Return on Equity) | H15: =C38/B7 -> -0.64071504
A16: Less 4% Vacancy | B16: =B15*-0.04 -> -54 | C16: =B16*12 -> -648 | G16: Mortgage Pay Down yr 1 | H16: =PPMT(H7/12,1,H8*12,B8)*12 -> -9528.5838
A17: Additional Income (Laundry) | B17: 0 | C17: =B17*12 -> 0 | G17: Tax Savings at 33% | H17: =C38*0.33 -> -21143.596
A18: Calculated Gross Revenue | B18: =SUM(B15:B17) -> 1296 | C18: =B18*12 -> 15552
G19: Rules of Thumb
G20: 50% Rule
A21: Estimated Expenses | B21: Monthly | C21: Annually | G21: 2% Rule | H21: =$B$15/$B$5 -> 0.00135
A22: Management Fees | B22: =B15*D22 -> 0 | C22: =B22*12 -> 0 | D22: 0 | E22: =IF(D22=0,1,0) -> 1 | G22: DSCR | H22: =B35/(B37+B36) -> 0.15907285
A23: Property Taxes / Year | B23: 107 | C23: =B23*12 -> 1284 | D23: 0.0108
A24: Insurance / Year | B24: 80 | C24: =B24*12 -> 960 | D24: =C24/B5 -> 0.00096
A25: HOA / year
A26: Electricity | C26: =B26*12 -> 0 | G26: Emergency Fund Needed (6 months) | H26: =B33*$I$26+SUM(B36:B37)*$I$26 -> 39811.752 | I26: 6 | J26: months
A27: Nat Gas | C27: =B27*12 -> 0 | H27: =H26/2 -> 19905.876 | I27: =I26/2 -> 3 | J27: months
A28: Water/Sewer | C28: =B28*12 -> 0
A29: Building Maintenance | B29: 54 | C29: =B29*12 -> 648 | D29: =C29/C15 -> 0.04
A30: Grounds Cleanup/Services Maintenance/Snow Removal | C30: =B30*12 -> 0
A31: Yearly Safety Inspection | B31: 8 | C31: =B31*12 -> 96
A32: Umbrella Insurance (Allstate Anchorage) | B32: 37 | C32: =B32*12 -> 444
A33: Totals | B33: =SUM(B22:B32) -> 286 | C33: =SUM(C22:C32) -> 3432
A35: Net Operating Income | B35: =B18-B33 -> 1010 | C35: =C18-C33 -> 12120 | D35: DSCR | E35: =B35/(B37+B36) -> 0.15907285
A36: HELOC Payment | B36: =H5 -> 586.49333 | C36: =B36*12 -> 7037.92 | D36: =IF(B36=H5,1,0) -> 1
A37: Conventional Loan Payment | B37: =-PMT($H$7/12,$H$8*12,$B$8) -> 5762.7986 | C37: =B37*12 -> 69153.584 | D37: Cap Rate | E37: =C35/B5 -> 0.01212
A38: Cash Flow | B38: =B35-B37-B36 -> -5339.292 | C38: =B38*12 -> -64071.504 | G38: NOI/value
A41: Estimated CapEx | B41: Timeline of Repair (yrs) | C41: Cost per Unit | D41: Total Cost | E41: Monthly Cost
A42: Roof | B42: 5 | C42: 7000 | D42: =C42 -> 7000 | E42: =D42/B42/12 -> 116.66667
A43: Master Bath | B43: 10 | D43: =C43 -> 0 | E43: =D43/B43/12 -> 0
...

Sheet 7yr IRR Financing
A1: ='Quick HELOC Loan Calc'!$A$1 &" FINANCING CALCULATIONS" -> FINANCING CALCULATIONS
B4: Year 1 | C4: Year 2 | D4: Year 3 | E4: Year 4 | F4: Year 5 | G4: Year 6 | H4: Year 7
A5: Maintenance | B5: 0.04 | C5: 0.04 | D5: 0.04 | E5: 0.04 | F5: 0.04 | G5: 0.04 | H5: 0.04
A6: Property Appreciation | B6: 0.04 | C6: 0.04 | D6: 0.04 | E6: 0.04 | F6: 0.04 | G6: 0.04 | H6: 0.04
A7: Rental Appreciation | B7: 0.03 | C7: 0.03 | D7: 0.03 | E7: 0.03 | F7: 0.03 | G7: 0.03 | H7: 0.03
A8: Tax/Insurance/HOA Appreciation | B8: 0.015 | C8: 0.015 | D8: 0.015 | E8: 0.015 | F8: 0.015 | G8: 0.015 | H8: 0.015
A9: Vacancy | B9: 0.04 | C9: 0.04 | D9: 0.04 | E9: 0.04 | F9: 0.04 | G9: 0.04 | H9: 0.04
B11: Year 1 | C11: Year 2 | D11: Year 3 | E11: Year 4 | F11: Year 5 | G11: Year 6 | H11: Year 7
A12: Revenues
A13: Rental Income | B13: ='Quick HELOC Loan Calc'!C15 -> 16200 | C13: =SUM(B$13+(C$7*B$13)) -> 16686 | D13: =SUM(C$13+(D$7*C$13)) -> 17186.58 | E13: =SUM(D$13+(E$7*D$13)) -> 17702.177 | F13: =SUM(E$13+(F$7*E$13)) -> 18233.243 | G13: =SUM(F$13+(G$7*F$13)) -> 18780.24 | H13: =SUM(G$13+(H$7*G$13)) -> 19343.647
B14: =B13/12 -> 1350 | C14: =C13/12 -> 1390.5 | D14: =D13/12 -> 1432.215 | E14: =E13/12 -> 1475.1815 | F14: =F13/12 -> 1519.4369 | G14: =G13/12 -> 1565.02 | H14: =H13/12 -> 1611.9706
A15: Vacancy Rate | B15: =-(B13*B9) -> -648 | C15: =-(C13*C9) -> -667.44 | D15: =-(D13*D9) -> -687.4632 | E15: =-(E13*E9) -> -708.0871 | F15: =-(F13*F9) -> -729.32971 | G15: =-(G13*G9) -> -751.2096 | H15: =-(H13*H9) -> -773.74589
A16: Net Rental Income | B16: =SUM(B13,B15) -> 15552 | C16: =SUM(C13,C15) -> 16018.56 | D16: =SUM(D13,D15) -> 16499.117 | E16: =SUM(E13,E15) -> 16994.09 | F16: =SUM(F13,F15) -> 17503.913 | G16: =SUM(G13,G15) -> 18029.03 | H16: =SUM(H13,H15) -> 18569.901
A18: Expenses
A19: Property Taxes | B19: ='Quick HELOC Loan Calc'!C23 -> 1284 | C19: =B$19+(B$19*C$8) -> 1303.26 | D19: =C$19+(C$19*D$8) -> 1322.8089 | E19: =D$19+(D$19*E$8) -> 1342.651 | F19: =E$19+(E$19*F$8) -> 1362.7908 | G19: =F$19+(F$19*G$8) -> 1383.2327 | H19: =G$19+(G$19*H$8) -> 1403.9812
A20: Insurance | B20: ='Quick HELOC Loan Calc'!C24 -> 960 | C20: =B20+(B20*C8) -> 974.4 | D20: =C20+(C20*D8) -> 989.016 | E20: =D20+(D20*E8) -> 1003.8512 | F20: =E20+(E20*F8) -> 1018.909 | G20: =F20+(F20*G8) -> 1034.1926 | H20: =G20+(G20*H8) -> 1049.7055
A21: Property Mgmt | C21: =C13*0.08 -> 1334.88 | D21: =D13*0.08 -> 1374.9264 | E21: =E13*0.08 -> 1416.1742 | F21: =F13*0.08 -> 1458.6594 | G21: =G13*0.08 -> 1502.4192 | H21: =H13*0.08 -> 1547.4918 | I21: $5000 management credit
A22: Lease Fee | B22: 0 | C22: 0 | D22: 250 | E22: 0 | F22: 250 | G22: 0 | H22: 250
A23: Management Renewal Fee | D23: 250 | E23: 250 | F23: 250 | H23: 250
A24: HOA | B24: ='[1]Input Info'!B14 -> 0 | C24: =B24+(B24*C8) -> 0 | D24: =C24+(C24*D8) -> 0 | E24: =D24+(D24*E8) -> 0 | F24: =E24+(E24*F8) -> 0 | G24: =F24+(F24*G8) -> 0 | H24: =G24+(G24*H8) -> 0
A25: Maintenance & Repairs | B25: =B13*B5 -> 648 | C25: =C13*C5 -> 667.44 | D25: =D13*D5 -> 687.4632 | E25: =E13*E5 -> 708.0871 | F25: =F13*F5 -> 729.32971 | G25: =G13*G5 -> 751.2096 | H25: =H13*H5 -> 773.74589
A26: Yearly Inspection | B26: 100 | C26: 100 | D26: 100 | E26: 100 | F26: 100 | G26: 100 | H26: 100
A27: Umbrella Insurance | B27: =33*12 -> 396 | C27: =33*12 -> 396 | D27: =33*12 -> 396 | E27: =33*12 -> 396 | F27: =33*12 -> 396 | G27: =33*12 -> 396 | H27: =33*12 -> 396
A28: Total Expenses | B28: =SUM(B19:B27) -> 3388 | C28: =SUM(C19:C27) -> 4775.98 | D28: =SUM(D19:D27) -> 5370.2145 | E28: =SUM(E19:E27) -> 5216.7636 | F28: =SUM(F19:F27) -> 5565.6889 | G28: =SUM(G19:G27) -> 5167.0541 | H28: =SUM(H19:H27) -> 5770.9243
A30: Net Operating Income (NOI) | B30: =SUM(B16-B28) -> 12164 | C30: =SUM(C16-C28) -> 11242.58 | D30: =SUM(D16-D28) -> 11128.902 | E30: =SUM(E16-E28) -> 11777.327 | F30: =SUM(F16-F28) -> 11938.224 | G30: =SUM(G16-G28) -> 12861.976 | H30: =SUM(H16-H28) -> 12798.977
A32: Cash Flow
A33: NOI (Cash Available) | B33: =B30 -> 12164 | C33: =C30 -> 11242.58 | D33: =D30 -> 11128.902 | E33: =E30 -> 11777.327 | F33: =F30 -> 11938.224 | G33: =G30 -> 12861.976 | H33: =H30 -> 12798.977
A34: Conventional Mortgage | B34: =SUM('Quick HELOC Loan Calc'!$B$37*12) -> 69153.584 | C34: =SUM('Quick HELOC Loan Calc'!$B$37*12) -> 69153.584 | D34: =SUM('Quick HELOC Loan Calc'!$B$37*12) -> 69153.584 | E34: =SUM('Quick HELOC Loan Calc'!$B$37*12) -> 69153.584 | F34: =SUM('Quick HELOC Loan Calc'!$B$37*12) -> 69153.584 | G34: =SUM('Quick HELOC Loan Calc'!$B$37*12) -> 69153.584 | H34: =SUM('Quick HELOC Loan Calc'!$B$37*12) -> 69153.584
A35: HELOC Mortgage | B35: ='Quick HELOC Loan Calc'!C36 -> 7037.92 | I35: Interest Only - Pay off on 1 year anniversary
A36: Total Cash Flow | B36: =SUM(B33-B34-B35) -> -64027.504 | C36: =SUM(C33-C34-C35) -> -57911.004 | D36: =SUM(D33-D34-D35) -> -58024.681 | E36: =SUM(E33-E34-E35) -> -57376.257 | F36: =SUM(F33-F34-F35) -> -57215.36 | G36: =SUM(G33-G34-G35) -> -56291.607 | H36: =SUM(H33-H34-H35) -> -56354.607
A37: Monthly Cash Flow | B37: =B36/12 -> -5335.6253 | C37: =C36/12 -> -4825.917 | D37: =D36/12 -> -4835.3901 | E37: =E36/12 -> -4781.3548 | F37: =F36/12 -> -4767.9466 | G37: =G36/12 -> -4690.9673 | H37: =H36/12 -> -4696.2172
A38: DSCR | B38: =B33/SUM(B34:B35) -> 0.15965035 | C38: =C33/SUM(C34:C35) -> 0.16257408 | D38: =D33/SUM(D34:D35) -> 0.16093023 | E38: =E33/SUM(E34:E35) -> 0.17030682 | F38: =F33/SUM(F34:F35) -> 0.17263348 | G38: =G33/SUM(G34:G35) -> 0.18599146 | H38: =H33/SUM(H34:H35) -> 0.18508046
A39: Equity Accrued | B39: =-CUMPRINC('Quick HELOC Loan Calc'!$H$7/12,'Quick HELOC Loan Calc'!$H$8*12,'Quick HELOC Loan Calc'!$B$8,1,12,0) -> 9823.3065 | C39: =-CUMPRINC('Quick HELOC Loan Calc'!$H$7/12,'Quick HELOC Loan Calc'!$H$8*12,'Quick HELOC Loan Calc'!$B$8,13,24,0) -> 10494.23 | D39: =-CUMPRINC('Quick HELOC Loan Calc'!$H$7/12,'Quick HELOC Loan Calc'!$H$8*12,'Quick HELOC Loan Calc'!$B$8,25,36,0) -> 11210.977 | E39: =-CUMPRINC('Quick HELOC Loan Calc'!$H$7/12,'Quick HELOC Loan Calc'!$H$8*12,'Quick HELOC Loan Calc'!$B$8,37,48,0) -> 11976.677 | F39: =-CUMPRINC('Quick HELOC Loan Calc'!$H$7/12,'Quick HELOC Loan Calc'!$H$8*12,'Quick HELOC Loan Calc'!$B$8,49,60,0) -> 12794.673 | G39: =-CUMPRINC('Quick HELOC Loan Calc'!$H$7/12,'Quick HELOC Loan Calc'!$H$8*12,'Quick HELOC Loan Calc'!$B$8,61,72,0) -> 13668.539 | H39: =-CUMPRINC('Quick HELOC Loan Calc'!$H$7/12,'Quick HELOC Loan Calc'!$H$8*12,'Quick HELOC Loan Calc'!$B$8,73,84,0) -> 14602.088
A40: Appreciation | B40: =SUM(B6*'Quick HELOC Loan Calc'!$B$5) -> 40000 | C40: =(SUM(B40)+'Quick HELOC Loan Calc'!$B$5)*C$6 -> 41600 | D40: =('Quick HELOC Loan Calc'!$B$5+C40+B40)*D$6 -> 43264 | E40: =('Quick HELOC Loan Calc'!$B$5+D40+C40+B40)*E$6 -> 44994.56 | F40: =('Quick HELOC Loan Calc'!$B$5+E40+D40+C40+B40)*F$6 -> 46794.342 | G40: =('Quick HELOC Loan Calc'!$B$5+F40+E40+D40+C40+B40)*G$6 -> 48666.116 | H40: =('Quick HELOC Loan Calc'!$B$5+G40+F40+E40+D40+C40+B40)*H$6 -> 50612.761
A41: Total Return | B41: =SUM(B36+B39+B40) -> -14204.197 | C41: =SUM(C36+C39+C40) -> -5816.7739 | D41: =SUM(D36+D39+D40) -> -3549.7048 | E41: =SUM(E36+E39+E40) -> -405.0203 | F41: =SUM(F36+F39+F40) -> 2373.6561 | G41: =SUM(G36+G39+G40) -> 6043.0472 | H41: =SUM(H36+H39+H40) -> 8860.2419
A42: Total ROI | B42: =SUM(B41/'[1]Input Info'!$B$18) -> -0.33819517 | C42: =SUM(C41/'[1]Input Info'!$B$18) -> -0.13849462 | D42: =SUM(D41/'[1]Input Info'!$B$18) -> -0.08451678 | E42: =SUM(E41/'[1]Input Info'!$B$18) -> -0.0096433404 | F42: =SUM(F41/'[1]Input Info'!$B$18) -> 0.056515622 | G42: =SUM(G41/'[1]Input Info'!$B$18) -> 0.14388208 | H42: =SUM(H41/'[1]Input Info'!$B$18) -> 0.21095814
A43: Average ROI | G43: =AVERAGE(B42:H42) -> -0.022784867
A44: Estimated Value at Year 7 | G44: ='[1]Input Info'!B5+(SUM('7yr IRR Financing'!B40:H40)) -> 455931.78
A45: Loan Paid Down over 7 Years | G45: =SUM(B39:H39) -> 84570.49
A46: Total returns are based on calculations of external data and is subject to change. Estimated returns are estimated, and may not factor in all scenarios or costs. REI Nation, LLC and Premier Property Management Group, LLC have offered this estimator of returns in good faith. We realize that there are alternate methods to calculate return, and that some assumptions may not be applicable for your calculations. Data provided for the calculation is the user’s responsibility. We do not make any representations or warranties of any kind on the information provided. We also disclaim any liability or responsibility for the accuracy, correctness, or completeness of any information provided. *All calculations include estimated maintenance, estimated vacancy, estimated property management fees, estimated equity accrual, estimated property taxes, estimated insurance and estimated appreciation.

Sheet 10 Year
A1: Year | B1: 1 | C1: 2 | D1: 3 | E1: 4 | F1: 5 | G1: 6 | H1: 7 | I1: 8 | J1: 9 | K1: 10
A2: Property Income | L2: Desired Return | M2: 0.08 | N2: match stock market
A3: Rent | B3: ='Quick HELOC Loan Calc'!C15 -> 16200 | C3: =B3*(1+C5) -> 16783.2 | D3: =C3*(1+D5) -> 17387.395 | E3: =D3*(1+E5) -> 18013.341 | F3: =E3*(1+F5) -> 18661.822 | G3: =F3*(1+G5) -> 19333.647 | H3: =G3*(1+H5) -> 20029.659 | I3: =H3*(1+I5) -> 20750.726 | J3: =I3*(1+J5) -> 21497.752 | K3: =J3*(1+K5) -> 22271.672
A4: Monthly Rent | B4: =B3/12 -> 1350 | C4: =C3/12 -> 1398.6 | D4: =D3/12 -> 1448.9496 | E4: =E3/12 -> 1501.1118 | F4: =F3/12 -> 1555.1518 | G4: =G3/12 -> 1611.1373 | H4: =H3/12 -> 1669.1382 | I4: =I3/12 -> 1729.2272 | ... K4: =K3/12 -> 1855.9726 | M4: IRR | P4: NPV
A5: Rent Appreciation | B5: 0.036 | C5: =$B$5 -> 0.036 | D5: =$B$5 -> 0.036 | E5: =$B$5 -> 0.036 | F5: =$B$5 -> 0.036 | G5: =$B$5 -> 0.036 | H5: =$B$5 -> 0.036 | I5: =$B$5 -> 0.036 | J5: =$B$5 -> 0.036 | K5: =$B$5 -> 0.036 | M5: 45536 | N5: 0 | O5: =-SUM('Quick HELOC Loan Calc'!B6:B7) -> -140000 | P5: =O5 -> -140000
A6: Vacancy Loss | B6: 0.04 | C6: =$B$6 -> 0.04 | D6: =$B$6 -> 0.04 | E6: =$B$6 -> 0.04 | F6: =$B$6 -> 0.04 | G6: =$B$6 -> 0.04 | H6: =$B$6 -> 0.04 | I6: =$B$6 -> 0.04 | J6: =$B$6 -> 0.04 | K6: =$B$6 -> 0.04 | M6: 45901 | N6: 1 | O6: =B30 -> -64027.504 | P6: =O6/(1+$M$2)^N6 -> -59284.726
M7: 46266 | N7: 2 | O7: =C30 -> -57861.456 | P7: =O7/(1+$M$2)^N7 -> -49606.872
A8: Operating Income | B8: =B3*(1-B6) -> 15552 | C8: =C3*(1-C6) -> 16111.872 | D8: =D3*(1-D6) -> 16691.899 | E8: =E3*(1-E6) -> 17292.808 | F8: =F3*(1-F6) -> 17915.349 | G8: =G3*(1-G6) -> 18560.301 | H8: =H3*(1-H6) -> 19228.472 | I8: =I3*(1-I6) -> 19920.697 | ... K8: =K3*(1-K6) -> 21380.805 | M8: 46631 | N8: 3 | O8: =D30 -> -57919.908 | P8: =O8/(1+$M$2)^N8 -> -45978.69
M9: 46997 | N9: 4 | O9: =E30 -> -57212.363 | P9: =O9/(1+$M$2)^N9 -> -42052.794
A10: Property Expenses | M10: 47362 | N10: 5 | O10: =F30 -> -56988.166 | P10: =O10/(1+$M$2)^N10 -> -38785.188
A11: Management Fee | B11: =0.08 -> 0.08 | C11: =$B$11 -> 0.08 | D11: =$B$11 -> 0.08 | E11: =$B$11 -> 0.08 | F11: =$B$11 -> 0.08 | G11: =$B$11 -> 0.08 | H11: =$B$11 -> 0.08 | I11: =$B$11 -> 0.08 | J11: =$B$11 -> 0.08 | K11: =$B$11 -> 0.08 | M11: 47727 | N11: 6 | O11: =G30 -> -55996.721 | P11: =O11/(1+$M$2)^N11 -> -35287.433
A12: Management Fees | B12: =IF('Quick HELOC Loan Calc'!$E$22=1,"Waived",'Quick HELOC Loan Calc'!$C$22) -> Waived | C12: =C3*C11 -> 1342.656 | D12: =D3*D11 -> 1390.9916 | E12: =E3*E11 -> 1441.0673 | F12: =F3*F11 -> 1492.9457 | G12: =G3*G11 -> 1546.6918 | H12: =H3*H11 -> 1602.3727 | I12: =I3*I11 -> 1660.0581 | J12: =J3*J11 -> 1719.8202 | K12: =K3*K11 -> 1781.7337 | M12: 48092 | N12: 7 | O12: =H30 -> -55987.409 | P12: =O12/(1+$M$2)^N12 -> -32668.115
A13: Property Taxes (1.5%) | B13: ='Quick HELOC Loan Calc'!C23 -> 1284 | C13: =B36*($B$13/'Quick HELOC Loan Calc'!$B$5) -> 1335.36 | D13: =C36*($B$13/'Quick HELOC Loan Calc'!$B$5) -> 1386.72 | E13: =D36*($B$13/'Quick HELOC Loan Calc'!$B$5) -> 1440.1344 | F13: =E36*($B$13/'Quick HELOC Loan Calc'!$B$5) -> 1495.6032 | G13: =F36*($B$13/'Quick HELOC Loan Calc'!$B$5) -> 1553.2086 | H13: =G36*($B$13/'Quick HELOC Loan Calc'!$B$5) -> 1613.0327 | I13: =H36*($B$13/'Quick HELOC Loan Calc'!$B$5) -> 1675.161 | J13: =I36*($B$13/'Quick HELOC Loan Calc'!$B$5) -> 1739.6824 | K13: =J36*($B$13/'Quick HELOC Loan Calc'!$B$5) -> 1806.6888 | M13: 48458 | N13: 8 | O13: =I30 -> -54959.586 | P13: =O13/(1+$M$2)^N13 -> -29692.954
A14: Insurance (1.5%) | B14: ='Quick HELOC Loan Calc'!C24 -> 960 | C14: =B14+(B14*0.015) -> 974.4 | D14: =C14+(C14*0.015) -> 989.016 | E14: =D14+(D14*0.015) -> 1003.8512 | F14: =E14+(E14*0.015) -> 1018.909 | G14: =F14+(F14*0.015) -> 1034.1926 | H14: =G14+(G14*0.015) -> 1049.7055 | I14: =H14+(H14*0.015) -> 1065.4511 | J14: =I14+(I14*0.015) -> 1081.4329 | K14: =J14+(J14*0.015) -> 1097.6544 | M14: 48823 | N14: 9 | O14: =J30 -> -54912.587 | P14: =O14/(1+$M$2)^N14 -> -27469.965
A15: Maintenance/Repairs (4%) | B15: =IF('Quick HELOC Loan Calc'!$C$29=0,"Seller Covered",'Quick HELOC Loan Calc'!$C$29) -> 648 | C15: =C3*0.04 -> 671.328 | D15: =D3*0.04 -> 695.49581 | E15: =E3*0.04 -> 720.53366 | F15: =F3*0.04 -> 746.47287 | G15: =G3*0.04 -> 773.34589 | H15: =H3*0.04 -> 801.18634 | I15: =I3*0.04 -> 830.02905 | J15: =J3*0.04 -> 859.9101 | K15: =K3*0.04 -> 890.86686 | M15: 49188 | N15: 10 | O15: =K30+K36-('Quick HELOC Loan Calc'!B8-SUM('10 Year'!B38:K38)) -> 641816.22 | P15: =O15/(1+$M$2)^N15 -> 297285.09
A16: Leasing Fee | B16: 0 | C16: 0 | D16: 250 | E16: 0 | F16: 250 | G16: 0 | H16: 250 | I16: 0 | J16: 250 | K16: 0 | O16: =XIRR(O5:O15,M5:M15) -> -0.0035256736 | P16: =SUM(P5:P15) -> -203541.64
A17: Annual Safety Inspection | B17: 100 | C17: 100 | D17: 100 | E17: 100 | F17: 100 | G17: 100 | H17: 100 | I17: 100 | J17: 100 | K17: 100
A18: Management Renewal Fee | D18: 250 | E18: 250 | F18: 250 | H18: 250 | J18: 250 | K18: 250
A19: HOA Fees | B19: 0 | C19: 0 | D19: 0 | E19: 0 | F19: 0 | G19: 0 | H19: 0 | I19: 0 | J19: 0 | K19: 0
A20: Umbrella Insurance | B20: =33*12 -> 396 | C20: =33*12 -> 396 | D20: =33*12 -> 396 | E20: =33*12 -> 396 | F20: =33*12 -> 396 | G20: =33*12 -> 396 | H20: =33*12 -> 396 | I20: =33*12 -> 396 | ... K20: =33*12 -> 396
A22: Operating Expenses | B22: =SUM(B12:B20) -> 3388 | C22: =SUM(C12:C20) -> 4819.744 | D22: =SUM(D12:D20) -> 5458.2234 | E22: =SUM(E12:E20) -> 5351.5866 | F22: =SUM(F12:F20) -> 5749.9308 | G22: =SUM(G12:G20) -> 5403.4389 | H22: =SUM(H12:H20) -> 6062.2973 | I22: =SUM(I12:I20) -> 5726.6993 | ... K22: =SUM(K12:K20) -> 6322.9438
A24: Net Operating Income (NOI) | B24: =B8-B22 -> 12164 | C24: =C8-C22 -> 11292.128 | D24: =D8-D22 -> 11233.676 | E24: =E8-E22 -> 11941.221 | F24: =F8-F22 -> 12165.418 | G24: =G8-G22 -> 13156.863 | H24: =H8-H22 -> 13166.175 | I24: =I8-I22 -> 14193.998 | ... K24: =K8-K22 -> 15057.861
A25: Capitalization Rate (CAP Rate) | B25: =B24/'Quick HELOC Loan Calc'!$B$5 -> 0.012164 | C25: =C24/'Quick HELOC Loan Calc'!$B$5 -> 0.011292128 | D25: =D24/'Quick HELOC Loan Calc'!$B$5 -> 0.011233676 | E25: =E24/'Quick HELOC Loan Calc'!$B$5 -> 0.011941221 | F25: =F24/'Quick HELOC Loan Calc'!$B$5 -> 0.012165418 | G25: =G24/'Quick HELOC Loan Calc'!$B$5 -> 0.013156863 | H25: =H24/'Quick HELOC Loan Calc'!$B$5 -> 0.013166175 | I25: =I24/'Quick HELOC Loan Calc'!$B$5 -> 0.014193998 | ... K25: =K24/'Quick HELOC Loan Calc'!$B$5 -> 0.015057861
A27: Key Investment Indicators
A28: Mortgage Payment | B28: =PMT('Quick HELOC Loan Calc'!$H$7/12, 'Quick HELOC Loan Calc'!$H$8*12,'Quick HELOC Loan Calc'!$B$8)*12 -> -69153.584 | C28: =PMT('Quick HELOC Loan Calc'!$H$7/12, 'Quick HELOC Loan Calc'!$H$8*12,'Quick HELOC Loan Calc'!$B$8)*12 -> -69153.584 | D28: =PMT('Quick HELOC Loan Calc'!$H$7/12, 'Quick HELOC Loan Calc'!$H$8*12,'Quick HELOC Loan Calc'!$B$8)*12 -> -69153.584 | E28: =PMT('Quick HELOC Loan Calc'!$H$7/12, 'Quick HELOC Loan Calc'!$H$8*12,'Quick HELOC Loan Calc'!$B$8)*12 -> -69153.584 | F28: =PMT('Quick HELOC Loan Calc'!$H$7/12, 'Quick HELOC Loan Calc'!$H$8*12,'Quick HELOC Loan Calc'!$B$8)*12 -> -69153.584 | G28: =PMT('Quick HELOC Loan Calc'!$H$7/12, 'Quick HELOC Loan Calc'!$H$8*12,'Quick HELOC Loan Calc'!$B$8)*12 -> -69153.584 | H28: =PMT('Quick HELOC Loan Calc'!$H$7/12, 'Quick HELOC Loan Calc'!$H$8*12,'Quick HELOC Loan Calc'!$B$8)*12 -> -69153.584 | I28: =PMT('Quick HELOC Loan Calc'!$H$7/12, 'Quick HELOC Loan Calc'!$H$8*12,'Quick HELOC Loan Calc'!$B$8)*12 -> -69153.584 | ... K28: =PMT('Quick HELOC Loan Calc'!$H$7/12, 'Quick HELOC Loan Calc'!$H$8*12,'Quick HELOC Loan Calc'!$B$8)*12 -> -69153.584
A29: ="HELOC Payment ($"& SUM('Quick HELOC Loan Calc'!B6,'Quick HELOC Loan Calc'!B7)-('Quick HELOC Loan Calc'!$C$5)&")" -> HELOC Payment ($92974) | B29: =-'Quick HELOC Loan Calc'!$C$36 -> -7037.92
A30: Net Cash Flow | B30: =B24+B28+B29 -> -64027.504 | C30: =C24+C28+C29 -> -57861.456 | D30: =D24+D28+D29 -> -57919.908 | E30: =E24+E28+E29 -> -57212.363 | F30: =F24+F28+F29 -> -56988.166 | G30: =G24+G28+G29 -> -55996.721 | H30: =H24+H28+H29 -> -55987.409 | I30: =I24+I28+I29 -> -54959.586 | ... K30: =K24+K28+K29 -> -54095.723 | L30: =SUM(B30:K30) -> -569961.42 | M30: FV of all cash flows
A31: Monthly Cash Flow | B31: =B30/12 -> -5335.6253 | C31: =C30/12 -> -4821.788 | D31: =D30/12 -> -4826.659 | E31: =E30/12 -> -4767.6969 | F31: =F30/12 -> -4749.0138 | G31: =G30/12 -> -4666.3934 | H31: =H30/12 -> -4665.6174 | I31: =I30/12 -> -4579.9655 | ... K31: =K30/12 -> -4507.9769
A32: ="Discounted Cash Flow (DCF) @"&M2&"% return" -> Discounted Cash Flow (DCF) @0.08% return | B32: =B30/(1+$M$2)^B1 -> -59284.726 | C32: =C30/(1+$M$2)^C1 -> -49606.872 | D32: =D30/(1+$M$2)^D1 -> -45978.69 | E32: =E30/(1+$M$2)^E1 -> -42052.794 | F32: =F30/(1+$M$2)^F1 -> -38785.188 | G32: =G30/(1+$M$2)^G1 -> -35287.433 | H32: =H30/(1+$M$2)^H1 -> -32668.115 | I32: =I30/(1+$M$2)^I1 -> -29692.954 | ... K32: =K30/(1+$M$2)^K1 -> -25056.787 | L32: =SUM(B32:K32) -> -385883.52 | M32: PV of all cash flows
A33: Cash on Cash ROI | B33: =B30/(SUM('Quick HELOC Loan Calc'!$B$7,'Quick HELOC Loan Calc'!$B$6)) -> -0.45733931 | C33: =C30/(SUM('Quick HELOC Loan Calc'!$B$7,'Quick HELOC Loan Calc'!$B$6)) -> -0.41329611 | D33: =D30/(SUM('Quick HELOC Loan Calc'!$B$7,'Quick HELOC Loan Calc'!$B$6)) -> -0.41371363 | E33: =E30/(SUM('Quick HELOC Loan Calc'!$B$7,'Quick HELOC Loan Calc'!$B$6)) -> -0.40865973 | F33: =F30/(SUM('Quick HELOC Loan Calc'!$B$7,'Quick HELOC Loan Calc'!$B$6)) -> -0.40705833 | G33: =G30/(SUM('Quick HELOC Loan Calc'!$B$7,'Quick HELOC Loan Calc'!$B$6)) -> -0.39997658 | H33: =H30/(SUM('Quick HELOC Loan Calc'!$B$7,'Quick HELOC Loan Calc'!$B$6)) -> -0.39991006 | I33: =I30/(SUM('Quick HELOC Loan Calc'!$B$7,'Quick HELOC Loan Calc'!$B$6)) -> -0.39256847 | ... K33: =K30/(SUM('Quick HELOC Loan Calc'!$B$7,'Quick HELOC Loan Calc'!$B$6)) -> -0.38639802
A35: Property Appreciation | B35: 0.04 | C35: =$B$35 -> 0.04 | D35: =$B$35 -> 0.04 | E35: =$B$35 -> 0.04 | F35: =$B$35 -> 0.04 | G35: =$B$35 -> 0.04 | H35: =$B$35 -> 0.04 | I35: =$B$35 -> 0.04 | J35: =$B$35 -> 0.04 | K35: =$B$35 -> 0.04
A36: Property Value | B36: ='Quick HELOC Loan Calc'!$B$5*(1+'10 Year'!B35) -> 1040000 | C36: =B36+B37 -> 1080000 | D36: =C36+C37 -> 1121600 | E36: =D36+D37 -> 1164800 | F36: =E36+E37 -> 1209664 | G36: =F36+F37 -> 1256256 | H36: =G36+G37 -> 1304642.6 | I36: =H36+H37 -> 1354892.8 | J36: =I36+I37 -> 1407078.5 | K36: =J36+J37 -> 1461274.2
A37: Property Appreciation | B37: ='Quick HELOC Loan Calc'!$B$5*B35 -> 40000 | C37: =B36*C35 -> 41600 | D37: =C36*D35 -> 43200 | E37: =D36*E35 -> 44864 | F37: =E36*F35 -> 46592 | G37: =F36*G35 -> 48386.56 | H37: =G36*H35 -> 50250.24 | I37: =H36*I35 -> 52185.702 | J37: =I36*J35 -> 54195.712 | K37: =J36*K35 -> 56283.14
A38: Mortgage Principle Reduction | B38: =-CUMPRINC('Quick HELOC Loan Calc'!$H$7/12,'Quick HELOC Loan Calc'!$H$8*12,'Quick HELOC Loan Calc'!$B$8,1,12,0) -> 9823.3065 | C38: =-CUMPRINC('Quick HELOC Loan Calc'!$H$7/12,'Quick HELOC Loan Calc'!$H$8*12,'Quick HELOC Loan Calc'!$B$8,13,24,0) -> 10494.23 | D38: =-CUMPRINC('Quick HELOC Loan Calc'!$H$7/12,'Quick HELOC Loan Calc'!$H$8*12,'Quick HELOC Loan Calc'!$B$8,25,36,0) -> 11210.977 | E38: =-CUMPRINC('Quick HELOC Loan Calc'!$H$7/12,'Quick HELOC Loan Calc'!$H$8*12,'Quick HELOC Loan Calc'!$B$8,37,48,0) -> 11976.677 | F38: =-CUMPRINC('Quick HELOC Loan Calc'!$H$7/12,'Quick HELOC Loan Calc'!$H$8*12,'Quick HELOC Loan Calc'!$B$8,49,60,0) -> 12794.673 | G38: =-CUMPRINC('Quick HELOC Loan Calc'!$H$7/12,'Quick HELOC Loan Calc'!$H$8*12,'Quick HELOC Loan Calc'!$B$8,61,72,0) -> 13668.539 | H38: =-CUMPRINC('Quick HELOC Loan Calc'!$H$7/12,'Quick HELOC Loan Calc'!$H$8*12,'Quick HELOC Loan Calc'!$B$8,73,84,0) -> 14602.088 | I38: =-CUMPRINC('Quick HELOC Loan Calc'!$H$7/12,'Quick HELOC Loan Calc'!$H$8*12,'Quick HELOC Loan Calc'!$B$8,85,96,0) -> 15599.398 | J38: =-CUMPRINC('Quick HELOC Loan Calc'!$H$7/12,'Quick HELOC Loan Calc'!$H$8*12,'Quick HELOC Loan Calc'!$B$8,97,108,0) -> 16664.823 | K38: =-CUMPRINC('Quick HELOC Loan Calc'!$H$7/12,'Quick HELOC Loan Calc'!$H$8*12,'Quick HELOC Loan Calc'!$B$8,109,120,0) -> 17803.017
A39: Net Tax Savings (33% Bracket) | B39: =B30*0.25 -> -16006.876 | C39: =C30*0.25 -> -14465.364 | D39: =D30*0.25 -> -14479.977 | E39: =E30*0.25 -> -14303.091 | F39: =F30*0.25 -> -14247.041 | G39: =G30*0.25 -> -13999.18 | H39: =H30*0.25 -> -13996.852 | I39: =I30*0.25 -> -13739.896 | ... K39: =K30*0.25 -> -13523.931
A40: Tax ROI | B40: =B39/SUM('Quick HELOC Loan Calc'!$B$6:$B$7) -> -0.11433483 | C40: =C39/SUM('Quick HELOC Loan Calc'!$B$6:$B$7) -> -0.10332403 | D40: =D39/SUM('Quick HELOC Loan Calc'!$B$6:$B$7) -> -0.10342841 | E40: =E39/SUM('Quick HELOC Loan Calc'!$B$6:$B$7) -> -0.10216493 | F40: =F39/SUM('Quick HELOC Loan Calc'!$B$6:$B$7) -> -0.10176458 | G40: =G39/SUM('Quick HELOC Loan Calc'!$B$6:$B$7) -> -0.099994145 | H40: =H39/SUM('Quick HELOC Loan Calc'!$B$6:$B$7) -> -0.099977516 | I40: =I39/SUM('Quick HELOC Loan Calc'!$B$6:$B$7) -> -0.098142118 | ... K40: =K39/SUM('Quick HELOC Loan Calc'!$B$6:$B$7) -> -0.096599505
A41: Total Return (Not counting appreciation) | B41: =SUM(B30,B38,B39) -> -70211.073 | C41: =SUM(C30,C38,C39) -> -61832.59 | D41: =SUM(D30,D38,D39) -> -61188.908 | E41: =SUM(E30,E38,E39) -> -59538.777 | F41: =SUM(F30,F38,F39) -> -58440.534 | G41: =SUM(G30,G38,G39) -> -56327.363 | H41: =SUM(H30,H38,H39) -> -55382.173 | I41: =SUM(I30,I38,I39) -> -53100.084 | ... K41: =SUM(K30,K38,K39) -> -49816.637
A42: Total ROI | B42: =B41/SUM('Quick HELOC Loan Calc'!$B$6:$B$7) -> -0.50150767 | C42: =C41/SUM('Quick HELOC Loan Calc'!$B$6:$B$7) -> -0.44166136 | D42: =D41/SUM('Quick HELOC Loan Calc'!$B$6:$B$7) -> -0.43706363 | E42: =E41/SUM('Quick HELOC Loan Calc'!$B$6:$B$7) -> -0.42527698 | F42: =F41/SUM('Quick HELOC Loan Calc'!$B$6:$B$7) -> -0.41743238 | G42: =G41/SUM('Quick HELOC Loan Calc'!$B$6:$B$7) -> -0.40233831 | H42: =H41/SUM('Quick HELOC Loan Calc'!$B$6:$B$7) -> -0.39558695 | I42: =I41/SUM('Quick HELOC Loan Calc'!$B$6:$B$7) -> -0.37928632 | ... K42: =K41/SUM('Quick HELOC Loan Calc'!$B$6:$B$7) -> -0.35583312 | L42: =SUM(B42:K42)/K1 -> -0.41272432 | M42: AAR
L43: =('10 Year'!K36/'Quick HELOC Loan Calc'!B5)^(1/'10 Year'!K1)-1 -> 0.038659439 | M43: CAGR
A45: Total Property Equity (not counting appreciation) | B45: =SUM('Quick HELOC Loan Calc'!$B$7,'10 Year'!B38) -> 109823.31 | C45: =B45+C38 -> 120317.54 | D45: =C45+D38 -> 131528.51 | E45: =D45+E38 -> 143505.19 | F45: =E45+F38 -> 156299.86 | G45: =F45+G38 -> 169968.4 | H45: =G45+H38 -> 184570.49 | I45: =H45+I38 -> 200169.89 | J45: =I45+J38 -> 216834.71 | K45: =J45+K38 -> 234637.73
...

Sheet Calculators
A3: Year | C3: Annual ROI | G3: Year | I3: Annual ROI | S3: IRR | T3: =XIRR(T4:T10,R4:R10) -> 0.21632629
A4: 0 | B4: 100000 | G4: 0 | H4: 100000 | M4: Present Value=Future Value /( 1+i)^n | R4: 45292 | S4: Initial Investment | T4: -8500000
A5: =A4+1 -> 1 | B5: 110000 | C5: =(B5/B4)-1 -> 0.1 | G5: =G4+1 -> 1 | H5: 110000 | I5: =(H5/H4)-1 -> 0.1 | M5: interest | N5: 0.08 | R5: =R4+365 -> 45657 | S5: Year 1 Cashflow | T5: =-$T$4*$U$5 -> 1360000 | U5: 0.16 | V5: Cash On Cash
A6: =A5+1 -> 2 | B6: 105000 | C6: =(B6/B5)-1 -> -0.045454545 | G6: =G5+1 -> 2 | H6: 105000 | I6: =(H6/H5)-1 -> -0.045454545 | M6: time (yrs) | N6: 5 | O6: =N6*12 -> 60 | R6: =R5+365 -> 46022 | S6: Year 2 Cashflow | T6: =-$T$4*$U$5 -> 1360000
A7: =A6+1 -> 3 | B7: 120000 | C7: =(B7/B6)-1 -> 0.14285714 | G7: =G6+1 -> 3 | H7: 120000 | I7: =(H7/H6)-1 -> 0.14285714 | R7: =R6+365 -> 46387 | S7: Year 3 Cashflow | T7: =-$T$4*$U$5 -> 1360000
A8: =A7+1 -> 4 | B8: =B7+5000 -> 125000 | C8: =(B8/B7)-1 -> 0.041666667 | G8: =G7+1 -> 4 | H8: =H7+5000 -> 125000 | I8: =(H8/H7)-1 -> 0.041666667 | R8: =R7+365 -> 46752 | S8: Year 4 Cashflow | T8: =-$T$4*$U$5 -> 1360000
A9: =A8+1 -> 5 | B9: =B8+5000 -> 130000 | C9: =(B9/B8)-1 -> 0.04 | G9: =G8+1 -> 5 | H9: =H8+5000 -> 130000 | I9: =(H9/H8)-1 -> 0.04 | R9: =R8+365 -> 47117 | S9: Year 5 Cashflow | T9: =-$T$4*$U$5 -> 1360000
A10: =A9+1 -> 6 | B10: =B9+5000 -> 135000 | C10: =(B10/B9)-1 -> 0.038461538 | R10: =R9+365 -> 47482 | S10: 6 | T10: =-T4*(1+U10)^S10 -> 14813534 | U10: 0.097 | V10: Assumed Appreciation
A11: =A10+1 -> 7 | B11: =B10+5000 -> 140000 | C11: =(B11/B10)-1 -> 0.037037037 | I11: =(H9-H4)/H4 -> 0.3 | J11: ROI
A12: =A11+1 -> 8 | B12: =B11+5000 -> 145000 | C12: =(B12/B11)-1 -> 0.035714286 | I12: =SUM(I5:I9)/COUNT(I5:I9) -> 0.055813853 | J12: AAR
A13: =A12+1 -> 9 | B13: =B12+5000 -> 150000 | C13: =(B13/B12)-1 -> 0.034482759 | I13: =(H9/H4)^(1/COUNT(I4:I9))-1 -> 0.053873952 | J13: CAGR | M13: 0.105 | N13: projected Cash On Cash Return
A14: =A13+1 -> 10 | B14: =B13+5000 -> 155000 | C14: =(B14/B13)-1 -> 0.033333333 | I14: =H9/H4 -> 1.3 | J14: Equity Multiplier | M14: 8500000 | N14: initial investment
M15: =O15*12 -> 60 | N15: hold period | O15: 5
C16: =(B14-B4)/B4 -> 0.55 | D16: ROI
C17: =SUM(C5:C14)/COUNT(C5:C14) -> 0.045809822 | D17: AAR | M17: Future | N17: =M14*(1+M13/12)^(M15) -> 14336125 | O17: =N17/M14 -> 1.686603 | P17: Equity Multiple
C18: =(B14/B4)^(1/COUNT(C4:C14))-1 -> 0.044800014 | D18: CAGR | M18: CAGR | N18: =(N17/M14)^(1/(M15))-1 -> 0.00875
C19: =B14/B4 -> 1.55 | D19: Equity Multiplier

Sheet STR Calculator
H1: Heloc Down Payment | I1: 0.0825
H2: Heloc Loan Terms | I2: 20 | J2: yrs
A3: =B5 -> 852000 | B3: asking price | H3: HELOC Amount | I3: =SUM(B7+B6-C5-C4) -> 64280
C4: 5000 | D4: earnest money | H4: HELOC P&I Payment | I4: =-PMT($I$1/12,$I$2*12,I3) -> 547.7078 | J4: =I4*12 -> 6572.4936 | L4: IRR | M4: =IRR(M5:M11) -> -0.022363608
A5: Purchase Price | B5: 852000 | C5: 50000 | D5: cash | H5: HELOC Principle Payment | I5: =-PPMT($I$1/12,1,$I$2*12,I3) -> 105.7828 | J5: =I5*12 -> 1269.3936 | L5: Initial Investment | M5: =-B5 -> -852000
A6: Closing Costs (4%) | B6: =B5*0.04 -> 34080 | H6: HELOC Interest Only Payment | I6: =-IPMT($I$1/12,1,$I$2*12,I3) -> 441.925 | J6: =I6*12 -> 5303.1 | L6: Year 1 Cashflow | M6: ='STR 10 Year'!B32 -> 1974.819
A7: Down Payment | B7: =B5*C7 -> 85200 | C7: 0.1 | D7: downpayment | L7: Year 2 Cashflow | M7: ='10 Year'!C30 -> -57861.456
A8: Total Loan Amount | B8: =B5-B7 -> 766800 | H8: Conventional Loan Interest Rate | I8: 0.08 | L8: Year 3 Cashflow | M8: ='10 Year'!D30 -> -57919.908
H9: Loan Term | I9: 30 | J9: yrs | L9: Year 4 Cashflow | M9: ='10 Year'!E30 -> -57212.363
H10: Monthly Payment on Purchase Price | I10: =-PMT($I$8/12,$I$9*12,$B$8) -> 5626.5068 | L10: Year 5 Cashflow | M10: ='10 Year'!F30 -> -56988.166
A11: All In Price (Purchase+Repairs) | B11: =SUM(B5) -> 852000 | H11: Monthly Interest Payment on Purchase Price | I11: =-IPMT($I$8/12,1,$I$9*12,$B$8) -> 5112 | L11: 6 | M11: =B5*(1+0.02)^L11 -> 959490.38 | N11: assumes 2%/yr appreciation
A12: Estimated ARV (After Repair Value) | B12: =B5 -> 852000 | H12: Monthly Principle Payment on Purchase Price | I12: =-PPMT($I$8/12,1,$I$9*12,$B$8) -> 514.50675 | J12: =I12*12 -> 6174.081
B14: Nightly | C14: Monthly | D14: Annually | H14: Financials
A15: Average Rent | B15: 400 | C15: =B15*30.5 -> 12200 | D15: =C15*12 -> 146400 | H15: Cash On Cash Return (CoC) | I15: =C45/SUM(B6:B7) -> -0.029832168
A16: Occupancy Rate | B16: 0.85 | C16: =-C15*(1-B16) -> -1830 | D16: =C16*12 -> -21960 | H16: ROI (Return on Investment) | I16: =(SUM($B$6:$B$7)/B5) -> 0.14
A17: Additional Income (Laundry/Storage etc) | C17: 0 | D17: =C17*12 -> 0 | H17: ROE (Return on Equity) | I17: =C45/B7 -> -0.041765036
A18: Calculated Gross Revenue | C18: =SUM(C15:C17) -> 10370 | D18: =C18*12 -> 124440 | H18: Mortgage Pay Down yr 1 | I18: =PPMT(I8/12,1,I9*12,B8)*12 -> -6174.081
H19: Tax Savings at 33% | I19: =C45*0.33 -> -1174.2657
A21: Estimated Expenses | B21: Nightly/per stay | C21: Monthly | D21: Annually | H21: Rules of Thumb
A22: Management Fees | C22: =C15*E22 -> 0 | D22: =C22*12 -> 0 | E22: 0 | F22: =IF(E22=0,1,0) -> 1 | H22: 50% Rule
A23: Subscriptions (AirDnA/Pricelabs/Guesty/Hospitable) | C23: =20+40+40+40 -> 140 | D23: =C23*12 -> 1680 | H23: 2% Rule | I23: =$C$15/$B$5 -> 0.014319249
A24: AirBnB / VRBO Fee (3% of nightly) | C24: =C18*0.03 -> 311.1 | D24: =C24*12 -> 3733.2 | H24: DSCR | I24: =B41/(B43+B42) -> 1.0005715
A25: Property Taxes / Year | C25: 200 | D25: =C25*12 -> 2400 | E25: =D25/B5 -> 0.0028169014
A26: Insurance / Year | C26: 320 | D26: =C26*12 -> 3840 | E26: =D26/B5 -> 0.0045070423
A27: Cleaners (per stay, average 6/month) | B27: =E27*6/30.5 -> 29.508197 | C27: =B27*30.5 -> 900 | D27: =C27*12 -> 10800 | E27: 150 | K27: months
A28: Handyman | C28: 250 | D28: =C28*12 -> 3000 | H28: Emergency Fund Needed (6 months) | I28: =C39*$J$28+SUM(B42:B43)*$J$28 -> 62199.191 | J28: 6 | K28: months
A29: HOA / year | C29: 40 | D29: =C29*12 -> 480 | E29: =D29/B5 -> 0.00056338028 | I29: =I28/2 -> 31099.595 | J29: =J28/2 -> 3
A30: Electricity | C30: 1000 | D30: =C30*12 -> 12000
A31: Nat Gas | C31: 500 | D31: =C31*12 -> 6000
A32: WIFI / Cable | C32: 150 | D32: =C32*12 -> 1800
A33: Water/Sewer | C33: 350 | D33: =C33*12 -> 4200
A34: Building Maintenance (future Repairs) | C34: 100 | D34: =C34*12 -> 1200 | E34: =D34/D15 -> 0.0081967213
A35: Grounds Cleanup/Services Maintenance/Snow Removal | D35: =C35*12 -> 0
A36: City Permit Fees | C36: 0 | D36: =C36*12 -> 0
A37: Incidentals (Soap/Toilet Paper/Coffee/Creamer etc)
A38: Umbrella Insurance (Allstate Anchorage) | C38: 37 | D38: =C38*12 -> 444
A39: Totals | C39: =SUM(C22:C38) -> 4298.1 | D39: =SUM(D22:D38) -> 51577.2
A41: Net Operating Income | B41: =C18-C39 -> 6071.9 | C41: =D18-D39 -> 72862.8 | D41: DSCR | E41: =B41/(B43+B42) -> 1.0005715
A42: HELOC Payment (Interest Only) | B42: =I6 -> 441.925 | C42: =B42*12 -> 5303.1 | D42: =IF(B42=I6,1,0) -> 1
A43: Conventional Loan Payment | B43: =-PMT($I$8/12,$I$9*12,$B$8) -> 5626.5068 | C43: =B43*12 -> 67518.081 | D43: Cap Rate | E43: =C41/B5 -> 0.085519718
...

Sheet Interest Rate Comparison
A1: Purchase Price | C1: 0.1 | D1: 0.15 | E1: 0.2 | F1: 0.25 | H1: 5% Increase in Down Payment | I1: Time to recoup
A2: ='STR Calculator'!B5 -> 852000 | B2: Down Payment | C2: =$A$2*C1 -> 85200 | D2: =$A$2*D1 -> 127800 | E2: =$A$2*E1 -> 170400 | F2: =$A$2*F1 -> 213000 | H2: =D2-C2 -> 42600
A3: 30 | B3: 0.0825 | C3: =PMT($B$3/12,$A$3*12,($A$2-C2)) -> -5760.7123 | D3: =PMT($B$3/12,$A$3*12,($A$2-D2)) -> -5440.6727 | E3: =PMT($B$3/12,$A$3*12,($A$2-E2)) -> -5120.6332 | F3: =PMT($B$3/12,$A$3*12,($A$2-F2)) -> -4800.5936 | G3: =B3 -> 0.0825 | H3: =D3-C3 -> 320.03957 | I3: =$H$2/H3/12 -> 11.092378
B4: 0.08 | C4: =PMT($B$4/12,$A$3*12,($A$2-C2)) -> -5626.5068 | D4: =PMT($B$4/12,$A$3*12,($A$2-D2)) -> -5313.923 | E4: =PMT($B$4/12,$A$3*12,($A$2-E2)) -> -5001.3393 | F4: =PMT($B$4/12,$A$3*12,($A$2-F2)) -> -4688.7556 | G4: =B4 -> 0.08 | H4: =D4-C4 -> 312.58371 | I4: =$H$2/H4/12 -> 11.356958
B5: 0.0775 | C5: =PMT($B$5/12,$A$3*12,($A$2-C2)) -> -5493.4491 | D5: =PMT($B$5/12,$A$3*12,($A$2-D2)) -> -5188.2575 | E5: =PMT($B$5/12,$A$3*12,($A$2-E2)) -> -4883.0659 | F5: =PMT($B$5/12,$A$3*12,($A$2-F2)) -> -4577.8742 | G5: =B5 -> 0.0775 | H5: =D5-C5 -> 305.19162 | I5: =$H$2/H5/12 -> 11.632036
B6: 0.075 | C6: =PMT($B$6/12,$A$3*12,($A$2-C2)) -> -5361.5769 | D6: =PMT($B$6/12,$A$3*12,($A$2-D2)) -> -5063.7115 | E6: =PMT($B$6/12,$A$3*12,($A$2-E2)) -> -4765.8461 | F6: =PMT($B$6/12,$A$3*12,($A$2-F2)) -> -4467.9807 | G6: =B6 -> 0.075 | H6: =D6-C6 -> 297.86538 | I6: =$H$2/H6/12 -> 11.918136
B7: 0.0725 | C7: =PMT($B$7/12,$A$3*12,($A$2-C2)) -> -5230.9277 | D7: =PMT($B$7/12,$A$3*12,($A$2-D2)) -> -4940.3206 | E7: =PMT($B$7/12,$A$3*12,($A$2-E2)) -> -4649.7135 | F7: =PMT($B$7/12,$A$3*12,($A$2-F2)) -> -4359.1064 | G7: =B7 -> 0.0725 | H7: =D7-C7 -> 290.6071 | I7: =$H$2/H7/12 -> 12.215806
B8: 0.07 | C8: =PMT($B$8/12,$A$3*12,($A$2-C2)) -> -5101.5395 | D8: =PMT($B$8/12,$A$3*12,($A$2-D2)) -> -4818.1207 | E8: =PMT($B$8/12,$A$3*12,($A$2-E2)) -> -4534.7018 | F8: =PMT($B$8/12,$A$3*12,($A$2-F2)) -> -4251.2829 | G8: =B8 -> 0.07 | H8: =D8-C8 -> 283.41886 | I8: =$H$2/H8/12 -> 12.525631
G9: Higher delta between P&I payment at higher interest rate compared to lower = shorter payout, when factoring in increased down payment for lower rate
A12: Down Payment % | B12: Down Payment | C12: Interest Rate | D12: ="Interest Paid on Down Payment by Year "&ROUND(I4,0) -> Interest Paid on Down Payment by Year 11 | E12: Down Payment Difference | F12: ="Interest Saved by Larger DownPayment @ year "&ROUND(I4,0) -> Interest Saved by Larger DownPayment @ year 11 | G12: Down Payment vs Interest Saved | H12: =ROUND(I4,0)&"yr FV of down payment saved @ 8%" -> 11yr FV of down payment saved @ 8% | I12: PV of Interest Saved/Lost | J12: ="Cum Interest Paid Year "&ROUND(I4,0) -> Cum Interest Paid Year 11 | K12: Interest Saved Compared to 10% Loan | L12: Total Interest Paid - Life of Loan
A13: =C1 -> 0.1 | B13: =$A$2*A13 -> 85200 | C13: =B4 -> 0.08 | D13: 71056 | E13: 0 | F13: 0 | G13: =F13-E13 -> 0 | H13: 0 | I13: 0 | J13: 639505 | K13: 0 | L13: 1270301
A14: =D1 -> 0.15 | B14: =$A$2*A14 -> 127800 | C14: =B4 -> 0.08 | D14: 106584 | E14: =B14-B13 -> 42600 | F14: =D14-D13 -> 35528 | G14: =F14-E14 -> -7072 | H14: =E14*(1+0.08)^I4 -> 102094.37 | I14: =G14/(1+C14)^I4 -> -2950.87 | J14: 603997 | K14: =J13-J14 -> 35508 | L14: 1199728 | M14: =L14+H14 -> 1301822.4
A15: =E1 -> 0.2 | B15: =$A$2*A15 -> 170400 | C15: =B5 -> 0.0775 | D15: 131454 | E15: =B15-B13 -> 85200 | F15: =D15-D13 -> 60398 | G15: =F15-E15 -> -24802 | H15: =E15*(1+0.08)^I4 -> 204188.73 | I15: =G15/(1+C15)^I4 -> -10624.904 | J15: 525816 | K15: =J13-J15 -> 113689 | L15: 1034105 | M15: =L15+H15 -> 1238293.7
K17: Present Value=Future Value /( 1+i)^n

Sheet Amoritization Scenario 10
A1: If deciding between different Down Payment % and Interest Rates, compare Cumulative Interest Payment over duration to recoup additional Down Payment Lump Sum, to see which is better. NPV / PV/FV money calculation
C3: sqft | J3: Interest | K3: ='Interest Rate Comparison'!B3 -> 0.0825 | N3: =K3/12 -> 0.006875 | O3: r | W3: Interest | X3: ='Interest Rate Comparison'!B4 -> 0.08 | AA3: =X3/12 -> 0.0066666667 | AB3: r | AJ3: Interest | AK3: ='Interest Rate Comparison'!B5 -> 0.0775 | AN3: =AK3/12 -> 0.0064583333 | AO3: r | AW3: Interest | AX3: ='Interest Rate Comparison'!B6 -> 0.075 | BA3: =AX3/12 -> 0.00625 | BB3: r | BJ3: Interest | BK3: ='Interest Rate Comparison'!B7 -> 0.0725 | BN3: =BK3/12 -> 0.0060416667 | BO3: r | BW3: Interest | BX3: ='Interest Rate Comparison'!B8 -> 0.07 | CA3: =BX3/12 -> 0.0058333333 | CB3: r
C4: $/sqft Market Estimate | J4: Term | K4: =$L$4*12 -> 360 | L4: ='STR Calculator'!I9 -> 30 | M4: years | N4: =(1+N3)^K4 -> 11.781506 | O4: (1+r)^n | W4: Term | X4: =$L$4*12 -> 360 | Y4: 30 | Z4: years | AA4: =(1+AA3)^X4 -> 10.93573 | AB4: (1+r)^n | AJ4: Term | AK4: =$L$4*12 -> 360 | AL4: 30 | AM4: years | AN4: =(1+AN3)^AK4 -> 10.150514 | AO4: (1+r)^n | AW4: Term | AX4: =$L$4*12 -> 360 | AY4: 30 | AZ4: years | BA4: =(1+BA3)^AX4 -> 9.4215339 | BB4: (1+r)^n | BJ4: Term | BK4: =$L$4*12 -> 360 | BL4: 30 | BM4: years | BN4: =(1+BN3)^BK4 -> 8.744772 | BO4: (1+r)^n | BW4: Term | BX4: =$L$4*12 -> 360 | BY4: 30 | BZ4: years | CA4: =(1+CA3)^BX4 -> 8.1164975 | CB4: (1+r)^n
A5: Original Purchase Price | B5: ='STR Calculator'!B5 -> 852000 | C5: =B5/B3 -> #DIV/0! | D5: sqft | J5: Monthly Payment | W5: Monthly Payment | AJ5: Monthly Payment | AW5: Monthly Payment | BJ5: Monthly Payment | BW5: Monthly Payment
A6: Down Payment | B6: 0.1
A7: Current Loan Balance | B7: =B5-(B5*B6) -> 766800 | C7: as of 11/13/22 | J7: paymentNumber | K7: paymentDate | L7: startingBalance | M7: Monthly Payment | N7: principalPayment | O7: Principle Pay Down | P7: interestPayment | Q7: Interest Percent | R7: cumulativePrincipal | S7: cumulativeInterest | T7: endingBalance | U7: Total Paid End of Loan | W7: paymentNumber | X7: paymentDate | Y7: startingBalance | Z7: Monthly Payment | AA7: principalPayment | AB7: Principle Pay Down | AC7: interestPayment | AD7: Interest Percent | AE7: cumulativePrincipal | AF7: cumulativeInterest | AG7: endingBalance | AH7: Total Paid End of Loan | AJ7: paymentNumber | AK7: paymentDate | AL7: startingBalance | AM7: Monthly Payment | AN7: principalPayment | AO7: Principle Pay Down | AP7: interestPayment | AQ7: Interest Percent | AR7: cumulativePrincipal | AS7: cumulativeInterest | AT7: endingBalance | AU7: Total Paid End of Loan | AW7: paymentNumber | AX7: paymentDate | AY7: startingBalance | AZ7: Monthly Payment | BA7: principalPayment | BB7: Principle Pay Down | BC7: interestPayment | BD7: Interest Percent | BE7: cumulativePrincipal | BF7: cumulativeInterest | BG7: endingBalance | BH7: Total Paid End of Loan | BJ7: paymentNumber | BK7: paymentDate | BL7: startingBalance | BM7: Monthly Payment | BN7: principalPayment | BO7: Principle Pay Down | BP7: interestPayment | BQ7: Interest Percent | BR7: cumulativePrincipal | BS7: cumulativeInterest | BT7: endingBalance | BU7: Total Paid End of Loan | BW7: paymentNumber | BX7: paymentDate | BY7: startingBalance | BZ7: Monthly Payment | CA7: principalPayment | CB7: Principle Pay Down | CC7: interestPayment | CD7: Interest Percent | CE7: cumulativePrincipal | CF7: cumulativeInterest | CG7: endingBalance | CH7: Total Paid End of Loan
A8: Current Equity | B8: =B5-B7 -> 85200 | J8: 1 | K8: 44866 | L8: ='Amoritization Scenario 10'!$B$7 -> 766800 | M8: =$L$8/((($N$4)-1)/($N$3*$N$4)) -> 5760.7123 | N8: =M8-P8 -> 488.96232 | O8: =(N8/L8)*12 -> 0.0076519925 | P8: =L8*($K$3/12) -> 5271.75 | Q8: =(P8/L8)*12 -> 0.0825 | R8: =N8 -> 488.96232 | S8: =P8 -> 5271.75 | T8: =L8-N8 -> 766311.04 | U8: =R8+S8 -> 5760.7123 | W8: 1 | X8: 44866 | Y8: ='Amoritization Scenario 10'!$B$7 -> 766800 | Z8: =$Y$8/((($AA$4)-1)/($AA$3*$AA$4)) -> 5626.5068 | AA8: =Z8-AC8 -> 514.50675 | AB8: =(AA8/Y8)*12 -> 0.0080517489 | AC8: =Y8*($X$3/12) -> 5112 | AD8: =(AC8/Y8)*12 -> 0.08 | AE8: =AA8 -> 514.50675 | AF8: =AC8 -> 5112 | AG8: =Y8-AA8 -> 766285.49 | AH8: =AE8+AF8 -> 5626.5068 | AJ8: 1 | AK8: 44866 | AL8: ='Amoritization Scenario 10'!$B$7 -> 766800 | AM8: =$AL$8/((($AN$4)-1)/($AN$3*$AN$4)) -> 5493.4491 | AN8: =AM8-AP8 -> 541.1991 | AO8: =(AN8/AL8)*12 -> 0.0084694695 | AP8: =AL8*($AK$3/12) -> 4952.25 | AQ8: =(AP8/AL8)*12 -> 0.0775 | AR8: =AN8 -> 541.1991 | AS8: =AP8 -> 4952.25 | AT8: =AL8-AN8 -> 766258.8 | AU8: =AR8+AS8 -> 5493.4491 | AW8: 1 | AX8: 44866 | AY8: ='Amoritization Scenario 10'!$B$7 -> 766800 | AZ8: =$AY$8/((($BA$4)-1)/($BA$3*$BA$4)) -> 5361.5769 | BA8: =AZ8-BC8 -> 569.07685 | BB8: =(BA8/AY8)*12 -> 0.008905741 | BC8: =AY8*($AX$3/12) -> 4792.5 | BD8: =(BC8/AY8)*12 -> 0.075 | BE8: =BA8 -> 569.07685 | BF8: =BC8 -> 4792.5 | BG8: =AY8-BA8 -> 766230.92 | BH8: =BE8+BF8 -> 5361.5769 | BJ8: 1 | BK8: 44866 | BL8: ='Amoritization Scenario 10'!$B$7 -> 766800 | BM8: =$BL$8/((($BN$4)-1)/($BN$3*$BN$4)) -> 5230.9277 | BN8: =BM8-BP8 -> 598.17772 | BO8: =(BN8/BL8)*12 -> 0.0093611536 | BP8: =BL8*($BK$3/12) -> 4632.75 | BQ8: =(BP8/BL8)*12 -> 0.0725 | BR8: =BN8 -> 598.17772 | BS8: =BP8 -> 4632.75 | BT8: =BL8-BN8 -> 766201.82 | BU8: =BR8+BS8 -> 5230.9277 | BW8: 1 | BX8: 44866 | BY8: ='Amoritization Scenario 10'!$B$7 -> 766800 | BZ8: =$BY$8/((($CA$4)-1)/($CA$3*$CA$4)) -> 5101.5395 | CA8: =BZ8-CC8 -> 628.53953 | CB8: =(CA8/BY8)*12 -> 0.0098362994 | CC8: =BY8*($BX$3/12) -> 4473 | CD8: =(CC8/BY8)*12 -> 0.07 | CE8: =CA8 -> 628.53953 | CF8: =CC8 -> 4473 | CG8: =BY8-CA8 -> 766171.46 | CH8: =CE8+CF8 -> 5101.5395
J9: 2 | K9: 44896 | L9: =T8 -> 766311.04 | M9: =$L$8/((($N$4)-1)/($N$3*$N$4)) -> 5760.7123 | N9: =M9-P9 -> 492.32394 | O9: =(N9/L9)*12 -> 0.007709516 | P9: =L9*($K$3/12) -> 5268.3884 | Q9: =(P9/L9)*12 -> 0.0825 | R9: =R8+N9 -> 981.28626 | S9: =S8+P9 -> 10540.138 | T9: =L9-N9 -> 765818.71 | U9: =R9+S9 -> 11521.425 | W9: 2 | X9: 44896 | Y9: =AG8 -> 766285.49 | Z9: =Z8 -> 5626.5068 | AA9: =Z9-AC9 -> 517.9368 | AB9: =(AA9/Y9)*12 -> 0.0081108694 | AC9: =Y9*($X$3/12) -> 5108.57 | AD9: =(AC9/Y9)*12 -> 0.08 | AE9: =AE8+AA9 -> 1032.4436 | AF9: =AF8+AC9 -> 10220.57 | AG9: =Y9-AA9 -> 765767.56 | AH9: =AE9+AF9 -> 11253.014 | AJ9: 2 | AK9: 44896 | AL9: =AT8 -> 766258.8 | AM9: =AM8 -> 5493.4491 | AN9: =AM9-AP9 -> 544.69434 | AO9: =(AN9/AL9)*12 -> 0.0085301886 | AP9: =AL9*($AK$3/12) -> 4948.7548 | AQ9: =(AP9/AL9)*12 -> 0.0775 | AR9: =AR8+AN9 -> 1085.8934 | AS9: =AS8+AP9 -> 9901.0048 | AT9: =AL9-AN9 -> 765714.11 | AU9: =AR9+AS9 -> 10986.898 | AW9: 2 | AX9: 44896 | AY9: =BG8 -> 766230.92 | AZ9: =AZ8 -> 5361.5769 | BA9: =AZ9-BC9 -> 572.63358 | BB9: =(BA9/AY9)*12 -> 0.0089680575 | BC9: =AY9*($AX$3/12) -> 4788.9433 | BD9: =(BC9/AY9)*12 -> 0.075 | BE9: =BE8+BA9 -> 1141.7104 | BF9: =BF8+BC9 -> 9581.4433 | BG9: =AY9-BA9 -> 765658.29 | BH9: =BE9+BF9 -> 10723.154 | BJ9: 2 | BK9: 44896 | BL9: =BT8 -> 766201.82 | BM9: =BM8 -> 5230.9277 | BN9: =BM9-BP9 -> 601.79171 | BO9: =(BN9/BL9)*12 -> 0.009425063 | BP9: =BL9*($BK$3/12) -> 4629.136 | BQ9: =(BP9/BL9)*12 -> 0.0725 | BR9: =BR8+BN9 -> 1199.9694 | BS9: =BS8+BP9 -> 9261.886 | BT9: =BL9-BN9 -> 765600.03 | BU9: =BR9+BS9 -> 10461.855 | BW9: 2 | BX9: 44896 | BY9: =CG8 -> 766171.46 | BZ9: =BZ8 -> 5101.5395 | CA9: =BZ9-CC9 -> 632.20601 | CB9: =(CA9/BY9)*12 -> 0.0099017943 | CC9: =BY9*($BX$3/12) -> 4469.3335 | CD9: =(CC9/BY9)*12 -> 0.07 | CE9: =CE8+CA9 -> 1260.7455 | CF9: =CF8+CC9 -> 8942.3335 | CG9: =BY9-CA9 -> 765539.25 | CH9: =CE9+CF9 -> 10203.079
A10: Year | B10: ="Cum Interest @ "&K3&"%" -> Cum Interest @ 0.0825% | C10: ="Cum Interest @ "&X3&"%" -> Cum Interest @ 0.08% | D10: ="Cum Interest @ "&AK3&"%" -> Cum Interest @ 0.0775% | E10: ="Cum Interest @ "&AX3&"%" -> Cum Interest @ 0.075% | F10: ="Cum Interest @ "&BK3&"%" -> Cum Interest @ 0.0725% | G10: ="Cum Interest @ "&BX3&"%" -> Cum Interest @ 0.07% | J10: 3 | K10: 44927 | L10: =T9 -> 765818.71 | M10: =$L$8/((($N$4)-1)/($N$3*$N$4)) -> 5760.7123 | N10: =M10-P10 -> 495.70866 | O10: =(N10/L10)*12 -> 0.0077675093 | P10: =L10*($K$3/12) -> 5265.0037 | Q10: =(P10/L10)*12 -> 0.0825 | R10: =R9+N10 -> 1476.9949 | S10: =S9+P10 -> 15805.142 | T10: =L10-N10 -> 765323.01 | U10: =R10+S10 -> 17282.137 | W10: 3 | X10: 44927 | Y10: =AG9 -> 765767.56 | Z10: =Z9 -> 5626.5068 | AA10: =Z10-AC10 -> 521.38971 | AB10: =(AA10/Y10)*12 -> 0.0081704643 | AC10: =Y10*($X$3/12) -> 5105.117 | AD10: =(AC10/Y10)*12 -> 0.08 | AE10: =AE9+AA10 -> 1553.8333 | AF10: =AF9+AC10 -> 15325.687 | AG10: =Y10-AA10 -> 765246.17 | AH10: =AE10+AF10 -> 16879.52 | AJ10: 3 | AK10: 44927 | AL10: =AT9 -> 765714.11 | AM10: =AM9 -> 5493.4491 | AN10: =AM10-AP10 -> 548.21216 | AO10: =(AN10/AL10)*12 -> 0.0085913866 | AP10: =AL10*($AK$3/12) -> 4945.2369 | AQ10: =(AP10/AL10)*12 -> 0.0775 | AR10: =AR9+AN10 -> 1634.1056 | AS10: =AS9+AP10 -> 14846.242 | AT10: =AL10-AN10 -> 765165.89 | AU10: =AR10+AS10 -> 16480.347 | AW10: 3 | AX10: 44927 | AY10: =BG9 -> 765658.29 | AZ10: =AZ9 -> 5361.5769 | BA10: =AZ10-BC10 -> 576.21254 | BB10: =(BA10/AY10)*12 -> 0.009030857 | BC10: =AY10*($AX$3/12) -> 4785.3643 | BD10: =(BC10/AY10)*12 -> 0.075 | BE10: =BE9+BA10 -> 1717.923 | BF10: =BF9+BC10 -> 14366.808 | BG10: =AY10-BA10 -> 765082.08 | BH10: =BE10+BF10 -> 16084.731 | BJ10: 3 | BK10: 44927 | BL10: =BT9 -> 765600.03 | BM10: =BM9 -> 5230.9277 | BN10: =BM10-BP10 -> 605.42753 | BO10: =(BN10/BL10)*12 -> 0.0094894594 | BP10: =BL10*($BK$3/12) -> 4625.5002 | BQ10: =(BP10/BL10)*12 -> 0.0725 | BR10: =BR9+BN10 -> 1805.397 | BS10: =BS9+BP10 -> 13887.386 | BT10: =BL10-BN10 -> 764994.6 | BU10: =BR10+BS10 -> 15692.783 | BW10: 3 | BX10: 44927 | BY10: =CG9 -> 765539.25 | BZ10: =BZ9 -> 5101.5395 | CA10: =BZ10-CC10 -> 635.89388 | CB10: =(CA10/BY10)*12 -> 0.0099677796 | CC10: =BY10*($BX$3/12) -> 4465.6457 | CD10: =(CC10/BY10)*12 -> 0.07 | CE10: =CE9+CA10 -> 1896.6394 | CF10: =CF9+CC10 -> 13407.979 | CG10: =BY10-CA10 -> 764903.36 | CH10: =CE10+CF10 -> 15304.619
A11: 1 | B11: =VLOOKUP($A$11*12,$J$7:$U$367,10) -> 63033.969 | C11: =VLOOKUP(A11*12,$W$7:$AH$367,10) -> 61112.51 | D11: =VLOOKUP(A11*12,$AJ$7:$AU$367,10) -> 59191.275 | E11: =VLOOKUP(A11*12,$AW$7:$BH$367,10) -> 57270.296 | F11: =VLOOKUP(A11*12,$BJ$7:$BU$367,10) -> 55349.607 | G11: =VLOOKUP(A11*12,$BW$7:$CH$367,10) -> 53429.245 | J11: 4 | K11: 44958 | L11: =T10 -> 765323.01 | M11: =$L$8/((($N$4)-1)/($N$3*$N$4)) -> 5760.7123 | N11: =M11-P11 -> 499.11666 | O11: =(N11/L11)*12 -> 0.0078259766 | P11: =L11*($K$3/12) -> 5261.5957 | Q11: =(P11/L11)*12 -> 0.0825 | R11: =R10+N11 -> 1976.1116 | S11: =S10+P11 -> 21066.738 | T11: =L11-N11 -> 764823.89 | U11: =R11+S11 -> 23042.849 | W11: 4 | X11: 44958 | Y11: =AG10 -> 765246.17 | Z11: =Z10 -> 5626.5068 | AA11: =Z11-AC11 -> 524.86564 | AB11: =(AA11/Y11)*12 -> 0.008230538 | AC11: =Y11*($X$3/12) -> 5101.6411 | AD11: =(AC11/Y11)*12 -> 0.08 | AE11: =AE10+AA11 -> 2078.6989 | AF11: =AF10+AC11 -> 20427.328 | AG11: =Y11-AA11 -> 764721.3 | AH11: =AE11+AF11 -> 22506.027 | AJ11: 4 | AK11: 44958 | AL11: =AT10 -> 765165.89 | AM11: =AM10 -> 5493.4491 | AN11: =AM11-AP11 -> 551.7527 | AO11: =(AN11/AL11)*12 -> 0.0086530678 | AP11: =AL11*($AK$3/12) -> 4941.6964 | AQ11: =(AP11/AL11)*12 -> 0.0775 | AR11: =AR10+AN11 -> 2185.8583 | AS11: =AS10+AP11 -> 19787.938 | AT11: =AL11-AN11 -> 764614.14 | AU11: =AR11+AS11 -> 21973.796 | AW11: 4 | AX11: 44958 | AY11: =BG10 -> 765082.08 | AZ11: =AZ10 -> 5361.5769 | BA11: =AZ11-BC11 -> 579.81387 | BB11: =(BA11/AY11)*12 -> 0.0090941438 | BC11: =AY11*($AX$3/12) -> 4781.763 | BD11: =(BC11/AY11)*12 -> 0.075 | BE11: =BE10+BA11 -> 2297.7368 | BF11: =BF10+BC11 -> 19148.571 | BG11: =AY11-BA11 -> 764502.26 | BH11: =BE11+BF11 -> 21446.307 | BJ11: 4 | BK11: 44958 | BL11: =BT10 -> 764994.6 | BM11: =BM10 -> 5230.9277 | BN11: =BM11-BP11 -> 609.08532 | BO11: =(BN11/BL11)*12 -> 0.009554347 | BP11: =BL11*($BK$3/12) -> 4621.8424 | BQ11: =(BP11/BL11)*12 -> 0.0725 | BR11: =BR10+BN11 -> 2414.4823 | BS11: =BS10+BP11 -> 18509.229 | BT11: =BL11-BN11 -> 764385.52 | BU11: =BR11+BS11 -> 20923.711 | BW11: 4 | BX11: 44958 | BY11: =CG10 -> 764903.36 | BZ11: =BZ10 -> 5101.5395 | CA11: =BZ11-CC11 -> 639.60326 | CB11: =(CA11/BY11)*12 -> 0.01003426 | CC11: =BY11*($BX$3/12) -> 4461.9363 | CD11: =(CC11/BY11)*12 -> 0.07 | CE11: =CE10+CA11 -> 2536.2427 | CF11: =CF10+CC11 -> 17869.915 | CG11: =BY11-CA11 -> 764263.76 | CH11: =CE11+CF11 -> 20406.158
A12: =A11+1 -> 2 | B12: =VLOOKUP(A12*12,$J$7:$U$367,10) -> 125545.68 | C12: =VLOOKUP(A12*12,$W$7:$AH$367,10) -> 121693.36 | D12: =VLOOKUP(A12*12,$AJ$7:$AU$367,10) -> 117842.03 | E12: =VLOOKUP(A12*12,$AW$7:$BH$367,10) -> 113991.84 | F12: =VLOOKUP(A12*12,$BJ$7:$BU$367,10) -> 110142.91 | G12: =VLOOKUP(A12*12,$BW$7:$CH$367,10) -> 106295.41 | J12: 5 | K12: 44986 | L12: =T11 -> 764823.89 | M12: =$L$8/((($N$4)-1)/($N$3*$N$4)) -> 5760.7123 | N12: =M12-P12 -> 502.54809 | O12: =(N12/L12)*12 -> 0.0078849224 | P12: =L12*($K$3/12) -> 5258.1642 | Q12: =(P12/L12)*12 -> 0.0825 | R12: =R11+N12 -> 2478.6597 | S12: =S11+P12 -> 26324.902 | T12: =L12-N12 -> 764321.34 | U12: =R12+S12 -> 28803.562 | W12: 5 | X12: 44986 | Y12: =AG11 -> 764721.3 | Z12: =Z11 -> 5626.5068 | AA12: =Z12-AC12 -> 528.36475 | AB12: =(AA12/Y12)*12 -> 0.008291095 | AC12: =Y12*($X$3/12) -> 5098.142 | AD12: =(AC12/Y12)*12 -> 0.08 | AE12: =AE11+AA12 -> 2607.0636 | AF12: =AF11+AC12 -> 25525.47 | AG12: =Y12-AA12 -> 764192.94 | AH12: =AE12+AF12 -> 28132.534 | AJ12: 5 | AK12: 44986 | AL12: =AT11 -> 764614.14 | AM12: =AM11 -> 5493.4491 | AN12: =AM12-AP12 -> 555.3161 | AO12: =(AN12/AL12)*12 -> 0.0087152367 | AP12: =AL12*($AK$3/12) -> 4938.133 | AQ12: =(AP12/AL12)*12 -> 0.0775 | AR12: =AR11+AN12 -> 2741.1744 | AS12: =AS11+AP12 -> 24726.071 | AT12: =AL12-AN12 -> 764058.83 | AU12: =AR12+AS12 -> 27467.245 | AW12: 5 | AX12: 44986 | AY12: =BG11 -> 764502.26 | AZ12: =AZ11 -> 5361.5769 | BA12: =AZ12-BC12 -> 583.43771 | BB12: =(BA12/AY12)*12 -> 0.0091579225 | BC12: =AY12*($AX$3/12) -> 4778.1391 | BD12: =(BC12/AY12)*12 -> 0.075 | BE12: =BE11+BA12 -> 2881.1746 | BF12: =BF11+BC12 -> 23926.71 | BG12: =AY12-BA12 -> 763918.83 | BH12: =BE12+BF12 -> 26807.884 | BJ12: 5 | BK12: 44986 | BL12: =BT11 -> 764385.52 | BM12: =BM11 -> 5230.9277 | BN12: =BM12-BP12 -> 612.76521 | BO12: =(BN12/BL12)*12 -> 0.0096197303 | BP12: =BL12*($BK$3/12) -> 4618.1625 | BQ12: =(BP12/BL12)*12 -> 0.0725 | BR12: =BR11+BN12 -> 3027.2475 | BS12: =BS11+BP12 -> 23127.391 | BT12: =BL12-BN12 -> 763772.75 | BU12: =BR12+BS12 -> 26154.639 | BW12: 5 | BX12: 44986 | BY12: =CG11 -> 764263.76 | BZ12: =BZ11 -> 5101.5395 | CA12: =BZ12-CC12 -> 643.33428 | CB12: =(CA12/BY12)*12 -> 0.01010124 | CC12: =BY12*($BX$3/12) -> 4458.2053 | CD12: =(CC12/BY12)*12 -> 0.07 | CE12: =CE11+CA12 -> 3179.577 | CF12: =CF11+CC12 -> 22328.121 | CG12: =BY12-CA12 -> 763620.42 | CH12: =CE12+CF12 -> 25507.698
A13: =A12+1 -> 3 | B13: =VLOOKUP(A13*12,$J$7:$U$367,10) -> 187490.38 | C13: =VLOOKUP(A13*12,$W$7:$AH$367,10) -> 181698.42 | D13: =VLOOKUP(A13*12,$AJ$7:$AU$367,10) -> 175908.87 | E13: =VLOOKUP(A13*12,$AW$7:$BH$367,10) -> 170122.02 | F13: =VLOOKUP(A13*12,$BJ$7:$BU$367,10) -> 164338.21 | G13: =VLOOKUP(A13*12,$BW$7:$CH$367,10) -> 158557.78 | J13: 6 | K13: 45017 | L13: =T12 -> 764321.34 | M13: =$L$8/((($N$4)-1)/($N$3*$N$4)) -> 5760.7123 | N13: =M13-P13 -> 506.00311 | O13: =(N13/L13)*12 -> 0.0079443513 | P13: =L13*($K$3/12) -> 5254.7092 | Q13: =(P13/L13)*12 -> 0.0825 | R13: =R12+N13 -> 2984.6628 | S13: =S12+P13 -> 31579.611 | T13: =L13-N13 -> 763815.34 | U13: =R13+S13 -> 34564.274 | W13: 6 | X13: 45017 | Y13: =AG12 -> 764192.94 | Z13: =Z12 -> 5626.5068 | AA13: =Z13-AC13 -> 531.88718 | AB13: =(AA13/Y13)*12 -> 0.0083521396 | AC13: =Y13*($X$3/12) -> 5094.6196 | AD13: =(AC13/Y13)*12 -> 0.08 | AE13: =AE12+AA13 -> 3138.9508 | AF13: =AF12+AC13 -> 30620.09 | AG13: =Y13-AA13 -> 763661.05 | AH13: =AE13+AF13 -> 33759.041 | AJ13: 6 | AK13: 45017 | AL13: =AT12 -> 764058.83 | AM13: =AM12 -> 5493.4491 | AN13: =AM13-AP13 -> 558.90252 | AO13: =(AN13/AL13)*12 -> 0.0087778977 | AP13: =AL13*($AK$3/12) -> 4934.5466 | AQ13: =(AP13/AL13)*12 -> 0.0775 | AR13: =AR12+AN13 -> 3300.0769 | AS13: =AS12+AP13 -> 29660.618 | AT13: =AL13-AN13 -> 763499.92 | AU13: =AR13+AS13 -> 32960.695 | AW13: 6 | AX13: 45017 | AY13: =BG12 -> 763918.83 | AZ13: =AZ12 -> 5361.5769 | BA13: =AZ13-BC13 -> 587.08419 | BB13: =(BA13/AY13)*12 -> 0.0092221975 | BC13: =AY13*($AX$3/12) -> 4774.4927 | BD13: =(BC13/AY13)*12 -> 0.075 | BE13: =BE12+BA13 -> 3468.2587 | BF13: =BF12+BC13 -> 28701.202 | BG13: =AY13-BA13 -> 763331.74 | BH13: =BE13+BF13 -> 32169.461 | BJ13: 6 | BK13: 45017 | BL13: =BT12 -> 763772.75 | BM13: =BM12 -> 5230.9277 | BN13: =BM13-BP13 -> 616.46734 | BO13: =(BN13/BL13)*12 -> 0.009685614 | BP13: =BL13*($BK$3/12) -> 4614.4604 | BQ13: =(BP13/BL13)*12 -> 0.0725 | BR13: =BR12+BN13 -> 3643.7148 | BS13: =BS12+BP13 -> 27741.851 | BT13: =BL13-BN13 -> 763156.29 | BU13: =BR13+BS13 -> 31385.566 | BW13: 6 | BX13: 45017 | BY13: =CG12 -> 763620.42 | BZ13: =BZ12 -> 5101.5395 | CA13: =BZ13-CC13 -> 647.08707 | CB13: =(CA13/BY13)*12 -> 0.010168723 | CC13: =BY13*($BX$3/12) -> 4454.4525 | CD13: =(CC13/BY13)*12 -> 0.07 | CE13: =CE12+CA13 -> 3826.664 | CF13: =CF12+CC13 -> 26782.573 | CG13: =BY13-CA13 -> 762973.34 | CH13: =CE13+CF13 -> 30609.237
A14: =A13+1 -> 4 | B14: =VLOOKUP(A14*12,$J$7:$U$367,10) -> 248819.48 | C14: =VLOOKUP(A14*12,$W$7:$AH$367,10) -> 241079.91 | D14: =VLOOKUP(A14*12,$AJ$7:$AU$367,10) -> 233344.88 | E14: =VLOOKUP(A14*12,$AW$7:$BH$367,10) -> 225614.94 | F14: =VLOOKUP(A14*12,$BJ$7:$BU$367,10) -> 217890.67 | G14: =VLOOKUP(A14*12,$BW$7:$CH$367,10) -> 210172.71 | J14: 7 | K14: 45047 | L14: =T13 -> 763815.34 | M14: =$L$8/((($N$4)-1)/($N$3*$N$4)) -> 5760.7123 | N14: =M14-P14 -> 509.48188 | O14: =(N14/L14)*12 -> 0.0080042678 | P14: =L14*($K$3/12) -> 5251.2304 | Q14: =(P14/L14)*12 -> 0.0825 | R14: =R13+N14 -> 3494.1446 | S14: =S13+P14 -> 36830.842 | T14: =L14-N14 -> 763305.86 | U14: =R14+S14 -> 40324.986 | W14: 7 | X14: 45047 | Y14: =AG13 -> 763661.05 | Z14: =Z13 -> 5626.5068 | AA14: =Z14-AC14 -> 535.43309 | AB14: =(AA14/Y14)*12 -> 0.0084136766 | AC14: =Y14*($X$3/12) -> 5091.0737 | AD14: =(AC14/Y14)*12 -> 0.08 | AE14: =AE13+AA14 -> 3674.3839 | AF14: =AF13+AC14 -> 35711.163 | AG14: =Y14-AA14 -> 763125.62 | AH14: =AE14+AF14 -> 39385.547 | AJ14: 7 | AK14: 45047 | AL14: =AT13 -> 763499.92 | AM14: =AM13 -> 5493.4491 | AN14: =AM14-AP14 -> 562.5121 | AO14: =(AN14/AL14)*12 -> 0.0088410554 | AP14: =AL14*($AK$3/12) -> 4930.937 | AQ14: =(AP14/AL14)*12 -> 0.0775 | AR14: =AR13+AN14 -> 3862.589 | AS14: =AS13+AP14 -> 34591.555 | AT14: =AL14-AN14 -> 762937.41 | AU14: =AR14+AS14 -> 38454.144 | AW14: 7 | AX14: 45047 | AY14: =BG13 -> 763331.74 | AZ14: =AZ13 -> 5361.5769 | BA14: =AZ14-BC14 -> 590.75347 | BB14: =(BA14/AY14)*12 -> 0.0092869735 | BC14: =AY14*($AX$3/12) -> 4770.8234 | BD14: =(BC14/AY14)*12 -> 0.075 | BE14: =BE13+BA14 -> 4059.0122 | BF14: =BF13+BC14 -> 33472.026 | BG14: =AY14-BA14 -> 762740.99 | BH14: =BE14+BF14 -> 37531.038 | BJ14: 7 | BK14: 45047 | BL14: =BT13 -> 763156.29 | BM14: =BM13 -> 5230.9277 | BN14: =BM14-BP14 -> 620.19183 | BO14: =(BN14/BL14)*12 -> 0.0097520024 | BP14: =BL14*($BK$3/12) -> 4610.7359 | BQ14: =(BP14/BL14)*12 -> 0.0725 | BR14: =BR13+BN14 -> 4263.9066 | BS14: =BS13+BP14 -> 32352.587 | BT14: =BL14-BN14 -> 762536.09 | BU14: =BR14+BS14 -> 36616.494 | BW14: 7 | BX14: 45047 | BY14: =CG13 -> 762973.34 | BZ14: =BZ13 -> 5101.5395 | CA14: =BZ14-CC14 -> 650.86174 | CB14: =(CA14/BY14)*12 -> 0.010236715 | CC14: =BY14*($BX$3/12) -> 4450.6778 | CD14: =(CC14/BY14)*12 -> 0.07 | CE14: =CE13+CA14 -> 4477.5258 | CF14: =CF13+CC14 -> 31233.251 | CG14: =BY14-CA14 -> 762322.47 | CH14: =CE14+CF14 -> 35710.777
